Workbook

Sheet 00_使用说明
A1: T01-03 | 使用说明
A2: 编制基线 · 2026-09-26 | 第4份复查优先；用户明确答复与全局定案优先 | 设计资料，未接入游戏
A3: 返回说明 | B3: 39 条记录 | 表头可筛选 | 依据中的B1／B2／B3／R4／Q01与原行号可回查12表
A5: 记录ID | B5: 类别 | C5: 主题／分表 | D5: 说明 | E5: 记录性质 | F5: 依据
A6: U01 | B6: 定位 | C6: 本文件职责 | D6: 规定不同品级使用既有机制的深度、边界与审查要求；不充当完整强度评分公式。 | E6: 本次编制基线 | F6: B3§二十八 L812–835
A7: U02 | B7: 来源优先级 | C7: 三批＋第4份复查 | D7: 第4份复查及用户最新定案优先。2026-09-29共鸣同步为结丹10／元婴20／化神30；原文旧门槛已覆盖，历史原话保留。 | E7: 用户指定 | F7: 本轮用户请求；R4
A8: U03 | B8: 权威入口 | C8: 02_能力权限主表 | D8: 只在能力主表维护品级权限。03～05是按能力ID自动引用的矩阵视图；不独立手改。 | E8: 编制结构 | F8: R4§七 L252–286
A9: U04 | B9: 参照 | C9: 与前两词典分工 | D9: 01负责机制语言，02负责状态／控制语义，03负责品级深度；具体规则按核心定案与前两份词典。 | E9: 本次编制基线 | F9: B3§二十八 L812–835
A10: U05 | B10: 概念 | C10: 品级≠境界／稀有度／强化／剧情地位 | D10: 四者分列；有剧情、数值大或效果多，都不足以自动提高机制品级。 | E10: 本次编制基线 | F10: B1§一 L16–95
A11: U06 | B11: 符号 | C11: ◎ 核心常规 | D11: 本品级可常规使用的核心设计空间；不表示每件物品都必须使用。 | E11: 符号定义 | F11: B3§一 L18–40
A12: U07 | B12: 符号 | C12: ○ 正常辅助 | D12: 允许作为正常辅助机制；与◎都属于常规许可。 | E12: 符号定义 | F12: B3§一 L18–40
A13: U08 | B13: 符号 | C13: △ 少量候选 | D13: 不作为常规最低品级的依据；必须描述范围、次数、节奏与理由，不能只写“很轻”。不代表具体资产已批准。 | E13: 符号定义 | F13: B3§一 L18–40；R4§七 L252–286
A14: U09 | B14: 符号 | C14: ◇ 明确例外 | D14: 该品级仅在具体物品例外被确认后可用；当前没有因本表而自动批准的物品例外。 | E14: 符号定义 | F14: B3§一 L18–40；R4§十二 L422–446
A15: U10 | B15: 符号 | C15: — 非常规空间 | D15: 普通物品不进入；不是程序不支持，也不因一件例外变成新常规。 | E15: 符号定义 | F15: B3§一 L18–40；B3§十八 L548–569
A16: U11 | B16: 符号 | C16: ? 待专项／停用／基础 | D16: ?为原稿有分歧或未给起点；停用不可生成；基础为所有品级继承的后台规则，不是特色词条。 | E16: 编制标记 | F16: 核心01§1.8；R4§九 L312–355
... A44: U25 | B44: 状态口径 | C44: 编制基线与正式资产 | D44: 前三批与复查构成词典编制基线；不冒称每个符号都经过用户逐项确认。专案、候选、未定项须随资产再审。 | E44: 使用边界 | F44: 本轮编制

Sheet 01_品级总纲
A1: T01-03 | 品级总纲
A2: 编制基线 · 2026-09-26 | 第4份复查优先；用户明确答复与全局定案优先 | 设计资料，未接入游戏
A3: 返回说明 | B3: 7 条记录 | 表头可筛选 | 依据中的B1／B2／B3／R4／Q01与原行号可回查12表
A5: 品级 | B5: 复杂度参考 | C5: 核心定位 | D5: 玩家认知／玩法 | E5: 常规使用门槛 | F5: 设计预算与取舍 | G5: 禁止误读／边界 | H5: 依据
A6: 下品 | B6: L0 | C6: 无属性基础器具 | D6: 认识器具类别及基础参数取舍 | E6: 凡人可用 | F6: 同阶段比较速度、命中、费用、占格等 | G6: 不做特色状态／控制／邻接／来源玩法 | H6: B1§十一 L443–466～十六；R4§九 L312–355
A7: 凡品 | B7: L0～L1 | C7: 固定单元素与一种简单状态可组合 | D7: 认识属性与状态 | E7: 凡人可用 | F7: 允许简单数值差异，不以Effect行数定级 | G7: 凡品开放固定单元素＋一种简单状态；不据此开放双状态、复杂监听、来源改写、自由功能槽。 | H7: 原编制基线；t01-08凡品第2／3批与用户直接更正、FP02；2026-09-28
A8: 良品 | B8: L1～L2 | C8: 一个清楚、可搭配的特色机制 | D8: 简单监听／计数／读状态／邻接 | E8: 炼气起 | F8: 通常一个机制中心，不能靠低数值掩盖高规则权限 | G8: 公共状态转换、他器当前CD和敌器控制不因“轻”字常规下放 | H8: B1§二十六 L780–800～三十六；R4§七 L252–286
A9: 上品 | B9: L2～L3 | C9: 一个成熟的局部构筑核心 | D9: 管理状态兑现、领域、恢复防护或控制 | E9: 筑基起 | F9: 一个主中心及少量支撑；投入随概念同步审查 | G9: 不默认为局部共享池常规品级；给另一武器赋固定元素在此开放 | H9: B2§二 L32–45～八；R4§七 L252–286；Q01 L3–5
A10: 灵品 | B10: L3～L4 | C10: 两个成熟机制实质耦合 | D10: 单向联动／取舍／阶段衔接／反馈 | E10: 结丹起 | F10: 通常1～2个观察变量；检查双方有独立玩法 | G10: 不要求闭环；不把“3次攻击→火球”一个中心误判为双核心 | H10: R4§五 L181–224；B2§九 L272–287～十七
A11: 玄品 | B11: L4～L5 | C11: 在明确范围内改变规则 | D11: 发动、来源、阵式或连携规则核心 | E11: 元婴起 | F11: 通常一个规则核心加1～2个支撑 | G11: 权限不自动豁免全局限制；有限次数不降低规则权力层级 | H11: B2§十八 L519–536～二十六；R4§七 L252–286
A12: 仙品 | B12: 按当前成长阶段，无L6 | C12: 专属身份＋长期成长＋代表性能力 | D12: 独特战术选择，能力与边界成对设计 | E12: 按各成长阶段条件；不统一等化神 | F12: 按同阶段、同阵位及投入比较；不必始终强过玄品 | G12: 六项对照与档案见10表；“开场择相甲”仅工作名和标杆方向 | H12: R4§一 L9–37～四、八；B2§二十七 L741–760～三十四

Sheet 02_能力权限主表
A1: T01-03 | 能力权限主表
A2: 编制基线 · 2026-09-26 | 第4份复查优先；用户明确答复与全局定案优先 | 设计资料，未接入游戏
A3: 返回说明 | B3: 103 条记录 | 表头可筛选 | 依据中的B1／B2／B3／R4／Q01与原行号可回查12表
A5: 能力ID | B5: 能力名称 | C5: 常规最低品级 | D5: 下品 | E5: 凡品 | F5: 良品 | G5: 上品 | H5: 灵品 | I5: 玄品 | J5: 仙品 | K5: 基础／特色 | L5: 权限边界 | M5: 前置／未决 | N5: 规则状态 | O5: 已确认例外 | P5: 依据
A6: C001 | B6: 基础攻击／防护／恢复 | C6: =IF(D6="停用","停用",IF(D6="基础","全品级基础",IF(OR(D6="◎",D6="○"),D$5,IF(OR(E6="◎",E6="○"),E$5,IF(OR(F6="◎",F6="○"),F$5,IF(OR(G6="◎",G6="○"),G$5,IF(OR(H6="◎",H6="○"),H$5,IF(OR(I6="◎",I6="○"),I$5,"未设常规起点")))))))) -> 下品 | D6: ◎ | E6: ◎ | F6: ◎ | G6: ◎ | H6: ◎ | I6: ◎ | J6: 专案 | K6: 基础动作 | L6: 作为器具类别主体动作；下品无七属性、无状态联动。伤害包只有一种Attack_Type，Element与来源另记，不以品级豁免唯一类型规则。 | M6: 按具体资产填写参数 | N6: 编制基线；全局规则优先 | O6: 无已确认物品例外 | P6: B1§十二 L467–509；B3§三 L65–128
A7: C002 | B7: 基础参数与类别固有标签 | C7: =IF(D7="停用","停用",IF(D7="基础","全品级基础",IF(OR(D7="◎",D7="○"),D$5,IF(OR(E7="◎",E7="○"),E$5,IF(OR(F7="◎",F7="○"),F$5,IF(OR(G7="◎",G7="○"),G$5,IF(OR(H7="◎",H7="○"),H$5,IF(OR(I7="◎",I7="○"),I$5,"未设常规起点")))))))) -> 下品 | D7: ◎ | E7: ◎ | F7: ◎ | G7: ◎ | H7: ◎ | I7: ◎ | J7: 专案 | K7: 基础规格 | L7: 攻击、CD、命中、费用、护甲、占格、物理甲型等；参数差异不自动增加机制中心。 | M7: 按具体资产填写参数 | N7: 编制基线；全局规则优先 | O7: 无已确认物品例外 | P7: B1§八 L371–398；B1§十二 L467–509
A8: C003 | B8: 基础轮转与手动／自动模式 | C8: =IF(D8="停用","停用",IF(D8="基础","全品级基础",IF(OR(D8="◎",D8="○"),D$5,IF(OR(E8="◎",E8="○"),E$5,IF(OR(F8="◎",F8="○"),F$5,IF(OR(G8="◎",G8="○"),G$5,IF(OR(H8="◎",H8="○"),H$5,IF(OR(I8="◎",I8="○"),I$5,"未设常规起点")))))))) -> 下品 | D8: ◎ | E8: ◎ | F8: ◎ | G8: ◎ | H8: ◎ | I8: ◎ | J8: 专案 | K8: 基础动作 | L8: 正常发动仍检查目标、资源、控制等；不可用低品级理由省略后台判断。 | M8: 按具体资产填写参数 | N8: 编制基线；全局规则优先 | O8: 无已确认物品例外 | P8: B3§三 L65–128；核心01§1.4
A9: C004 | B9: 标准事件、叠加与资格检查 | C9: =IF(D9="停用","停用",IF(D9="基础","全品级基础",IF(OR(D9="◎",D9="○"),D$5,IF(OR(E9="◎",E9="○"),E$5,IF(OR(F9="◎",F9="○"),F$5,IF(OR(G9="◎",G9="○"),G$5,IF(OR(H9="◎",H9="○"),H$5,IF(OR(I9="◎",I9="○"),I$5,"未设常规起点")))))))) -> 全品级基础 | D9: 基础 | E9: 基础 | F9: 基础 | G9: 基础 | H9: 基础 | I9: 基础 | J9: 基础 | K9: 后台必备 | L9: 所有器具都产生合法事件并遵守基础叠加、去重、暴击与命中规则；不等于带特色监听词条。 | M9: 按具体资产填写参数 | N9: 编制基线；全局规则优先 | O9: 无已确认物品例外 | P9: R4§九 L312–355；B3§三 L65–128
A10: C005 | B10: 真实来源记录与显示 | C10: =IF(D10="停用","停用",IF(D10="基础","全品级基础",IF(OR(D10="◎",D10="○"),D$5,IF(OR(E10="◎",E10="○"),E$5,IF(OR(F10="◎",F10="○"),F$5,IF(OR(G10="◎",G10="○"),G$5,IF(OR(H10="◎",H10="○"),H$5,IF(OR(I10="◎",I10="○"),I$5,"未设常规起点")))))))) -> 全品级基础 | D10: 基础 | E10: 基础 | F10: 基础 | G10: 基础 | H10: 基础 | I10: 基础 | J10: 基础 | K10: 后台必备 | L10: 记录真实施加者、器具、效果与因果；不因任何品级省略或伪装。 | M10: 按具体资产填写参数 | N10: 编制基线；全局规则优先 | O10: 无已确认物品例外 | P10: B3§十二 L359–390
A11: C006 | B11: 器具固定自带单一元素属性 | C11: =IF(D11="停用","停用",IF(D11="基础","全品级基础",IF(OR(D11="◎",D11="○"),D$5,IF(OR(E11="◎",E11="○"),E$5,IF(OR(F11="◎",F11="○"),F$5,IF(OR(G11="◎",G11="○"),G$5,IF(OR(H11="◎",H11="○"),H$5,IF(OR(I11="◎",I11="○"),I$5,"未设常规起点")))))))) -> 凡品 | D11: — | E11: ◎ | F11: ◎ | G11: ◎ | H11: ◎ | I11: ◎ | J11: 专案 | K11: 特色权限 | L11: 凡品开始允许，仍可设计无属性高品级；固定属性不等于独立附伤包。 | M11: 按具体资产填写参数 | N11: 编制基线；全局规则优先 | O11: 无已确认物品例外 | P11: B1§十九 L636–661；R4§九 L312–355
A12: C007 | B12: 固定双属性／复合标签（攻击／检索） | C12: =IF(D12="停用","停用",IF(D12="基础","全品级基础",IF(OR(D12="◎",D12="○"),D$5,IF(OR(E12="◎",E12="○"),E$5,IF(OR(F12="◎",F12="○"),F$5,IF(OR(G12="◎",G12="○"),G$5,IF(OR(H12="◎",H12="○"),H$5,IF(OR(I12="◎",I12="○"),I$5,"未设常规起点")))))))) -> 良品 | D12: — | E12: △ | F12: ○ | G12: ◎ | H12: ◎ | I12: ◎ | J12: 专案 | K12: 特色权限 | L12: 仅按适用攻击元素或检索标签使用，保留合规多元素攻击；不授权同一防具同时拥有多个当前防御元素，不授权同一伤害包具有多个Attack Type。不自动改写来源；须明确各伤害包、元素分量及基础规则。 | M12: 按具体资产填写参数 | N12: 编制基线；全局规则优先 | O12: 无已确认物品例外 | P12: B3§十二 L359–390
A13: C008 | B13: 临时给另一武器赋予固定元素 | C13: =IF(D13="停用","停用",IF(D13="基础","全品级基础",IF(OR(D13="◎",D13="○"),D$5,IF(OR(E13="◎",E13="○"),E$5,IF(OR(F13="◎",F13="○"),F$5,IF(OR(G13="◎",G13="○"),G$5,IF(OR(H13="◎",H13="○"),H$5,IF(OR(I13="◎",I13="○"),I$5,"未设常规起点")))))))) -> 上品 | D13: — | E13: — | F13: — | G13: ◎ | H13: ◎ | I13: ◎ | J13: 专案 | K13: 特色权限 | L13: 用户确认上品常规起点；是否替换原属性或追加属性须由资产明确，不自动获得来源或连携资格。 | M13: 附加／替换、目标、持续、费用待具体资产 | N13: 用户已定起点；参数待资产 | O13: 无已确认物品例外 | P13: Q01 L3–5；R4§九 L312–355
A14: C009 | B14: 受限自主选择固定身份／配置 | C14: =IF(D14="停用","停用",IF(D14="基础","全品级基础",IF(OR(D14="◎",D14="○"),D$5,IF(OR(E14="◎",E14="○"),E$5,IF(OR(F14="◎",F14="○"),F$5,IF(OR(G14="◎",G14="○"),G$5,IF(OR(H14="◎",H14="○"),H$5,IF(OR(I14="◎",I14="○"),I$5,"未设常规起点")))))))) -> 未设常规起点 | D14: ? | E14: ? | F14: ? | G14: ? | H14: ? | I14: ? | J14: 专案 | K14: 特色权限 | L14: 仙品择相是参考方向；其他品级的自主改换能力未给统一起点，不能从固定属性行推导。 | M14: 非仙品适用起点待具体方案；仙品按六项标准 | N14: 编制基线；含待专项单元格 | O14: 无已确认物品例外 | P14: R4§二 L38–119；R4§六 L225–251；R4§九 L312–355
A15: C010 | B15: 元素攻击与额外状态等独立收益组合 | C15: =IF(D15="停用","停用",IF(D15="基础","全品级基础",IF(OR(D15="◎",D15="○"),D$5,IF(OR(E15="◎",E15="○"),E$5,IF(OR(F15="◎",F15="○"),F$5,IF(OR(G15="◎",G15="○"),G$5,IF(OR(H15="◎",H15="○"),H$5,IF(OR(I15="◎",I15="○"),I$5,"未设常规起点")))))))) -> 凡品 | D15: — | E15: ○ | F15: ○ | G15: ◎ | H15: ◎ | I15: ◎ | J15: 专案 | K15: 特色权限 | L15: 凡品常规允许固定单元素＋一种简单状态的组合，仍按各状态已定触发门槛与容量；不顺带开放双状态、复杂监听、来源改写或自由功能槽。其他多份独立收益组合仍须审查。 | M15: 按具体资产填写参数 | N15: 本次08覆盖旧“凡品少量候选、良品常规”口径，许可限本行明确范围。 | O15: 无已确认物品例外 | P15: R4§七历史口径；t01-08凡品第2／3批与用户直接更正、FP02；2026-09-28
A16: C011 | B16: 简单条件发动 | C16: =IF(D16="停用","停用",IF(D16="基础","全品级基础",IF(OR(D16="◎",D16="○"),D$5,IF(OR(E16="◎",E16="○"),E$5,IF(OR(F16="◎",F16="○"),F$5,IF(OR(G16="◎",G16="○"),G$5,IF(OR(H16="◎",H16="○"),H$5,IF(OR(I16="◎",I16="○"),I$5,"未设常规起点")))))))) -> 良品 | D16: — | E16: △ | F16: ◎ | G16: ◎ | H16: ◎ | I16: ◎ | J16: 专案 | K16: 特色权限 | L16: 一条直观条件；凡品限极简单特定候选，不扩展成计数／状态兑现链。 | M16: 按具体资产填写参数 | N16: 编制基线；全局规则优先 | O16: 无已确认物品例外 | P16: B3§三 L65–128
A17: C012 | B17: 待发／预备式 | C17: =IF(D17="停用","停用",IF(D17="基础","全品级基础",IF(OR(D17="◎",D17="○"),D$5,IF(OR(E17="◎",E17="○"),E$5,IF(OR(F17="◎",F17="○"),F$5,IF(OR(G17="◎",G17="○"),G$5,IF(OR(H17="◎",H17="○"),H$5,IF(OR(I17="◎",I17="○"),I$5,"未设常规起点")))))))) -> 良品 | D17: — | E17: △ | F17: ○ | G17: ◎ | H17: ◎ | I17: ◎ | J17: 专案 | K17: 特色权限 | L17: 等待资格与支付时点按01；已定冻结／禁用／沉默对旧待发资格的处理继续生效。 | M17: 按具体资产填写参数 | N17: 编制基线；全局规则优先 | O17: 无已确认物品例外 | P17: B3§三 L65–128；核心01§1.4、§1.8
... A108: C103 | B108: 简单静态附加数值 | C108: =IF(D108="停用","停用",IF(D108="基础","全品级基础",IF(OR(D108="◎",D108="○"),D$5,IF(OR(E108="◎",E108="○"),E$5,IF(OR(F108="◎",F108="○"),F$5,IF(OR(G108="◎",G108="○"),G$5,IF(OR(H108="◎",H108="○"),H$5,IF(OR(I108="◎",I108="○"),I$5,"未设常规起点")))))))) -> 凡品 | D108: — | E108: ◎ | F108: ◎ | G108: ◎ | H108: ◎ | I108: ◎ | J108: 专案 | K108: 特色权限 | L108: 凡品可直接提高某项数值；状态条件、事件计数与按层动态收益另查。数值大小仍须预算。 | M108: 按具体资产填写参数 | N108: 编制基线；全局规则优先 | O108: 无已确认物品例外 | P108: B1§二十三 L724–739

Sheet 03_M机制权限
A1: T01-03 | M机制权限
A2: 按能力ID引用02主表；排序不改变对应关系。◎核心 ○常规辅助 △有限候选 ◇明确例外 —非常规 ?待专项；仙品看10表。
A3: 返回说明 | B3: 164 条记录 | 表头可筛选 | 依据中的B1／B2／B3／R4／Q01与原行号可回查12表
A5: 模块 | B5: 能力ID | C5: 能力名称 | D5: 常规最低品级 | E5: 下品 | F5: 凡品 | G5: 良品 | H5: 上品 | I5: 灵品 | J5: 玄品 | K5: 仙品 | L5: 权限边界 | M5: 前置／未决 | N5: 规则状态 | O5: 依据
A6: M01 发动范式 | B6: C003 | C6: =INDEX('02_能力权限主表'!$B$6:$B$108,MATCH($B6,'02_能力权限主表'!$A$6:$A$108,0)) -> 基础轮转与手动／自动模式 | D6: =INDEX('02_能力权限主表'!$C$6:$C$108,MATCH($B6,'02_能力权限主表'!$A$6:$A$108,0)) -> 下品 | E6: =INDEX('02_能力权限主表'!$D$6:$D$108,MATCH($B6,'02_能力权限主表'!$A$6:$A$108,0)) -> ◎ | F6: =INDEX('02_能力权限主表'!$E$6:$E$108,MATCH($B6,'02_能力权限主表'!$A$6:$A$108,0)) -> ◎ | G6: =INDEX('02_能力权限主表'!$F$6:$F$108,MATCH($B6,'02_能力权限主表'!$A$6:$A$108,0)) -> ◎ | H6: =INDEX('02_能力权限主表'!$G$6:$G$108,MATCH($B6,'02_能力权限主表'!$A$6:$A$108,0)) -> ◎ | I6: =INDEX('02_能力权限主表'!$H$6:$H$108,MATCH($B6,'02_能力权限主表'!$A$6:$A$108,0)) -> ◎ | J6: =INDEX('02_能力权限主表'!$I$6:$I$108,MATCH($B6,'02_能力权限主表'!$A$6:$A$108,0)) -> ◎ | K6: =INDEX('02_能力权限主表'!$J$6:$J$108,MATCH($B6,'02_能力权限主表'!$A$6:$A$108,0)) -> 专案 | L6: =INDEX('02_能力权限主表'!$L$6:$L$108,MATCH($B6,'02_能力权限主表'!$A$6:$A$108,0)) -> 正常发动仍检查目标、资源、控制等；不可用低品级理由省略后台判断。 | M6: =INDEX('02_能力权限主表'!$M$6:$M$108,MATCH($B6,'02_能力权限主表'!$A$6:$A$108,0)) -> 按具体资产填写参数 | N6: =INDEX('02_能力权限主表'!$N$6:$N$108,MATCH($B6,'02_能力权限主表'!$A$6:$A$108,0)) -> 编制基线；全局规则优先 | O6: =INDEX('02_能力权限主表'!$P$6:$P$108,MATCH($B6,'02_能力权限主表'!$A$6:$A$108,0)) -> B3§三 L65–128；核心01§1.4
A7: M01 发动范式 | B7: C011 | C7: =INDEX('02_能力权限主表'!$B$6:$B$108,MATCH($B7,'02_能力权限主表'!$A$6:$A$108,0)) -> 简单条件发动 | D7: =INDEX('02_能力权限主表'!$C$6:$C$108,MATCH($B7,'02_能力权限主表'!$A$6:$A$108,0)) -> 良品 | E7: =INDEX('02_能力权限主表'!$D$6:$D$108,MATCH($B7,'02_能力权限主表'!$A$6:$A$108,0)) -> — | F7: =INDEX('02_能力权限主表'!$E$6:$E$108,MATCH($B7,'02_能力权限主表'!$A$6:$A$108,0)) -> △ | G7: =INDEX('02_能力权限主表'!$F$6:$F$108,MATCH($B7,'02_能力权限主表'!$A$6:$A$108,0)) -> ◎ | H7: =INDEX('02_能力权限主表'!$G$6:$G$108,MATCH($B7,'02_能力权限主表'!$A$6:$A$108,0)) -> ◎ | I7: =INDEX('02_能力权限主表'!$H$6:$H$108,MATCH($B7,'02_能力权限主表'!$A$6:$A$108,0)) -> ◎ | J7: =INDEX('02_能力权限主表'!$I$6:$I$108,MATCH($B7,'02_能力权限主表'!$A$6:$A$108,0)) -> ◎ | K7: =INDEX('02_能力权限主表'!$J$6:$J$108,MATCH($B7,'02_能力权限主表'!$A$6:$A$108,0)) -> 专案 | L7: =INDEX('02_能力权限主表'!$L$6:$L$108,MATCH($B7,'02_能力权限主表'!$A$6:$A$108,0)) -> 一条直观条件；凡品限极简单特定候选，不扩展成计数／状态兑现链。 | M7: =INDEX('02_能力权限主表'!$M$6:$M$108,MATCH($B7,'02_能力权限主表'!$A$6:$A$108,0)) -> 按具体资产填写参数 | N7: =INDEX('02_能力权限主表'!$N$6:$N$108,MATCH($B7,'02_能力权限主表'!$A$6:$A$108,0)) -> 编制基线；全局规则优先 | O7: =INDEX('02_能力权限主表'!$P$6:$P$108,MATCH($B7,'02_能力权限主表'!$A$6:$A$108,0)) -> B3§三 L65–128
A8: M01 发动范式 | B8: C012 | C8: =INDEX('02_能力权限主表'!$B$6:$B$108,MATCH($B8,'02_能力权限主表'!$A$6:$A$108,0)) -> 待发／预备式 | D8: =INDEX('02_能力权限主表'!$C$6:$C$108,MATCH($B8,'02_能力权限主表'!$A$6:$A$108,0)) -> 良品 | E8: =INDEX('02_能力权限主表'!$D$6:$D$108,MATCH($B8,'02_能力权限主表'!$A$6:$A$108,0)) -> — | F8: =INDEX('02_能力权限主表'!$E$6:$E$108,MATCH($B8,'02_能力权限主表'!$A$6:$A$108,0)) -> △ | G8: =INDEX('02_能力权限主表'!$F$6:$F$108,MATCH($B8,'02_能力权限主表'!$A$6:$A$108,0)) -> ○ | H8: =INDEX('02_能力权限主表'!$G$6:$G$108,MATCH($B8,'02_能力权限主表'!$A$6:$A$108,0)) -> ◎ | I8: =INDEX('02_能力权限主表'!$H$6:$H$108,MATCH($B8,'02_能力权限主表'!$A$6:$A$108,0)) -> ◎ | J8: =INDEX('02_能力权限主表'!$I$6:$I$108,MATCH($B8,'02_能力权限主表'!$A$6:$A$108,0)) -> ◎ | K8: =INDEX('02_能力权限主表'!$J$6:$J$108,MATCH($B8,'02_能力权限主表'!$A$6:$A$108,0)) -> 专案 | L8: =INDEX('02_能力权限主表'!$L$6:$L$108,MATCH($B8,'02_能力权限主表'!$A$6:$A$108,0)) -> 等待资格与支付时点按01；已定冻结／禁用／沉默对旧待发资格的处理继续生效。 | M8: =INDEX('02_能力权限主表'!$M$6:$M$108,MATCH($B8,'02_能力权限主表'!$A$6:$A$108,0)) -> 按具体资产填写参数 | N8: =INDEX('02_能力权限主表'!$N$6:$N$108,MATCH($B8,'02_能力权限主表'!$A$6:$A$108,0)) -> 编制基线；全局规则优先 | O8: =INDEX('02_能力权限主表'!$P$6:$P$108,MATCH($B8,'02_能力权限主表'!$A$6:$A$108,0)) -> B3§三 L65–128；核心01§1.4、§1.8
A9: M01 发动范式 | B9: C013 | C9: =INDEX('02_能力权限主表'!$B$6:$B$108,MATCH($B9,'02_能力权限主表'!$A$6:$A$108,0)) -> 简单延迟生效 | D9: =INDEX('02_能力权限主表'!$C$6:$C$108,MATCH($B9,'02_能力权限主表'!$A$6:$A$108,0)) -> 良品 | E9: =INDEX('02_能力权限主表'!$D$6:$D$108,MATCH($B9,'02_能力权限主表'!$A$6:$A$108,0)) -> — | F9: =INDEX('02_能力权限主表'!$E$6:$E$108,MATCH($B9,'02_能力权限主表'!$A$6:$A$108,0)) -> △ | G9: =INDEX('02_能力权限主表'!$F$6:$F$108,MATCH($B9,'02_能力权限主表'!$A$6:$A$108,0)) -> ○ | H9: =INDEX('02_能力权限主表'!$G$6:$G$108,MATCH($B9,'02_能力权限主表'!$A$6:$A$108,0)) -> ◎ | I9: =INDEX('02_能力权限主表'!$H$6:$H$108,MATCH($B9,'02_能力权限主表'!$A$6:$A$108,0)) -> ◎ | J9: =INDEX('02_能力权限主表'!$I$6:$I$108,MATCH($B9,'02_能力权限主表'!$A$6:$A$108,0)) -> ◎ | K9: =INDEX('02_能力权限主表'!$J$6:$J$108,MATCH($B9,'02_能力权限主表'!$A$6:$A$108,0)) -> 专案 | L9: =INDEX('02_能力权限主表'!$L$6:$L$108,MATCH($B9,'02_能力权限主表'!$A$6:$A$108,0)) -> 如已发动效果延迟1秒落地；计时本身不等于高品级。不得恢复蓄势机制。 | M9: =INDEX('02_能力权限主表'!$M$6:$M$108,MATCH($B9,'02_能力权限主表'!$A$6:$A$108,0)) -> 按具体资产填写参数 | N9: =INDEX('02_能力权限主表'!$N$6:$N$108,MATCH($B9,'02_能力权限主表'!$A$6:$A$108,0)) -> 编制基线；全局规则优先 | O9: =INDEX('02_能力权限主表'!$P$6:$P$108,MATCH($B9,'02_能力权限主表'!$A$6:$A$108,0)) -> B3§四 L129–152；核心01§1.8
A10: M01 发动范式 | B10: C014 | C10: =INDEX('02_能力权限主表'!$B$6:$B$108,MATCH($B10,'02_能力权限主表'!$A$6:$A$108,0)) -> 蓄势／蓄势中断（停用） | D10: =INDEX('02_能力权限主表'!$C$6:$C$108,MATCH($B10,'02_能力权限主表'!$A$6:$A$108,0)) -> 停用 | E10: =INDEX('02_能力权限主表'!$D$6:$D$108,MATCH($B10,'02_能力权限主表'!$A$6:$A$108,0)) -> 停用 | F10: =INDEX('02_能力权限主表'!$E$6:$E$108,MATCH($B10,'02_能力权限主表'!$A$6:$A$108,0)) -> 停用 | G10: =INDEX('02_能力权限主表'!$F$6:$F$108,MATCH($B10,'02_能力权限主表'!$A$6:$A$108,0)) -> 停用 | H10: =INDEX('02_能力权限主表'!$G$6:$G$108,MATCH($B10,'02_能力权限主表'!$A$6:$A$108,0)) -> 停用 | I10: =INDEX('02_能力权限主表'!$H$6:$H$108,MATCH($B10,'02_能力权限主表'!$A$6:$A$108,0)) -> 停用 | J10: =INDEX('02_能力权限主表'!$I$6:$I$108,MATCH($B10,'02_能力权限主表'!$A$6:$A$108,0)) -> 停用 | K10: =INDEX('02_能力权限主表'!$J$6:$J$108,MATCH($B10,'02_能力权限主表'!$A$6:$A$108,0)) -> 停用 | L10: =INDEX('02_能力权限主表'!$L$6:$L$108,MATCH($B10,'02_能力权限主表'!$A$6:$A$108,0)) -> 用户已全局去除。三批旧词只在原文追溯，不可作为任何品级候选。 | M10: =INDEX('02_能力权限主表'!$M$6:$M$108,MATCH($B10,'02_能力权限主表'!$A$6:$A$108,0)) -> 不开放；恢复须另有明确新决定 | N10: =INDEX('02_能力权限主表'!$N$6:$N$108,MATCH($B10,'02_能力权限主表'!$A$6:$A$108,0)) -> 既有定案：停用 | O10: =INDEX('02_能力权限主表'!$P$6:$P$108,MATCH($B10,'02_能力权限主表'!$A$6:$A$108,0)) -> 核心01§1.8；t01-01 T01-D03
A11: M01 发动范式 | B11: C015 | C11: =INDEX('02_能力权限主表'!$B$6:$B$108,MATCH($B11,'02_能力权限主表'!$A$6:$A$108,0)) -> 改写其他器具发动方式 | D11: =INDEX('02_能力权限主表'!$C$6:$C$108,MATCH($B11,'02_能力权限主表'!$A$6:$A$108,0)) -> 玄品 | E11: =INDEX('02_能力权限主表'!$D$6:$D$108,MATCH($B11,'02_能力权限主表'!$A$6:$A$108,0)) -> — | F11: =INDEX('02_能力权限主表'!$E$6:$E$108,MATCH($B11,'02_能力权限主表'!$A$6:$A$108,0)) -> — | G11: =INDEX('02_能力权限主表'!$F$6:$F$108,MATCH($B11,'02_能力权限主表'!$A$6:$A$108,0)) -> — | H11: =INDEX('02_能力权限主表'!$G$6:$G$108,MATCH($B11,'02_能力权限主表'!$A$6:$A$108,0)) -> — | I11: =INDEX('02_能力权限主表'!$H$6:$H$108,MATCH($B11,'02_能力权限主表'!$A$6:$A$108,0)) -> ◇ | J11: =INDEX('02_能力权限主表'!$I$6:$I$108,MATCH($B11,'02_能力权限主表'!$A$6:$A$108,0)) -> ◎ | K11: =INDEX('02_能力权限主表'!$J$6:$J$108,MATCH($B11,'02_能力权限主表'!$A$6:$A$108,0)) -> 专案 | L11: =INDEX('02_能力权限主表'!$L$6:$L$108,MATCH($B11,'02_能力权限主表'!$A$6:$A$108,0)) -> 玄品常规；灵品只能逐件明确例外。保留支付、控制、待发、原CD等边界。 | M11: =INDEX('02_能力权限主表'!$M$6:$M$108,MATCH($B11,'02_能力权限主表'!$A$6:$A$108,0)) -> 按具体资产填写参数 | N11: =INDEX('02_能力权限主表'!$N$6:$N$108,MATCH($B11,'02_能力权限主表'!$A$6:$A$108,0)) -> 编制基线；全局规则优先 | O11: =INDEX('02_能力权限主表'!$P$6:$P$108,MATCH($B11,'02_能力权限主表'!$A$6:$A$108,0)) -> R4§七 L252–286；B2§十九 L537–558
A12: M02 事件与监听 | B12: C004 | C12: =INDEX('02_能力权限主表'!$B$6:$B$108,MATCH($B12,'02_能力权限主表'!$A$6:$A$108,0)) -> 标准事件、叠加与资格检查 | D12: =INDEX('02_能力权限主表'!$C$6:$C$108,MATCH($B12,'02_能力权限主表'!$A$6:$A$108,0)) -> 全品级基础 | E12: =INDEX('02_能力权限主表'!$D$6:$D$108,MATCH($B12,'02_能力权限主表'!$A$6:$A$108,0)) -> 基础 | F12: =INDEX('02_能力权限主表'!$E$6:$E$108,MATCH($B12,'02_能力权限主表'!$A$6:$A$108,0)) -> 基础 | G12: =INDEX('02_能力权限主表'!$F$6:$F$108,MATCH($B12,'02_能力权限主表'!$A$6:$A$108,0)) -> 基础 | H12: =INDEX('02_能力权限主表'!$G$6:$G$108,MATCH($B12,'02_能力权限主表'!$A$6:$A$108,0)) -> 基础 | I12: =INDEX('02_能力权限主表'!$H$6:$H$108,MATCH($B12,'02_能力权限主表'!$A$6:$A$108,0)) -> 基础 | J12: =INDEX('02_能力权限主表'!$I$6:$I$108,MATCH($B12,'02_能力权限主表'!$A$6:$A$108,0)) -> 基础 | K12: =INDEX('02_能力权限主表'!$J$6:$J$108,MATCH($B12,'02_能力权限主表'!$A$6:$A$108,0)) -> 基础 | L12: =INDEX('02_能力权限主表'!$L$6:$L$108,MATCH($B12,'02_能力权限主表'!$A$6:$A$108,0)) -> 所有器具都产生合法事件并遵守基础叠加、去重、暴击与命中规则；不等于带特色监听词条。 | M12: =INDEX('02_能力权限主表'!$M$6:$M$108,MATCH($B12,'02_能力权限主表'!$A$6:$A$108,0)) -> 按具体资产填写参数 | N12: =INDEX('02_能力权限主表'!$N$6:$N$108,MATCH($B12,'02_能力权限主表'!$A$6:$A$108,0)) -> 编制基线；全局规则优先 | O12: =INDEX('02_能力权限主表'!$P$6:$P$108,MATCH($B12,'02_能力权限主表'!$A$6:$A$108,0)) -> R4§九 L312–355；B3§三 L65–128
A13: M02 事件与监听 | B13: C014 | C13: =INDEX('02_能力权限主表'!$B$6:$B$108,MATCH($B13,'02_能力权限主表'!$A$6:$A$108,0)) -> 蓄势／蓄势中断（停用） | D13: =INDEX('02_能力权限主表'!$C$6:$C$108,MATCH($B13,'02_能力权限主表'!$A$6:$A$108,0)) -> 停用 | E13: =INDEX('02_能力权限主表'!$D$6:$D$108,MATCH($B13,'02_能力权限主表'!$A$6:$A$108,0)) -> 停用 | F13: =INDEX('02_能力权限主表'!$E$6:$E$108,MATCH($B13,'02_能力权限主表'!$A$6:$A$108,0)) -> 停用 | G13: =INDEX('02_能力权限主表'!$F$6:$F$108,MATCH($B13,'02_能力权限主表'!$A$6:$A$108,0)) -> 停用 | H13: =INDEX('02_能力权限主表'!$G$6:$G$108,MATCH($B13,'02_能力权限主表'!$A$6:$A$108,0)) -> 停用 | I13: =INDEX('02_能力权限主表'!$H$6:$H$108,MATCH($B13,'02_能力权限主表'!$A$6:$A$108,0)) -> 停用 | J13: =INDEX('02_能力权限主表'!$I$6:$I$108,MATCH($B13,'02_能力权限主表'!$A$6:$A$108,0)) -> 停用 | K13: =INDEX('02_能力权限主表'!$J$6:$J$108,MATCH($B13,'02_能力权限主表'!$A$6:$A$108,0)) -> 停用 | L13: =INDEX('02_能力权限主表'!$L$6:$L$108,MATCH($B13,'02_能力权限主表'!$A$6:$A$108,0)) -> 用户已全局去除。三批旧词只在原文追溯，不可作为任何品级候选。 | M13: =INDEX('02_能力权限主表'!$M$6:$M$108,MATCH($B13,'02_能力权限主表'!$A$6:$A$108,0)) -> 不开放；恢复须另有明确新决定 | N13: =INDEX('02_能力权限主表'!$N$6:$N$108,MATCH($B13,'02_能力权限主表'!$A$6:$A$108,0)) -> 既有定案：停用 | O13: =INDEX('02_能力权限主表'!$P$6:$P$108,MATCH($B13,'02_能力权限主表'!$A$6:$A$108,0)) -> 核心01§1.8；t01-01 T01-D03
A14: M02 事件与监听 | B14: C016 | C14: =INDEX('02_能力权限主表'!$B$6:$B$108,MATCH($B14,'02_能力权限主表'!$A$6:$A$108,0)) -> 使用自身命中／受击的直接特效 | D14: =INDEX('02_能力权限主表'!$C$6:$C$108,MATCH($B14,'02_能力权限主表'!$A$6:$A$108,0)) -> 凡品 | E14: =INDEX('02_能力权限主表'!$D$6:$D$108,MATCH($B14,'02_能力权限主表'!$A$6:$A$108,0)) -> — | F14: =INDEX('02_能力权限主表'!$E$6:$E$108,MATCH($B14,'02_能力权限主表'!$A$6:$A$108,0)) -> ○ | G14: =INDEX('02_能力权限主表'!$F$6:$F$108,MATCH($B14,'02_能力权限主表'!$A$6:$A$108,0)) -> ◎ | H14: =INDEX('02_能力权限主表'!$G$6:$G$108,MATCH($B14,'02_能力权限主表'!$A$6:$A$108,0)) -> ◎ | I14: =INDEX('02_能力权限主表'!$H$6:$H$108,MATCH($B14,'02_能力权限主表'!$A$6:$A$108,0)) -> ◎ | J14: =INDEX('02_能力权限主表'!$I$6:$I$108,MATCH($B14,'02_能力权限主表'!$A$6:$A$108,0)) -> ◎ | K14: =INDEX('02_能力权限主表'!$J$6:$J$108,MATCH($B14,'02_能力权限主表'!$A$6:$A$108,0)) -> 专案 | L14: =INDEX('02_能力权限主表'!$L$6:$L$108,MATCH($B14,'02_能力权限主表'!$A$6:$A$108,0)) -> 凡品为直接单一效果；复杂监听与反向反馈按更高机制项。 | M14: =INDEX('02_能力权限主表'!$M$6:$M$108,MATCH($B14,'02_能力权限主表'!$A$6:$A$108,0)) -> 按具体资产填写参数 | N14: =INDEX('02_能力权限主表'!$N$6:$N$108,MATCH($B14,'02_能力权限主表'!$A$6:$A$108,0)) -> 编制基线；全局规则优先 | O14: =INDEX('02_能力权限主表'!$P$6:$P$108,MATCH($B14,'02_能力权限主表'!$A$6:$A$108,0)) -> B3§三 L65–128
A15: M02 事件与监听 | B15: C017 | C15: =INDEX('02_能力权限主表'!$B$6:$B$108,MATCH($B15,'02_能力权限主表'!$A$6:$A$108,0)) -> 监听其他器具或全盘事件 | D15: =INDEX('02_能力权限主表'!$C$6:$C$108,MATCH($B15,'02_能力权限主表'!$A$6:$A$108,0)) -> 良品 | E15: =INDEX('02_能力权限主表'!$D$6:$D$108,MATCH($B15,'02_能力权限主表'!$A$6:$A$108,0)) -> — | F15: =INDEX('02_能力权限主表'!$E$6:$E$108,MATCH($B15,'02_能力权限主表'!$A$6:$A$108,0)) -> — | G15: =INDEX('02_能力权限主表'!$F$6:$F$108,MATCH($B15,'02_能力权限主表'!$A$6:$A$108,0)) -> ◎ | H15: =INDEX('02_能力权限主表'!$G$6:$G$108,MATCH($B15,'02_能力权限主表'!$A$6:$A$108,0)) -> ◎ | I15: =INDEX('02_能力权限主表'!$H$6:$H$108,MATCH($B15,'02_能力权限主表'!$A$6:$A$108,0)) -> ◎ | J15: =INDEX('02_能力权限主表'!$I$6:$I$108,MATCH($B15,'02_能力权限主表'!$A$6:$A$108,0)) -> ◎ | K15: =INDEX('02_能力权限主表'!$J$6:$J$108,MATCH($B15,'02_能力权限主表'!$A$6:$A$108,0)) -> 专案 | L15: =INDEX('02_能力权限主表'!$L$6:$L$108,MATCH($B15,'02_能力权限主表'!$A$6:$A$108,0)) -> 良品一条直观触发链；真实事件只记一次，来源过滤仍合法。 | M15: =INDEX('02_能力权限主表'!$M$6:$M$108,MATCH($B15,'02_能力权限主表'!$A$6:$A$108,0)) -> 按具体资产填写参数 | N15: =INDEX('02_能力权限主表'!$N$6:$N$108,MATCH($B15,'02_能力权限主表'!$A$6:$A$108,0)) -> 编制基线；全局规则优先 | O15: =INDEX('02_能力权限主表'!$P$6:$P$108,MATCH($B15,'02_能力权限主表'!$A$6:$A$108,0)) -> B1§二十八 L821–840；B3§三 L65–128
A16: M02 事件与监听 | B16: C096 | C16: =INDEX('02_能力权限主表'!$B$6:$B$108,MATCH($B16,'02_能力权限主表'!$A$6:$A$108,0)) -> 监听连携成功事件 | D16: =INDEX('02_能力权限主表'!$C$6:$C$108,MATCH($B16,'02_能力权限主表'!$A$6:$A$108,0)) -> 上品 | E16: =INDEX('02_能力权限主表'!$D$6:$D$108,MATCH($B16,'02_能力权限主表'!$A$6:$A$108,0)) -> — | F16: =INDEX('02_能力权限主表'!$E$6:$E$108,MATCH($B16,'02_能力权限主表'!$A$6:$A$108,0)) -> — | G16: =INDEX('02_能力权限主表'!$F$6:$F$108,MATCH($B16,'02_能力权限主表'!$A$6:$A$108,0)) -> △ | H16: =INDEX('02_能力权限主表'!$G$6:$G$108,MATCH($B16,'02_能力权限主表'!$A$6:$A$108,0)) -> ◎ | I16: =INDEX('02_能力权限主表'!$H$6:$H$108,MATCH($B16,'02_能力权限主表'!$A$6:$A$108,0)) -> ◎ | J16: =INDEX('02_能力权限主表'!$I$6:$I$108,MATCH($B16,'02_能力权限主表'!$A$6:$A$108,0)) -> ◎ | K16: =INDEX('02_能力权限主表'!$J$6:$J$108,MATCH($B16,'02_能力权限主表'!$A$6:$A$108,0)) -> 专案 | L16: =INDEX('02_能力权限主表'!$L$6:$L$108,MATCH($B16,'02_能力权限主表'!$A$6:$A$108,0)) -> 只监听实际合法成功事件，不因物品高品级制造成功。 | M16: =INDEX('02_能力权限主表'!$M$6:$M$108,MATCH($B16,'02_能力权限主表'!$A$6:$A$108,0)) -> 按具体资产填写参数 | N16: =INDEX('02_能力权限主表'!$N$6:$N$108,MATCH($B16,'02_能力权限主表'!$A$6:$A$108,0)) -> 编制基线；全局规则优先 | O16: =INDEX('02_能力权限主表'!$P$6:$P$108,MATCH($B16,'02_能力权限主表'!$A$6:$A$108,0)) -> B3§十三 L391–425
A17: M02 事件与监听 | B17: C102 | C17: =INDEX('02_能力权限主表'!$B$6:$B$108,MATCH($B17,'02_能力权限主表'!$A$6:$A$108,0)) -> 简单追击／反击特色 | D17: =INDEX('02_能力权限主表'!$C$6:$C$108,MATCH($B17,'02_能力权限主表'!$A$6:$A$108,0)) -> 良品 | E17: =INDEX('02_能力权限主表'!$D$6:$D$108,MATCH($B17,'02_能力权限主表'!$A$6:$A$108,0)) -> — | F17: =INDEX('02_能力权限主表'!$E$6:$E$108,MATCH($B17,'02_能力权限主表'!$A$6:$A$108,0)) -> — | G17: =INDEX('02_能力权限主表'!$F$6:$F$108,MATCH($B17,'02_能力权限主表'!$A$6:$A$108,0)) -> ○ | H17: =INDEX('02_能力权限主表'!$G$6:$G$108,MATCH($B17,'02_能力权限主表'!$A$6:$A$108,0)) -> ◎ | I17: =INDEX('02_能力权限主表'!$H$6:$H$108,MATCH($B17,'02_能力权限主表'!$A$6:$A$108,0)) -> ◎ | J17: =INDEX('02_能力权限主表'!$I$6:$I$108,MATCH($B17,'02_能力权限主表'!$A$6:$A$108,0)) -> ◎ | K17: =INDEX('02_能力权限主表'!$J$6:$J$108,MATCH($B17,'02_能力权限主表'!$A$6:$A$108,0)) -> 专案 | L17: =INDEX('02_能力权限主表'!$L$6:$L$108,MATCH($B17,'02_能力权限主表'!$A$6:$A$108,0)) -> 基础合法暴击、命中不等于特色追击；良品特色仍服从追击／反击顺序与来源资格，不复制全部伤害包。 | M17: =INDEX('02_能力权限主表'!$M$6:$M$108,MATCH($B17,'02_能力权限主表'!$A$6:$A$108,0)) -> 按具体资产填写参数 | N17: =INDEX('02_能力权限主表'!$N$6:$N$108,MATCH($B17,'02_能力权限主表'!$A$6:$A$108,0)) -> 编制基线；全局规则优先 | O17: =INDEX('02_能力权限主表'!$P$6:$P$108,MATCH($B17,'02_能力权限主表'!$A$6:$A$108,0)) -> B1§三十一 L895–912；核心01§1.4、§3.3
... A169: M10 来源与资格 | B169: C101 | C169: =INDEX('02_能力权限主表'!$B$6:$B$108,MATCH($B169,'02_能力权限主表'!$A$6:$A$108,0)) -> 改变连携节点来源资格 | D169: =INDEX('02_能力权限主表'!$C$6:$C$108,MATCH($B169,'02_能力权限主表'!$A$6:$A$108,0)) -> 玄品 | E169: =INDEX('02_能力权限主表'!$D$6:$D$108,MATCH($B169,'02_能力权限主表'!$A$6:$A$108,0)) -> — | F169: =INDEX('02_能力权限主表'!$E$6:$E$108,MATCH($B169,'02_能力权限主表'!$A$6:$A$108,0)) -> — | G169: =INDEX('02_能力权限主表'!$F$6:$F$108,MATCH($B169,'02_能力权限主表'!$A$6:$A$108,0)) -> — | H169: =INDEX('02_能力权限主表'!$G$6:$G$108,MATCH($B169,'02_能力权限主表'!$A$6:$A$108,0)) -> — | I169: =INDEX('02_能力权限主表'!$H$6:$H$108,MATCH($B169,'02_能力权限主表'!$A$6:$A$108,0)) -> ◇ | J169: =INDEX('02_能力权限主表'!$I$6:$I$108,MATCH($B169,'02_能力权限主表'!$A$6:$A$108,0)) -> ◎ | K169: =INDEX('02_能力权限主表'!$J$6:$J$108,MATCH($B169,'02_能力权限主表'!$A$6:$A$108,0)) -> 专案 | L169: =INDEX('02_能力权限主表'!$L$6:$L$108,MATCH($B169,'02_能力权限主表'!$A$6:$A$108,0)) -> 与数值／窗口辅助分开；若提前系统解锁，另登记全局规则例外。 | M169: =INDEX('02_能力权限主表'!$M$6:$M$108,MATCH($B169,'02_能力权限主表'!$A$6:$A$108,0)) -> 按具体资产填写参数 | N169: =INDEX('02_能力权限主表'!$N$6:$N$108,MATCH($B169,'02_能力权限主表'!$A$6:$A$108,0)) -> 编制基线；全局规则优先 | O169: =INDEX('02_能力权限主表'!$P$6:$P$108,MATCH($B169,'02_能力权限主表'!$A$6:$A$108,0)) -> R4§七 L252–286；B3§十三 L391–425

Sheet 04_状态操作权限
A1: T01-03 | 状态操作权限
A2: 按能力ID引用02主表；排序不改变对应关系。◎核心 ○常规辅助 △有限候选 ◇明确例外 —非常规 ?待专项；仙品看10表。
A3: 返回说明 | B3: 63 条记录 | 表头可筛选 | 依据中的B1／B2／B3／R4／Q01与原行号可回查12表
A5: 状态／操作 | B5: 能力ID | C5: 能力名称 | D5: 常规最低品级 | E5: 下品 | F5: 凡品 | G5: 良品 | H5: 上品 | I5: 灵品 | J5: 玄品 | K5: 仙品 | L5: 权限边界 | M5: 前置／未决 | N5: 规则状态 | O5: 依据
A6: S1 核心状态 | B6: C010 | C6: =INDEX('02_能力权限主表'!$B$6:$B$108,MATCH($B6,'02_能力权限主表'!$A$6:$A$108,0)) -> 元素攻击与额外状态等独立收益组合 | D6: =INDEX('02_能力权限主表'!$C$6:$C$108,MATCH($B6,'02_能力权限主表'!$A$6:$A$108,0)) -> 凡品 | E6: =INDEX('02_能力权限主表'!$D$6:$D$108,MATCH($B6,'02_能力权限主表'!$A$6:$A$108,0)) -> — | F6: =INDEX('02_能力权限主表'!$E$6:$E$108,MATCH($B6,'02_能力权限主表'!$A$6:$A$108,0)) -> ○ | G6: =INDEX('02_能力权限主表'!$F$6:$F$108,MATCH($B6,'02_能力权限主表'!$A$6:$A$108,0)) -> ○ | H6: =INDEX('02_能力权限主表'!$G$6:$G$108,MATCH($B6,'02_能力权限主表'!$A$6:$A$108,0)) -> ◎ | I6: =INDEX('02_能力权限主表'!$H$6:$H$108,MATCH($B6,'02_能力权限主表'!$A$6:$A$108,0)) -> ◎ | J6: =INDEX('02_能力权限主表'!$I$6:$I$108,MATCH($B6,'02_能力权限主表'!$A$6:$A$108,0)) -> ◎ | K6: =INDEX('02_能力权限主表'!$J$6:$J$108,MATCH($B6,'02_能力权限主表'!$A$6:$A$108,0)) -> 专案 | L6: =INDEX('02_能力权限主表'!$L$6:$L$108,MATCH($B6,'02_能力权限主表'!$A$6:$A$108,0)) -> 凡品常规允许固定单元素＋一种简单状态的组合，仍按各状态已定触发门槛与容量；不顺带开放双状态、复杂监听、来源改写或自由功能槽。其他多份独立收益组合仍须审查。 | M6: =INDEX('02_能力权限主表'!$M$6:$M$108,MATCH($B6,'02_能力权限主表'!$A$6:$A$108,0)) -> 按具体资产填写参数 | N6: =INDEX('02_能力权限主表'!$N$6:$N$108,MATCH($B6,'02_能力权限主表'!$A$6:$A$108,0)) -> 本次08覆盖旧“凡品少量候选、良品常规”口径，许可限本行明确范围。 | O6: =INDEX('02_能力权限主表'!$P$6:$P$108,MATCH($B6,'02_能力权限主表'!$A$6:$A$108,0)) -> R4§七历史口径；t01-08凡品第2／3批与用户直接更正、FP02；2026-09-28
A7: S1 核心状态 | B7: C028 | C7: =INDEX('02_能力权限主表'!$B$6:$B$108,MATCH($B7,'02_能力权限主表'!$A$6:$A$108,0)) -> 两个成熟机制实质耦合 | D7: =INDEX('02_能力权限主表'!$C$6:$C$108,MATCH($B7,'02_能力权限主表'!$A$6:$A$108,0)) -> 灵品 | E7: =INDEX('02_能力权限主表'!$D$6:$D$108,MATCH($B7,'02_能力权限主表'!$A$6:$A$108,0)) -> — | F7: =INDEX('02_能力权限主表'!$E$6:$E$108,MATCH($B7,'02_能力权限主表'!$A$6:$A$108,0)) -> — | G7: =INDEX('02_能力权限主表'!$F$6:$F$108,MATCH($B7,'02_能力权限主表'!$A$6:$A$108,0)) -> — | H7: =INDEX('02_能力权限主表'!$G$6:$G$108,MATCH($B7,'02_能力权限主表'!$A$6:$A$108,0)) -> △ | I7: =INDEX('02_能力权限主表'!$H$6:$H$108,MATCH($B7,'02_能力权限主表'!$A$6:$A$108,0)) -> ◎ | J7: =INDEX('02_能力权限主表'!$I$6:$I$108,MATCH($B7,'02_能力权限主表'!$A$6:$A$108,0)) -> ◎ | K7: =INDEX('02_能力权限主表'!$J$6:$J$108,MATCH($B7,'02_能力权限主表'!$A$6:$A$108,0)) -> 专案 | L7: =INDEX('02_能力权限主表'!$L$6:$L$108,MATCH($B7,'02_能力权限主表'!$A$6:$A$108,0)) -> 单向联动、共享取舍、阶段衔接、反馈均可；必须各自具有可管理玩法，不要求A→B→A。上品△仅候选，仍需按两个成熟核心审查。 | M7: =INDEX('02_能力权限主表'!$M$6:$M$108,MATCH($B7,'02_能力权限主表'!$A$6:$A$108,0)) -> 按具体资产填写参数 | N7: =INDEX('02_能力权限主表'!$N$6:$N$108,MATCH($B7,'02_能力权限主表'!$A$6:$A$108,0)) -> 编制基线；全局规则优先 | O7: =INDEX('02_能力权限主表'!$P$6:$P$108,MATCH($B7,'02_能力权限主表'!$A$6:$A$108,0)) -> R4§五 L181–224；B2§十六 L470–491
A8: S1 核心状态 | B8: C038 | C8: =INDEX('02_能力权限主表'!$B$6:$B$108,MATCH($B8,'02_能力权限主表'!$A$6:$A$108,0)) -> S1核心状态施加／增层 | D8: =INDEX('02_能力权限主表'!$C$6:$C$108,MATCH($B8,'02_能力权限主表'!$A$6:$A$108,0)) -> 凡品 | E8: =INDEX('02_能力权限主表'!$D$6:$D$108,MATCH($B8,'02_能力权限主表'!$A$6:$A$108,0)) -> — | F8: =INDEX('02_能力权限主表'!$E$6:$E$108,MATCH($B8,'02_能力权限主表'!$A$6:$A$108,0)) -> ◎ | G8: =INDEX('02_能力权限主表'!$F$6:$F$108,MATCH($B8,'02_能力权限主表'!$A$6:$A$108,0)) -> ◎ | H8: =INDEX('02_能力权限主表'!$G$6:$G$108,MATCH($B8,'02_能力权限主表'!$A$6:$A$108,0)) -> ◎ | I8: =INDEX('02_能力权限主表'!$H$6:$H$108,MATCH($B8,'02_能力权限主表'!$A$6:$A$108,0)) -> ◎ | J8: =INDEX('02_能力权限主表'!$I$6:$I$108,MATCH($B8,'02_能力权限主表'!$A$6:$A$108,0)) -> ◎ | K8: =INDEX('02_能力权限主表'!$J$6:$J$108,MATCH($B8,'02_能力权限主表'!$A$6:$A$108,0)) -> 专案 | L8: =INDEX('02_能力权限主表'!$L$6:$L$108,MATCH($B8,'02_能力权限主表'!$A$6:$A$108,0)) -> Buff按自身；Debuff按施加者，主角辅助归主角、独立怪物读自身。不能照抄B3§六的目标容量旧口径。 | M8: =INDEX('02_能力权限主表'!$M$6:$M$108,MATCH($B8,'02_能力权限主表'!$A$6:$A$108,0)) -> 具体状态、层数、容量来源按资产 | N8: =INDEX('02_能力权限主表'!$N$6:$N$108,MATCH($B8,'02_能力权限主表'!$A$6:$A$108,0)) -> 编制基线；全局规则优先 | O8: =INDEX('02_能力权限主表'!$P$6:$P$108,MATCH($B8,'02_能力权限主表'!$A$6:$A$108,0)) -> B3§五 L153–194；核心01§1.8
A9: S1 核心状态 | B9: C039 | C9: =INDEX('02_能力权限主表'!$B$6:$B$108,MATCH($B9,'02_能力权限主表'!$A$6:$A$108,0)) -> S1有无／简单层数读取 | D9: =INDEX('02_能力权限主表'!$C$6:$C$108,MATCH($B9,'02_能力权限主表'!$A$6:$A$108,0)) -> 良品 | E9: =INDEX('02_能力权限主表'!$D$6:$D$108,MATCH($B9,'02_能力权限主表'!$A$6:$A$108,0)) -> — | F9: =INDEX('02_能力权限主表'!$E$6:$E$108,MATCH($B9,'02_能力权限主表'!$A$6:$A$108,0)) -> — | G9: =INDEX('02_能力权限主表'!$F$6:$F$108,MATCH($B9,'02_能力权限主表'!$A$6:$A$108,0)) -> ◎ | H9: =INDEX('02_能力权限主表'!$G$6:$G$108,MATCH($B9,'02_能力权限主表'!$A$6:$A$108,0)) -> ◎ | I9: =INDEX('02_能力权限主表'!$H$6:$H$108,MATCH($B9,'02_能力权限主表'!$A$6:$A$108,0)) -> ◎ | J9: =INDEX('02_能力权限主表'!$I$6:$I$108,MATCH($B9,'02_能力权限主表'!$A$6:$A$108,0)) -> ◎ | K9: =INDEX('02_能力权限主表'!$J$6:$J$108,MATCH($B9,'02_能力权限主表'!$A$6:$A$108,0)) -> 专案 | L9: =INDEX('02_能力权限主表'!$L$6:$L$108,MATCH($B9,'02_能力权限主表'!$A$6:$A$108,0)) -> 良品有无、简单阈值或少量读层；不等于成熟消费转换。 | M9: =INDEX('02_能力权限主表'!$M$6:$M$108,MATCH($B9,'02_能力权限主表'!$A$6:$A$108,0)) -> 按具体资产填写参数 | N9: =INDEX('02_能力权限主表'!$N$6:$N$108,MATCH($B9,'02_能力权限主表'!$A$6:$A$108,0)) -> 编制基线；全局规则优先 | O9: =INDEX('02_能力权限主表'!$P$6:$P$108,MATCH($B9,'02_能力权限主表'!$A$6:$A$108,0)) -> B1§三十 L865–894；B3§五 L153–194
A10: S1 核心状态 | B10: C040 | C10: =INDEX('02_能力权限主表'!$B$6:$B$108,MATCH($B10,'02_能力权限主表'!$A$6:$A$108,0)) -> S1层数阈值利用 | D10: =INDEX('02_能力权限主表'!$C$6:$C$108,MATCH($B10,'02_能力权限主表'!$A$6:$A$108,0)) -> 良品 | E10: =INDEX('02_能力权限主表'!$D$6:$D$108,MATCH($B10,'02_能力权限主表'!$A$6:$A$108,0)) -> — | F10: =INDEX('02_能力权限主表'!$E$6:$E$108,MATCH($B10,'02_能力权限主表'!$A$6:$A$108,0)) -> — | G10: =INDEX('02_能力权限主表'!$F$6:$F$108,MATCH($B10,'02_能力权限主表'!$A$6:$A$108,0)) -> ○ | H10: =INDEX('02_能力权限主表'!$G$6:$G$108,MATCH($B10,'02_能力权限主表'!$A$6:$A$108,0)) -> ◎ | I10: =INDEX('02_能力权限主表'!$H$6:$H$108,MATCH($B10,'02_能力权限主表'!$A$6:$A$108,0)) -> ◎ | J10: =INDEX('02_能力权限主表'!$I$6:$I$108,MATCH($B10,'02_能力权限主表'!$A$6:$A$108,0)) -> ◎ | K10: =INDEX('02_能力权限主表'!$J$6:$J$108,MATCH($B10,'02_能力权限主表'!$A$6:$A$108,0)) -> 专案 | L10: =INDEX('02_能力权限主表'!$L$6:$L$108,MATCH($B10,'02_能力权限主表'!$A$6:$A$108,0)) -> 读层与耗层分开，按明确快照和新层参与资格。 | M10: =INDEX('02_能力权限主表'!$M$6:$M$108,MATCH($B10,'02_能力权限主表'!$A$6:$A$108,0)) -> 按具体资产填写参数 | N10: =INDEX('02_能力权限主表'!$N$6:$N$108,MATCH($B10,'02_能力权限主表'!$A$6:$A$108,0)) -> 编制基线；全局规则优先 | O10: =INDEX('02_能力权限主表'!$P$6:$P$108,MATCH($B10,'02_能力权限主表'!$A$6:$A$108,0)) -> B3§五 L153–194
A11: S1 核心状态 | B11: C041 | C11: =INDEX('02_能力权限主表'!$B$6:$B$108,MATCH($B11,'02_能力权限主表'!$A$6:$A$108,0)) -> S1公共状态主动消耗兑现 | D11: =INDEX('02_能力权限主表'!$C$6:$C$108,MATCH($B11,'02_能力权限主表'!$A$6:$A$108,0)) -> 上品 | E11: =INDEX('02_能力权限主表'!$D$6:$D$108,MATCH($B11,'02_能力权限主表'!$A$6:$A$108,0)) -> — | F11: =INDEX('02_能力权限主表'!$E$6:$E$108,MATCH($B11,'02_能力权限主表'!$A$6:$A$108,0)) -> — | G11: =INDEX('02_能力权限主表'!$F$6:$F$108,MATCH($B11,'02_能力权限主表'!$A$6:$A$108,0)) -> △ | H11: =INDEX('02_能力权限主表'!$G$6:$G$108,MATCH($B11,'02_能力权限主表'!$A$6:$A$108,0)) -> ◎ | I11: =INDEX('02_能力权限主表'!$H$6:$H$108,MATCH($B11,'02_能力权限主表'!$A$6:$A$108,0)) -> ◎ | J11: =INDEX('02_能力权限主表'!$I$6:$I$108,MATCH($B11,'02_能力权限主表'!$A$6:$A$108,0)) -> ◎ | K11: =INDEX('02_能力权限主表'!$J$6:$J$108,MATCH($B11,'02_能力权限主表'!$A$6:$A$108,0)) -> 专案 | L11: =INDEX('02_能力权限主表'!$L$6:$L$108,MATCH($B11,'02_能力权限主表'!$A$6:$A$108,0)) -> 常规上品；良品只保留具体少量候选，不等于公共状态互转。 | M11: =INDEX('02_能力权限主表'!$M$6:$M$108,MATCH($B11,'02_能力权限主表'!$A$6:$A$108,0)) -> 按具体资产填写参数 | N11: =INDEX('02_能力权限主表'!$N$6:$N$108,MATCH($B11,'02_能力权限主表'!$A$6:$A$108,0)) -> 编制基线；全局规则优先 | O11: =INDEX('02_能力权限主表'!$P$6:$P$108,MATCH($B11,'02_能力权限主表'!$A$6:$A$108,0)) -> B3§五 L153–194；R4§七 L252–286
A12: S1 核心状态 | B12: C042 | C12: =INDEX('02_能力权限主表'!$B$6:$B$108,MATCH($B12,'02_能力权限主表'!$A$6:$A$108,0)) -> 公共状态转换／成熟兑现 | D12: =INDEX('02_能力权限主表'!$C$6:$C$108,MATCH($B12,'02_能力权限主表'!$A$6:$A$108,0)) -> 上品 | E12: =INDEX('02_能力权限主表'!$D$6:$D$108,MATCH($B12,'02_能力权限主表'!$A$6:$A$108,0)) -> — | F12: =INDEX('02_能力权限主表'!$E$6:$E$108,MATCH($B12,'02_能力权限主表'!$A$6:$A$108,0)) -> — | G12: =INDEX('02_能力权限主表'!$F$6:$F$108,MATCH($B12,'02_能力权限主表'!$A$6:$A$108,0)) -> ◇ | H12: =INDEX('02_能力权限主表'!$G$6:$G$108,MATCH($B12,'02_能力权限主表'!$A$6:$A$108,0)) -> ◎ | I12: =INDEX('02_能力权限主表'!$H$6:$H$108,MATCH($B12,'02_能力权限主表'!$A$6:$A$108,0)) -> ◎ | J12: =INDEX('02_能力权限主表'!$I$6:$I$108,MATCH($B12,'02_能力权限主表'!$A$6:$A$108,0)) -> ◎ | K12: =INDEX('02_能力权限主表'!$J$6:$J$108,MATCH($B12,'02_能力权限主表'!$A$6:$A$108,0)) -> 专案 | L12: =INDEX('02_能力权限主表'!$L$6:$L$108,MATCH($B12,'02_能力权限主表'!$A$6:$A$108,0)) -> 常规上品起；明确输入、输出、容量不足与失败处理。良品专属标记消费不授权公共状态互转。 | M12: =INDEX('02_能力权限主表'!$M$6:$M$108,MATCH($B12,'02_能力权限主表'!$A$6:$A$108,0)) -> 按具体资产填写参数 | N12: =INDEX('02_能力权限主表'!$N$6:$N$108,MATCH($B12,'02_能力权限主表'!$A$6:$A$108,0)) -> 编制基线；全局规则优先 | O12: =INDEX('02_能力权限主表'!$P$6:$P$108,MATCH($B12,'02_能力权限主表'!$A$6:$A$108,0)) -> R4§七 L252–286；B2§四 L70–165
A13: S1 核心状态 | B13: C043 | C13: =INDEX('02_能力权限主表'!$B$6:$B$108,MATCH($B13,'02_能力权限主表'!$A$6:$A$108,0)) -> 增加明确的状态容量 | D13: =INDEX('02_能力权限主表'!$C$6:$C$108,MATCH($B13,'02_能力权限主表'!$A$6:$A$108,0)) -> 上品 | E13: =INDEX('02_能力权限主表'!$D$6:$D$108,MATCH($B13,'02_能力权限主表'!$A$6:$A$108,0)) -> — | F13: =INDEX('02_能力权限主表'!$E$6:$E$108,MATCH($B13,'02_能力权限主表'!$A$6:$A$108,0)) -> △ | G13: =INDEX('02_能力权限主表'!$F$6:$F$108,MATCH($B13,'02_能力权限主表'!$A$6:$A$108,0)) -> △ | H13: =INDEX('02_能力权限主表'!$G$6:$G$108,MATCH($B13,'02_能力权限主表'!$A$6:$A$108,0)) -> ○ | I13: =INDEX('02_能力权限主表'!$H$6:$H$108,MATCH($B13,'02_能力权限主表'!$A$6:$A$108,0)) -> ◎ | J13: =INDEX('02_能力权限主表'!$I$6:$I$108,MATCH($B13,'02_能力权限主表'!$A$6:$A$108,0)) -> ◎ | K13: =INDEX('02_能力权限主表'!$J$6:$J$108,MATCH($B13,'02_能力权限主表'!$A$6:$A$108,0)) -> 专案 | L13: =INDEX('02_能力权限主表'!$L$6:$L$108,MATCH($B13,'02_能力权限主表'!$A$6:$A$108,0)) -> 凡品可有少量指定容量来源；容量与共鸣分开。禁用仍装备道具固有加成保留，主角换装下降立即截层。 | M13: =INDEX('02_能力权限主表'!$M$6:$M$108,MATCH($B13,'02_能力权限主表'!$A$6:$A$108,0)) -> 按具体资产填写参数 | N13: =INDEX('02_能力权限主表'!$N$6:$N$108,MATCH($B13,'02_能力权限主表'!$A$6:$A$108,0)) -> 编制基线；全局规则优先 | O13: =INDEX('02_能力权限主表'!$P$6:$P$108,MATCH($B13,'02_能力权限主表'!$A$6:$A$108,0)) -> B3§五 L153–194；核心01§1.8
A14: S1 核心状态 | B14: C044 | C14: =INDEX('02_能力权限主表'!$B$6:$B$108,MATCH($B14,'02_能力权限主表'!$A$6:$A$108,0)) -> 修改具体状态运行规则 | D14: =INDEX('02_能力权限主表'!$C$6:$C$108,MATCH($B14,'02_能力权限主表'!$A$6:$A$108,0)) -> 灵品 | E14: =INDEX('02_能力权限主表'!$D$6:$D$108,MATCH($B14,'02_能力权限主表'!$A$6:$A$108,0)) -> — | F14: =INDEX('02_能力权限主表'!$E$6:$E$108,MATCH($B14,'02_能力权限主表'!$A$6:$A$108,0)) -> — | G14: =INDEX('02_能力权限主表'!$F$6:$F$108,MATCH($B14,'02_能力权限主表'!$A$6:$A$108,0)) -> — | H14: =INDEX('02_能力权限主表'!$G$6:$G$108,MATCH($B14,'02_能力权限主表'!$A$6:$A$108,0)) -> △ | I14: =INDEX('02_能力权限主表'!$H$6:$H$108,MATCH($B14,'02_能力权限主表'!$A$6:$A$108,0)) -> ○ | J14: =INDEX('02_能力权限主表'!$I$6:$I$108,MATCH($B14,'02_能力权限主表'!$A$6:$A$108,0)) -> ◎ | K14: =INDEX('02_能力权限主表'!$J$6:$J$108,MATCH($B14,'02_能力权限主表'!$A$6:$A$108,0)) -> 专案 | L14: =INDEX('02_能力权限主表'!$L$6:$L$108,MATCH($B14,'02_能力权限主表'!$A$6:$A$108,0)) -> 上品候选、灵品可针对具体状态，玄品成熟规则权限；须声明准确修改字段，不自动突破全局规则。 | M14: =INDEX('02_能力权限主表'!$M$6:$M$108,MATCH($B14,'02_能力权限主表'!$A$6:$A$108,0)) -> 按具体资产填写参数 | N14: =INDEX('02_能力权限主表'!$N$6:$N$108,MATCH($B14,'02_能力权限主表'!$A$6:$A$108,0)) -> 编制基线；全局规则优先 | O14: =INDEX('02_能力权限主表'!$P$6:$P$108,MATCH($B14,'02_能力权限主表'!$A$6:$A$108,0)) -> B2§十四 L426–445；B3§五 L153–194
A15: S2 通用战术状态 | B15: C010 | C15: =INDEX('02_能力权限主表'!$B$6:$B$108,MATCH($B15,'02_能力权限主表'!$A$6:$A$108,0)) -> 元素攻击与额外状态等独立收益组合 | D15: =INDEX('02_能力权限主表'!$C$6:$C$108,MATCH($B15,'02_能力权限主表'!$A$6:$A$108,0)) -> 凡品 | E15: =INDEX('02_能力权限主表'!$D$6:$D$108,MATCH($B15,'02_能力权限主表'!$A$6:$A$108,0)) -> — | F15: =INDEX('02_能力权限主表'!$E$6:$E$108,MATCH($B15,'02_能力权限主表'!$A$6:$A$108,0)) -> ○ | G15: =INDEX('02_能力权限主表'!$F$6:$F$108,MATCH($B15,'02_能力权限主表'!$A$6:$A$108,0)) -> ○ | H15: =INDEX('02_能力权限主表'!$G$6:$G$108,MATCH($B15,'02_能力权限主表'!$A$6:$A$108,0)) -> ◎ | I15: =INDEX('02_能力权限主表'!$H$6:$H$108,MATCH($B15,'02_能力权限主表'!$A$6:$A$108,0)) -> ◎ | J15: =INDEX('02_能力权限主表'!$I$6:$I$108,MATCH($B15,'02_能力权限主表'!$A$6:$A$108,0)) -> ◎ | K15: =INDEX('02_能力权限主表'!$J$6:$J$108,MATCH($B15,'02_能力权限主表'!$A$6:$A$108,0)) -> 专案 | L15: =INDEX('02_能力权限主表'!$L$6:$L$108,MATCH($B15,'02_能力权限主表'!$A$6:$A$108,0)) -> 凡品常规允许固定单元素＋一种简单状态的组合，仍按各状态已定触发门槛与容量；不顺带开放双状态、复杂监听、来源改写或自由功能槽。其他多份独立收益组合仍须审查。 | M15: =INDEX('02_能力权限主表'!$M$6:$M$108,MATCH($B15,'02_能力权限主表'!$A$6:$A$108,0)) -> 按具体资产填写参数 | N15: =INDEX('02_能力权限主表'!$N$6:$N$108,MATCH($B15,'02_能力权限主表'!$A$6:$A$108,0)) -> 本次08覆盖旧“凡品少量候选、良品常规”口径，许可限本行明确范围。 | O15: =INDEX('02_能力权限主表'!$P$6:$P$108,MATCH($B15,'02_能力权限主表'!$A$6:$A$108,0)) -> R4§七历史口径；t01-08凡品第2／3批与用户直接更正、FP02；2026-09-28
A16: S2 通用战术状态 | B16: C028 | C16: =INDEX('02_能力权限主表'!$B$6:$B$108,MATCH($B16,'02_能力权限主表'!$A$6:$A$108,0)) -> 两个成熟机制实质耦合 | D16: =INDEX('02_能力权限主表'!$C$6:$C$108,MATCH($B16,'02_能力权限主表'!$A$6:$A$108,0)) -> 灵品 | E16: =INDEX('02_能力权限主表'!$D$6:$D$108,MATCH($B16,'02_能力权限主表'!$A$6:$A$108,0)) -> — | F16: =INDEX('02_能力权限主表'!$E$6:$E$108,MATCH($B16,'02_能力权限主表'!$A$6:$A$108,0)) -> — | G16: =INDEX('02_能力权限主表'!$F$6:$F$108,MATCH($B16,'02_能力权限主表'!$A$6:$A$108,0)) -> — | H16: =INDEX('02_能力权限主表'!$G$6:$G$108,MATCH($B16,'02_能力权限主表'!$A$6:$A$108,0)) -> △ | I16: =INDEX('02_能力权限主表'!$H$6:$H$108,MATCH($B16,'02_能力权限主表'!$A$6:$A$108,0)) -> ◎ | J16: =INDEX('02_能力权限主表'!$I$6:$I$108,MATCH($B16,'02_能力权限主表'!$A$6:$A$108,0)) -> ◎ | K16: =INDEX('02_能力权限主表'!$J$6:$J$108,MATCH($B16,'02_能力权限主表'!$A$6:$A$108,0)) -> 专案 | L16: =INDEX('02_能力权限主表'!$L$6:$L$108,MATCH($B16,'02_能力权限主表'!$A$6:$A$108,0)) -> 单向联动、共享取舍、阶段衔接、反馈均可；必须各自具有可管理玩法，不要求A→B→A。上品△仅候选，仍需按两个成熟核心审查。 | M16: =INDEX('02_能力权限主表'!$M$6:$M$108,MATCH($B16,'02_能力权限主表'!$A$6:$A$108,0)) -> 按具体资产填写参数 | N16: =INDEX('02_能力权限主表'!$N$6:$N$108,MATCH($B16,'02_能力权限主表'!$A$6:$A$108,0)) -> 编制基线；全局规则优先 | O16: =INDEX('02_能力权限主表'!$P$6:$P$108,MATCH($B16,'02_能力权限主表'!$A$6:$A$108,0)) -> R4§五 L181–224；B2§十六 L470–491
A17: S2 通用战术状态 | B17: C042 | C17: =INDEX('02_能力权限主表'!$B$6:$B$108,MATCH($B17,'02_能力权限主表'!$A$6:$A$108,0)) -> 公共状态转换／成熟兑现 | D17: =INDEX('02_能力权限主表'!$C$6:$C$108,MATCH($B17,'02_能力权限主表'!$A$6:$A$108,0)) -> 上品 | E17: =INDEX('02_能力权限主表'!$D$6:$D$108,MATCH($B17,'02_能力权限主表'!$A$6:$A$108,0)) -> — | F17: =INDEX('02_能力权限主表'!$E$6:$E$108,MATCH($B17,'02_能力权限主表'!$A$6:$A$108,0)) -> — | G17: =INDEX('02_能力权限主表'!$F$6:$F$108,MATCH($B17,'02_能力权限主表'!$A$6:$A$108,0)) -> ◇ | H17: =INDEX('02_能力权限主表'!$G$6:$G$108,MATCH($B17,'02_能力权限主表'!$A$6:$A$108,0)) -> ◎ | I17: =INDEX('02_能力权限主表'!$H$6:$H$108,MATCH($B17,'02_能力权限主表'!$A$6:$A$108,0)) -> ◎ | J17: =INDEX('02_能力权限主表'!$I$6:$I$108,MATCH($B17,'02_能力权限主表'!$A$6:$A$108,0)) -> ◎ | K17: =INDEX('02_能力权限主表'!$J$6:$J$108,MATCH($B17,'02_能力权限主表'!$A$6:$A$108,0)) -> 专案 | L17: =INDEX('02_能力权限主表'!$L$6:$L$108,MATCH($B17,'02_能力权限主表'!$A$6:$A$108,0)) -> 常规上品起；明确输入、输出、容量不足与失败处理。良品专属标记消费不授权公共状态互转。 | M17: =INDEX('02_能力权限主表'!$M$6:$M$108,MATCH($B17,'02_能力权限主表'!$A$6:$A$108,0)) -> 按具体资产填写参数 | N17: =INDEX('02_能力权限主表'!$N$6:$N$108,MATCH($B17,'02_能力权限主表'!$A$6:$A$108,0)) -> 编制基线；全局规则优先 | O17: =INDEX('02_能力权限主表'!$P$6:$P$108,MATCH($B17,'02_能力权限主表'!$A$6:$A$108,0)) -> R4§七 L252–286；B2§四 L70–165
... A68: OP17 免疫／抵抗 | B68: C065 | C68: =INDEX('02_能力权限主表'!$B$6:$B$108,MATCH($B68,'02_能力权限主表'!$A$6:$A$108,0)) -> 单一免疫／抵抗 | D68: =INDEX('02_能力权限主表'!$C$6:$C$108,MATCH($B68,'02_能力权限主表'!$A$6:$A$108,0)) -> 良品 | E68: =INDEX('02_能力权限主表'!$D$6:$D$108,MATCH($B68,'02_能力权限主表'!$A$6:$A$108,0)) -> — | F68: =INDEX('02_能力权限主表'!$E$6:$E$108,MATCH($B68,'02_能力权限主表'!$A$6:$A$108,0)) -> △ | G68: =INDEX('02_能力权限主表'!$F$6:$F$108,MATCH($B68,'02_能力权限主表'!$A$6:$A$108,0)) -> ○ | H68: =INDEX('02_能力权限主表'!$G$6:$G$108,MATCH($B68,'02_能力权限主表'!$A$6:$A$108,0)) -> ◎ | I68: =INDEX('02_能力权限主表'!$H$6:$H$108,MATCH($B68,'02_能力权限主表'!$A$6:$A$108,0)) -> ◎ | J68: =INDEX('02_能力权限主表'!$I$6:$I$108,MATCH($B68,'02_能力权限主表'!$A$6:$A$108,0)) -> ◎ | K68: =INDEX('02_能力权限主表'!$J$6:$J$108,MATCH($B68,'02_能力权限主表'!$A$6:$A$108,0)) -> 专案 | L68: =INDEX('02_能力权限主表'!$L$6:$L$108,MATCH($B68,'02_能力权限主表'!$A$6:$A$108,0)) -> 明确是阻止施加、降低成功率、减层还是减时间；不因免疫词自动拥有全部权限。 | M68: =INDEX('02_能力权限主表'!$M$6:$M$108,MATCH($B68,'02_能力权限主表'!$A$6:$A$108,0)) -> 按具体资产填写参数 | N68: =INDEX('02_能力权限主表'!$N$6:$N$108,MATCH($B68,'02_能力权限主表'!$A$6:$A$108,0)) -> 编制基线；全局规则优先 | O68: =INDEX('02_能力权限主表'!$P$6:$P$108,MATCH($B68,'02_能力权限主表'!$A$6:$A$108,0)) -> B3§七 L217–260；t01-02 OP17

Sheet 05_空间时序来源权限
A1: T01-03 | 空间时序来源权限
A2: 按能力ID引用02主表；排序不改变对应关系。◎核心 ○常规辅助 △有限候选 ◇明确例外 —非常规 ?待专项；仙品看10表。
A3: 返回说明 | B3: 55 条记录 | 表头可筛选 | 依据中的B1／B2／B3／R4／Q01与原行号可回查12表
A5: 专项 | B5: 能力ID | C5: 能力名称 | D5: 常规最低品级 | E5: 下品 | F5: 凡品 | G5: 良品 | H5: 上品 | I5: 灵品 | J5: 玄品 | K5: 仙品 | L5: 权限边界 | M5: 前置／未决 | N5: 规则状态 | O5: 依据
A6: 空间 | B6: C027 | C6: =INDEX('02_能力权限主表'!$B$6:$B$108,MATCH($B6,'02_能力权限主表'!$A$6:$A$108,0)) -> 局部共享资源池 | D6: =INDEX('02_能力权限主表'!$C$6:$C$108,MATCH($B6,'02_能力权限主表'!$A$6:$A$108,0)) -> 灵品 | E6: =INDEX('02_能力权限主表'!$D$6:$D$108,MATCH($B6,'02_能力权限主表'!$A$6:$A$108,0)) -> — | F6: =INDEX('02_能力权限主表'!$E$6:$E$108,MATCH($B6,'02_能力权限主表'!$A$6:$A$108,0)) -> — | G6: =INDEX('02_能力权限主表'!$F$6:$F$108,MATCH($B6,'02_能力权限主表'!$A$6:$A$108,0)) -> — | H6: =INDEX('02_能力权限主表'!$G$6:$G$108,MATCH($B6,'02_能力权限主表'!$A$6:$A$108,0)) -> ◇ | I6: =INDEX('02_能力权限主表'!$H$6:$H$108,MATCH($B6,'02_能力权限主表'!$A$6:$A$108,0)) -> ○ | J6: =INDEX('02_能力权限主表'!$I$6:$I$108,MATCH($B6,'02_能力权限主表'!$A$6:$A$108,0)) -> ◎ | K6: =INDEX('02_能力权限主表'!$J$6:$J$108,MATCH($B6,'02_能力权限主表'!$A$6:$A$108,0)) -> 专案 | L6: =INDEX('02_能力权限主表'!$L$6:$L$108,MATCH($B6,'02_能力权限主表'!$A$6:$A$108,0)) -> 灵品常规小而明确的绑定／邻接／同领域共享；上品不默认开放，玄品可做成熟网络。 | M6: =INDEX('02_能力权限主表'!$M$6:$M$108,MATCH($B6,'02_能力权限主表'!$A$6:$A$108,0)) -> 按具体资产填写参数 | N6: =INDEX('02_能力权限主表'!$N$6:$N$108,MATCH($B6,'02_能力权限主表'!$A$6:$A$108,0)) -> 编制基线；全局规则优先 | O6: =INDEX('02_能力权限主表'!$P$6:$P$108,MATCH($B6,'02_能力权限主表'!$A$6:$A$108,0)) -> R4§七 L252–286；B2§十三 L398–425
A7: 空间 | B7: C029 | C7: =INDEX('02_能力权限主表'!$B$6:$B$108,MATCH($B7,'02_能力权限主表'!$A$6:$A$108,0)) -> 自身格／直接目标 | D7: =INDEX('02_能力权限主表'!$C$6:$C$108,MATCH($B7,'02_能力权限主表'!$A$6:$A$108,0)) -> 下品 | E7: =INDEX('02_能力权限主表'!$D$6:$D$108,MATCH($B7,'02_能力权限主表'!$A$6:$A$108,0)) -> ◎ | F7: =INDEX('02_能力权限主表'!$E$6:$E$108,MATCH($B7,'02_能力权限主表'!$A$6:$A$108,0)) -> ◎ | G7: =INDEX('02_能力权限主表'!$F$6:$F$108,MATCH($B7,'02_能力权限主表'!$A$6:$A$108,0)) -> ◎ | H7: =INDEX('02_能力权限主表'!$G$6:$G$108,MATCH($B7,'02_能力权限主表'!$A$6:$A$108,0)) -> ◎ | I7: =INDEX('02_能力权限主表'!$H$6:$H$108,MATCH($B7,'02_能力权限主表'!$A$6:$A$108,0)) -> ◎ | J7: =INDEX('02_能力权限主表'!$I$6:$I$108,MATCH($B7,'02_能力权限主表'!$A$6:$A$108,0)) -> ◎ | K7: =INDEX('02_能力权限主表'!$J$6:$J$108,MATCH($B7,'02_能力权限主表'!$A$6:$A$108,0)) -> 专案 | L7: =INDEX('02_能力权限主表'!$L$6:$L$108,MATCH($B7,'02_能力权限主表'!$A$6:$A$108,0)) -> 目标资格与来源资格分别检查。 | M7: =INDEX('02_能力权限主表'!$M$6:$M$108,MATCH($B7,'02_能力权限主表'!$A$6:$A$108,0)) -> 按具体资产填写参数 | N7: =INDEX('02_能力权限主表'!$N$6:$N$108,MATCH($B7,'02_能力权限主表'!$A$6:$A$108,0)) -> 编制基线；全局规则优先 | O7: =INDEX('02_能力权限主表'!$P$6:$P$108,MATCH($B7,'02_能力权限主表'!$A$6:$A$108,0)) -> B3§九 L293–313
A8: 空间 | B8: C030 | C8: =INDEX('02_能力权限主表'!$B$6:$B$108,MATCH($B8,'02_能力权限主表'!$A$6:$A$108,0)) -> 正交邻接 | D8: =INDEX('02_能力权限主表'!$C$6:$C$108,MATCH($B8,'02_能力权限主表'!$A$6:$A$108,0)) -> 良品 | E8: =INDEX('02_能力权限主表'!$D$6:$D$108,MATCH($B8,'02_能力权限主表'!$A$6:$A$108,0)) -> — | F8: =INDEX('02_能力权限主表'!$E$6:$E$108,MATCH($B8,'02_能力权限主表'!$A$6:$A$108,0)) -> — | G8: =INDEX('02_能力权限主表'!$F$6:$F$108,MATCH($B8,'02_能力权限主表'!$A$6:$A$108,0)) -> ◎ | H8: =INDEX('02_能力权限主表'!$G$6:$G$108,MATCH($B8,'02_能力权限主表'!$A$6:$A$108,0)) -> ◎ | I8: =INDEX('02_能力权限主表'!$H$6:$H$108,MATCH($B8,'02_能力权限主表'!$A$6:$A$108,0)) -> ◎ | J8: =INDEX('02_能力权限主表'!$I$6:$I$108,MATCH($B8,'02_能力权限主表'!$A$6:$A$108,0)) -> ◎ | K8: =INDEX('02_能力权限主表'!$J$6:$J$108,MATCH($B8,'02_能力权限主表'!$A$6:$A$108,0)) -> 专案 | L8: =INDEX('02_能力权限主表'!$L$6:$L$108,MATCH($B8,'02_能力权限主表'!$A$6:$A$108,0)) -> 常规简单邻接仍从良品开放；下品两组与凡品三组具名防具联动例外见本行。固定坐标和尺寸按04，摆盘与战斗不可旋转。 | M8: =INDEX('02_能力权限主表'!$M$6:$M$108,MATCH($B8,'02_能力权限主表'!$A$6:$A$108,0)) -> 按具体资产填写参数 | N8: =INDEX('02_能力权限主表'!$N$6:$N$108,MATCH($B8,'02_能力权限主表'!$A$6:$A$108,0)) -> 下品Q01及本批凡品具名例外；常规门槛未整体下放。 | O8: =INDEX('02_能力权限主表'!$P$6:$P$108,MATCH($B8,'02_能力权限主表'!$A$6:$A$108,0)) -> 原编制基线；t01-08下品Q01及后续品级更正；t01-08凡品第2／3批与用户直接更正、FP02；2026-09-28；2026-09-29用户RV05～RV09；docs/t01-08_朋友反馈核对与逐项处理_2026-09-29.md
A9: 空间 | B9: C031 | C9: =INDEX('02_能力权限主表'!$B$6:$B$108,MATCH($B9,'02_能力权限主表'!$A$6:$A$108,0)) -> 定向邻接 | D9: =INDEX('02_能力权限主表'!$C$6:$C$108,MATCH($B9,'02_能力权限主表'!$A$6:$A$108,0)) -> 良品 | E9: =INDEX('02_能力权限主表'!$D$6:$D$108,MATCH($B9,'02_能力权限主表'!$A$6:$A$108,0)) -> — | F9: =INDEX('02_能力权限主表'!$E$6:$E$108,MATCH($B9,'02_能力权限主表'!$A$6:$A$108,0)) -> — | G9: =INDEX('02_能力权限主表'!$F$6:$F$108,MATCH($B9,'02_能力权限主表'!$A$6:$A$108,0)) -> ○ | H9: =INDEX('02_能力权限主表'!$G$6:$G$108,MATCH($B9,'02_能力权限主表'!$A$6:$A$108,0)) -> ◎ | I9: =INDEX('02_能力权限主表'!$H$6:$H$108,MATCH($B9,'02_能力权限主表'!$A$6:$A$108,0)) -> ◎ | J9: =INDEX('02_能力权限主表'!$I$6:$I$108,MATCH($B9,'02_能力权限主表'!$A$6:$A$108,0)) -> ◎ | K9: =INDEX('02_能力权限主表'!$J$6:$J$108,MATCH($B9,'02_能力权限主表'!$A$6:$A$108,0)) -> 专案 | L9: =INDEX('02_能力权限主表'!$L$6:$L$108,MATCH($B9,'02_能力权限主表'!$A$6:$A$108,0)) -> 按阵盘固定坐标明确方向；不可旋转，不隐含连线网络。 | M9: =INDEX('02_能力权限主表'!$M$6:$M$108,MATCH($B9,'02_能力权限主表'!$A$6:$A$108,0)) -> 按具体资产填写参数 | N9: =INDEX('02_能力权限主表'!$N$6:$N$108,MATCH($B9,'02_能力权限主表'!$A$6:$A$108,0)) -> 编制基线；全局规则优先 | O9: =INDEX('02_能力权限主表'!$P$6:$P$108,MATCH($B9,'02_能力权限主表'!$A$6:$A$108,0)) -> B3§九 L293–313
A10: 空间 | B10: C032 | C10: =INDEX('02_能力权限主表'!$B$6:$B$108,MATCH($B10,'02_能力权限主表'!$A$6:$A$108,0)) -> 边缘／角落／同行／同列 | D10: =INDEX('02_能力权限主表'!$C$6:$C$108,MATCH($B10,'02_能力权限主表'!$A$6:$A$108,0)) -> 良品 | E10: =INDEX('02_能力权限主表'!$D$6:$D$108,MATCH($B10,'02_能力权限主表'!$A$6:$A$108,0)) -> — | F10: =INDEX('02_能力权限主表'!$E$6:$E$108,MATCH($B10,'02_能力权限主表'!$A$6:$A$108,0)) -> — | G10: =INDEX('02_能力权限主表'!$F$6:$F$108,MATCH($B10,'02_能力权限主表'!$A$6:$A$108,0)) -> ○ | H10: =INDEX('02_能力权限主表'!$G$6:$G$108,MATCH($B10,'02_能力权限主表'!$A$6:$A$108,0)) -> ◎ | I10: =INDEX('02_能力权限主表'!$H$6:$H$108,MATCH($B10,'02_能力权限主表'!$A$6:$A$108,0)) -> ◎ | J10: =INDEX('02_能力权限主表'!$I$6:$I$108,MATCH($B10,'02_能力权限主表'!$A$6:$A$108,0)) -> ◎ | K10: =INDEX('02_能力权限主表'!$J$6:$J$108,MATCH($B10,'02_能力权限主表'!$A$6:$A$108,0)) -> 专案 | L10: =INDEX('02_能力权限主表'!$L$6:$L$108,MATCH($B10,'02_能力权限主表'!$A$6:$A$108,0)) -> 只作简单位置条件；动态范围与多锚点另查。 | M10: =INDEX('02_能力权限主表'!$M$6:$M$108,MATCH($B10,'02_能力权限主表'!$A$6:$A$108,0)) -> 按具体资产填写参数 | N10: =INDEX('02_能力权限主表'!$N$6:$N$108,MATCH($B10,'02_能力权限主表'!$A$6:$A$108,0)) -> 编制基线；全局规则优先 | O10: =INDEX('02_能力权限主表'!$P$6:$P$108,MATCH($B10,'02_能力权限主表'!$A$6:$A$108,0)) -> B3§九 L293–313
A11: 空间 | B11: C033 | C11: =INDEX('02_能力权限主表'!$B$6:$B$108,MATCH($B11,'02_能力权限主表'!$A$6:$A$108,0)) -> 距离N格条件 | D11: =INDEX('02_能力权限主表'!$C$6:$C$108,MATCH($B11,'02_能力权限主表'!$A$6:$A$108,0)) -> 上品 | E11: =INDEX('02_能力权限主表'!$D$6:$D$108,MATCH($B11,'02_能力权限主表'!$A$6:$A$108,0)) -> — | F11: =INDEX('02_能力权限主表'!$E$6:$E$108,MATCH($B11,'02_能力权限主表'!$A$6:$A$108,0)) -> — | G11: =INDEX('02_能力权限主表'!$F$6:$F$108,MATCH($B11,'02_能力权限主表'!$A$6:$A$108,0)) -> △ | H11: =INDEX('02_能力权限主表'!$G$6:$G$108,MATCH($B11,'02_能力权限主表'!$A$6:$A$108,0)) -> ◎ | I11: =INDEX('02_能力权限主表'!$H$6:$H$108,MATCH($B11,'02_能力权限主表'!$A$6:$A$108,0)) -> ◎ | J11: =INDEX('02_能力权限主表'!$I$6:$I$108,MATCH($B11,'02_能力权限主表'!$A$6:$A$108,0)) -> ◎ | K11: =INDEX('02_能力权限主表'!$J$6:$J$108,MATCH($B11,'02_能力权限主表'!$A$6:$A$108,0)) -> 专案 | L11: =INDEX('02_能力权限主表'!$L$6:$L$108,MATCH($B11,'02_能力权限主表'!$A$6:$A$108,0)) -> 良品少量简单距离条件；距离度量与纳入单元明确。 | M11: =INDEX('02_能力权限主表'!$M$6:$M$108,MATCH($B11,'02_能力权限主表'!$A$6:$A$108,0)) -> 按具体资产填写参数 | N11: =INDEX('02_能力权限主表'!$N$6:$N$108,MATCH($B11,'02_能力权限主表'!$A$6:$A$108,0)) -> 编制基线；全局规则优先 | O11: =INDEX('02_能力权限主表'!$P$6:$P$108,MATCH($B11,'02_能力权限主表'!$A$6:$A$108,0)) -> B3§九 L293–313
A12: 空间 | B12: C034 | C12: =INDEX('02_能力权限主表'!$B$6:$B$108,MATCH($B12,'02_能力权限主表'!$A$6:$A$108,0)) -> 动态领域 | D12: =INDEX('02_能力权限主表'!$C$6:$C$108,MATCH($B12,'02_能力权限主表'!$A$6:$A$108,0)) -> 上品 | E12: =INDEX('02_能力权限主表'!$D$6:$D$108,MATCH($B12,'02_能力权限主表'!$A$6:$A$108,0)) -> — | F12: =INDEX('02_能力权限主表'!$E$6:$E$108,MATCH($B12,'02_能力权限主表'!$A$6:$A$108,0)) -> — | G12: =INDEX('02_能力权限主表'!$F$6:$F$108,MATCH($B12,'02_能力权限主表'!$A$6:$A$108,0)) -> — | H12: =INDEX('02_能力权限主表'!$G$6:$G$108,MATCH($B12,'02_能力权限主表'!$A$6:$A$108,0)) -> ◎ | I12: =INDEX('02_能力权限主表'!$H$6:$H$108,MATCH($B12,'02_能力权限主表'!$A$6:$A$108,0)) -> ◎ | J12: =INDEX('02_能力权限主表'!$I$6:$I$108,MATCH($B12,'02_能力权限主表'!$A$6:$A$108,0)) -> ◎ | K12: =INDEX('02_能力权限主表'!$J$6:$J$108,MATCH($B12,'02_能力权限主表'!$A$6:$A$108,0)) -> 专案 | L12: =INDEX('02_能力权限主表'!$L$6:$L$108,MATCH($B12,'02_能力权限主表'!$A$6:$A$108,0)) -> 上品通常一个作用核心；动态进入／离开、目标快照由具体资产选择。 | M12: =INDEX('02_能力权限主表'!$M$6:$M$108,MATCH($B12,'02_能力权限主表'!$A$6:$A$108,0)) -> 按具体资产填写参数 | N12: =INDEX('02_能力权限主表'!$N$6:$N$108,MATCH($B12,'02_能力权限主表'!$A$6:$A$108,0)) -> 编制基线；全局规则优先 | O12: =INDEX('02_能力权限主表'!$P$6:$P$108,MATCH($B12,'02_能力权限主表'!$A$6:$A$108,0)) -> B2§五 L166–199；B3§九 L293–313
A13: 空间 | B13: C035 | C13: =INDEX('02_能力权限主表'!$B$6:$B$108,MATCH($B13,'02_能力权限主表'!$A$6:$A$108,0)) -> 依附／绑定关系 | D13: =INDEX('02_能力权限主表'!$C$6:$C$108,MATCH($B13,'02_能力权限主表'!$A$6:$A$108,0)) -> 良品 | E13: =INDEX('02_能力权限主表'!$D$6:$D$108,MATCH($B13,'02_能力权限主表'!$A$6:$A$108,0)) -> — | F13: =INDEX('02_能力权限主表'!$E$6:$E$108,MATCH($B13,'02_能力权限主表'!$A$6:$A$108,0)) -> — | G13: =INDEX('02_能力权限主表'!$F$6:$F$108,MATCH($B13,'02_能力权限主表'!$A$6:$A$108,0)) -> ○ | H13: =INDEX('02_能力权限主表'!$G$6:$G$108,MATCH($B13,'02_能力权限主表'!$A$6:$A$108,0)) -> ◎ | I13: =INDEX('02_能力权限主表'!$H$6:$H$108,MATCH($B13,'02_能力权限主表'!$A$6:$A$108,0)) -> ◎ | J13: =INDEX('02_能力权限主表'!$I$6:$I$108,MATCH($B13,'02_能力权限主表'!$A$6:$A$108,0)) -> ◎ | K13: =INDEX('02_能力权限主表'!$J$6:$J$108,MATCH($B13,'02_能力权限主表'!$A$6:$A$108,0)) -> 专案 | L13: =INDEX('02_能力权限主表'!$L$6:$L$108,MATCH($B13,'02_能力权限主表'!$A$6:$A$108,0)) -> 绑定不赋予免费调用权，不自动转移来源或抵消控制。 | M13: =INDEX('02_能力权限主表'!$M$6:$M$108,MATCH($B13,'02_能力权限主表'!$A$6:$A$108,0)) -> 按具体资产填写参数 | N13: =INDEX('02_能力权限主表'!$N$6:$N$108,MATCH($B13,'02_能力权限主表'!$A$6:$A$108,0)) -> 编制基线；全局规则优先 | O13: =INDEX('02_能力权限主表'!$P$6:$P$108,MATCH($B13,'02_能力权限主表'!$A$6:$A$108,0)) -> B3§九 L293–313
A14: 空间 | B14: C036 | C14: =INDEX('02_能力权限主表'!$B$6:$B$108,MATCH($B14,'02_能力权限主表'!$A$6:$A$108,0)) -> 多器具连续结构／连线／阵眼 | D14: =INDEX('02_能力权限主表'!$C$6:$C$108,MATCH($B14,'02_能力权限主表'!$A$6:$A$108,0)) -> 灵品 | E14: =INDEX('02_能力权限主表'!$D$6:$D$108,MATCH($B14,'02_能力权限主表'!$A$6:$A$108,0)) -> — | F14: =INDEX('02_能力权限主表'!$E$6:$E$108,MATCH($B14,'02_能力权限主表'!$A$6:$A$108,0)) -> — | G14: =INDEX('02_能力权限主表'!$F$6:$F$108,MATCH($B14,'02_能力权限主表'!$A$6:$A$108,0)) -> — | H14: =INDEX('02_能力权限主表'!$G$6:$G$108,MATCH($B14,'02_能力权限主表'!$A$6:$A$108,0)) -> △ | I14: =INDEX('02_能力权限主表'!$H$6:$H$108,MATCH($B14,'02_能力权限主表'!$A$6:$A$108,0)) -> ○ | J14: =INDEX('02_能力权限主表'!$I$6:$I$108,MATCH($B14,'02_能力权限主表'!$A$6:$A$108,0)) -> ◎ | K14: =INDEX('02_能力权限主表'!$J$6:$J$108,MATCH($B14,'02_能力权限主表'!$A$6:$A$108,0)) -> 专案 | L14: =INDEX('02_能力权限主表'!$L$6:$L$108,MATCH($B14,'02_能力权限主表'!$A$6:$A$108,0)) -> 上品仅有限候选，灵品小型关系，玄品成熟阵式；T07具体规则未因此完成。 | M14: =INDEX('02_能力权限主表'!$M$6:$M$108,MATCH($B14,'02_能力权限主表'!$A$6:$A$108,0)) -> 按具体资产填写参数 | N14: =INDEX('02_能力权限主表'!$N$6:$N$108,MATCH($B14,'02_能力权限主表'!$A$6:$A$108,0)) -> 编制基线；全局规则优先 | O14: =INDEX('02_能力权限主表'!$P$6:$P$108,MATCH($B14,'02_能力权限主表'!$A$6:$A$108,0)) -> B3§九 L293–313；B2§二十二 L612–638
A15: 空间 | B15: C037 | C15: =INDEX('02_能力权限主表'!$B$6:$B$108,MATCH($B15,'02_能力权限主表'!$A$6:$A$108,0)) -> 改变空间规则本身 | D15: =INDEX('02_能力权限主表'!$C$6:$C$108,MATCH($B15,'02_能力权限主表'!$A$6:$A$108,0)) -> 玄品 | E15: =INDEX('02_能力权限主表'!$D$6:$D$108,MATCH($B15,'02_能力权限主表'!$A$6:$A$108,0)) -> — | F15: =INDEX('02_能力权限主表'!$E$6:$E$108,MATCH($B15,'02_能力权限主表'!$A$6:$A$108,0)) -> — | G15: =INDEX('02_能力权限主表'!$F$6:$F$108,MATCH($B15,'02_能力权限主表'!$A$6:$A$108,0)) -> — | H15: =INDEX('02_能力权限主表'!$G$6:$G$108,MATCH($B15,'02_能力权限主表'!$A$6:$A$108,0)) -> — | I15: =INDEX('02_能力权限主表'!$H$6:$H$108,MATCH($B15,'02_能力权限主表'!$A$6:$A$108,0)) -> △ | J15: =INDEX('02_能力权限主表'!$I$6:$I$108,MATCH($B15,'02_能力权限主表'!$A$6:$A$108,0)) -> ◎ | K15: =INDEX('02_能力权限主表'!$J$6:$J$108,MATCH($B15,'02_能力权限主表'!$A$6:$A$108,0)) -> 专案 | L15: =INDEX('02_能力权限主表'!$L$6:$L$108,MATCH($B15,'02_能力权限主表'!$A$6:$A$108,0)) -> 必须指明改变的空间判定；已有位置、尺寸、路径规则不被品级名自动覆盖。 | M15: =INDEX('02_能力权限主表'!$M$6:$M$108,MATCH($B15,'02_能力权限主表'!$A$6:$A$108,0)) -> 按具体资产填写参数 | N15: =INDEX('02_能力权限主表'!$N$6:$N$108,MATCH($B15,'02_能力权限主表'!$A$6:$A$108,0)) -> 编制基线；全局规则优先 | O15: =INDEX('02_能力权限主表'!$P$6:$P$108,MATCH($B15,'02_能力权限主表'!$A$6:$A$108,0)) -> B3§九 L293–313
A16: 时序 | B16: C003 | C16: =INDEX('02_能力权限主表'!$B$6:$B$108,MATCH($B16,'02_能力权限主表'!$A$6:$A$108,0)) -> 基础轮转与手动／自动模式 | D16: =INDEX('02_能力权限主表'!$C$6:$C$108,MATCH($B16,'02_能力权限主表'!$A$6:$A$108,0)) -> 下品 | E16: =INDEX('02_能力权限主表'!$D$6:$D$108,MATCH($B16,'02_能力权限主表'!$A$6:$A$108,0)) -> ◎ | F16: =INDEX('02_能力权限主表'!$E$6:$E$108,MATCH($B16,'02_能力权限主表'!$A$6:$A$108,0)) -> ◎ | G16: =INDEX('02_能力权限主表'!$F$6:$F$108,MATCH($B16,'02_能力权限主表'!$A$6:$A$108,0)) -> ◎ | H16: =INDEX('02_能力权限主表'!$G$6:$G$108,MATCH($B16,'02_能力权限主表'!$A$6:$A$108,0)) -> ◎ | I16: =INDEX('02_能力权限主表'!$H$6:$H$108,MATCH($B16,'02_能力权限主表'!$A$6:$A$108,0)) -> ◎ | J16: =INDEX('02_能力权限主表'!$I$6:$I$108,MATCH($B16,'02_能力权限主表'!$A$6:$A$108,0)) -> ◎ | K16: =INDEX('02_能力权限主表'!$J$6:$J$108,MATCH($B16,'02_能力权限主表'!$A$6:$A$108,0)) -> 专案 | L16: =INDEX('02_能力权限主表'!$L$6:$L$108,MATCH($B16,'02_能力权限主表'!$A$6:$A$108,0)) -> 正常发动仍检查目标、资源、控制等；不可用低品级理由省略后台判断。 | M16: =INDEX('02_能力权限主表'!$M$6:$M$108,MATCH($B16,'02_能力权限主表'!$A$6:$A$108,0)) -> 按具体资产填写参数 | N16: =INDEX('02_能力权限主表'!$N$6:$N$108,MATCH($B16,'02_能力权限主表'!$A$6:$A$108,0)) -> 编制基线；全局规则优先 | O16: =INDEX('02_能力权限主表'!$P$6:$P$108,MATCH($B16,'02_能力权限主表'!$A$6:$A$108,0)) -> B3§三 L65–128；核心01§1.4
A17: 时序 | B17: C012 | C17: =INDEX('02_能力权限主表'!$B$6:$B$108,MATCH($B17,'02_能力权限主表'!$A$6:$A$108,0)) -> 待发／预备式 | D17: =INDEX('02_能力权限主表'!$C$6:$C$108,MATCH($B17,'02_能力权限主表'!$A$6:$A$108,0)) -> 良品 | E17: =INDEX('02_能力权限主表'!$D$6:$D$108,MATCH($B17,'02_能力权限主表'!$A$6:$A$108,0)) -> — | F17: =INDEX('02_能力权限主表'!$E$6:$E$108,MATCH($B17,'02_能力权限主表'!$A$6:$A$108,0)) -> △ | G17: =INDEX('02_能力权限主表'!$F$6:$F$108,MATCH($B17,'02_能力权限主表'!$A$6:$A$108,0)) -> ○ | H17: =INDEX('02_能力权限主表'!$G$6:$G$108,MATCH($B17,'02_能力权限主表'!$A$6:$A$108,0)) -> ◎ | I17: =INDEX('02_能力权限主表'!$H$6:$H$108,MATCH($B17,'02_能力权限主表'!$A$6:$A$108,0)) -> ◎ | J17: =INDEX('02_能力权限主表'!$I$6:$I$108,MATCH($B17,'02_能力权限主表'!$A$6:$A$108,0)) -> ◎ | K17: =INDEX('02_能力权限主表'!$J$6:$J$108,MATCH($B17,'02_能力权限主表'!$A$6:$A$108,0)) -> 专案 | L17: =INDEX('02_能力权限主表'!$L$6:$L$108,MATCH($B17,'02_能力权限主表'!$A$6:$A$108,0)) -> 等待资格与支付时点按01；已定冻结／禁用／沉默对旧待发资格的处理继续生效。 | M17: =INDEX('02_能力权限主表'!$M$6:$M$108,MATCH($B17,'02_能力权限主表'!$A$6:$A$108,0)) -> 按具体资产填写参数 | N17: =INDEX('02_能力权限主表'!$N$6:$N$108,MATCH($B17,'02_能力权限主表'!$A$6:$A$108,0)) -> 编制基线；全局规则优先 | O17: =INDEX('02_能力权限主表'!$P$6:$P$108,MATCH($B17,'02_能力权限主表'!$A$6:$A$108,0)) -> B3§三 L65–128；核心01§1.4、§1.8
... A60: 基础 | B60: C004 | C60: =INDEX('02_能力权限主表'!$B$6:$B$108,MATCH($B60,'02_能力权限主表'!$A$6:$A$108,0)) -> 标准事件、叠加与资格检查 | D60: =INDEX('02_能力权限主表'!$C$6:$C$108,MATCH($B60,'02_能力权限主表'!$A$6:$A$108,0)) -> 全品级基础 | E60: =INDEX('02_能力权限主表'!$D$6:$D$108,MATCH($B60,'02_能力权限主表'!$A$6:$A$108,0)) -> 基础 | F60: =INDEX('02_能力权限主表'!$E$6:$E$108,MATCH($B60,'02_能力权限主表'!$A$6:$A$108,0)) -> 基础 | G60: =INDEX('02_能力权限主表'!$F$6:$F$108,MATCH($B60,'02_能力权限主表'!$A$6:$A$108,0)) -> 基础 | H60: =INDEX('02_能力权限主表'!$G$6:$G$108,MATCH($B60,'02_能力权限主表'!$A$6:$A$108,0)) -> 基础 | I60: =INDEX('02_能力权限主表'!$H$6:$H$108,MATCH($B60,'02_能力权限主表'!$A$6:$A$108,0)) -> 基础 | J60: =INDEX('02_能力权限主表'!$I$6:$I$108,MATCH($B60,'02_能力权限主表'!$A$6:$A$108,0)) -> 基础 | K60: =INDEX('02_能力权限主表'!$J$6:$J$108,MATCH($B60,'02_能力权限主表'!$A$6:$A$108,0)) -> 基础 | L60: =INDEX('02_能力权限主表'!$L$6:$L$108,MATCH($B60,'02_能力权限主表'!$A$6:$A$108,0)) -> 所有器具都产生合法事件并遵守基础叠加、去重、暴击与命中规则；不等于带特色监听词条。 | M60: =INDEX('02_能力权限主表'!$M$6:$M$108,MATCH($B60,'02_能力权限主表'!$A$6:$A$108,0)) -> 按具体资产填写参数 | N60: =INDEX('02_能力权限主表'!$N$6:$N$108,MATCH($B60,'02_能力权限主表'!$A$6:$A$108,0)) -> 编制基线；全局规则优先 | O60: =INDEX('02_能力权限主表'!$P$6:$P$108,MATCH($B60,'02_能力权限主表'!$A$6:$A$108,0)) -> R4§九 L312–355；B3§三 L65–128

Sheet 06_复杂度与投入
A1: T01-03 | 复杂度与投入
A2: 编制基线 · 2026-09-26 | 第4份复查优先；用户明确答复与全局定案优先 | 设计资料，未接入游戏
A3: 返回说明 | B3: 37 条记录 | 表头可筛选 | 依据中的B1／B2／B3／R4／Q01与原行号可回查12表
A5: 记录ID | B5: 分类 | C5: 标尺／字段 | D5: 设计要求 | E5: 边界与误区 | F5: 性质 | G5: 依据
A6: CX01 | B6: L复杂度 | C6: L0 基础器具层 | D6: 类别基础攻击、防护、恢复；基本参数差异。 | E6: 不是强度公式；不按模块数量、文字长度或效果行数判级。 | F6: 设计标尺 | G6: B1§三 L129–247；R4§五 L181–224
A7: CX02 | B7: L复杂度 | C7: L1 单一附加性质 | D7: 一个直接、容易理解的属性或特殊效果。 | E7: 不是强度公式；不按模块数量、文字长度或效果行数判级。 | F7: 设计标尺 | G7: B1§三 L129–247；R4§五 L181–224
A8: CX03 | B8: L复杂度 | C8: L2 条件机制层 | D8: 简单监听、计数、状态读层、邻接、追击等特色。 | E8: 不是强度公式；不按模块数量、文字长度或效果行数判级。 | F8: 设计标尺 | G8: B1§三 L129–247；R4§五 L181–224
A9: CX04 | B9: L复杂度 | C9: L3 系统操纵层 | D9: 成熟状态消费／转换、领域、他器CD、控制、恢复防护转换。 | E9: 不是强度公式；不按模块数量、文字长度或效果行数判级。 | F9: 设计标尺 | G9: B1§三 L129–247；R4§五 L181–224
A10: CX05 | B10: L复杂度 | C10: L4 双核心耦合层 | D10: 两个成熟机制各有可管理玩法，一个的运行实质性改变另一个；不要求反馈闭环。 | E10: 不是强度公式；不按模块数量、文字长度或效果行数判级。 | F10: 设计标尺 | G10: B1§三 L129–247；R4§五 L181–224
A11: CX06 | B11: L复杂度 | C11: L5 规则改写层 | D11: 限定范围内改变发动、来源、主动／派生身份、连携合法性或成熟阵式规则。数值／窗口辅助另分级。 | E11: 不是强度公式；不按模块数量、文字长度或效果行数判级。 | F11: 设计标尺 | G11: B1§三 L129–247；R4§五 L181–224
A12: CX07 | B12: G判断维度 | C12: G1 机制深度 | D12: 判断与兑现经过几层？ | E12: 同时看实际收益、操作负担、投入和取得条件；选择多不保证价值高。 | F12: 设计标尺 | G12: B1§二 L96–128；R4§六 L225–251
A13: CX08 | B13: G判断维度 | C13: G2 系统跨度 | D13: 连接几个系统、各自是否有独立玩法？ | E13: 同时看实际收益、操作负担、投入和取得条件；选择多不保证价值高。 | F13: 设计标尺 | G13: B1§二 L96–128；R4§六 L225–251
A14: CX09 | B14: G判断维度 | C14: G3 条件复杂度 | D14: 是否监听事件、计数、状态和空间？ | E14: 同时看实际收益、操作负担、投入和取得条件；选择多不保证价值高。 | F14: 设计标尺 | G14: B1§二 L96–128；R4§六 L225–251
A15: CX10 | B15: G判断维度 | C15: G4 战场影响范围 | D15: 自身、邻接、领域或敌方全盘？ | E15: 同时看实际收益、操作负担、投入和取得条件；选择多不保证价值高。 | F15: 设计标尺 | G15: B1§二 L96–128；R4§六 L225–251
A16: CX11 | B16: G判断维度 | C16: G5 构筑中心度 | D16: 是辅助还是可围绕其组织构筑？ | E16: 同时看实际收益、操作负担、投入和取得条件；选择多不保证价值高。 | F16: 设计标尺 | G16: B1§二 L96–128；R4§六 L225–251
... A42: CX37 | B42: 机制中心 | C42: 基础动作与特色中心 | D42: 基础斩击／恢复不加一个中心；单条3次攻击→触发即使调用多个M模块仍可只有一个中心。 | E42: 两条独立数值加成不是两个成熟机制；L4看实质耦合。 | F42: 设计标尺 | G42: B1§五 L266–290～九；R4§五 L181–224

Sheet 07_风险与审核
A1: T01-03 | 风险与审核
A2: 编制基线 · 2026-09-26 | 第4份复查优先；用户明确答复与全局定案优先 | 设计资料，未接入游戏
A3: 返回说明 | B3: 26 条记录 | 表头可筛选 | 依据中的B1／B2／B3／R4／Q01与原行号可回查12表
A5: 检查ID | B5: 分类 | C5: 检查项 | D5: 审查要求 | E5: 边界／所需证据 | F5: 依据
A6: AK01 | B6: 风险标签 | C6: RISK_SOURCE_REWRITE｜来源身份改写 | D6: 枚举获得／保留／不获得的暴击、状态、监听、共鸣、连携资格；检查来源未被抹去。 | E6: 这是审核触发条件，不等于已经发现或禁止该能力。 | F6: B3§十九 L570–598～二十一；R4§十 L356–393
A7: AK02 | B7: 风险标签 | C7: RISK_ACTIVATION_REWRITE｜发动方式改写 | D7: 检查原CD、待发、外部调用、控制、退出模式与已支付费用。 | E7: 这是审核触发条件，不等于已经发现或禁止该能力。 | F7: B3§十九 L570–598～二十一；R4§十 L356–393
A8: AK03 | B8: 风险标签 | C8: RISK_CHAIN_LOOP｜触发循环 | D8: 用真实事件与独立机会检验可终止性；不重复通知、不复制整链，不一刀切吞真实多次机会。 | E8: 这是审核触发条件，不等于已经发现或禁止该能力。 | F8: B3§十九 L570–598～二十一；R4§十 L356–393
A9: AK04 | B9: 风险标签 | C9: RISK_CONTROL_LOCK｜控制长期覆盖 | D9: 按组合后的受控时间、空档、重新施加、解除与抗性检查；单次短不等于组合轻。 | E9: 这是审核触发条件，不等于已经发现或禁止该能力。 | F9: B3§十九 L570–598～二十一；R4§十 L356–393
A10: AK05 | B10: 风险标签 | C10: RISK_RESOURCE_LOOP｜资源反馈与产出 | D10: 净产资源可以成立；查时间／阵位／投入、零时间无限触发、重复收益和绕过支付。 | E10: 这是审核触发条件，不等于已经发现或禁止该能力。 | F10: B3§十九 L570–598～二十一；R4§十 L356–393
A11: AK06 | B11: 风险标签 | C11: RISK_CAPACITY_RULE｜容量与已有层数 | D11: 区分容量主体、变更原因、当前层数与共鸣；主角换装立即截层，禁用保留固有容量。 | E11: 这是审核触发条件，不等于已经发现或禁止该能力。 | F11: B3§十九 L570–598～二十一；R4§十 L356–393
A12: AK07 | B12: 十步流程 | C12: 1 类别与概念投入 | D12: 确认器具类别、基础动作，同时写预期阶段、占格、节奏、费用、范围、材料来源类型。 | E12: 六项粗投入不能全空。 | F12: B3§二十二 L657–673；R4§十 L356–393；R4§十二 L422–446
A13: AK08 | B13: 十步流程 | C13: 2 一句话机制中心 | D13: 写玩家需要理解和管理的核心；分开基础动作与特色机制。 | E13: 区分一个中心、多效果并列与两个成熟核心。 | F13: B3§二十二 L657–673；R4§十 L356–393；R4§十二 L422–446
