Workbook

Sheet 00_说明
A1: 142项物品 · 基准价首版建议
A3: 2026-10-12｜蓝色数字可调整；黑色为公式结果；所有逐件基准价均为建议。
A5: 玩家买入因数 | B5: 1.5 | C5: 向上取整 | D5: 已确认：买入基准价的150%。
A6: 玩家卖出因数 | B6: 0.5 | C6: 向下取整 | D6: 已确认：卖出基准价的50%，不基于买价再折算。
A8: 范围：36武器＋36防具＋22法器＋16丹药＋5暗器＋14妖材＋4药材＋2矿石＋7阵盘。已覆盖当前142种库存定义；同名不同品级按独立ID计。
A11: 本表未写入游戏价目。高阶阵盘价格为阶段梯度估值，尚无中后期收入依据；定价不等于青石镇有现货，也不代表解除任务／收藏／上阵物品禁售。
A14: 品类 | B14: 数量 | C14: 最低基准价 | D14: 最高基准价 | E14: 定价侧重
A15: 武器 | B15: =COUNTA('01_全部价目'!D5:D40) -> 36 | C15: =MIN('01_全部价目'!E5:E40) -> 30 | D15: =MAX('01_全部价目'!E5:E40) -> 216 | E15: 伤害、轮转、耗体、占格与条件状态共同判断。
A16: 防具 | B16: =COUNTA('01_全部价目'!D41:D76) -> 36 | C16: =MIN('01_全部价目'!E41:E76) -> 12 | D16: =MAX('01_全部价目'!E41:E76) -> 176 | E16: 区分护甲上限、实际回甲与受击准备；上限不等于开战满甲。
A17: 法器 | B17: =COUNTA('01_全部价目'!D77:D98) -> 22 | C17: =MIN('01_全部价目'!E77:E98) -> 80 | D17: =MAX('01_全部价目'!E77:E98) -> 228 | E17: 可重复使用，考虑供能、回复上限和耗灵。
A18: 丹药 | B18: =COUNTA('01_全部价目'!D99:D114) -> 16 | C18: =MIN('01_全部价目'!E99:E114) -> 8 | D18: =MAX('01_全部价目'!E99:E114) -> 24 | E18: 按单份计价；补给可负担，专门抗性药保持低价。
A19: 暗器 | B19: =COUNTA('01_全部价目'!D115:D119) -> 5 | C19: =MIN('01_全部价目'!E115:E119) -> 12 | D19: =MAX('01_全部价目'!E115:E119) -> 20 | E19: 按单件计价；零资源爆发仍会永久消耗物品。
A20: 妖材 | B20: =COUNTA('01_全部价目'!D120:D133) -> 14 | C20: =MIN('01_全部价目'!E120:E133) -> 16 | D20: =MAX('01_全部价目'!E120:E133) -> 80 | E20: 只计材料价值；掉率可参考，制作需求仍待定。
A21: 药材 | B21: =COUNTA('01_全部价目'!D134:D137) -> 4 | C21: =MIN('01_全部价目'!E134:E137) -> 4 | D21: =MAX('01_全部价目'!E134:E137) -> 6 | E21: 低价基础原料；不虚构配方数量。
A22: 矿石 | B22: =COUNTA('01_全部价目'!D138:D139) -> 2 | C22: =MIN('01_全部价目'!E138:E139) -> 8 | D22: =MAX('01_全部价目'!E138:E139) -> 8 | E22: 现两种同阶矿石暂同价。
A23: 阵盘 | B23: =COUNTA('01_全部价目'!D140:D146) -> 7 | C23: =MIN('01_全部价目'!E140:E146) -> 60 | D23: =MAX('01_全部价目'!E140:E146) -> 307200 | E23: 格数、资源与状态上限、境界跨度；高阶为低置信估值。
A25: 建议锚点：止血丹基准8（买12／卖4）；青石短剑基准60（买90／卖30）；凡品铁剑基准140（买210／卖70）。其他条目在同类中按效果与成本校正，并非全类统一倍率。
A28: 收益页仅用既有掉率乘以建议卖价做静态期望核对，不是游戏已到账收益、不是模拟或最终平衡。材料卖钱之外的收入、实战耗药、制作成本及商铺库存仍需后续衔接。

Sheet 01_全部价目
A1: 全部价目｜1份／件的灵石价格
A3: 只编辑E列基准价或说明页因数；F/G买卖价、M相对演示价差额会自动更新。空白演示价表示目前未在样例货架上。
A4: 序号 | B4: 品类 | C4: 品级 | D4: 物品名称 | E4: 建议基准价 | F4: 玩家买入价 | G4: 玩家卖出价 | H4: 单位 | I4: 经营场所 | J4: 定价理由 | K4: 校价关注 | L4: 原演示买价 | M4: 建议买价差 | N4: 稳定物品ID
A5: 1 | B5: 武器 | C5: 下品 | D5: 青石短剑 | E5: 60 | F5: =ROUNDUP(E5*'00_说明'!$B$5,0) -> 90 | G5: =ROUNDDOWN(E5*'00_说明'!$B$6,0) -> 30 | H5: 件 | I5: 普通商铺 | J5: 下品主武器锚点；11伤／5.5秒、耗体3，适合持续使用。 | K5: 初稿待审；未作实战经济平衡 | L5: 80 | M5: =IF(ISNUMBER(L5),F5-L5,"") -> 10 | N5: base.map_item.qingshi_short_sword
A6: 2 | B6: 武器 | C6: 下品 | D6: 猎弓 | E6: 64 | F6: =ROUNDUP(E6*'00_说明'!$B$5,0) -> 96 | G6: =ROUNDDOWN(E6*'00_说明'!$B$6,0) -> 32 | H6: 件 | I6: 普通商铺 | J6: 14穿刺／7秒；两格远程器型，耗体5限制持续输出。 | K6: 初稿待审；未作实战经济平衡 | L6: 100 | M6: =IF(ISNUMBER(L6),F6-L6,"") -> -4 | N6: base.map_item.hunting_bow
A7: 3 | B7: 武器 | C7: 下品 | D7: 短柄铁锤 | E7: 60 | F7: =ROUNDUP(E7*'00_说明'!$B$5,0) -> 90 | G7: =ROUNDDOWN(E7*'00_说明'!$B$6,0) -> 30 | H7: 件 | I7: 普通商铺 | J7: 12钝击／6秒、耗体4，和短剑处于同档。 | K7: 初稿待审；未作实战经济平衡 | L7: 90 | M7: =IF(ISNUMBER(L7),F7-L7,"") -> 0 | N7: base.map_item.short_iron_hammer
A8: 4 | B8: 武器 | C8: 下品 | D8: 铁刀 | E8: 36 | F8: =ROUNDUP(E8*'00_说明'!$B$5,0) -> 54 | G8: =ROUNDDOWN(E8*'00_说明'!$B$6,0) -> 18 | H8: 件 | I8: 普通商铺 | J8: 单格入门刀；6伤／4.5秒，低伤低耗体。 | K8: 初稿待审；未作实战经济平衡 | M8: =IF(ISNUMBER(L8),F8-L8,"") | N8: base.map_item.t01_0002
A9: 5 | B9: 武器 | C9: 下品 | D9: 柴斧 | E9: 56 | F9: =ROUNDUP(E9*'00_说明'!$B$5,0) -> 84 | G9: =ROUNDDOWN(E9*'00_说明'!$B$6,0) -> 28 | H9: 件 | I9: 普通商铺 | J9: 20伤爆发较高，但8.5秒轮转且耗体6，略低于通用短剑。 | K9: 初稿待审；未作实战经济平衡 | L9: 70 | M9: =IF(ISNUMBER(L9),F9-L9,"") -> 14 | N9: base.map_item.t01_0003
A10: 6 | B10: 武器 | C10: 下品 | D10: 匕首 | E10: 30 | F10: =ROUNDUP(E10*'00_说明'!$B$5,0) -> 45 | G10: =ROUNDDOWN(E10*'00_说明'!$B$6,0) -> 15 | H10: 件 | I10: 普通商铺 | J10: 单格、3.5秒快轮转；4点基础伤害，作为便宜起步选择。 | K10: 初稿待审；未作实战经济平衡 | M10: =IF(ISNUMBER(L10),F10-L10,"") | N10: base.map_item.t01_0005
A11: 7 | B11: 武器 | C11: 下品 | D11: 长枪 | E11: 72 | F11: =ROUNDUP(E11*'00_说明'!$B$5,0) -> 108 | G11: =ROUNDDOWN(E11*'00_说明'!$B$6,0) -> 36 | H11: 件 | I11: 普通商铺 | J11: 24伤单次爆发；三格占用、9秒CD与耗体7限制溢价。 | K11: 初稿待审；未作实战经济平衡 | M11: =IF(ISNUMBER(L11),F11-L11,"") | N11: base.map_item.t01_0006
A12: 8 | B12: 武器 | C12: 下品 | D12: 石印 | E12: 30 | F12: =ROUNDUP(E12*'00_说明'!$B$5,0) -> 45 | G12: =ROUNDDOWN(E12*'00_说明'!$B$6,0) -> 15 | H12: 件 | I12: 普通商铺 | J12: 单格基础钝击；8伤／6.5秒，不按大伤武器定价。 | K12: 初稿待审；未作实战经济平衡 | M12: =IF(ISNUMBER(L12),F12-L12,"") | N12: base.map_item.t01_0008
A13: 9 | B13: 武器 | C13: 下品 | D13: 皮鞭 | E13: 64 | F13: =ROUNDUP(E13*'00_说明'!$B$5,0) -> 96 | G13: =ROUNDDOWN(E13*'00_说明'!$B$6,0) -> 32 | H13: 件 | I13: 普通商铺 | J13: 10伤／4秒的较快轮转，但占三格，限制加价。 | K13: 初稿待审；未作实战经济平衡 | M13: =IF(ISNUMBER(L13),F13-L13,"") | N13: base.map_item.t01_0009
A14: 10 | B14: 武器 | C14: 凡品 | D14: 铁剑 | E14: 140 | F14: =ROUNDUP(E14*'00_说明'!$B$5,0) -> 210 | G14: =ROUNDDOWN(E14*'00_说明'!$B$6,0) -> 70 | H14: 件 | I14: 普通商铺 | J14: 18伤／5.5秒、耗体3；凡品纯伤主武器锚点。 | K14: 初稿待审；未作实战经济平衡 | M14: =IF(ISNUMBER(L14),F14-L14,"") | N14: base.map_item.t01_0028
A15: 11 | B15: 武器 | C15: 凡品 | D15: 赤纹剑 | E15: 160 | F15: =ROUNDUP(E15*'00_说明'!$B$5,0) -> 240 | G15: =ROUNDDOWN(E15*'00_说明'!$B$6,0) -> 80 | H15: 件 | I15: 普通商铺 | J15: 16伤并附1灼烧；伤害与持续状态兼顾。 | K15: 初稿待审；未作实战经济平衡 | L15: 240 | M15: =IF(ISNUMBER(L15),F15-L15,"") -> 0 | N15: base.map_item.t01_0029
A16: 12 | B16: 武器 | C16: 凡品 | D16: 寒水剑 | E16: 168 | F16: =ROUNDUP(E16*'00_说明'!$B$5,0) -> 252 | G16: =ROUNDDOWN(E16*'00_说明'!$B$6,0) -> 84 | H16: 件 | I16: 普通商铺 | J16: 17伤并附1寒霜；配合主动水攻，控制价值需构筑兑现。 | K16: 初稿待审；未作实战经济平衡 | M16: =IF(ISNUMBER(L16),F16-L16,"") | N16: base.map_item.t01_0030
A17: 13 | B17: 武器 | C17: 凡品 | D17: 钢刀 | E17: 112 | F17: =ROUNDUP(E17*'00_说明'!$B$5,0) -> 168 | G17: =ROUNDDOWN(E17*'00_说明'!$B$6,0) -> 56 | H17: 件 | I17: 普通商铺 | J17: 单格10伤并可施加流血；需伤及气血，低耗体有利循环。 | K17: 初稿待审；未作实战经济平衡 | M17: =IF(ISNUMBER(L17),F17-L17,"") | N17: base.map_item.t01_0031
A18: 14 | B18: 武器 | C18: 凡品 | D18: 金纹刀 | E18: 128 | F18: =ROUNDUP(E18*'00_说明'!$B$5,0) -> 192 | G18: =ROUNDDOWN(E18*'00_说明'!$B$6,0) -> 64 | H18: 件 | I18: 普通商铺 | J18: 单格12伤附锋痕；轮转比钢刀慢，略增协同估值。 | K18: 初稿待审；未作实战经济平衡 | M18: =IF(ISNUMBER(L18),F18-L18,"") | N18: base.map_item.t01_0032
A19: 15 | B19: 武器 | C19: 凡品 | D19: 赤焰刀 | E19: 128 | F19: =ROUNDUP(E19*'00_说明'!$B$5,0) -> 192 | G19: =ROUNDDOWN(E19*'00_说明'!$B$6,0) -> 64 | H19: 件 | I19: 普通商铺 | J19: 单格11伤附破甲；依赖后续主动火伤，不无限抬高功能价。 | K19: 初稿待审；未作实战经济平衡 | M19: =IF(ISNUMBER(L19),F19-L19,"") | N19: base.map_item.t01_0033
A20: 16 | B20: 武器 | C20: 凡品 | D20: 开山斧 | E20: 188 | F20: =ROUNDUP(E20*'00_说明'!$B$5,0) -> 282 | G20: =ROUNDDOWN(E20*'00_说明'!$B$6,0) -> 94 | H20: 件 | I20: 普通商铺 | J20: 30伤附2疲惫；爆发高，8.5秒与耗体6约束持续性。 | K20: 初稿待审；未作实战经济平衡 | M20: =IF(ISNUMBER(L20),F20-L20,"") | N20: base.map_item.t01_0034
A21: 17 | B21: 武器 | C21: 凡品 | D21: 金刚斧 | E21: 184 | F21: =ROUNDUP(E21*'00_说明'!$B$5,0) -> 276 | G21: =ROUNDDOWN(E21*'00_说明'!$B$6,0) -> 92 | H21: 件 | I21: 普通商铺 | J21: 28伤附2锋痕；作为大伤与金系协同件。 | K21: 初稿待审；未作实战经济平衡 | M21: =IF(ISNUMBER(L21),F21-L21,"") | N21: base.map_item.t01_0035
A22: 18 | B22: 武器 | C22: 凡品 | D22: 厚土斧 | E22: 184 | F22: =ROUNDUP(E22*'00_说明'!$B$5,0) -> 276 | G22: =ROUNDDOWN(E22*'00_说明'!$B$6,0) -> 92 | H22: 件 | I22: 普通商铺 | J22: 28伤附2重伤；压制回复与资源，价格接近同型斧。 | K22: 初稿待审；未作实战经济平衡 | M22: =IF(ISNUMBER(L22),F22-L22,"") | N22: base.map_item.t01_0036
A23: 19 | B23: 武器 | C23: 凡品 | D23: 桑木弓 | E23: 152 | F23: =ROUNDUP(E23*'00_说明'!$B$5,0) -> 228 | G23: =ROUNDDOWN(E23*'00_说明'!$B$6,0) -> 76 | H23: 件 | I23: 普通商铺 | J23: 24穿刺／7秒；凡品纯伤弓，未额外施加状态。 | K23: 初稿待审；未作实战经济平衡 | M23: =IF(ISNUMBER(L23),F23-L23,"") | N23: base.map_item.t01_0037
A24: 20 | B24: 武器 | C24: 凡品 | D24: 水纹弓 | E24: 164 | F24: =ROUNDUP(E24*'00_说明'!$B$5,0) -> 246 | G24: =ROUNDDOWN(E24*'00_说明'!$B$6,0) -> 82 | H24: 件 | I24: 普通商铺 | J24: 20伤附1枯脉；以功能补偿部分直伤。 | K24: 初稿待审；未作实战经济平衡 | M24: =IF(ISNUMBER(L24),F24-L24,"") | N24: base.map_item.t01_0038
A25: 21 | B25: 武器 | C25: 凡品 | D25: 雷纹弓 | E25: 176 | F25: =ROUNDUP(E25*'00_说明'!$B$5,0) -> 264 | G25: =ROUNDDOWN(E25*'00_说明'!$B$6,0) -> 88 | H25: 件 | I25: 普通商铺 | J25: 22伤附1连环；雷攻配合价值，耗体6略高。 | K25: 初稿待审；未作实战经济平衡 | M25: =IF(ISNUMBER(L25),F25-L25,"") | N25: base.map_item.t01_0039
A26: 22 | B26: 武器 | C26: 凡品 | D26: 精铁匕 | E26: 104 | F26: =ROUNDUP(E26*'00_说明'!$B$5,0) -> 156 | G26: =ROUNDDOWN(E26*'00_说明'!$B$6,0) -> 52 | H26: 件 | I26: 普通商铺 | J26: 单格8伤／3.5秒，伤及气血才施加流血；低门槛快攻。 | K26: 初稿待审；未作实战经济平衡 | M26: =IF(ISNUMBER(L26),F26-L26,"") | N26: base.map_item.t01_0040
A27: 23 | B27: 武器 | C27: 凡品 | D27: 风刃匕 | E27: 128 | F27: =ROUNDUP(E27*'00_说明'!$B$5,0) -> 192 | G27: =ROUNDDOWN(E27*'00_说明'!$B$6,0) -> 64 | H27: 件 | I27: 普通商铺 | J27: 单格3秒快攻并附失衡；轮转与控制带来溢价。 | K27: 初稿待审；未作实战经济平衡 | M27: =IF(ISNUMBER(L27),F27-L27,"") | N27: base.map_item.t01_0041
A28: 24 | B28: 武器 | C28: 凡品 | D28: 青木枪 | E28: 196 | F28: =ROUNDUP(E28*'00_说明'!$B$5,0) -> 294 | G28: =ROUNDDOWN(E28*'00_说明'!$B$6,0) -> 98 | H28: 件 | I28: 普通商铺 | J28: 34伤附2缠绕；三格与耗体7限制价格上浮。 | K28: 初稿待审；未作实战经济平衡 | M28: =IF(ISNUMBER(L28),F28-L28,"") | N28: base.map_item.t01_0042
A29: 25 | B29: 武器 | C29: 凡品 | D29: 雷纹枪 | E29: 216 | F29: =ROUNDUP(E29*'00_说明'!$B$5,0) -> 324 | G29: =ROUNDDOWN(E29*'00_说明'!$B$6,0) -> 108 | H29: 件 | I29: 普通商铺 | J29: 38伤附2雷印；凡品长枪高端，9.5秒和耗体8为代价。 | K29: 初稿待审；未作实战经济平衡 | L29: 320 | M29: =IF(ISNUMBER(L29),F29-L29,"") -> 4 | N29: base.map_item.t01_0043
A30: 26 | B30: 武器 | C30: 凡品 | D30: 炎纹锤 | E30: 160 | F30: =ROUNDUP(E30*'00_说明'!$B$5,0) -> 240 | G30: =ROUNDDOWN(E30*'00_说明'!$B$6,0) -> 80 | H30: 件 | I30: 普通商铺 | J30: 20钝击附1破甲；中速主武器与火系协同。 | K30: 初稿待审；未作实战经济平衡 | M30: =IF(ISNUMBER(L30),F30-L30,"") | N30: base.map_item.t01_0044
A31: 27 | B31: 武器 | C31: 凡品 | D31: 石骨锤 | E31: 164 | F31: =ROUNDUP(E31*'00_说明'!$B$5,0) -> 246 | G31: =ROUNDDOWN(E31*'00_说明'!$B$6,0) -> 82 | H31: 件 | I31: 普通商铺 | J31: 26钝击／7秒的纯伤器具；不额外计算未有的控制。 | K31: 初稿待审；未作实战经济平衡 | M31: =IF(ISNUMBER(L31),F31-L31,"") | N31: base.map_item.t01_0045
A32: 28 | B32: 武器 | C32: 凡品 | D32: 镇土印 | E32: 112 | F32: =ROUNDUP(E32*'00_说明'!$B$5,0) -> 168 | G32: =ROUNDDOWN(E32*'00_说明'!$B$6,0) -> 56 | H32: 件 | I32: 普通商铺 | J32: 单格16钝击附疲惫；7秒慢轮转抑制溢价。 | K32: 初稿待审；未作实战经济平衡 | M32: =IF(ISNUMBER(L32),F32-L32,"") | N32: base.map_item.t01_0046
A33: 29 | B33: 武器 | C33: 凡品 | D33: 雷纹印 | E33: 136 | F33: =ROUNDUP(E33*'00_说明'!$B$5,0) -> 204 | G33: =ROUNDDOWN(E33*'00_说明'!$B$6,0) -> 68 | H33: 件 | I33: 普通商铺 | J33: 单格14伤，命中自身加雷蕴；兼作雷系积累件。 | K33: 初稿待审；未作实战经济平衡 | M33: =IF(ISNUMBER(L33),F33-L33,"") | N33: base.map_item.t01_0047
A34: 30 | B34: 武器 | C34: 凡品 | D34: 藤鞭 | E34: 176 | F34: =ROUNDUP(E34*'00_说明'!$B$5,0) -> 264 | G34: =ROUNDDOWN(E34*'00_说明'!$B$6,0) -> 88 | H34: 件 | I34: 普通商铺 | J34: 14伤／4秒附毒蚀；持续施毒有价值，三格占用。 | K34: 初稿待审；未作实战经济平衡 | M34: =IF(ISNUMBER(L34),F34-L34,"") | N34: base.map_item.t01_0048
A35: 31 | B35: 武器 | C35: 凡品 | D35: 雷鞭 | E35: 184 | F35: =ROUNDUP(E35*'00_说明'!$B$5,0) -> 276 | G35: =ROUNDDOWN(E35*'00_说明'!$B$6,0) -> 92 | H35: 件 | I35: 普通商铺 | J35: 15伤／4.5秒附雷印；频率较高，但占三格。 | K35: 初稿待审；未作实战经济平衡 | L35: 300 | M35: =IF(ISNUMBER(L35),F35-L35,"") -> -24 | N35: base.map_item.t01_0049
A36: 32 | B36: 武器 | C36: 凡品 | D36: 刺血匕 | E36: 136 | F36: =ROUNDUP(E36*'00_说明'!$B$5,0) -> 204 | G36: =ROUNDDOWN(E36*'00_说明'!$B$6,0) -> 68 | H36: 件 | I36: 普通商铺 | J36: 单格可施2流血；需伤及气血，按条件效果计价。 | K36: 初稿待审；未作实战经济平衡 | M36: =IF(ISNUMBER(L36),F36-L36,"") | N36: base.map_item.t01_0050
A37: 33 | B37: 武器 | C37: 凡品 | D37: 震骨锤 | E37: 196 | F37: =ROUNDUP(E37*'00_说明'!$B$5,0) -> 294 | G37: =ROUNDDOWN(E37*'00_说明'!$B$6,0) -> 98 | H37: 件 | I37: 普通商铺 | J37: 32钝击附2重伤；高爆发但9秒和耗体7限制循环。 | K37: 初稿待审；未作实战经济平衡 | M37: =IF(ISNUMBER(L37),F37-L37,"") | N37: base.map_item.t01_0051
A38: 34 | B38: 武器 | C38: 凡品 | D38: 清风印 | E38: 168 | F38: =ROUNDUP(E38*'00_说明'!$B$5,0) -> 252 | G38: =ROUNDDOWN(E38*'00_说明'!$B$6,0) -> 84 | H38: 件 | I38: 普通商铺 | J38: 单格驱散载体兼13伤；功能溢价仍受7秒CD约束。 | K38: 初稿待审；未作实战经济平衡 | L38: 280 | M38: =IF(ISNUMBER(L38),F38-L38,"") -> -28 | N38: base.map_item.t01_0052
A39: 35 | B39: 武器 | C39: 凡品 | D39: 荆鞭 | E39: 176 | F39: =ROUNDUP(E39*'00_说明'!$B$5,0) -> 264 | G39: =ROUNDDOWN(E39*'00_说明'!$B$6,0) -> 88 | H39: 件 | I39: 普通商铺 | J39: 16伤附缠绕；三格木系铺垫件，与藤鞭同档。 | K39: 初稿待审；未作实战经济平衡 | M39: =IF(ISNUMBER(L39),F39-L39,"") | N39: base.map_item.t01_0053
A40: 36 | B40: 武器 | C40: 凡品 | D40: 赤焰枪 | E40: 208 | F40: =ROUNDUP(E40*'00_说明'!$B$5,0) -> 312 | G40: =ROUNDDOWN(E40*'00_说明'!$B$6,0) -> 104 | H40: 件 | I40: 普通商铺 | J40: 36伤附2灼烧；高伤火枪，耗体8、三格占用。 | K40: 初稿待审；未作实战经济平衡 | M40: =IF(ISNUMBER(L40),F40-L40,"") | N40: base.map_item.t01_0054
A41: 37 | B41: 防具 | C41: 下品 | D41: 粗布甲 | E41: 48 | F41: =ROUNDUP(E41*'00_说明'!$B$5,0) -> 72 | G41: =ROUNDDOWN(E41*'00_说明'!$B$6,0) -> 24 | H41: 件 | I41: 普通商铺 | J41: 轻甲上限7、每6秒回4；布装联动有价值，仍保持入门价。 | K41: 初稿待审；未作实战经济平衡 | L41: 60 | M41: =IF(ISNUMBER(L41),F41-L41,"") -> 12 | N41: base.map_item.coarse_cloth_armor
...

Sheet 02_实际效果
A1: 实际效果｜来自当前库存注册后的物品说明
A3: 本页为当前实现证据，不是新增玩法。用于核对价格依据；掉落材料与敌人阵盘器官分开，阵盘占格栏显示实盘格数。
A4: 序号 | B4: 物品名称 | C4: 品级 | D4: 占格／盘格 | E4: 冷却秒 | F4: 耗体 | G4: 耗灵 | H4: 当前实装说明 | I4: 来源文件 | J4: 来源行 | K4: 来源／掉落补充
A5: 1 | B5: 青石短剑 | C5: 下品 | D5: 1.0×2.0 | E5: 5.5 | F5: 3 | G5: 0 | H5: 冷却：5.5秒，耗费3点体力，对敌方造成11点斩击伤害。 | I5: data/maps/inventory_items.json | J5: 3
A6: 2 | B6: 猎弓 | C6: 下品 | D6: 1.0×2.0 | E6: 7 | F6: 5 | G6: 0 | H6: 冷却：7.0秒，耗费5点体力，对敌方造成14点穿刺伤害。 | I6: data/maps/inventory_items.json | J6: 108
A7: 3 | B7: 短柄铁锤 | C7: 下品 | D7: 1.0×2.0 | E7: 6 | F7: 4 | G7: 0 | H7: 冷却：6.0秒，耗费4点体力，对敌方造成12点钝击伤害。 | I7: data/maps/inventory_items.json | J7: 213
A8: 4 | B8: 铁刀 | C8: 下品 | D8: 1.0×1.0 | E8: 4.5 | F8: 2 | G8: 0 | H8: 冷却：4.5秒，耗费2点体力，对敌方造成6点斩击伤害。 | I8: data/maps/inventory_items.json | J8: 38
A9: 5 | B9: 柴斧 | C9: 下品 | D9: 2.0×1.0 | E9: 8.5 | F9: 6 | G9: 0 | H9: 冷却：8.5秒，耗费6点体力，对敌方造成20点斩击伤害。 | I9: data/maps/inventory_items.json | J9: 73
A10: 6 | B10: 匕首 | C10: 下品 | D10: 1.0×1.0 | E10: 3.5 | F10: 2 | G10: 0 | H10: 冷却：3.5秒，耗费2点体力，对敌方造成4点穿刺伤害。 | I10: data/maps/inventory_items.json | J10: 143
A11: 7 | B11: 长枪 | C11: 下品 | D11: 3.0×1.0 | E11: 9 | F11: 7 | G11: 0 | H11: 冷却：9.0秒，耗费7点体力，对敌方造成24点穿刺伤害。 | I11: data/maps/inventory_items.json | J11: 178
A12: 8 | B12: 石印 | C12: 下品 | D12: 1.0×1.0 | E12: 6.5 | F12: 3 | G12: 0 | H12: 冷却：6.5秒，耗费3点体力，对敌方造成8点钝击伤害。 | I12: data/maps/inventory_items.json | J12: 248
A13: 9 | B13: 皮鞭 | C13: 下品 | D13: 3.0×1.0 | E13: 4 | F13: 3 | G13: 0 | H13: 冷却：4.0秒，耗费3点体力，对敌方造成10点钝击伤害。 | I13: data/maps/inventory_items.json | J13: 283
A14: 10 | B14: 铁剑 | C14: 凡品 | D14: 1.0×2.0 | E14: 5.5 | F14: 3 | G14: 0 | H14: 冷却：5.5秒，耗费3点体力，对敌方造成18点斩击伤害。 | I14: data/maps/inventory_items.json | J14: 318
A15: 11 | B15: 赤纹剑 | C15: 凡品 | D15: 1.0×2.0 | E15: 5.5 | F15: 4 | G15: 0 | H15: 冷却：5.5秒，耗费4点体力，对敌方造成16点斩击伤害。 命中后向敌方施加1层灼烧。 | I15: data/maps/inventory_items.json | J15: 353
A16: 12 | B16: 寒水剑 | C16: 凡品 | D16: 1.0×2.0 | E16: 6 | F16: 4 | G16: 0 | H16: 冷却：6.0秒，耗费4点体力，对敌方造成17点斩击伤害。 命中后向敌方施加1层寒霜。 | I16: data/maps/inventory_items.json | J16: 396
... A119: 115 | B119: 火砂 | C119: 凡品 | D119: 1.0×1.0 | E119: 9 | F119: 0 | G119: 0 | H119: 冷却：9.0秒，对敌方造成30点法术型伤害。 同一具体物品仅一叠，每叠最多10份。暗器首轮从完整CD开始，发动后消耗一件。 | I119: data/maps/inventory_items.json | J119: 4392
A120: 116 | B120: 赤鬃兽心 | C120: 下品 | D120: 1.0×1.0 | E120: 0 | F120: 0 | G120: 0 | H120: 赤鬃獠猪掉落的兽材。仅作材料，不能放入战斗阵盘。 | I120: data/maps/enemy_materials.json | J120: 95 | K120: 赤鬃獠猪；常规独立掉落10%；首胜必得
A121: 117 | B121: 厚鬃皮 | C121: 下品 | D121: 2.0×2.0 | E121: 0 | F121: 0 | G121: 0 | H121: 赤鬃獠猪掉落的兽材。仅作材料，不能放入战斗阵盘。 | I121: data/maps/enemy_materials.json | J121: 26 | K121: 赤鬃獠猪；常规独立掉落25%
A122: 118 | B122: 獠猪铁蹄 | C122: 下品 | D122: 1.0×1.0 | E122: 0 | F122: 0 | G122: 0 | H122: 赤鬃獠猪掉落的兽材。仅作材料，不能放入战斗阵盘。 | I122: data/maps/enemy_materials.json | J122: 49 | K122: 赤鬃獠猪；常规独立掉落25%
A123: 119 | B123: 赤鬃 | C123: 下品 | D123: 1.0×1.0 | E123: 0 | F123: 0 | G123: 0 | H123: 赤鬃獠猪掉落的兽材。仅作材料，不能放入战斗阵盘。 | I123: data/maps/enemy_materials.json | J123: 72 | K123: 赤鬃獠猪；常规独立掉落25%
A124: 120 | B124: 赤鬃獠牙 | C124: 下品 | D124: 1.0×2.0 | E124: 0 | F124: 0 | G124: 0 | H124: 赤鬃獠猪掉落的兽材。仅作材料，不能放入战斗阵盘。 | I124: data/maps/enemy_materials.json | J124: 3 | K124: 赤鬃獠猪；常规独立掉落25%
A125: 121 | B125: 河鼋尖喙 | C125: 下品 | D125: 1.0×1.0 | E125: 0 | F125: 0 | G125: 0 | H125: 青壳河鼋掉落的兽材。仅作材料，不能放入战斗阵盘。 | I125: data/maps/enemy_materials.json | J125: 214 | K125: 青壳河鼋；常规独立掉落25%
A126: 122 | B126: 青壳甲片 | C126: 下品 | D126: 2.0×2.0 | E126: 0 | F126: 0 | G126: 0 | H126: 青壳河鼋掉落的兽材。仅作材料，不能放入战斗阵盘。 | I126: data/maps/enemy_materials.json | J126: 190 | K126: 青壳河鼋；常规独立掉落25%
A127: 123 | B127: 河鼋尾骨 | C127: 下品 | D127: 1.0×2.0 | E127: 0 | F127: 0 | G127: 0 | H127: 青壳河鼋掉落的兽材。仅作材料，不能放入战斗阵盘。 | I127: data/maps/enemy_materials.json | J127: 238 | K127: 青壳河鼋；常规独立掉落25%
A128: 124 | B128: 山狼利爪 | C128: 下品 | D128: 1.0×2.0 | E128: 0 | F128: 0 | G128: 0 | H128: 灰脊山狼掉落的兽材。仅作材料，不能放入战斗阵盘。 | I128: data/maps/enemy_materials.json | J128: 118 | K128: 灰脊山狼；常规独立掉落25%
A129: 125 | B129: 山狼尖牙 | C129: 下品 | D129: 1.0×1.0 | E129: 0 | F129: 0 | G129: 0 | H129: 灰脊山狼掉落的兽材。仅作材料，不能放入战斗阵盘。 | I129: data/maps/enemy_materials.json | J129: 142 | K129: 灰脊山狼；常规独立掉落25%
A130: 126 | B130: 山狼皮 | C130: 下品 | D130: 1.0×1.0 | E130: 0 | F130: 0 | G130: 0 | H130: 灰脊山狼掉落的兽材。仅作材料，不能放入战斗阵盘。 | I130: data/maps/enemy_materials.json | J130: 166 | K130: 灰脊山狼；常规独立掉落25%
A131: 127 | B131: 岩雉硬喙 | C131: 下品 | D131: 1.0×1.0 | E131: 0 | F131: 0 | G131: 0 | H131: 青翎岩雉掉落的兽材。仅作材料，不能放入战斗阵盘。 | I131: data/maps/enemy_materials.json | J131: 286 | K131: 青翎岩雉；常规独立掉落25%
... A139: 135 | B139: 粗铁矿 | C139: 下品 | D139: 1.0×1.0 | E139: 0 | F139: 0 | G139: 0 | H139: 灰黑色矿石，质地坚实，可用于打造普通铁质装备。 | I139: data/maps/minerals.json | J139: 3 | K139: 溪湾砂矿
A140: 136 | B140: 普通行囊 | C140: 下品 | D140: 3×3 | E140: 0 | F140: 0 | G140: 0 | H140: 寻常修士使用的基础行囊。 适用境界：凡人及以上。 上限：气血+5，体力+5。 | I140: data/maps/qinglan_boards.json | J140: 3
A141: 137 | B141: 青岚 · 晓岚 | C141: 下品 | D141: 4×3 | E141: 0 | F141: 0 | G141: 0 | H141: 出自青岚宗的制式阵盘。 适用境界：凡人及以上。 上限：气血+10，体力+10。 自身增益上限：生机+4，轻灵+4。 | I141: data/maps/qinglan_boards.json | J141: 24
A142: 138 | B142: 青岚 · 听风 | C142: 凡品 | D142: 4×4 | E142: 0 | F142: 0 | G142: 0 | H142: 出自青岚宗的制式阵盘。 适用境界：炼气及以上。 上限：气血+20，体力+15，灵力+10。 自身增益上限：生机+8，轻灵+4，坚韧+2。 施加减益上限：失衡+2，驱散+2。 | I142: data/maps/qinglan_boards.json | J142: 46
A143: 139 | B143: 青岚 · 凝翠 | C143: 良品 | D143: 5×4 | E143: 0 | F143: 0 | G143: 0 | H143: 出自青岚宗的制式阵盘。 适用境界：筑基及以上。 上限：气血+30，体力+20，灵力+30。 自身增益上限：生机+12，轻灵+8，坚韧+4。 施加减益上限：失衡+4，驱散+4。 | I143: data/maps/qinglan_boards.json | J143: 68
A144: 140 | B144: 青岚 · 流霞 | C144: 上品 | D144: 5×5 | E144: 0 | F144: 0 | G144: 0 | H144: 出自青岚宗的制式阵盘。 适用境界：结丹及以上。 上限：气血+40，体力+25，灵力+40。 自身增益上限：生机+16，轻灵+8，坚韧+6。 施加减益上限：失衡+6，驱散+6。 | I144: data/maps/qinglan_boards.json | J144: 90
A145: 141 | B145: 青岚 · 凌霄 | C145: 灵品 | D145: 6×5 | E145: 0 | F145: 0 | G145: 0 | H145: 出自青岚宗的制式阵盘。 适用境界：元婴及以上。 上限：气血+50，体力+30，灵力+50。 自身增益上限：生机+20，轻灵+12，坚韧+8。 施加减益上限：失衡+6，驱散+6。 | I145: data/maps/qinglan_boards.json | J145: 113
A146: 142 | B146: 青岚 · 太虚 | C146: 玄品 | D146: 6×6 | E146: 0 | F146: 0 | G146: 0 | H146: 出自青岚宗的制式阵盘。 适用境界：化神及以上。 上限：气血+60，体力+40，灵力+60。 自身增益上限：生机+24，轻灵+12，坚韧+10。 施加减益上限：失衡+8，驱散+8。 | I146: data/maps/qinglan_boards.json | J146: 136

Sheet 03_收益核对
A1: 材料出售期望｜静态核对，未进行战斗模拟
A3: 金额随价目表变更；仅计算既有掉落概率×建议卖价，不扣耗药，不含修为／历练，当前游戏出售功能尚未启用。
A5: 怪物 | B5: 掉落物 | C5: 常规掉率 | D5: 建议卖价 | E5: 常规期望收入 | F5: 该种怪首胜掉率 | G5: 该种怪首胜期望收入 | H5: 来源／说明
A6: 赤鬃獠猪 | B6: 厚鬃皮 | C6: 0.25 | D6: ='01_全部价目'!G121 -> 16 | E6: =C6*D6 -> 4 | F6: 0.25 | G6: =F6*D6 -> 4 | H6: data/enemies/chisong_liaozhu.json
A7: 赤鬃獠猪 | B7: 赤鬃獠牙 | C7: 0.25 | D7: ='01_全部价目'!G124 -> 14 | E7: =C7*D7 -> 3.5 | F7: 0.25 | G7: =F7*D7 -> 3.5 | H7: data/enemies/chisong_liaozhu.json
A8: 赤鬃獠猪 | B8: 獠猪铁蹄 | C8: 0.25 | D8: ='01_全部价目'!G122 -> 10 | E8: =C8*D8 -> 2.5 | F8: 0.25 | G8: =F8*D8 -> 2.5 | H8: data/enemies/chisong_liaozhu.json
A9: 赤鬃獠猪 | B9: 赤鬃 | C9: 0.25 | D9: ='01_全部价目'!G123 -> 10 | E9: =C9*D9 -> 2.5 | F9: 0.25 | G9: =F9*D9 -> 2.5 | H9: data/enemies/chisong_liaozhu.json
A10: 赤鬃獠猪 | B10: 赤鬃兽心 | C10: 0.1 | D10: ='01_全部价目'!G120 -> 40 | E10: =C10*D10 -> 4 | F10: 1 | G10: =F10*D10 -> 40 | H10: data/enemies/chisong_liaozhu.json；首胜凭证按怪物种类，非每个节点
A11: 赤鬃獠猪合计 | E11: =SUM(E6:E10) -> 16.5 | G11: =SUM(G6:G10) -> 52.5 | H11: 长期平均值；一次战斗可能没有任何材料。
A13: 灰脊山狼 | B13: 山狼利爪 | C13: 0.25 | D13: ='01_全部价目'!G128 -> 10 | E13: =C13*D13 -> 2.5 | F13: 0.25 | G13: =F13*D13 -> 2.5 | H13: data/enemies/huiji_shanlang.json
A14: 灰脊山狼 | B14: 山狼尖牙 | C14: 0.25 | D14: ='01_全部价目'!G129 -> 9 | E14: =C14*D14 -> 2.25 | F14: 0.25 | G14: =F14*D14 -> 2.25 | H14: data/enemies/huiji_shanlang.json
A15: 灰脊山狼 | B15: 山狼皮 | C15: 0.25 | D15: ='01_全部价目'!G130 -> 8 | E15: =C15*D15 -> 2 | F15: 0.25 | G15: =F15*D15 -> 2 | H15: data/enemies/huiji_shanlang.json
A16: 灰脊山狼合计 | E16: =SUM(E13:E15) -> 6.75 | G16: =SUM(G13:G15) -> 6.75 | H16: 长期平均值；一次战斗可能没有任何材料。
A18: 青壳河鼋 | B18: 青壳甲片 | C18: 0.25 | D18: ='01_全部价目'!G126 -> 14 | E18: =C18*D18 -> 3.5 | F18: 0.25 | G18: =F18*D18 -> 3.5 | H18: data/enemies/qingke_heyuan.json
A19: 青壳河鼋 | B19: 河鼋尖喙 | C19: 0.25 | D19: ='01_全部价目'!G125 -> 9 | E19: =C19*D19 -> 2.25 | F19: 0.25 | G19: =F19*D19 -> 2.25 | H19: data/enemies/qingke_heyuan.json
A20: 青壳河鼋 | B20: 河鼋尾骨 | C20: 0.25 | D20: ='01_全部价目'!G127 -> 11 | E20: =C20*D20 -> 2.75 | F20: 0.25 | G20: =F20*D20 -> 2.75 | H20: data/enemies/qingke_heyuan.json
A21: 青壳河鼋合计 | E21: =SUM(E18:E20) -> 8.5 | G21: =SUM(G18:G20) -> 8.5 | H21: 长期平均值；一次战斗可能没有任何材料。
A23: 青翎岩雉 | B23: 青翎 | C23: 0.25 | D23: ='01_全部价目'!G133 -> 12 | E23: =C23*D23 -> 3 | F23: 0.25 | G23: =F23*D23 -> 3 | H23: data/enemies/qingling_yanzhi.json
A24: 青翎岩雉 | B24: 岩雉硬喙 | C24: 0.25 | D24: ='01_全部价目'!G131 -> 9 | E24: =C24*D24 -> 2.25 | F24: 0.25 | G24: =F24*D24 -> 2.25 | H24: data/enemies/qingling_yanzhi.json
A25: 青翎岩雉 | B25: 岩雉钩爪 | C25: 0.25 | D25: ='01_全部价目'!G132 -> 10 | E25: =C25*D25 -> 2.5 | F25: 0.25 | G25: =F25*D25 -> 2.5 | H25: data/enemies/qingling_yanzhi.json
A26: 青翎岩雉合计 | E26: =SUM(E23:E25) -> 7.75 | G26: =SUM(G23:G25) -> 7.75 | H26: 长期平均值；一次战斗可能没有任何材料。
A28: 对照：三种普通怪材料理论收入为每胜6.75～8.5灵石，赤鬃獠猪常规16.5、该种怪首胜52.5。止血丹购买12，青石短剑90；如果每战频繁自动耗药，单靠卖兽材可能无法覆盖支出，需结合赠药／宝箱／其他收入再测。
A32: 采集物 | B32: 快速／1天 | C32: 预计数量 | D32: 单件卖价 | E32: 预计出售收入 | F32: 深入／3天数量 | G32: 预计出售收入 | H32: 来源／说明
A33: 苦艾叶 | B33: 数量=1+0或1 | C33: 1.5 | D33: ='01_全部价目'!G134 -> 2 | E33: =C33*D33 -> 3 | F33: 3.5 | G33: =F33*D33 -> 7 | H33: 既有采药／采矿每次额外0或1，各50%。
A34: 青藤根 | B34: 数量=1+0或1 | C34: 1.5 | D34: ='01_全部价目'!G135 -> 2 | E34: =C34*D34 -> 3 | F34: 3.5 | G34: =F34*D34 -> 7 | H34: 青藤根尚未正式投放；本行仅同方式假设。
A35: 溪露苔 | B35: 数量=1+0或1 | C35: 1.5 | D35: ='01_全部价目'!G136 -> 3 | E35: =C35*D35 -> 4.5 | F35: 3.5 | G35: =F35*D35 -> 10.5 | H35: 既有采药／采矿每次额外0或1，各50%。
A36: 止血草 | B36: 数量=1+0或1 | C36: 1.5 | D36: ='01_全部价目'!G137 -> 2 | E36: =C36*D36 -> 3 | F36: 3.5 | G36: =F36*D36 -> 7 | H36: 既有采药／采矿每次额外0或1，各50%。
A37: 赤铜矿 | B37: 数量=1+0或1 | C37: 1.5 | D37: ='01_全部价目'!G138 -> 4 | E37: =C37*D37 -> 6 | F37: 3.5 | G37: =F37*D37 -> 14 | H37: 既有采药／采矿每次额外0或1，各50%。
A38: 粗铁矿 | B38: 数量=1+0或1 | C38: 1.5 | D38: ='01_全部价目'!G139 -> 4 | E38: =C38*D38 -> 6 | F38: 3.5 | G38: =F38*D38 -> 14 | H38: 既有采药／采矿每次额外0或1，各50%。

Sheet 04_来源与边界
A1: 来源与效力边界
A4: 性质 | B4: 文件／依据 | C4: 内容与边界 | D4: 状态
A5: 用户定案 | B5: docs/01_核心定案_七系功法与战斗规则.md §1.51 | C5: 四店分类、买入150%／卖出50%，买入上取整／卖出下取整。 | D5: 已确认
A6: 价格建议 | B6: docs/sources/item-base-price-proposal-2026-10-12.json | C6: 142项逐件基准价与理由由本轮拟定，尚未获最终确认，未接入游戏。 | D6: 待审
A7: 实装读取 | B7: MapLoadoutStore.create_state → ItemTooltip.effect_text | C7: 只读加载内容注册表并导出142条说明；未读取正式存档，未执行战斗模拟。 | D7: 已核对
A8: 游戏价目 | B8: data/shops/item_base_prices.json | C8: 正式prices仍为空；没有将本表写入该文件，现有样例购买价保持。 | D8: 保持现状
A9: 禁售保护 | B9: docs/01_核心定案_七系功法与战斗规则.md §1.51 | C9: 已上阵／当前使用阵盘不可直接售；收藏默认禁售，关键与任务品禁售。基准价不替代售卖资格检查。 | D9: 规则已定；出售未接
A10: 未纳入 | B10: docs/sources/wuming-jiuci-enemies-2026-10-08.json | C10: 旧祠18项兽材只在设计记录，未注册库存；独立修炼库35书／56术也不视为实物商品。 | D10: 后续新增实物再补价
A11: 高阶估值 | B11: 青岚·听风／凝翠／流霞／凌霄／太虚 | C11: 按晓岚300起步、每境界4倍的建议梯度临时估值；不是基于已验证中后期收入。不得据测试档赠送高阶盘推定正式经济。 | D11: 低置信度，待经济复核
A12: 生产约束 | B12: docs/t01-05-材料与锻造词典_编制与审校记录_2026-09-27.md | C12: 制作配方／投入数量未接；现阶段不能验证买材→制作→出售的成本与利润。 | D12: 后续校验
A13: 购买范围 | B13: data/shops/trade_rules.json | C13: 经营类别不等于货架。各店资格、库存、补货与高阶货品投放需独立配置。 | D13: 不得由估价自动上架
A14: 表格读取 | B14: 01_全部价目 E列；00_说明 B5/B6 | C14: 蓝色为建议输入；黑色为公式与派生值；每份／件统一计价。修改表格只重算表内价格，不自动回写JSON或游戏文件。 | D14: 可修改重算
A15: 验证范围 | B15: openpyxl回读＋整数算术核对 | C15: 公式与缓存逐项一致、142项ID无遗漏重复、已核对源文件哈希；环境无Excel/LibreOffice，未做原生排版渲染。 | D15: 打开本地表格时可核对布局
... A20: 实际数据 | B20: data/maps/qinglan_boards.json | C20: SHA256 061a9fe4bfdb20fc7adc9d5698d1f3fc12e672d7e4f758cba8605af987bcb435 | D20: 只读来源
