Workbook

Sheet 使用说明
A1: 《口袋修仙》有效物品效果清单
A2: 当前 Demo 0.1.4 SDK 中 effectList 非空的 1691 件公开物品；一个工作簿内含主清单、逐条效果明细和统计汇总。
A4: 数据版本 | B4: 0.1.4
A5: 生成时间 | B5: 2026-09-24 22:30:03
A6: 物品数量 | B6: 1691
A7: 筛选规则 | B7: 只收录 effectList 非空的物品；空效果的材料、配方、储物袋等未纳入。
A8: 来源文件 | B8: D:\SteamLibrary\steamapps\common\口袋修仙 Demo\ModSDK\reference\domains\items\base-item-public-catalog.json
A9: 来源 SHA-256 | B9: bc235fc8b3753e4e656ab89731336b73107b5b4802e07cd41aa86b6f07a7b2ea
A10: 主清单 | B10: 一行一件物品，适合按 ID、类别、品阶、元素、效果类型和摘要筛选。
A11: 效果明细 | B11: 一行一条基础效果或一条功法成长层效果；保留对应 JSON，便于核对精确字段。
A12: 统计汇总 | B12: 类别、品阶、元素和效果类型的数量统计；打开 Excel 后自动重算公式。
A13: 字段说明 | B13: 品阶保留 SDK 原始代码，避免对未在文档中明确公布的中文名称进行猜译。
A14: 注意 | B14: 这是 SDK 对外公开目录，不代表游戏内部未公开/未发布内容。

Sheet 物品清单
A1: 序号 | B1: 物品ID | C1: 名称 | D1: 类别 | E1: 类别代码 | F1: 品阶代码 | G1: 元素 | H1: 元素代码 | I1: 尺寸 | J1: 占格数 | K1: 价格 | L1: 可获得 | M1: 获取渠道 | N1: 效果数 | O1: 效果类型 | P1: 效果类型代码 | Q1: 效果摘要 | R1: 标签 | S1: 物品描述 | T1: 图标名 | U1: 覆写策略
A2: 1 | B2: 100001 | C2: 炼体术 | D2: 功法 | E2: scripture | F2: common | G2: 无 | H2: none | I2: 1×1 | J2: 1 | K2: 35 | L2: 是 | M2: bazaar | N2: 2 | O2: 被动效果；功法成长 | P2: passive；scriptureProgression | Q2: 被动效果：每消耗 1 点体力，获得 1 点修为 | 功法成长：第1层（无）：每消耗 1 点体力，获得 1 点修为 | 第2层（修为≥120）：每消耗 1 点体力，获得 2 点修为 | 第3层（修为≥760；境界≥炼气4层）：每消耗 1 点体力，获得 3 点修为 | 第4层（修为≥2450；境界≥炼气4层）：每消耗 1 点体力，获得 4 点修为 | S2: 麻绳束起的旧竹简外覆符纹封皮，字迹不尚玄奥，却处处透着打熬筋骨的笨功夫。 | T2: scripture_bound_bamboo_scroll_1x1 | U2: onboardingProtected
A3: 2 | B3: 100002 | C3: 云字养气册 | D3: 功法 | E3: scripture | F3: common | G3: 木 | H3: wood | I3: 1×1 | J3: 1 | K3: 35 | L3: 是 | M3: bazaar | N3: 2 | O3: 条件触发；功法成长 | P3: triggered；scriptureProgression | Q3: 条件触发：每获得 1 点气血，获得 3 点修为 | 功法成长：第1层（无）：每获得 1 点气血，获得 3 点修为 | 第2层（修为≥210）：每获得 1 点气血，获得 6 点修为 | 第3层（修为≥540）：每获得 1 点气血，获得 9 点修为 | 第4层（修为≥2950）：每获得 1 点气血，获得 12 点修为 | S3: 青润玉简卷筒上云纹鎏金细密，展开时清气如云字舒卷，像宗门内门才许借阅的养气灵简。 | T3: scripture_cloudseal_manual_1x1 | U3: allowed
A4: 3 | B4: 100003 | C4: 聚气册 | D4: 功法 | E4: scripture | F4: common | G4: 火 | H4: fire | I4: 1×1 | J4: 1 | K4: 35 | L4: 是 | M4: bazaar | N4: 3 | O4: 周期触发；条件触发；功法成长 | P4: periodicPulse；triggered；scriptureProgression | Q4: 周期触发：获得 10 点修为 | 条件触发：每当有丹药耗尽时，获得 10 点修为 | 功法成长：第1层（无）：获得 10 点修为；每当有丹药耗尽时，获得 10 点修为 | 第2层（修为≥210）：获得 25 点修为；每当有丹药耗尽时，获得 20 点修为 | 第3层（修为≥760）：获得 40 点修为；每当有丹药耗尽时，获得 30 点修为 | S4: 厚册封面云纹回旋，纸页间藏着温和灵息，读来像把散乱真气一圈圈收回丹田。 | T4: scripture_qi_growth_manual_1x1 | U4: allowed
A5: 4 | B5: 100004 | C5: 月痕养息册 | D5: 功法 | E5: scripture | F5: common | G5: 无 | H5: none | I5: 1×2 | J5: 2 | K5: 35 | L5: 是 | M5: bazaar | N5: 3 | O5: 条件触发；被动效果；功法成长 | P5: triggered；passive；scriptureProgression | Q5: 条件触发：每获得 1 点法力，获得 1 点修为 | 被动效果：法力上限 +10 | 功法成长：第1层（无）：每获得 1 点法力，获得 1 点修为；法力上限 +10 | 第2层（修为≥150）：每获得 1 点法力，获得 2 点修为；法力上限 +20 | 第3层（修为≥780）：每获得 1 点法力，获得 3 点修为；法力上限 +30 | 第4层（修为≥3800）：每获得 1 点法力，获得 4 点修为；法力上限 +40 | S5: 竖长厚册封着一弯淡月痕，夜色下翻页时清辉入息，最能安顿浮躁心神。 | T5: scripture_moon_mark_codex_1x2 | U5: allowed
A6: 5 | B6: 100010 | C6: 五行入门篇 | D6: 功法 | E6: scripture | F6: common | G6: 无 | H6: none | I6: 1×1 | J6: 1 | K6: 35 | L6: 是 | M6: bazaar | N6: 2 | O6: 被动效果；功法成长 | P6: passive；scriptureProgression | Q6: 被动效果：每消耗 1 点法力，获得 1 点修为 | 功法成长：第1层（无）：每消耗 1 点法力，获得 1 点修为 | 第2层（修为≥140；境界≥炼气4层）：每消耗 1 点法力，获得 2 点修为 | 第3层（修为≥1000）：每消耗 1 点法力，获得 3 点修为 | 第4层（修为≥6000）：每消耗 1 点法力，获得 4 点修为 | S6: 米黄竹简以细绳整齐束起，五色细线隐约贯穿其间，像初入山门时领到的第一册传功简。 | T6: scripture_bound_bamboo_slips_1x1 | U6: allowed
A7: 6 | B7: 100011 | C7: 烈阳诀 | D7: 功法 | E7: scripture | F7: common | G7: 火 | H7: fire | I7: 1×1 | J7: 1 | K7: 35 | L7: 是 | M7: bazaar；beastDrop | N7: 3 | O7: 条件触发；被动效果；功法成长 | P7: triggered；passive；scriptureProgression | Q7: 条件触发：每获得 1 层炎热，获得 2 点修为 | 被动效果：炎热层数上限 +3 | 功法成长：第1层（无）：每获得 1 层炎热，获得 2 点修为；炎热层数上限 +3 | 第2层（修为≥160）：每获得 1 层炎热，获得 4 点修为；炎热层数上限 +6 | 第3层（修为≥840）：每获得 1 层炎热，获得 6 点修为；炎热层数上限 +9 | 第4层（修为≥2900）：每获得 1 层炎热，获得 8 点修为；炎热层数上限 +15 | S7: 卷轴正面日芒灼灼，金纹映得纸面微暖，展开时仿佛晨阳越过云海照进静室。 | T7: scripture_sunflare_scroll_1x1 | U7: allowed
A8: 7 | B8: 100012 | C8: 玄水雷纹诀 | D8: 功法 | E8: scripture | F8: common | G8: 雷 | H8: thunder | I8: 1×1 | J8: 1 | K8: 45 | L8: 是 | M8: bazaar | N8: 3 | O8: 说明/执行器；被动效果；功法成长 | P8: effectNote；passive；scriptureProgression | Q8: 说明/执行器：每获得 1 层引雷，获得 3 点修为 | 被动效果：引雷层数上限 +3 | 功法成长：第1层（无）：每获得 1 层引雷，获得 3 点修为；引雷层数上限 +3 | 第2层（修为≥200）：每获得 1 层引雷，获得 6 点修为；引雷层数上限 +6 | 第3层（修为≥920）：每获得 1 层引雷，获得 9 点修为；引雷层数上限 +9 | 第4层（修为≥1880）：每获得 1 层引雷，获得 12 点修为；引雷层数上限 +12 | R8: early_map_market | S8: 蓝金卷面雷纹与水流缠绕，冰晶碎芒沿卷轴边缘闪没，如深潭之下暗藏远雷。 | T8: scripture_waterthunder_scroll_1x1 | U8: allowed
A9: 8 | B9: 100013 | C9: 纳元印诀 | D9: 功法 | E9: scripture | F9: common | G9: 无 | H9: none | I9: 1×1 | J9: 1 | K9: 35 | L9: 是 | M9: bazaar | N9: 3 | O9: 被动效果；条件触发；功法成长 | P9: passive；triggered；scriptureProgression | Q9: 被动效果：法力上限 +0，任意功法突破后效果升级。；法力上限 | 条件触发：任意招式使用时，获得 10 点修为 | 功法成长：第1层（无）：法力上限 +0，任意功法突破后效果升级。；法力上限；任意招式使用时，获得 10 点修为 | 第2层（修为≥180）：法力上限 +0，任意功法突破后效果升级。；法力上限；任意招式使用时，获得 20 点修为 | 第3层（修为≥800）：法力上限 +0，任意功法突破后效果升级。；法力上限；任意招式使用时，获得 30 点修为 | 第4层（修为≥3500）：法力上限 +0，任意功法突破后效果升级。；法力上限；任意招式使用时，获得 40 点修为 | S9: 方形玉印牌层层收束云纹，印心一点灵光内敛，像把纳元心法压成可随身参悟的印诀。 | T9: implement_jade_tally_slips_1x1 | U9: allowed
A10: 9 | B10: 100014 | C10: 悟道玉简 | D10: 功法 | E10: scripture | F10: common | G10: 无 | H10: none | I10: 1×2 | J10: 2 | K10: 40 | L10: 是 | M10: bazaar | N10: 2 | O10: 条件触发；功法成长 | P10: triggered；scriptureProgression | Q10: 条件触发：每当其他功法累计获得 10 点修为时，本功法获得 1 点修为 | 功法成长：第1层（无）：每当其他功法累计获得 10 点修为时，本功法获得 1 点修为 | 第2层（修为≥190）：每当其他功法累计获得 10 点修为时，本功法获得 2 点修为 | 第3层（修为≥780）：每当其他功法累计获得 10 点修为时，本功法获得 3 点修为 | 第4层（修为≥2100）：每当其他功法累计获得 10 点修为时，本功法获得 4 点修为 | S10: 修长玉简并合成册，温白简面篆痕若隐若现，静置案头便有久经讲席的澄明气韵。 | T10: scripture_jade_slip_codex_f2315v1_1x2 | U10: allowed
A11: 10 | B11: 100015 | C11: 焰纹秘卷 | D11: 功法 | E11: scripture | F11: spirit | G11: 火 | H11: fire | I11: 1×1 | J11: 1 | K11: 70 | L11: 否 | M11: bazaar | N11: 3 | O11: 条件触发；被动效果；功法成长 | P11: triggered；passive；scriptureProgression | Q11: 条件触发：将每 1 层炎热转化为 4 点修为 | 被动效果：炎热层数上限 +6 | 功法成长：第1层（无）：将每 1 层炎热转化为 4 点修为；炎热层数上限 +6 | 第2层（修为≥15400）：将每 1 层炎热转化为 8 点修为；炎热层数上限 +12 | 第3层（修为≥44700）：将每 1 层炎热转化为 12 点修为；炎热层数上限 +18 | 第4层（修为≥52500）：将每 1 层炎热转化为 16 点修为；炎热层数上限 +24 | S11: 卷轴之上燃起赤焰纹路，似封存火行法诀。 | T11: scripture_flamecrest_scroll_1x1 | U11: allowed
A12: 11 | B12: 100016 | C12: 青木引灵简 | D12: 功法 | E12: scripture | F12: common | G12: 木 | H12: wood | I12: 1×1 | J12: 1 | K12: 35 | L12: 是 | M12: bazaar | N12: 3 | O12: 条件触发；被动效果；功法成长 | P12: triggered；passive；scriptureProgression | Q12: 条件触发：每当获得 1 层再生时，获得 2 点修为 | 被动效果：再生层数上限 +3 | 功法成长：第1层（无）：每当获得 1 层再生时，获得 2 点修为；再生层数上限 +3 | 第2层（修为≥95）：每当获得 1 层再生时，获得 4 点修为；再生层数上限 +6 | 第3层（修为≥920）：每当获得 1 层再生时，获得 6 点修为；再生层数上限 +9 | 第4层（修为≥2300）：每当获得 1 层再生时，获得 8 点修为；再生层数上限 +12 | S12: 成册竹简刻有叶纹，专擅引动青木灵息。 | T12: scripture_greenwood_spirit_slips_1x1 | U12: allowed
A13: 12 | B13: 100017 | C13: 寒波调息诀 | D13: 功法 | E13: scripture | F13: common | G13: 水 | H13: water | I13: 1×2 | J13: 2 | K13: 35 | L13: 是 | M13: bazaar | N13: 4 | O13: 说明/执行器；被动效果；功法成长 | P13: effectNote；passive；scriptureProgression | Q13: 说明/执行器：每获得 1 层寒冷或露水，获得 2 点修为 | 被动效果：寒冷层数上限 +5 | 被动效果：露水层数上限 +5 | 功法成长：第1层（无）：每获得 1 层寒冷或露水，获得 2 点修为；寒冷层数上限 +5；露水层数上限 +5 | 第2层（修为≥180）：每获得 1 层寒冷或露水，获得 4 点修为；寒冷层数上限 +10；露水层数上限 +10 | 第3层（修为≥840）：每获得 1 层寒冷或露水，获得 6 点修为；寒冷层数上限 +15；露水层数上限 +15 | 第4层（修为≥2350）：每获得 1 层寒冷或露水，获得 8 点修为；寒冷层数上限 +20；露水层数上限 +20 | S13: 蓝白卷页似有寒波细纹起伏，修行时能借寒意回纳法力。 | T13: scripture_bluejade_slip_1x2 | U13: allowed
A14: 13 | B14: 100018 | C14: 凝金阵诀 | D14: 功法 | E14: scripture | F14: common | G14: 金 | H14: metal | I14: 1×1 | J14: 1 | K14: 35 | L14: 是 | M14: questStoryReward | N14: 3 | O14: 条件触发；被动效果；功法成长 | P14: triggered；passive；scriptureProgression | Q14: 条件触发：每获得 1 层凝金，获得 2 点修为 | 被动效果：凝金层数上限 +3 | 功法成长：第1层（无）：每获得 1 层凝金，获得 2 点修为；凝金层数上限 +3 | 第2层（修为≥160）：每获得 1 层凝金，获得 4 点修为；凝金层数上限 +6 | 第3层（修为≥960）：每获得 1 层凝金，获得 6 点修为；凝金层数上限 +9 | 第4层（修为≥3500）：每获得 1 层凝金，获得 8 点修为；凝金层数上限 +12 | S14: 金纹短卷记着凝金阵列的入门法，需借周遭金气才会稳定运转。 | T14: scripture_crimson_talisman_scroll_1x1 | U14: allowed
A15: 14 | B15: 100020 | C15: 沉息归元诀 | D15: 功法 | E15: scripture | F15: common | G15: 土 | H15: earth | I15: 1×2 | J15: 2 | K15: 35 | L15: 是 | M15: bazaar；beastDrop | N15: 3 | O15: 条件触发；被动效果；功法成长 | P15: triggered；passive；scriptureProgression | Q15: 条件触发：每获得 1 层蓄势，获得 2 点修为 | 被动效果：蓄势层数上限 +3 | 功法成长：第1层（无）：每获得 1 层蓄势，获得 2 点修为；蓄势层数上限 +3 | 第2层（修为≥130）：每获得 1 层蓄势，获得 4 点修为；蓄势层数上限 +6 | 第3层（修为≥1120）：每获得 1 层蓄势，获得 6 点修为；蓄势层数上限 +9 | 第4层（修为≥1900）：每获得 1 层蓄势，获得 8 点修为；蓄势层数上限 +12 | S15: 土色册页沉稳厚重，字里行间像把重压一点点炼回体魄。 | T15: scripture_mountain_warding_stele_1x2 | U15: allowed
A16: 15 | B16: 100022 | C16: 搬山运气诀 | D16: 功法 | E16: scripture | F16: common | G16: 土 | H16: earth | I16: 1×1 | J16: 1 | K16: 35 | L16: 是 | M16: bazaar；beastDrop | N16: 4 | O16: 条件触发；被动效果；功法成长 | P16: triggered；passive；scriptureProgression | Q16: 条件触发：每获得 1 点体力，获得 1 点修为 | 被动效果：蓄势层数上限 +3 | 被动效果：体力上限 +10 | 功法成长：第1层（无）：每获得 1 点体力，获得 1 点修为；蓄势层数上限 +3；体力上限 +10 | 第2层（修为≥190）：每获得 1 点体力，获得 2 点修为；蓄势层数上限 +6；体力上限 +20 | 第3层（修为≥860）：每获得 1 点体力，获得 3 点修为；蓄势层数上限 +9；体力上限 +30 | 第4层（修为≥1940）：每获得 1 点体力，获得 4 点修为；蓄势层数上限 +12；体力上限 +40 | S16: 旧卷上绘着搬山行气的小人图，笔势沉稳，像把筋骨余力一点点转入丹田。 | T16: scripture_bamboo_cloud_scroll_1x1 | U16: allowed
A17: 16 | B17: 100023 | C17: 丹霞养火诀 | D17: 功法 | E17: scripture | F17: common | G17: 火 | H17: fire | I17: 2×2 | J17: 4 | K17: 70 | L17: 是 | M17: questStoryReward | N17: 3 | O17: 说明/执行器；被动效果；功法成长 | P17: effectNote；passive；scriptureProgression | Q17: 说明/执行器：每成功炼制 1 颗丹药，获得 200 点修为 | 被动效果：炼丹成功率 +5% | 功法成长：第1层（无）：每成功炼制 1 颗丹药，获得 200 点修为；炼丹成功率 +5% | 第2层（修为≥2150）：每成功炼制 1 颗丹药，获得 300 点修为；炼丹成功率 +10% | 第3层（修为≥5100）：每成功炼制 1 颗丹药，获得 400 点修为；炼丹成功率 +15% | 第4层（修为≥19100）：每成功炼制 1 颗丹药，获得 500 点修为；炼丹成功率 +20% | S17: 丹霞外院入门功法，重在以细火养息，先稳体力，再引火气入周天。 | T17: scripture_crimson_blaze_scroll_2x2 | U17: allowed
A18: 17 | B18: 100024 | C18: 青阙符旗诀 | D18: 功法 | E18: scripture | F18: common | G18: 土 | H18: earth | I18: 2×2 | J18: 4 | K18: 70 | L18: 是 | M18: questStoryReward | N18: 3 | O18: 条件触发；被动效果；功法成长 | P18: triggered；passive；scriptureProgression | Q18: 条件触发：每消耗 1 层蓄势时，获得 4 点修为 | 被动效果：蓄势层数上限 +15 | 功法成长：第1层（无）：每消耗 1 层蓄势时，获得 4 点修为；蓄势层数上限 +15 | 第2层（修为≥1640）：每消耗 1 层蓄势时，获得 8 点修为；蓄势层数上限 +20 | 第3层（修为≥6200）：每消耗 1 层蓄势时，获得 12 点修为；蓄势层数上限 +25 | 第4层（修为≥17500）：每消耗 1 层蓄势时，获得 16 点修为；蓄势层数上限 +30 | R18: scripture_100024 | S18: 青阙门入门功法，讲究以符意镇息，先立根基，再借阵势行气。 | T18: scripture_jade_hidden_scroll_2x2 | U18: allowed
A19: 18 | B19: 100025 | C19: 水月调息篇 | D19: 功法 | E19: scripture | F19: common | G19: 水 | H19: water | I19: 1×1 | J19: 1 | K19: 70 | L19: 是 | M19: questStoryReward | N19: 3 | O19: 条件触发；被动效果；功法成长 | P19: triggered；passive；scriptureProgression | Q19: 条件触发：每层露水恢复气血时，获得 4 点修为 | 被动效果：露水层数上限 +10 | 功法成长：第1层（无）：每层露水恢复气血时，获得 4 点修为；露水层数上限 +10 | 第2层（修为≥1840）：每层露水恢复气血时，获得 8 点修为；露水层数上限 +20 | 第3层（修为≥4600）：每层露水恢复气血时，获得 12 点修为；露水层数上限 +30 | 第4层（修为≥19800）：每层露水恢复气血时，获得 16 点修为；露水层数上限 +40 | S19: 水月别院入门功法，取月照静水之意，重在调息、回气与久战不乱。 | T19: scripture_astrolabe_scroll_1x1 | U19: allowed
A20: 19 | B20: 100027 | C20: 金刃诀 | D20: 功法 | E20: scripture | F20: common | G20: 金 | H20: metal | I20: 1×1 | J20: 1 | K20: 35 | L20: 是 | M20: bazaar | N20: 3 | O20: 条件触发；被动效果；功法成长 | P20: triggered；passive；scriptureProgression | Q20: 条件触发：每消耗 1 层凝金时，获得 2 点修为 | 被动效果：凝金层数上限 +3 | 功法成长：第1层（无）：每消耗 1 层凝金时，获得 2 点修为；凝金层数上限 +3 | 第2层（修为≥110）：每消耗 1 层凝金时，获得 4 点修为；凝金层数上限 +6 | 第3层（修为≥900）：每消耗 1 层凝金时，获得 6 点修为；凝金层数上限 +9 | 第4层（修为≥2450）：每消耗 1 层凝金时，获得 8 点修为；凝金层数上限 +12 | S20: 青绿秘册内页压着细密金纹，行气篇章如刀锋层叠，教人凝金养刃、借锋破敌。 | T20: scripture_jinrenjue_1x1 | U20: allowed
A21: 20 | B21: 100028 | C21: 铁甲诀 | D21: 功法 | E21: scripture | F21: common | G21: 无 | H21: none | I21: 1×1 | J21: 1 | K21: 35 | L21: 是 | M21: bazaar | N21: 3 | O21: 周期触发；被动效果；功法成长 | P21: periodicPulse；passive；scriptureProgression | Q21: 周期触发：消耗所有护甲，每消耗 1 层护甲，获得 1 点修为；每层护甲消耗时，获得 1 点修为 | 被动效果：护甲层数上限 +5 | 功法成长：第1层（无）：消耗所有护甲，每消耗 1 层护甲，获得 1 点修为；每层护甲消耗时，获得 1 点修为；护甲层数上限 +5 | 第2层（修为≥150）：消耗所有护甲，每消耗 1 层护甲，获得 2 点修为；每层护甲消耗时，获得 2 点修为；护甲层数上限 +10 | 第3层（修为≥470；境界≥炼气4层）：消耗所有护甲，每消耗 1 层护甲，获得 3 点修为；每层护甲消耗时，获得 3 点修为；护甲层数上限 +15 | 第4层（修为≥3150；境界≥炼气4层）：消耗所有护甲，每消耗 1 层护甲，获得 4 点修为；每层护甲消耗时，获得 4 点修为；护甲层数上限 +20 | S21: 青绿秘册绘满披甲负重的小人图，笔势厚拙，讲究以沉身磨力、以甲势护体。 | T21: scripture_tiejiajue_1x1 | U21: allowed
A22: 21 | B22: 100029 | C22: 青河听潮篇 | D22: 功法 | E22: scripture | F22: common | G22: 水 | H22: water | I22: 1×1 | J22: 1 | K22: 35 | L22: 是 | M22: bazaar | N22: 3 | O22: 条件触发；被动效果；功法成长 | P22: triggered；passive；scriptureProgression | Q22: 条件触发：每消耗 1 层露水时，获得 2 点修为 | 被动效果：露水层数上限 +3 | 功法成长：第1层（无）：每消耗 1 层露水时，获得 2 点修为；露水层数上限 +3 | 第2层（修为≥120；境界≥炼气层）：每消耗 1 层露水时，获得 4 点修为；露水层数上限 +6 | 第3层（修为≥760；境界≥炼气层）：每消耗 1 层露水时，获得 6 点修为；露水层数上限 +9 | 第4层（修为≥3950；境界≥炼气层）：每消耗 1 层露水时，获得 8 点修为；露水层数上限 +12 | S22: 潮声入息，辨微澜以静心。卷页含青河宗传承的水纹与旧印，静置时仍似能听见远处河声。 | T22: scripture_qinghe_tingchao_1x1 | U22: allowed
A23: 22 | B23: 100030 | C23: 伏流追息诀 | D23: 功法 | E23: scripture | F23: common | G23: 风 | H23: wind | I23: 1×1 | J23: 1 | K23: 35 | L23: 是 | M23: bazaar | N23: 4 | O23: 条件触发；被动效果；功法成长 | P23: triggered；passive；scriptureProgression | Q23: 条件触发：每获得 1 层敏捷或闪避时，获得 3 点修为 | 条件触发：每获得 1 层敏捷或闪避时，获得 3 点修为 | 被动效果：敏捷层数上限 +3 | 功法成长：第1层（无）：每获得 1 层敏捷或闪避时，获得 3 点修为；敏捷层数上限 +3 | 第2层（修为≥210；境界≥炼气层）：每获得 1 层敏捷或闪避时，获得 6 点修为；敏捷层数上限 +6 | 第3层（修为≥640；境界≥炼气层）：每获得 1 层敏捷或闪避时，获得 9 点修为；敏捷层数上限 +9 | 第4层（修为≥3200；境界≥炼气层）：每获得 1 层敏捷或闪避时，获得 12 点修为；敏捷层数上限 +12 | S23: 循伏流残痕，追索未绝之息。卷页含青河宗传承的水纹与旧印，静置时仍似能听见远处河声。 | T23: scripture_fuliu_zhuixi_1x1 | U23: allowed
A24: 23 | B24: 100031 | C24: 回澜牵机诀 | D24: 功法 | E24: scripture | F24: common | G24: 水 | H24: water | I24: 1×1 | J24: 1 | K24: 35 | L24: 是 | M24: bazaar | N24: 4 | O24: 条件触发；被动效果；功法成长 | P24: triggered；passive；scriptureProgression | Q24: 条件触发：每层露水恢复体力时，获得 1 点修为 | 被动效果：露水层数上限 +3 | 被动效果：体力上限 +10 | 功法成长：第1层（无）：每层露水恢复体力时，获得 1 点修为；露水层数上限 +3；体力上限 +10 | 第2层（修为≥210；境界≥炼气层）：每层露水恢复体力时，获得 2 点修为；露水层数上限 +6；体力上限 +20 | 第3层（修为≥680；境界≥炼气层）：每层露水恢复体力时，获得 3 点修为；露水层数上限 +9；体力上限 +30 | 第4层（修为≥4300；境界≥炼气层）：每层露水恢复体力时，获得 4 点修为；露水层数上限 +12；体力上限 +40 | S24: 借舟索阵钉卸力转势。卷页含青河宗传承的水纹与旧印，静置时仍似能听见远处河声。 | T24: scripture_huilan_qianji_1x1 | U24: allowed
A25: 24 | B25: 100042 | C25: 九川归海经 | D25: 功法 | E25: scripture | F25: common | G25: 水 | H25: water | I25: 2×3 | J25: 6 | K25: 50 | L25: 是 | M25: bazaar | N25: 3 | O25: 周期触发；被动效果；功法成长 | P25: periodicPulse；passive；scriptureProgression | Q25: 周期触发：消耗所有露水，每消耗 1 层获得 1 点修为 | 被动效果：露水层数上限 +10 | 功法成长：第1层（无）：消耗所有露水，每消耗 1 层获得 1 点修为；露水层数上限 +10 | 第2层（修为≥160；境界≥炼气4层）：消耗所有露水，每消耗 1 层获得 2 点修为；露水层数上限 +15 | 第3层（修为≥840；境界≥炼气6层）：消耗所有露水，每消耗 1 层获得 3 点修为；露水层数上限 +20 | 第4层（修为≥2250；境界≥筑基1层）：消耗所有露水，每消耗 1 层获得 4 点修为；露水层数上限 +25 | 第5层（修为≥10600；境界≥筑基2层）：消耗所有露水，每消耗 1 层获得 5 点修为；露水层数上限 +30 | 第6层（修为≥36700；境界≥筑基3层）：消耗所有露水，每消耗 1 层获得 6 点修为；露水层数上限 +35 | S25: 玉溪阁分汊水工以支流疏导总势的行气图谱，页间水线层层分合。 | T25: scripture_yuxi_jiuchuan_guihai_2x3 | U25: allowed
A26: 25 | B26: 100043 | C26: 青木引风诀 | D26: 功法 | E26: scripture | F26: common | G26: 木 | H26: wood | I26: 2×3 | J26: 6 | K26: 50 | L26: 是 | M26: bazaar；questStoryReward | N26: 5 | O26: 周期触发；条件触发；被动效果；功法成长 | P26: periodicPulse；triggered；passive；scriptureProgression | Q26: 周期触发：消耗所有再生，每消耗 1 层获得 2 点修为 | 条件触发：每当消耗 1 层敏捷时，获得 2 点修为 | 被动效果：再生层数上限 +2 | 被动效果：敏捷层数上限 +2 | 功法成长：第1层（无）：消耗所有再生，每消耗 1 层获得 2 点修为；每当消耗 1 层敏捷时，获得 2 点修为；再生层数上限 +2；敏捷层数上限 +2 | 第2层（修为≥170；境界≥炼气4层）：消耗所有再生，每消耗 1 层获得 4 点修为；每当消耗 1 层敏捷时，获得 4 点修为；再生层数上限 +4；敏捷层数上限 +4 | 第3层（修为≥800；境界≥炼气6层）：消耗所有再生，每消耗 1 层获得 6 点修为；每当消耗 1 层敏捷时，获得 6 点修为；再生层数上限 +6；敏捷层数上限 +6 | 第4层（修为≥2550；境界≥炼气10层）：消耗所有再生，每消耗 1 层获得 8 点修为；每当消耗 1 层敏捷时，获得 8 点修为；再生层数上限 +8；敏捷层数上限 +8 | 第5层（修为≥10800；境界≥筑基2层）：消耗所有再生，每消耗 1 层获得 10 点修为；每当消耗 1 层敏捷时，获得 10 点修为；再生层数上限 +10；敏捷层数上限 +10 | 第6层（修为≥32100；境界≥筑基3层）：消耗所有再生，每消耗 1 层获得 12 点修为；每当消耗 1 层敏捷时，获得 12 点修为；再生层数上限 +12；敏捷层数上限 +12 | S26: 以水息养木，以风势引灵；行气如舟，不与逆流争先。 | T26: scripture_yuxi_jiefeng_xingzhou_2x3 | U26: allowed
A27: 26 | B27: 100044 | C27: 金契封河十二章 | D27: 功法 | E27: scripture | F27: common | G27: 金 | H27: metal | I27: 2×3 | J27: 6 | K27: 50 | L27: 是 | M27: bazaar | N27: 2 | O27: 周期触发；功法成长 | P27: periodicPulse；scriptureProgression | Q27: 周期触发：消耗所有凝金，每消耗 1 层凝金，获得 4 点修为 | 功法成长：第1层（无）：消耗所有凝金，每消耗 1 层凝金，获得 4 点修为 | 第2层（修为≥210；境界≥炼气4层）：消耗所有凝金，每消耗 1 层凝金，获得 8 点修为 | 第3层（修为≥620；境界≥炼气6层）：消耗所有凝金，每消耗 1 层凝金，获得 12 点修为 | 第4层（修为≥2900；境界≥筑基1层）：消耗所有凝金，每消耗 1 层凝金，获得 16 点修为 | 第5层（修为≥12100；境界≥筑基2层）：消耗所有凝金，每消耗 1 层凝金，获得 20 点修为 | 第6层（修为≥40500；境界≥筑基3层）：消耗所有凝金，每消耗 1 层凝金，获得 24 点修为 | S27: 玉溪阁检校河契与器印的旧录，金线批注如水尺般严整分明。 | T27: scripture_yuxi_jinqi_fenghe_shierzhang_2x3 | U27: allowed
A28: 27 | B28: 100045 | C28: 炉火照寒潭 | D28: 功法 | E28: scripture | F28: common | G28: 火 | H28: fire | I28: 2×3 | J28: 6 | K28: 50 | L28: 是 | M28: bazaar | N28: 3 | O28: 周期触发；被动效果；功法成长 | P28: periodicPulse；passive；scriptureProgression | Q28: 周期触发：消耗所有炎热，每消耗 1 层炎热，获得 4 点修为 | 被动效果：炎热层数上限 +3 | 功法成长：第1层（无）：消耗所有炎热，每消耗 1 层炎热，获得 4 点修为；消耗所有炎热，每消耗 1 层炎热，获得 8 点修为；炎热层数上限 +3 | 第2层（修为≥140；境界≥炼气4层）：消耗所有炎热，每消耗 1 层炎热，获得 8 点修为；消耗所有炎热，每消耗 1 层炎热，获得 12 点修为；炎热层数上限 +6 | 第3层（修为≥640；境界≥炼气6层）：消耗所有炎热，每消耗 1 层炎热，获得 12 点修为；消耗所有炎热，每消耗 1 层炎热，获得 16 点修为；炎热层数上限 +9 | 第4层（修为≥2750；境界≥筑基1层）：消耗所有炎热，每消耗 1 层炎热，获得 16 点修为；炎热层数上限 +12 | 第5层（修为≥10900；境界≥筑基2层）：消耗所有炎热，每消耗 1 层炎热，获得 20 点修为；炎热层数上限 +15 | 第6层（修为≥27500；境界≥筑基3层）：消耗所有炎热，每消耗 1 层炎热，获得 24 点修为；炎热层数上限 +18 | S28: 玉溪阁百炉同开时收束冷热余势的秘诀，朱墨炉记之间留有冷蓝水痕。 | T28: scripture_yuxi_luhuo_zhao_hantan_2x3 | U28: allowed
A29: 28 | B29: 100046 | C29: 镇澜功 | D29: 功法 | E29: scripture | F29: common | G29: 土 | H29: earth | I29: 2×3 | J29: 6 | K29: 50 | L29: 是 | M29: bazaar | N29: 4 | O29: 周期触发；被动效果；功法成长 | P29: periodicPulse；passive；scriptureProgression | Q29: 周期触发：消耗所有蓄势，每消耗 1 层蓄势，获得 3 点修为 | 被动效果：护甲层数上限 +3 | 被动效果：蓄势层数上限 +2 | 功法成长：第1层（无）：消耗所有蓄势，每消耗 1 层蓄势，获得 3 点修为；护甲层数上限 +3；蓄势层数上限 +2 | 第2层（修为≥140；境界≥炼气4层）：消耗所有蓄势，每消耗 1 层蓄势，获得 6 点修为；护甲层数上限 +6；蓄势层数上限 +4 | 第3层（修为≥740；境界≥炼气6层）：消耗所有蓄势，每消耗 1 层蓄势，获得 9 点修为；护甲层数上限 +9；蓄势层数上限 +6 | 第4层（修为≥2900；境界≥筑基1层）：消耗所有蓄势，每消耗 1 层蓄势，获得 12 点修为；护甲层数上限 +12；蓄势层数上限 +8 | 第5层（修为≥11100；境界≥筑基2层）：消耗所有蓄势，每消耗 1 层蓄势，获得 15 点修为；护甲层数上限 +15；蓄势层数上限 +10 | 第6层（修为≥35900；境界≥筑基3层）：消耗所有蓄势，每消耗 1 层蓄势，获得 18 点修为；护甲层数上限 +18；蓄势层数上限 +12 | S29: 玉溪阁门闸承压与回澜的阵图，厚重闸线围住层层倒卷的水纹。 | T29: scripture_yuxi_zhenlan_gong_2x3 | U29: allowed
A30: 29 | B30: 100047 | C30: 太阴玄霜诀 | D30: 功法 | E30: scripture | F30: common | G30: 冰 | H30: ice | I30: 1×2 | J30: 2 | K30: 35 | L30: 是 | M30: bazaar | N30: 3 | O30: 条件触发；被动效果；功法成长 | P30: triggered；passive；scriptureProgression | Q30: 条件触发：每消耗 1 层寒冷，获得 2 点修为 | 被动效果：寒冷层数上限 +5 | 功法成长：第1层（无）：每消耗 1 层寒冷，获得 2 点修为；寒冷层数上限 +5 | 第2层（修为≥120；境界≥炼气层）：每消耗 1 层寒冷，获得 4 点修为；寒冷层数上限 +10 | 第3层（修为≥740；境界≥炼气层）：每消耗 1 层寒冷，获得 6 点修为；寒冷层数上限 +15 | 第4层（修为≥3550；境界≥炼气层）：每消耗 1 层寒冷，获得 8 点修为；寒冷层数上限 +20 | S30: 月白绢册以冰蚕丝装订，卷中水脉与霜纹交叠，讲究先蓄寒、再渡霜、终以万籁冰封镇住敌阵。 | T30: scripture_lunar_mystic_frost_art_1x2 | U30: allowed
A31: 30 | B31: 300001 | C31: 硬气丹 | D31: 丹药 | E31: pill | F31: common | G31: 土 | H31: earth | I31: 1×1 | J31: 1 | K31: 5 | L31: 是 | M31: bazaar；alchemyCrafting；dynamicRandomReward | N31: 1 | O31: 消耗品效果 | P31: consumable | Q31: 消耗品效果：坚硬上限永久 +1 | R31: buff_upper_limit | S31: 土金阵纹压在沉色丹丸表面，药气不浮不躁，入口后像把散劲慢慢坠进筋骨。 | T31: pill_hard_qi_pill_1x1 | U31: allowed
A32: 31 | B32: 300002 | C32: 温炉丹 | D32: 丹药 | E32: pill | F32: common | G32: 火 | H32: fire | I32: 1×1 | J32: 1 | K32: 2 | L32: 是 | M32: bazaar；alchemyCrafting；dynamicRandomReward | N32: 1 | O32: 消耗品效果 | P32: consumable | Q32: 消耗品效果：炎热上限永久 +1 | R32: buff_upper_limit | S32: 温润丹胚里封着一缕细火，热意不急不烈，只在靠近炉烟时显出柔和的助燃气。 | T32: pill_wenling_core_pellet_1x1 | U32: allowed
A33: 32 | B33: 300003 | C33: 温脉露丸 | D33: 丹药 | E33: pill | F33: common | G33: 无 | H33: none | I33: 1×1 | J33: 1 | K33: 3 | L33: 是 | M33: bazaar；alchemyCrafting；dynamicRandomReward | N33: 1 | O33: 消耗品效果 | P33: consumable | Q33: 消耗品效果：气血上限永久 +3 | R33: stat_upper_limit | S33: 青绿小瓶晶润轻盈，瓶中药露贴壁流转，开塞便有温脉回气的草木清香。 | T33: pill_verdant_dew_vial_1x1 | U33: allowed
A34: 33 | B34: 300004 | C34: 固元丸 | D34: 丹药 | E34: pill | F34: common | G34: 无 | H34: none | I34: 1×1 | J34: 1 | K34: 5 | L34: 是 | M34: bazaar；beastDrop；alchemyCrafting；dynamicRandomReward | N34: 1 | O34: 消耗品效果 | P34: consumable | Q34: 消耗品效果：体力上限永久 +3 | R34: stat_upper_limit | S34: 米白丹丸厚润如玉，金纹伏在表层不散，含入口中有一股稳稳固住根基的暖意。 | T34: pill_golden_pattern_foundation_dan_1x1 | U34: allowed
A35: 34 | B35: 300005 | C35: 聚气丹 | D35: 丹药 | E35: pill | F35: common | G35: 无 | H35: none | I35: 1×1 | J35: 1 | K35: 5 | L35: 是 | M35: bazaar；alchemyCrafting；dynamicRandomReward | N35: 1 | O35: 消耗品效果 | P35: consumable | Q35: 消耗品效果：法力上限永久 +3 | R35: stat_upper_limit | S35: 碧绿丹珠通透圆满，金纹细绕如聚拢云气，静置时也像在缓缓收纳游离灵息。 | T35: pill_qi_gathering_dan_1x1 | U35: allowed
A36: 35 | B36: 300011 | C36: 云纹聚气丹 | D36: 丹药 | E36: pill | F36: spirit | G36: 无 | H36: none | I36: 1×1 | J36: 1 | K36: 50 | L36: 是 | M36: bazaar；alchemyCrafting；dynamicRandomReward | N36: 1 | O36: 消耗品效果 | P36: consumable | Q36: 消耗品效果：法力上限永久 +30；法力上限 +30 | R36: stat_upper_limit | S36: 金黄丹珠外绕云气，珠体浑圆厚润，掌心一托便似晨雾凝成的温亮灵核。 | T36: pill_cloudpattern_golden_dan_1x1 | U36: allowed
A37: 36 | B37: 300012 | C37: 固元壮体丹 | D37: 丹药 | E37: pill | F37: spirit | G37: 无 | H37: none | I37: 1×1 | J37: 1 | K37: 50 | L37: 是 | M37: bazaar；beastDrop；alchemyCrafting；dynamicRandomReward | N37: 1 | O37: 消耗品效果 | P37: consumable | Q37: 消耗品效果：体力上限永久 +30；体力上限 +30 | R37: stat_upper_limit | S37: 暗红褐色丹丸置于厚实木碗，表面锻纹朴拙，药香沉入筋骨而不外扬。 | T37: pill_body_strengthening_pill_1x1 | U37: allowed
A38: 37 | B38: 300013 | C38: 凝血丹 | D38: 丹药 | E38: pill | F38: spirit | G38: 无 | H38: none | I38: 1×1 | J38: 1 | K38: 75 | L38: 是 | M38: bazaar；alchemyCrafting；dynamicRandomReward | N38: 1 | O38: 消耗品效果 | P38: consumable | Q38: 消耗品效果：精血上限永久 +6；精血上限 +6 | R38: stat_upper_limit | S38: 圆盒半启，赤金丹丸柔光内敛，药香中透出温厚血气。 | T38: pill_goldcore_case_1x1 | U38: allowed
A39: 38 | B39: 300015 | C39: 紫极蕴神丹 | D39: 丹药 | E39: pill | F39: spirit | G39: 无 | H39: none | I39: 1×1 | J39: 1 | K39: 75 | L39: 是 | M39: bazaar；alchemyCrafting；dynamicRandomReward | N39: 1 | O39: 消耗品效果 | P39: consumable | Q39: 消耗品效果：神识上限永久 +6；神识上限 +6 | R39: stat_upper_limit | S39: 深紫丹丸卧在细口瓷瓶旁，丹壳神纹细密如星，气息沉静而凝定，适合温养神识。 | T39: pill_purple_apex_spirit_nurturing_pill_1x1 | U39: allowed
A40: 39 | B40: 300016 | C40: 通玄丹 | D40: 丹药 | E40: pill | F40: spirit | G40: 无 | H40: none | I40: 1×1 | J40: 1 | K40: 75 | L40: 否 | M40: bazaar；alchemyCrafting | N40: 1 | O40: 消耗品效果 | P40: consumable | Q40: 消耗品效果：精血上限永久 +6；精血上限 +6 | R40: stat_upper_limit | S40: 蓝青丹丸置于细长瓷盘中央，纹理多向交织而不乱，像把纷繁灵思梳成一线清明。 | T40: pill_mystic_insight_pill_1x1 | U40: allowed
...

Sheet 效果明细
A1: 物品ID | B1: 名称 | C1: 类别 | D1: 品阶代码 | E1: 元素代码 | F1: 顶层效果序号 | G1: 作用层级 | H1: 功法层数 | I1: 突破要求 | J1: 突破目标 | K1: 限时(秒) | L1: 冷却(秒) | M1: 效果类型 | N1: 效果类型代码 | O1: 效果文字 | P1: 触发器代码 | Q1: 机制类型代码 | R1: 效果JSON
A2: 100001 | B2: 炼体术 | C2: 功法 | D2: common | E2: none | F2: 1 | G2: 基础/顶层 | M2: 被动效果 | N2: passive | O2: 每消耗 1 点体力，获得 1 点修为 | Q2: staminaConsumedToCultivation | R2: {"kind":"passive","label":"每消耗 1 点体力，获得 1 点修为","passiveEffect":{"type":"staminaConsumedToCultivation","value":1,"label":"每消耗 1 点体力，获得 1 点修为"}}
A3: 100001 | B3: 炼体术 | C3: 功法 | D3: common | E3: none | F3: 2 | G3: 功法成长层 | H3: 1 | I3: 无 | L3: 15 | M3: 被动效果 | N3: passive | O3: 每消耗 1 点体力，获得 1 点修为 | Q3: staminaConsumedToCultivation | R3: {"kind":"passive","label":"每消耗 1 点体力，获得 1 点修为","passiveEffect":{"type":"staminaConsumedToCultivation","value":1,"label":"每消耗 1 点体力，获得 1 点修为"}}
A4: 100001 | B4: 炼体术 | C4: 功法 | D4: common | E4: none | F4: 2 | G4: 功法成长层 | H4: 2 | I4: 修为≥120 | J4: 120 | K4: 190 | L4: 15 | M4: 被动效果 | N4: passive | O4: 每消耗 1 点体力，获得 2 点修为 | Q4: staminaConsumedToCultivation | R4: {"kind":"passive","label":"每消耗 1 点体力，获得 2 点修为","passiveEffect":{"type":"staminaConsumedToCultivation","value":2,"label":"每消耗 1 点体力，获得 2 点修为"}}
A5: 100001 | B5: 炼体术 | C5: 功法 | D5: common | E5: none | F5: 2 | G5: 功法成长层 | H5: 3 | I5: 修为≥760；境界≥炼气4层 | J5: 760 | K5: 230 | L5: 60 | M5: 被动效果 | N5: passive | O5: 每消耗 1 点体力，获得 3 点修为 | Q5: staminaConsumedToCultivation | R5: {"kind":"passive","label":"每消耗 1 点体力，获得 3 点修为","passiveEffect":{"type":"staminaConsumedToCultivation","value":3,"label":"每消耗 1 点体力，获得 3 点修为"}}
A6: 100001 | B6: 炼体术 | C6: 功法 | D6: common | E6: none | F6: 2 | G6: 功法成长层 | H6: 4 | I6: 修为≥2450；境界≥炼气4层 | J6: 2450 | K6: 230 | L6: 120 | M6: 被动效果 | N6: passive | O6: 每消耗 1 点体力，获得 4 点修为 | Q6: staminaConsumedToCultivation | R6: {"kind":"passive","label":"每消耗 1 点体力，获得 4 点修为","passiveEffect":{"type":"staminaConsumedToCultivation","value":4,"label":"每消耗 1 点体力，获得 4 点修为"}}
A7: 100002 | B7: 云字养气册 | C7: 功法 | D7: common | E7: wood | F7: 1 | G7: 基础/顶层 | M7: 条件触发 | N7: triggered | O7: 每获得 1 点气血，获得 3 点修为 | P7: onPrimaryStatGain | Q7: gainCultivation | R7: {"kind":"triggered","label":"每获得 1 点气血，获得 3 点修为","triggeredEffect":{"trigger":"onPrimaryStatGain","type":"gainCultivation","amount":2,"amountPerEventPrimaryStatGain":1,"eventPrimaryStatGainFilter":["health"]}}
A8: 100002 | B8: 云字养气册 | C8: 功法 | D8: common | E8: wood | F8: 2 | G8: 功法成长层 | H8: 1 | I8: 无 | L8: 15 | M8: 条件触发 | N8: triggered | O8: 每获得 1 点气血，获得 3 点修为 | P8: onPrimaryStatGain | Q8: gainCultivation | R8: {"kind":"triggered","label":"每获得 1 点气血，获得 3 点修为","triggeredEffect":{"trigger":"onPrimaryStatGain","type":"gainCultivation","amount":2,"amountPerEventPrimaryStatGain":1,"eventPrimaryStatGainFilter":["health"]}}
A9: 100002 | B9: 云字养气册 | C9: 功法 | D9: common | E9: wood | F9: 2 | G9: 功法成长层 | H9: 2 | I9: 修为≥210 | J9: 210 | K9: 275 | L9: 30 | M9: 条件触发 | N9: triggered | O9: 每获得 1 点气血，获得 6 点修为 | P9: onPrimaryStatGain | Q9: gainCultivation | R9: {"kind":"triggered","label":"每获得 1 点气血，获得 6 点修为","triggeredEffect":{"trigger":"onPrimaryStatGain","type":"gainCultivation","amount":4,"amountPerEventPrimaryStatGain":2,"eventPrimaryStatGainFilter":["health"]}}
A10: 100002 | B10: 云字养气册 | C10: 功法 | D10: common | E10: wood | F10: 2 | G10: 功法成长层 | H10: 3 | I10: 修为≥540 | J10: 540 | K10: 195 | L10: 90 | M10: 条件触发 | N10: triggered | O10: 每获得 1 点气血，获得 9 点修为 | P10: onPrimaryStatGain | Q10: gainCultivation | R10: {"kind":"triggered","label":"每获得 1 点气血，获得 9 点修为","triggeredEffect":{"trigger":"onPrimaryStatGain","type":"gainCultivation","amount":6,"amountPerEventPrimaryStatGain":3,"eventPrimaryStatGainFilter":["health"]}}
A11: 100002 | B11: 云字养气册 | C11: 功法 | D11: common | E11: wood | F11: 2 | G11: 功法成长层 | H11: 4 | I11: 修为≥2950 | J11: 2950 | K11: 240 | L11: 240 | M11: 条件触发 | N11: triggered | O11: 每获得 1 点气血，获得 12 点修为 | P11: onPrimaryStatGain | Q11: gainCultivation | R11: {"kind":"triggered","label":"每获得 1 点气血，获得 12 点修为","triggeredEffect":{"trigger":"onPrimaryStatGain","type":"gainCultivation","amount":8,"amountPerEventPrimaryStatGain":4,"eventPrimaryStatGainFilter":["health"]}}
A12: 100003 | B12: 聚气册 | C12: 功法 | D12: common | E12: fire | F12: 1 | G12: 基础/顶层 | M12: 周期触发 | N12: periodicPulse | O12: 获得 10 点修为 | R12: {"kind":"periodicPulse","periodicPulse":{"intervalSec":30,"label":"获得 10 点修为","cultivationGain":10}}
A13: 100003 | B13: 聚气册 | C13: 功法 | D13: common | E13: fire | F13: 2 | G13: 基础/顶层 | M13: 条件触发 | N13: triggered | O13: 每当有丹药耗尽时，获得 10 点修为 | P13: onConsumableExhausted | Q13: grantResources；cultivation；any | R13: {"kind":"triggered","label":"每当有丹药耗尽时，获得 10 点修为","triggeredEffect":{"trigger":"onConsumableExhausted","type":"grantResources","grants":[{"type":"cultivation","amount":10}],"support":"cultivationOnly","eventSource":{"target":{"type":"any"},"filter":{"categories":["pill"]}}}}
A14: 100003 | B14: 聚气册 | C14: 功法 | D14: common | E14: fire | F14: 3 | G14: 功法成长层 | H14: 1 | I14: 无 | L14: 15 | M14: 周期触发 | N14: periodicPulse | O14: 获得 10 点修为 | R14: {"kind":"periodicPulse","periodicPulse":{"intervalSec":30,"label":"获得 10 点修为","cultivationGain":10}}
A15: 100003 | B15: 聚气册 | C15: 功法 | D15: common | E15: fire | F15: 3 | G15: 功法成长层 | H15: 1 | I15: 无 | L15: 15 | M15: 条件触发 | N15: triggered | O15: 每当有丹药耗尽时，获得 10 点修为 | P15: onConsumableExhausted | Q15: grantResources；cultivation；any | R15: {"kind":"triggered","label":"每当有丹药耗尽时，获得 10 点修为","triggeredEffect":{"trigger":"onConsumableExhausted","type":"grantResources","grants":[{"type":"cultivation","amount":10}],"support":"cultivationOnly","eventSource":{"target":{"type":"any"},"filter":{"categories":["pill"]}}}}
A16: 100003 | B16: 聚气册 | C16: 功法 | D16: common | E16: fire | F16: 3 | G16: 功法成长层 | H16: 2 | I16: 修为≥210 | J16: 210 | K16: 290 | L16: 30 | M16: 周期触发 | N16: periodicPulse | O16: 获得 25 点修为 | R16: {"kind":"periodicPulse","periodicPulse":{"intervalSec":20,"label":"获得 25 点修为","cultivationGain":25}}
A17: 100003 | B17: 聚气册 | C17: 功法 | D17: common | E17: fire | F17: 3 | G17: 功法成长层 | H17: 2 | I17: 修为≥210 | J17: 210 | K17: 290 | L17: 30 | M17: 条件触发 | N17: triggered | O17: 每当有丹药耗尽时，获得 20 点修为 | P17: onConsumableExhausted | Q17: grantResources；cultivation；any | R17: {"kind":"triggered","label":"每当有丹药耗尽时，获得 20 点修为","triggeredEffect":{"trigger":"onConsumableExhausted","type":"grantResources","grants":[{"type":"cultivation","amount":20}],"support":"cultivationOnly","eventSource":{"target":{"type":"any"},"filter":{"categories":["pill"]}}}}
A18: 100003 | B18: 聚气册 | C18: 功法 | D18: common | E18: fire | F18: 3 | G18: 功法成长层 | H18: 3 | I18: 修为≥760 | J18: 760 | K18: 195 | L18: 120 | M18: 周期触发 | N18: periodicPulse | O18: 获得 40 点修为 | R18: {"kind":"periodicPulse","periodicPulse":{"intervalSec":15,"label":"获得 40 点修为","cultivationGain":40}}
A19: 100003 | B19: 聚气册 | C19: 功法 | D19: common | E19: fire | F19: 3 | G19: 功法成长层 | H19: 3 | I19: 修为≥760 | J19: 760 | K19: 195 | L19: 120 | M19: 条件触发 | N19: triggered | O19: 每当有丹药耗尽时，获得 30 点修为 | P19: onConsumableExhausted | Q19: grantResources；cultivation；any | R19: {"kind":"triggered","label":"每当有丹药耗尽时，获得 30 点修为","triggeredEffect":{"trigger":"onConsumableExhausted","type":"grantResources","grants":[{"type":"cultivation","amount":30}],"support":"cultivationOnly","eventSource":{"target":{"type":"any"},"filter":{"categories":["pill"]}}}}
A20: 100004 | B20: 月痕养息册 | C20: 功法 | D20: common | E20: none | F20: 1 | G20: 基础/顶层 | M20: 条件触发 | N20: triggered | O20: 每获得 1 点法力，获得 1 点修为 | P20: onPrimaryStatGain | Q20: gainCultivation | R20: {"kind":"triggered","label":"<cultivation>每获得 1 点法力，获得 1 点修为</cultivation>","triggeredEffect":{"trigger":"onPrimaryStatGain","type":"gainCultivation","amount":0,"amountPerEventPrimaryStatGain":1,"eventPrimaryStatGainFilter":["mana"]}}
A21: 100004 | B21: 月痕养息册 | C21: 功法 | D21: common | E21: none | F21: 2 | G21: 基础/顶层 | M21: 被动效果 | N21: passive | O21: 法力上限 +10 | Q21: primaryStatMaxFlatBonus | R21: {"kind":"passive","label":"法力上限 +10","passiveEffect":{"type":"primaryStatMaxFlatBonus","stat":"mana","value":10,"label":"法力上限 +10"}}
A22: 100004 | B22: 月痕养息册 | C22: 功法 | D22: common | E22: none | F22: 3 | G22: 功法成长层 | H22: 1 | I22: 无 | L22: 15 | M22: 条件触发 | N22: triggered | O22: 每获得 1 点法力，获得 1 点修为 | P22: onPrimaryStatGain | Q22: gainCultivation | R22: {"kind":"triggered","label":"<cultivation>每获得 1 点法力，获得 1 点修为</cultivation>","triggeredEffect":{"trigger":"onPrimaryStatGain","type":"gainCultivation","amount":0,"amountPerEventPrimaryStatGain":1,"eventPrimaryStatGainFilter":["mana"]}}
A23: 100004 | B23: 月痕养息册 | C23: 功法 | D23: common | E23: none | F23: 3 | G23: 功法成长层 | H23: 1 | I23: 无 | L23: 15 | M23: 被动效果 | N23: passive | O23: 法力上限 +10 | Q23: primaryStatMaxFlatBonus | R23: {"kind":"passive","label":"法力上限 +10","passiveEffect":{"type":"primaryStatMaxFlatBonus","stat":"mana","value":10,"label":"法力上限 +10"}}
A24: 100004 | B24: 月痕养息册 | C24: 功法 | D24: common | E24: none | F24: 3 | G24: 功法成长层 | H24: 2 | I24: 修为≥150 | J24: 150 | K24: 195 | L24: 30 | M24: 条件触发 | N24: triggered | O24: 每获得 1 点法力，获得 2 点修为 | P24: onPrimaryStatGain | Q24: gainCultivation | R24: {"kind":"triggered","label":"<cultivation>每获得 1 点法力，获得 2 点修为</cultivation>","triggeredEffect":{"trigger":"onPrimaryStatGain","type":"gainCultivation","amount":0,"amountPerEventPrimaryStatGain":2,"eventPrimaryStatGainFilter":["mana"]}}
A25: 100004 | B25: 月痕养息册 | C25: 功法 | D25: common | E25: none | F25: 3 | G25: 功法成长层 | H25: 2 | I25: 修为≥150 | J25: 150 | K25: 195 | L25: 30 | M25: 被动效果 | N25: passive | O25: 法力上限 +20 | Q25: primaryStatMaxFlatBonus | R25: {"kind":"passive","label":"法力上限 +20","passiveEffect":{"type":"primaryStatMaxFlatBonus","stat":"mana","value":20,"label":"法力上限 +20"}}
A26: 100004 | B26: 月痕养息册 | C26: 功法 | D26: common | E26: none | F26: 3 | G26: 功法成长层 | H26: 3 | I26: 修为≥780 | J26: 780 | K26: 205 | L26: 90 | M26: 条件触发 | N26: triggered | O26: 每获得 1 点法力，获得 3 点修为 | P26: onPrimaryStatGain | Q26: gainCultivation | R26: {"kind":"triggered","label":"<cultivation>每获得 1 点法力，获得 3 点修为</cultivation>","triggeredEffect":{"trigger":"onPrimaryStatGain","type":"gainCultivation","amount":0,"amountPerEventPrimaryStatGain":3,"eventPrimaryStatGainFilter":["mana"]}}
A27: 100004 | B27: 月痕养息册 | C27: 功法 | D27: common | E27: none | F27: 3 | G27: 功法成长层 | H27: 3 | I27: 修为≥780 | J27: 780 | K27: 205 | L27: 90 | M27: 被动效果 | N27: passive | O27: 法力上限 +30 | Q27: primaryStatMaxFlatBonus | R27: {"kind":"passive","label":"法力上限 +30","passiveEffect":{"type":"primaryStatMaxFlatBonus","stat":"mana","value":30,"label":"法力上限 +30"}}
A28: 100004 | B28: 月痕养息册 | C28: 功法 | D28: common | E28: none | F28: 3 | G28: 功法成长层 | H28: 4 | I28: 修为≥3800 | J28: 3800 | K28: 275 | L28: 120 | M28: 条件触发 | N28: triggered | O28: 每获得 1 点法力，获得 4 点修为 | P28: onPrimaryStatGain | Q28: gainCultivation | R28: {"kind":"triggered","label":"<cultivation>每获得 1 点法力，获得 4 点修为</cultivation>","triggeredEffect":{"trigger":"onPrimaryStatGain","type":"gainCultivation","amount":0,"amountPerEventPrimaryStatGain":4,"eventPrimaryStatGainFilter":["mana"]}}
A29: 100004 | B29: 月痕养息册 | C29: 功法 | D29: common | E29: none | F29: 3 | G29: 功法成长层 | H29: 4 | I29: 修为≥3800 | J29: 3800 | K29: 275 | L29: 120 | M29: 被动效果 | N29: passive | O29: 法力上限 +40 | Q29: primaryStatMaxFlatBonus | R29: {"kind":"passive","label":"法力上限 +40","passiveEffect":{"type":"primaryStatMaxFlatBonus","stat":"mana","value":40,"label":"法力上限 +40"}}
A30: 100010 | B30: 五行入门篇 | C30: 功法 | D30: common | E30: none | F30: 1 | G30: 基础/顶层 | M30: 被动效果 | N30: passive | O30: 每消耗 1 点法力，获得 1 点修为 | Q30: primaryStatConsumedToCultivation | R30: {"kind":"passive","passiveEffect":{"type":"primaryStatConsumedToCultivation","stat":"mana","cost":1,"gain":1,"label":"每消耗 1 点法力，获得 1 点修为"}}
A31: 100010 | B31: 五行入门篇 | C31: 功法 | D31: common | E31: none | F31: 2 | G31: 功法成长层 | H31: 1 | I31: 无 | L31: 15 | M31: 被动效果 | N31: passive | O31: 每消耗 1 点法力，获得 1 点修为 | Q31: primaryStatConsumedToCultivation | R31: {"kind":"passive","passiveEffect":{"type":"primaryStatConsumedToCultivation","stat":"mana","cost":1,"gain":1,"label":"每消耗 1 点法力，获得 1 点修为"}}
A32: 100010 | B32: 五行入门篇 | C32: 功法 | D32: common | E32: none | F32: 2 | G32: 功法成长层 | H32: 2 | I32: 修为≥140；境界≥炼气4层 | J32: 140 | K32: 210 | L32: 30 | M32: 被动效果 | N32: passive | O32: 每消耗 1 点法力，获得 2 点修为 | Q32: primaryStatConsumedToCultivation | R32: {"kind":"passive","passiveEffect":{"type":"primaryStatConsumedToCultivation","stat":"mana","cost":1,"gain":2,"label":"每消耗 1 点法力，获得 2 点修为"}}
A33: 100010 | B33: 五行入门篇 | C33: 功法 | D33: common | E33: none | F33: 2 | G33: 功法成长层 | H33: 3 | I33: 修为≥1000 | J33: 1000 | K33: 300 | L33: 60 | M33: 被动效果 | N33: passive | O33: 每消耗 1 点法力，获得 3 点修为 | Q33: primaryStatConsumedToCultivation | R33: {"kind":"passive","passiveEffect":{"type":"primaryStatConsumedToCultivation","stat":"mana","cost":1,"gain":3,"label":"每消耗 1 点法力，获得 3 点修为"}}
A34: 100010 | B34: 五行入门篇 | C34: 功法 | D34: common | E34: none | F34: 2 | G34: 功法成长层 | H34: 4 | I34: 修为≥6000 | J34: 6000 | K34: 285 | L34: 90 | M34: 被动效果 | N34: passive | O34: 每消耗 1 点法力，获得 4 点修为 | Q34: primaryStatConsumedToCultivation | R34: {"kind":"passive","passiveEffect":{"type":"primaryStatConsumedToCultivation","stat":"mana","cost":1,"gain":4,"label":"每消耗 1 点法力，获得 4 点修为"}}
A35: 100011 | B35: 烈阳诀 | C35: 功法 | D35: common | E35: fire | F35: 1 | G35: 基础/顶层 | M35: 条件触发 | N35: triggered | O35: 每获得 1 层炎热，获得 2 点修为 | P35: onBuffGain | Q35: gainCultivation | R35: {"kind":"triggered","label":"每获得 1 层炎热，获得 2 点修为","triggeredEffect":{"trigger":"onBuffGain","type":"gainCultivation","amount":0,"amountPerEventBuffStack":2,"eventBuffId":"heat"}}
A36: 100011 | B36: 烈阳诀 | C36: 功法 | D36: common | E36: fire | F36: 2 | G36: 基础/顶层 | M36: 被动效果 | N36: passive | O36: 炎热层数上限 +3 | Q36: buffStackCapBonus | R36: {"kind":"passive","label":"炎热层数上限 +3","passiveEffect":{"type":"buffStackCapBonus","buffId":"heat","value":3,"label":"炎热层数上限 +3"}}
A37: 100011 | B37: 烈阳诀 | C37: 功法 | D37: common | E37: fire | F37: 3 | G37: 功法成长层 | H37: 1 | I37: 无 | L37: 15 | M37: 条件触发 | N37: triggered | O37: 每获得 1 层炎热，获得 2 点修为 | P37: onBuffGain | Q37: gainCultivation | R37: {"kind":"triggered","label":"每获得 1 层炎热，获得 2 点修为","triggeredEffect":{"trigger":"onBuffGain","type":"gainCultivation","amount":0,"amountPerEventBuffStack":2,"eventBuffId":"heat"}}
A38: 100011 | B38: 烈阳诀 | C38: 功法 | D38: common | E38: fire | F38: 3 | G38: 功法成长层 | H38: 1 | I38: 无 | L38: 15 | M38: 被动效果 | N38: passive | O38: 炎热层数上限 +3 | Q38: buffStackCapBonus | R38: {"kind":"passive","label":"炎热层数上限 +3","passiveEffect":{"type":"buffStackCapBonus","buffId":"heat","value":3,"label":"炎热层数上限 +3"}}
A39: 100011 | B39: 烈阳诀 | C39: 功法 | D39: common | E39: fire | F39: 3 | G39: 功法成长层 | H39: 2 | I39: 修为≥160 | J39: 160 | K39: 230 | L39: 60 | M39: 条件触发 | N39: triggered | O39: 每获得 1 层炎热，获得 4 点修为 | P39: onBuffGain | Q39: gainCultivation | R39: {"kind":"triggered","label":"每获得 1 层炎热，获得 4 点修为","triggeredEffect":{"trigger":"onBuffGain","type":"gainCultivation","amount":0,"amountPerEventBuffStack":4,"eventBuffId":"heat"}}
A40: 100011 | B40: 烈阳诀 | C40: 功法 | D40: common | E40: fire | F40: 3 | G40: 功法成长层 | H40: 2 | I40: 修为≥160 | J40: 160 | K40: 230 | L40: 60 | M40: 被动效果 | N40: passive | O40: 炎热层数上限 +6 | Q40: buffStackCapBonus | R40: {"kind":"passive","label":"炎热层数上限 +6","passiveEffect":{"type":"buffStackCapBonus","buffId":"heat","value":6,"label":"炎热层数上限 +6"}}
...

Sheet 统计汇总
A1: 统计汇总
A2: 所有数量由“物品清单”工作表公式计算；一个物品可以同时含多种效果类型。
A4: 关键指标
A5: 有效物品总数 | B5: =COUNTA('物品清单'!$B:$B)-1
A6: 效果明细行数 | B6: 2064
E8: 类别 | F8: 代码 | G8: 数量 | H8: 品阶 | I8: 代码 | J8: 数量
E9: 法器 | F9: implement | G9: =COUNTIF('物品清单'!$E:$E,"implement") | H9: common | I9: common | J9: =COUNTIF('物品清单'!$F:$F,"common")
E10: 材料 | F10: material | G10: =COUNTIF('物品清单'!$E:$E,"material") | H10: spirit | I10: spirit | J10: =COUNTIF('物品清单'!$F:$F,"spirit")
E11: 招式 | F11: spell | G11: =COUNTIF('物品清单'!$E:$E,"spell") | H11: mystic | I11: mystic | J11: =COUNTIF('物品清单'!$F:$F,"mystic")
E12: 丹药 | F12: pill | G12: =COUNTIF('物品清单'!$E:$E,"pill") | H12: earth | I12: earth | J12: =COUNTIF('物品清单'!$F:$F,"earth")
E13: 阵法 | F13: formation | G13: =COUNTIF('物品清单'!$E:$E,"formation")
E14: 符箓 | F14: talisman | G14: =COUNTIF('物品清单'!$E:$E,"talisman")
E15: 投掷物 | F15: throwable | G15: =COUNTIF('物品清单'!$E:$E,"throwable")
E16: 功法 | F16: scripture | G16: =COUNTIF('物品清单'!$E:$E,"scripture")
E17: 占卜 | F17: divination | G17: =COUNTIF('物品清单'!$E:$E,"divination")
E18: 宝箱 | F18: chest | G18: =COUNTIF('物品清单'!$E:$E,"chest")
A25: 元素 | B25: 代码 | C25: 数量 | E25: 效果类型（按含该类型的物品数） | F25: 代码 | G25: 数量
A26: 水 | B26: water | C26: =COUNTIF('物品清单'!$H:$H,"water") | E26: 周期触发 | F26: periodicPulse | G26: =COUNTIF('物品清单'!$P:$P,"*periodicPulse*")
A27: 火 | B27: fire | C27: =COUNTIF('物品清单'!$H:$H,"fire") | E27: 条件触发 | F27: triggered | G27: =COUNTIF('物品清单'!$P:$P,"*triggered*")
A28: 金 | B28: metal | C28: =COUNTIF('物品清单'!$H:$H,"metal") | E28: 说明/执行器 | F28: effectNote | G28: =COUNTIF('物品清单'!$P:$P,"*effectNote*")
A29: 土 | B29: earth | C29: =COUNTIF('物品清单'!$H:$H,"earth") | E29: 消耗品效果 | F29: consumable | G29: =COUNTIF('物品清单'!$P:$P,"*consumable*")
A30: 木 | B30: wood | C30: =COUNTIF('物品清单'!$H:$H,"wood") | E30: 被动效果 | F30: passive | G30: =COUNTIF('物品清单'!$P:$P,"*passive*")
A31: 无 | B31: none | C31: =COUNTIF('物品清单'!$H:$H,"none") | E31: 功法成长 | F31: scriptureProgression | G31: =COUNTIF('物品清单'!$P:$P,"*scriptureProgression*")
A32: 风 | B32: wind | C32: =COUNTIF('物品清单'!$H:$H,"wind")
A33: 雷 | B33: thunder | C33: =COUNTIF('物品清单'!$H:$H,"thunder")
A34: 冰 | B34: ice | C34: =COUNTIF('物品清单'!$H:$H,"ice")
A35: poison | B35: poison | C35: =COUNTIF('物品清单'!$H:$H,"poison")
