Workbook

Sheet 00_使用说明
A1: t01-08｜使用说明
A2: 2026-09-28 · 27下品＋88凡品＝115件 · 候选数值／当前规则／游戏实现分列 · 不含平衡测试结论
A5: 记录ID | B5: 主题 | C5: 内容 | D5: 边界／状态 | E5: 依据
A6: U01 | B6: 组织方式 | C6: 六类别各自维护跨品级正文；总索引和统计由分类表派生。 | D6: 不另建下品副本作为第二份正文；以后新增品级仍进原类别表。 | E6: 用户本次问题；编制安排
A7: U02 | B7: 本批品级 | C7: 既有27件下品＋新增88件凡品＝115件；六类别正文跨品级维护。 | D7: 下品批次更正不适用于本次新增凡品；本次候选数值与旧基准分开。 | E7: 用户最新品级更正，2026-09-28；资料A/B/C
A8: U03 | B8: 最终数量 | C8: 累计36武器＋36防具＋22法器＋16丹药＋0符箓＋5暗器＝115。 | D8: 本批27武器＋28防具＋18法器＋10丹药＋5暗器＝88；退出编号不复用。 | E8: 资料A/B/C
A9: U04 | B9: 数值性质 | C9: 原下品武器绝对值仍未定；本批凡品88件已有候选数值。已有10件游戏配置单列参考。 | D9: 原资料称已测试≠本轮跑过游戏；参考配置不自动成为下品最终平衡。 | E9: 资料B；当前配置只读
A10: U05 | B10: 识别与引用 | C10: t01.asset.*为资产主表记录ID，不是新游戏注册ID；已有游戏ID保留映射。 | D10: 一件正式资产尚需合法机制、数值、制作／获取链及实现条件；不可把此表直接视作可运行JSON。 | E10: 项目工程约束；01～07
A11: U06 | B11: 公式与派生 | C11: 占格、名义回复率、组合上限和统计使用公式；公式缓存由独立输入计算后写入。 | D11: 无Excel引擎重新计算／真实渲染；名义比值不含资源、上限、控制、命中或战斗长度，不是平衡验证。 | E11: 编制验证口径
A12: U07 | B12: 当前确认 | C12: 下品Q01～Q04及本次FP01～FP06均已确认；当前没有待答题。普通灵障模板见19表。 | D12: 常规邻接仍从良品；限定下品两组、凡品三组基础联动。数值未试跑，升品承接延后。 | E12: 两批逐项答复；本轮凡品合并，2026-09-28
A13: U08 | B13: 实现范围 | C13: 本次编制资产主表及文档衔接，游戏配置只读。 | D13: 已有10件游戏配置仍为下品；本批新增凡品尚未注册游戏。旧配置差异见12表。 | E13: data/maps/inventory_items.json
A14: U09 | B14: 查阅 | C14: 01总索引；02～07分类；08数量；09联动；10甲型元素；11获取；12旧配置；13跨词典；14确认；15案例；16来源；17效果；18状态覆盖；19凡品规则；20试算；21修订停列。22元素／状态分开统计。 | D14: 所有无资产类别只有空模板行，不作为真实物品计数。 | E14: 本次编制

Sheet 01_总索引
A1: t01-08｜总索引
A2: 2026-09-28 · 27下品＋88凡品＝115件 · 候选数值／当前规则／游戏实现分列 · 不含平衡测试结论
A5: 资产ID | B5: 名称_分类表引用 | C5: 品级_分类表引用 | D5: 类别 | E5: 正文位置 | F5: 设计阶段 | G5: 实现核对 | H5: 资料依据
A6: t01.asset.0001 | B6: ='02_武器'!B6 -> 青石短剑 | C6: ='02_武器'!C6 -> 下品 | D6: 武器 | E6: 02_武器!A6 | F6: 骨架登记；绝对数值待平衡 | G6: 已有同名配置／品级一致；其他差异见12表 | H6: A；用户最新更正为下品
A7: t01.asset.0002 | B7: ='02_武器'!B7 -> 铁刀 | C7: ='02_武器'!C7 -> 下品 | D7: 武器 | E7: 02_武器!A7 | F7: 骨架登记；绝对数值待平衡 | G7: 尚无正式游戏配置 | H7: A；用户最新更正为下品
A8: t01.asset.0003 | B8: ='02_武器'!B8 -> 柴斧 | C8: ='02_武器'!C8 -> 下品 | D8: 武器 | E8: 02_武器!A8 | F8: 骨架登记；绝对数值待平衡 | G8: 尚无正式游戏配置 | H8: A；用户最新更正为下品
A9: t01.asset.0004 | B9: ='02_武器'!B9 -> 猎弓 | C9: ='02_武器'!C9 -> 下品 | D9: 武器 | E9: 02_武器!A9 | F9: 骨架登记；绝对数值待平衡 | G9: 已有同名配置／品级一致；其他差异见12表 | H9: A；用户最新更正为下品
A10: t01.asset.0005 | B10: ='02_武器'!B10 -> 匕首 | C10: ='02_武器'!C10 -> 下品 | D10: 武器 | E10: 02_武器!A10 | F10: 骨架登记；绝对数值待平衡 | G10: 尚无正式游戏配置 | H10: A；用户最新更正为下品
A11: t01.asset.0006 | B11: ='02_武器'!B11 -> 长枪 | C11: ='02_武器'!C11 -> 下品 | D11: 武器 | E11: 02_武器!A11 | F11: 骨架登记；绝对数值待平衡 | G11: 尚无正式游戏配置 | H11: A；用户最新更正为下品
A12: t01.asset.0007 | B12: ='02_武器'!B12 -> 短柄铁锤 | C12: ='02_武器'!C12 -> 下品 | D12: 武器 | E12: 02_武器!A12 | F12: 骨架登记；绝对数值待平衡 | G12: 已有同名配置／品级一致；其他差异见12表 | H12: A；用户最新更正为下品
A13: t01.asset.0008 | B13: ='02_武器'!B13 -> 石印 | C13: ='02_武器'!C13 -> 下品 | D13: 武器 | E13: 02_武器!A13 | F13: 骨架登记；绝对数值待平衡 | G13: 尚无正式游戏配置 | H13: A；用户最新更正为下品
A14: t01.asset.0009 | B14: ='02_武器'!B14 -> 皮鞭 | C14: ='02_武器'!C14 -> 下品 | D14: 武器 | E14: 02_武器!A14 | F14: 骨架登记；绝对数值待平衡 | G14: 尚无正式游戏配置 | H14: A；用户最新更正为下品
A15: t01.asset.0010 | B15: ='03_防具'!B6 -> 粗布甲 | C15: ='03_防具'!C6 -> 下品 | D15: 防具 | E15: 03_防具!A6 | F15: 保留资料已有值 | G15: 已有同名配置／品级一致；其他差异见12表 | H15: B2；C覆盖
A16: t01.asset.0011 | B16: ='03_防具'!B7 -> 铁甲 | C16: ='03_防具'!C7 -> 下品 | D16: 防具 | E16: 03_防具!A7 | F16: 新增试玩候选；本体6秒 | G16: 尚无正式游戏配置 | H16: B2；C覆盖
A17: t01.asset.0012 | B17: ='03_防具'!B8 -> 旧铁盔 | C17: ='03_防具'!C8 -> 下品 | D17: 防具 | E17: 03_防具!A8 | F17: 保留资料已有值；补甲型 | G17: 已有同名配置／品级一致；其他差异见12表 | H17: B2；C覆盖
A18: t01.asset.0013 | B18: ='03_防具'!B9 -> 木圆盾 | C18: ='03_防具'!C9 -> 下品 | D18: 防具 | E18: 03_防具!A9 | F18: 保留资料已有值；补甲型 | G18: 已有同名配置／品级一致；其他差异见12表 | H18: B2；C覆盖
A19: t01.asset.0014 | B19: ='03_防具'!B10 -> 布护臂 | C19: ='03_防具'!C10 -> 下品 | D19: 防具 | E19: 03_防具!A10 | F19: 新增试玩候选 | G19: 尚无正式游戏配置 | H19: B2；C覆盖
A20: t01.asset.0015 | B20: ='03_防具'!B11 -> 布护腿 | C20: ='03_防具'!C11 -> 下品 | D20: 防具 | E20: 03_防具!A11 | F20: 新增试玩候选 | G20: 尚无正式游戏配置 | H20: B2；C覆盖
A21: t01.asset.0016 | B21: ='03_防具'!B12 -> 铁护臂 | C21: ='03_防具'!C12 -> 下品 | D21: 防具 | E21: 03_防具!A12 | F21: C新增试玩候选 | G21: 尚无正式游戏配置 | H21: C
A22: t01.asset.0017 | B22: ='03_防具'!B13 -> 铁护腿 | C22: ='03_防具'!C13 -> 下品 | D22: 防具 | E22: 03_防具!A13 | F22: C新增试玩候选 | G22: 尚无正式游戏配置 | H22: C
A23: t01.asset.0018 | B23: ='04_法器'!B6 -> 温玉佩 | C23: ='04_法器'!C6 -> 下品 | D23: 法器 | E23: 04_法器!A6 | F23: 保留已有值 | G23: 已有同名配置／品级一致；其他差异见12表 | H23: B3
A24: t01.asset.0019 | B24: ='04_法器'!B7 -> 回春玉 | C24: ='04_法器'!C7 -> 下品 | D24: 法器 | E24: 04_法器!A7 | F24: 新增试玩候选 | G24: 尚无正式游戏配置 | H24: B3
A25: t01.asset.0020 | B25: ='04_法器'!B8 -> 养息珠 | C25: ='04_法器'!C8 -> 下品 | D25: 法器 | E25: 04_法器!A8 | F25: 新增试玩候选 | G25: 尚无正式游戏配置 | H25: B3
A26: t01.asset.0021 | B26: ='04_法器'!B9 -> 聚灵珠 | C26: ='04_法器'!C9 -> 下品 | D26: 法器 | E26: 04_法器!A9 | F26: 新增试玩候选 | G26: 尚无正式游戏配置 | H26: B3
A27: t01.asset.0022 | B27: ='05_丹药'!B6 -> 止血丹 | C27: ='05_丹药'!C6 -> 下品 | D27: 丹药 | E27: 05_丹药!A6 | F27: 保留资料已有值 | G27: 已有同名配置／品级一致；其他差异见12表 | H27: B4
A28: t01.asset.0023 | B28: ='05_丹药'!B7 -> 强筋丸 | C28: ='05_丹药'!C7 -> 下品 | D28: 丹药 | E28: 05_丹药!A7 | F28: 保留资料已有值 | G28: 已有同名配置／品级一致；其他差异见12表 | H28: B4
A29: t01.asset.0024 | B29: ='05_丹药'!B8 -> 消毒散 | C29: ='05_丹药'!C8 -> 下品 | D29: 丹药 | E29: 05_丹药!A8 | F29: 保留资料已有值 | G29: 已有同名配置／品级一致；其他差异见12表 | H29: B4
A30: t01.asset.0025 | B30: ='05_丹药'!B9 -> 回灵丹 | C30: ='05_丹药'!C9 -> 下品 | D30: 丹药 | E30: 05_丹药!A9 | F30: 新增试玩候选 | G30: 尚无正式游戏配置 | H30: B4
A31: t01.asset.0026 | B31: ='05_丹药'!B10 -> 金疮散 | C31: ='05_丹药'!C10 -> 下品 | D31: 丹药 | E31: 05_丹药!A10 | F31: 新增试玩候选 | G31: 尚无正式游戏配置 | H31: B4
A32: t01.asset.0027 | B32: ='05_丹药'!B11 -> 回元散 | C32: ='05_丹药'!C11 -> 下品 | D32: 丹药 | E32: 05_丹药!A11 | F32: 新增试玩候选 | G32: 尚无正式游戏配置 | H32: B4
A33: t01.asset.0028 | B33: ='02_武器'!B15 -> 铁剑 | C33: ='02_武器'!C15 -> 凡品 | D33: 武器 | E33: 02_武器!A15 | F33: 候选数值，未试跑 | G33: 未实现；无游戏注册ID | H33: 第1批基础；第2批微调；第3批复查；用户直接更正优先；W01
A34: t01.asset.0029 | B34: ='02_武器'!B16 -> 赤纹剑 | C34: ='02_武器'!C16 -> 凡品 | D34: 武器 | E34: 02_武器!A16 | F34: 候选数值，未试跑 | G34: 未实现；无游戏注册ID | H34: 第1批基础；第2批微调；第3批复查；用户直接更正优先；W02
A35: t01.asset.0030 | B35: ='02_武器'!B17 -> 寒水剑 | C35: ='02_武器'!C17 -> 凡品 | D35: 武器 | E35: 02_武器!A17 | F35: 候选数值，未试跑 | G35: 未实现；无游戏注册ID | H35: 第1批基础；第2批微调；第3批复查；用户直接更正优先；W03
A36: t01.asset.0031 | B36: ='02_武器'!B18 -> 钢刀 | C36: ='02_武器'!C18 -> 凡品 | D36: 武器 | E36: 02_武器!A18 | F36: 候选数值，未试跑 | G36: 未实现；无游戏注册ID | H36: 第1批基础；第2批微调；第3批复查；用户直接更正优先；W05
A37: t01.asset.0032 | B37: ='02_武器'!B19 -> 金纹刀 | C37: ='02_武器'!C19 -> 凡品 | D37: 武器 | E37: 02_武器!A19 | F37: 候选数值，未试跑 | G37: 未实现；无游戏注册ID | H37: 第1批基础；第2批微调；第3批复查；用户直接更正优先；W06
A38: t01.asset.0033 | B38: ='02_武器'!B20 -> 赤焰刀 | C38: ='02_武器'!C20 -> 凡品 | D38: 武器 | E38: 02_武器!A20 | F38: 候选数值，未试跑 | G38: 未实现；无游戏注册ID | H38: 第1批基础；第2批微调；第3批复查；用户直接更正优先；W07
A39: t01.asset.0034 | B39: ='02_武器'!B21 -> 开山斧 | C39: ='02_武器'!C21 -> 凡品 | D39: 武器 | E39: 02_武器!A21 | F39: 候选数值，未试跑 | G39: 未实现；无游戏注册ID | H39: 第1批基础；第2批微调；第3批复查；用户直接更正优先；W08
A40: t01.asset.0035 | B40: ='02_武器'!B22 -> 金刚斧 | C40: ='02_武器'!C22 -> 凡品 | D40: 武器 | E40: 02_武器!A22 | F40: 候选数值，未试跑 | G40: 未实现；无游戏注册ID | H40: 第1批基础；第2批微调；第3批复查；用户直接更正优先；W09
A41: t01.asset.0036 | B41: ='02_武器'!B23 -> 厚土斧 | C41: ='02_武器'!C23 -> 凡品 | D41: 武器 | E41: 02_武器!A23 | F41: 候选数值，未试跑 | G41: 未实现；无游戏注册ID | H41: 第1批基础；第2批微调；第3批复查；用户直接更正优先；W10
A42: t01.asset.0037 | B42: ='02_武器'!B24 -> 桑木弓 | C42: ='02_武器'!C24 -> 凡品 | D42: 武器 | E42: 02_武器!A24 | F42: 候选数值，未试跑 | G42: 未实现；无游戏注册ID | H42: 第1批基础；第2批微调；第3批复查；用户直接更正优先；W11
...

Sheet 02_武器
A1: t01-08｜武器
A2: 2026-09-28 · 27下品＋88凡品＝115件 · 候选数值／当前规则／游戏实现分列 · 不含平衡测试结论
A5: 资产ID | B5: 名称 | C5: 品级 | D5: 元素 | E5: 器型 | F5: Attack Type | G5: 宽_格 | H5: 高_格 | I5: 实际占格 | J5: 设计伤害 | K5: 设计CD_秒 | L5: 设计体力费 | M5: 伤害相对档 | N5: CD相对档 | O5: 体力相对档 | P5: 基础战斗性格 | Q5: 后续元素倾向_非本件 | R5: 边界 | S5: 机制引用 | T5: 现有游戏ID | U5: 设计状态 | V5: 来源 | W5: 来源编号 | X5: 状态 | Y5: 施加层数 | Z5: 状态时机与目标 | AA5: 灵力费 | AB5: 数量消耗 | AC5: 效果引用 | AD5: 本批元素规则
A6: t01.asset.0001 | B6: 青石短剑 | C6: 下品 | D6: NONE | E6: 剑 | F6: 斩击 | G6: 1 | H6: 2 | I6: =G6*H6 -> 2 | M6: 中 | N6: 中 | O6: 中 | P6: 均衡斩击基准 | Q6: 火、水 | R6: 不带状态／控制／邻接；无射程，猎弓不耗箭；石印为武器。 | S6: 01 M01/M06/M08；03权限；04九器型 | T6: base.map_item.qingshi_short_sword | U6: 待绝对数值；非生产配置 | V6: A；U
A7: t01.asset.0002 | B7: 铁刀 | C7: 下品 | D7: NONE | E7: 佩刀 | F7: 斩击 | G7: 1 | H7: 1 | I7: =G7*H7 -> 1 | M7: 中低 | N7: 中短 | O7: 中低 | P7: 紧凑、以空间换单击收益 | Q7: 金、火 | R7: 不带状态／控制／邻接；无射程，猎弓不耗箭；石印为武器。 | S7: 01 M01/M06/M08；03权限；04九器型 | T7: 未配置 | U7: 待绝对数值；非生产配置 | V7: A；U
A8: t01.asset.0003 | B8: 柴斧 | C8: 下品 | D8: NONE | E8: 斧 | F8: 斩击 | G8: 2 | H8: 1 | I8: =G8*H8 -> 2 | M8: 高 | N8: 中长 | O8: 高 | P8: 重斩、强调单次爆发 | Q8: 金、土 | R8: 不带状态／控制／邻接；无射程，猎弓不耗箭；石印为武器。 | S8: 01 M01/M06/M08；03权限；04九器型 | T8: 未配置 | U8: 待绝对数值；非生产配置 | V8: A；U
A9: t01.asset.0004 | B9: 猎弓 | C9: 下品 | D9: NONE | E9: 弓 | F9: 穿刺 | G9: 1 | H9: 2 | I9: =G9*H9 -> 2 | M9: 中 | N9: 中长 | O9: 中低 | P9: 稳节奏穿刺；耗力较轻为本批方向 | Q9: 木、水；兼容面广 | R9: 不带状态／控制／邻接；无射程，猎弓不耗箭；石印为武器。 | S9: 01 M01/M06/M08；03权限；04九器型 | T9: base.map_item.hunting_bow | U9: 待绝对数值；非生产配置 | V9: A；U
A10: t01.asset.0005 | B10: 匕首 | C10: 下品 | D10: NONE | E10: 短刃 | F10: 穿刺 | G10: 1 | H10: 1 | I10: =G10*H10 -> 1 | M10: 低 | N10: 短 | O10: 低 | P10: 小占格、快循环 | Q10: 金、风 | R10: 不带状态／控制／邻接；无射程，猎弓不耗箭；石印为武器。 | S10: 01 M01/M06/M08；03权限；04九器型 | T10: 未配置 | U10: 待绝对数值；非生产配置 | V10: A；U
A11: t01.asset.0006 | B11: 长枪 | C11: 下品 | D11: NONE | E11: 枪 | F11: 穿刺 | G11: 3 | H11: 1 | I11: =G11*H11 -> 3 | M11: 高 | N11: 长 | O11: 中高 | P11: 大占格换高单击 | Q11: 雷、金、木 | R11: 不带状态／控制／邻接；无射程，猎弓不耗箭；石印为武器。 | S11: 01 M01/M06/M08；03权限；04九器型 | T11: 未配置 | U11: 待绝对数值；非生产配置 | V11: A；U
A12: t01.asset.0007 | B12: 短柄铁锤 | C12: 下品 | D12: NONE | E12: 锤 | F12: 钝击 | G12: 1 | H12: 2 | I12: =G12*H12 -> 2 | M12: 中高 | N12: 中长 | O12: 中高 | P12: 偏沉重的钝击基准 | Q12: 土、火 | R12: 不带状态／控制／邻接；无射程，猎弓不耗箭；石印为武器。 | S12: 01 M01/M06/M08；03权限；04九器型 | T12: base.map_item.short_iron_hammer | U12: 待绝对数值；非生产配置 | V12: A；U
A13: t01.asset.0008 | B13: 石印 | C13: 下品 | D13: NONE | E13: 印 | F13: 钝击 | G13: 1 | H13: 1 | I13: =G13*H13 -> 1 | M13: 中低 | N13: 中 | O13: 中 | P13: 紧凑钝击，不追求快攻 | Q13: 土、雷 | R13: 不带状态／控制／邻接；无射程，猎弓不耗箭；石印为武器。 | S13: 01 M01/M06/M08；03权限；04九器型 | T13: 未配置 | U13: 待绝对数值；非生产配置 | V13: A；U
A14: t01.asset.0009 | B14: 皮鞭 | C14: 下品 | D14: NONE | E14: 鞭 | F14: 钝击 | G14: 3 | H14: 1 | I14: =G14*H14 -> 3 | M14: 低 | N14: 短 | O14: 中低 | P14: 大占格换高轮转频率 | Q14: 雷、木 | R14: 不带状态／控制／邻接；无射程，猎弓不耗箭；石印为武器。 | S14: 01 M01/M06/M08；03权限；04九器型 | T14: 未配置 | U14: 待绝对数值；非生产配置 | V14: A；U
A15: t01.asset.0028 | B15: 铁剑 | C15: 凡品 | D15: NONE | E15: 剑 | F15: 斩击 | G15: 1 | H15: 2 | I15: =G15*H15 -> 2 | J15: 18 | K15: 5.5 | L15: 3 | P15: 基础数值与元素 | R15: 不耗本体；体力为单把基础，多武器加算另查19／20表；无射程、弓不耗普通箭 | S15: 01 M01/M06/M08；03 C010；04武器 | U15: 候选数值，未试跑 | V15: 第1批基础；第2批微调；第3批复查；用户直接更正优先 | W15: W01 | Z15: 无；敌方 | AA15: 0 | AB15: 0 | AC15: t01.asset.0028.effect.01 | AD15: 固定元素与单状态匹配；不是运行时由状态改变元素
A16: t01.asset.0029 | B16: 赤纹剑 | C16: 凡品 | D16: 火 | E16: 剑 | F16: 斩击 | G16: 1 | H16: 2 | I16: =G16*H16 -> 2 | J16: 16 | K16: 5.5 | L16: 4 | P16: 基础＋单状态 | R16: 不耗本体；体力为单把基础，多武器加算另查19／20表；无射程、弓不耗普通箭；具体效果与施加时序依02和核心01，不由七系标签自动增加额外伤害。 | S16: 01 M01/M06/M08；03 C010；04武器 | U16: 候选数值，未试跑 | V16: 第1批基础；第2批微调；第3批复查；用户直接更正优先 | W16: W02 | X16: 灼烧 | Y16: 1 | Z16: 命中；敌方 | AA16: 0 | AB16: 0 | AC16: t01.asset.0029.effect.01；t01.asset.0029.effect.02 | AD16: 固定元素与单状态匹配；不是运行时由状态改变元素
A17: t01.asset.0030 | B17: 寒水剑 | C17: 凡品 | D17: 水 | E17: 剑 | F17: 斩击 | G17: 1 | H17: 2 | I17: =G17*H17 -> 2 | J17: 17 | K17: 6 | L17: 4 | P17: 基础＋单状态 | R17: 不耗本体；体力为单把基础，多武器加算另查19／20表；无射程、弓不耗普通箭；寒霜正常新层先施加、后由本次合格主动水攻触发；初霜专属额外层例外留后次。 | S17: 01 M01/M06/M08；03 C010；04武器 | U17: 候选数值，未试跑 | V17: 第1批基础；第2批微调；第3批复查；用户直接更正优先 | W17: W03 | X17: 寒霜 | Y17: 1 | Z17: 命中；敌方 | AA17: 0 | AB17: 0 | AC17: t01.asset.0030.effect.01；t01.asset.0030.effect.02 | AD17: 固定元素与单状态匹配；不是运行时由状态改变元素
A18: t01.asset.0031 | B18: 钢刀 | C18: 凡品 | D18: 金 | E18: 佩刀 | F18: 斩击 | G18: 1 | H18: 1 | I18: =G18*H18 -> 1 | J18: 10 | K18: 4.5 | L18: 2 | P18: 基础＋单状态 | R18: 不耗本体；体力为单把基础，多武器加算另查19／20表；无射程、弓不耗普通箭；本件流血须本次攻击实际伤及气血；只命中或只扣盾甲不足。 | S18: 01 M01/M06/M08；03 C010；04武器 | U18: 候选数值，未试跑 | V18: 第1批基础；第2批微调；第3批复查；用户直接更正优先 | W18: W05 | X18: 流血 | Y18: 1 | Z18: 实际伤到气血；敌方 | AA18: 0 | AB18: 0 | AC18: t01.asset.0031.effect.01；t01.asset.0031.effect.02 | AD18: 固定元素与单状态匹配；不是运行时由状态改变元素
A19: t01.asset.0032 | B19: 金纹刀 | C19: 凡品 | D19: 金 | E19: 佩刀 | F19: 斩击 | G19: 1 | H19: 1 | I19: =G19*H19 -> 1 | J19: 12 | K19: 5.5 | L19: 3 | P19: 基础＋单状态 | R19: 不耗本体；体力为单把基础，多武器加算另查19／20表；无射程、弓不耗普通箭；锋痕由合格武器攻击兑现；金光镜仍是法器来源，不因金元素或SPELL攻击类型取得武器资格。 | S19: 01 M01/M06/M08；03 C010；04武器 | U19: 候选数值，未试跑 | V19: 第1批基础；第2批微调；第3批复查；用户直接更正优先 | W19: W06 | X19: 锋痕 | Y19: 1 | Z19: 命中；敌方 | AA19: 0 | AB19: 0 | AC19: t01.asset.0032.effect.01；t01.asset.0032.effect.02 | AD19: 固定元素与单状态匹配；不是运行时由状态改变元素
A20: t01.asset.0033 | B20: 赤焰刀 | C20: 凡品 | D20: 火 | E20: 佩刀 | F20: 斩击 | G20: 1 | H20: 1 | I20: =G20*H20 -> 1 | J20: 11 | K20: 5.5 | L20: 3 | P20: 基础＋单状态 | R20: 不耗本体；体力为单把基础，多武器加算另查19／20表；无射程、弓不耗普通箭；具体效果与施加时序依02和核心01，不由七系标签自动增加额外伤害。 | S20: 01 M01/M06/M08；03 C010；04武器 | U20: 候选数值，未试跑 | V20: 第1批基础；第2批微调；第3批复查；用户直接更正优先 | W20: W07 | X20: 破甲 | Y20: 1 | Z20: 命中；敌方 | AA20: 0 | AB20: 0 | AC20: t01.asset.0033.effect.01；t01.asset.0033.effect.02 | AD20: 固定元素与单状态匹配；不是运行时由状态改变元素
A21: t01.asset.0034 | B21: 开山斧 | C21: 凡品 | D21: 土 | E21: 斧 | F21: 斩击 | G21: 2 | H21: 1 | I21: =G21*H21 -> 2 | J21: 30 | K21: 8.5 | L21: 6 | P21: 基础＋单状态 | R21: 不耗本体；体力为单把基础，多武器加算另查19／20表；无射程、弓不耗普通箭；具体效果与施加时序依02和核心01，不由七系标签自动增加额外伤害。 | S21: 01 M01/M06/M08；03 C010；04武器 | U21: 候选数值，未试跑 | V21: 第1批基础；第2批微调；第3批复查；用户直接更正优先 | W21: W08 | X21: 疲惫 | Y21: 2 | Z21: 命中；敌方 | AA21: 0 | AB21: 0 | AC21: t01.asset.0034.effect.01；t01.asset.0034.effect.02 | AD21: 固定元素与单状态匹配；不是运行时由状态改变元素
A22: t01.asset.0035 | B22: 金刚斧 | C22: 凡品 | D22: 金 | E22: 斧 | F22: 斩击 | G22: 2 | H22: 1 | I22: =G22*H22 -> 2 | J22: 28 | K22: 8.5 | L22: 6 | P22: 基础＋单状态 | R22: 不耗本体；体力为单把基础，多武器加算另查19／20表；无射程、弓不耗普通箭；锋痕由合格武器攻击兑现；金光镜仍是法器来源，不因金元素或SPELL攻击类型取得武器资格。 | S22: 01 M01/M06/M08；03 C010；04武器 | U22: 候选数值，未试跑 | V22: 第1批基础；第2批微调；第3批复查；用户直接更正优先 | W22: W09 | X22: 锋痕 | Y22: 2 | Z22: 命中；敌方 | AA22: 0 | AB22: 0 | AC22: t01.asset.0035.effect.01；t01.asset.0035.effect.02 | AD22: 固定元素与单状态匹配；不是运行时由状态改变元素
A23: t01.asset.0036 | B23: 厚土斧 | C23: 凡品 | D23: 土 | E23: 斧 | F23: 斩击 | G23: 2 | H23: 1 | I23: =G23*H23 -> 2 | J23: 28 | K23: 8.5 | L23: 6 | P23: 基础＋单状态 | R23: 不耗本体；体力为单把基础，多武器加算另查19／20表；无射程、弓不耗普通箭；具体效果与施加时序依02和核心01，不由七系标签自动增加额外伤害。 | S23: 01 M01/M06/M08；03 C010；04武器 | U23: 候选数值，未试跑 | V23: 第1批基础；第2批微调；第3批复查；用户直接更正优先 | W23: W10 | X23: 重伤 | Y23: 2 | Z23: 命中；敌方 | AA23: 0 | AB23: 0 | AC23: t01.asset.0036.effect.01；t01.asset.0036.effect.02 | AD23: 固定元素与单状态匹配；不是运行时由状态改变元素
A24: t01.asset.0037 | B24: 桑木弓 | C24: 凡品 | D24: 木 | E24: 弓 | F24: 穿刺 | G24: 1 | H24: 2 | I24: =G24*H24 -> 2 | J24: 24 | K24: 7 | L24: 5 | P24: 基础数值与元素 | R24: 不耗本体；体力为单把基础，多武器加算另查19／20表；无射程、弓不耗普通箭 | S24: 01 M01/M06/M08；03 C010；04武器 | U24: 候选数值，未试跑 | V24: 第1批基础；第2批微调；第3批复查；用户直接更正优先 | W24: W11 | Z24: 无；敌方 | AA24: 0 | AB24: 0 | AC24: t01.asset.0037.effect.01 | AD24: 固定元素与单状态匹配；不是运行时由状态改变元素
A25: t01.asset.0038 | B25: 水纹弓 | C25: 凡品 | D25: 水 | E25: 弓 | F25: 穿刺 | G25: 1 | H25: 2 | I25: =G25*H25 -> 2 | J25: 20 | K25: 7 | L25: 5 | P25: 基础＋单状态 | R25: 不耗本体；体力为单把基础，多武器加算另查19／20表；无射程、弓不耗普通箭；具体效果与施加时序依02和核心01，不由七系标签自动增加额外伤害。 | S25: 01 M01/M06/M08；03 C010；04武器 | U25: 候选数值，未试跑 | V25: 第1批基础；第2批微调；第3批复查；用户直接更正优先 | W25: W12 | X25: 枯脉 | Y25: 1 | Z25: 命中；敌方 | AA25: 0 | AB25: 0 | AC25: t01.asset.0038.effect.01；t01.asset.0038.effect.02 | AD25: 固定元素与单状态匹配；不是运行时由状态改变元素
A26: t01.asset.0039 | B26: 雷纹弓 | C26: 凡品 | D26: 雷 | E26: 弓 | F26: 穿刺 | G26: 1 | H26: 2 | I26: =G26*H26 -> 2 | J26: 22 | K26: 7 | L26: 6 | P26: 基础＋单状态 | R26: 不耗本体；体力为单把基础，多武器加算另查19／20表；无射程、弓不耗普通箭；连环供后续合格雷攻击利用；锁雷环无本体攻击，不直接制造雷击或闪电。 | S26: 01 M01/M06/M08；03 C010；04武器 | U26: 候选数值，未试跑 | V26: 第1批基础；第2批微调；第3批复查；用户直接更正优先 | W26: W14 | X26: 连环 | Y26: 1 | Z26: 命中；敌方 | AA26: 0 | AB26: 0 | AC26: t01.asset.0039.effect.01；t01.asset.0039.effect.02 | AD26: 固定元素与单状态匹配；不是运行时由状态改变元素
A27: t01.asset.0040 | B27: 精铁匕 | C27: 凡品 | D27: 金 | E27: 短刃 | F27: 穿刺 | G27: 1 | H27: 1 | I27: =G27*H27 -> 1 | J27: 8 | K27: 3.5 | L27: 2 | P27: 基础＋单状态 | R27: 不耗本体；体力为单把基础，多武器加算另查19／20表；无射程、弓不耗普通箭；本件流血须本次攻击实际伤及气血；只命中或只扣盾甲不足。 | S27: 01 M01/M06/M08；03 C010；04武器 | U27: 候选数值，未试跑 | V27: 第1批基础；第2批微调；第3批复查；用户直接更正优先 | W27: W15 | X27: 流血 | Y27: 1 | Z27: 实际伤到气血；敌方 | AA27: 0 | AB27: 0 | AC27: t01.asset.0040.effect.01；t01.asset.0040.effect.02 | AD27: 固定元素与单状态匹配；不是运行时由状态改变元素
A28: t01.asset.0041 | B28: 风刃匕 | C28: 凡品 | D28: 风 | E28: 短刃 | F28: 穿刺 | G28: 1 | H28: 1 | I28: =G28*H28 -> 1 | J28: 7 | K28: 3 | L28: 2 | P28: 基础＋单状态 | R28: 不耗本体；体力为单把基础，多武器加算另查19／20表；无射程、弓不耗普通箭；具体效果与施加时序依02和核心01，不由七系标签自动增加额外伤害。 | S28: 01 M01/M06/M08；03 C010；04武器 | U28: 候选数值，未试跑 | V28: 第1批基础；第2批微调；第3批复查；用户直接更正优先 | W28: W16 | X28: 失衡 | Y28: 1 | Z28: 命中；敌方 | AA28: 0 | AB28: 0 | AC28: t01.asset.0041.effect.01；t01.asset.0041.effect.02 | AD28: 固定元素与单状态匹配；不是运行时由状态改变元素
A29: t01.asset.0042 | B29: 青木枪 | C29: 凡品 | D29: 木 | E29: 枪 | F29: 穿刺 | G29: 3 | H29: 1 | I29: =G29*H29 -> 3 | J29: 34 | K29: 8.5 | L29: 7 | P29: 基础＋单状态 | R29: 不耗本体；体力为单把基础，多武器加算另查19／20表；无射程、弓不耗普通箭；缠绕由后续合格火、雷伤害利用；木攻击本身不因此获得火雷增幅。 | S29: 01 M01/M06/M08；03 C010；04武器 | U29: 候选数值，未试跑 | V29: 第1批基础；第2批微调；第3批复查；用户直接更正优先 | W29: W17 | X29: 缠绕 | Y29: 2 | Z29: 命中；敌方 | AA29: 0 | AB29: 0 | AC29: t01.asset.0042.effect.01；t01.asset.0042.effect.02 | AD29: 固定元素与单状态匹配；不是运行时由状态改变元素
A30: t01.asset.0043 | B30: 雷纹枪 | C30: 凡品 | D30: 雷 | E30: 枪 | F30: 穿刺 | G30: 3 | H30: 1 | I30: =G30*H30 -> 3 | J30: 38 | K30: 9.5 | L30: 8 | P30: 基础＋单状态 | R30: 不耗本体；体力为单把基础，多武器加算另查19／20表；无射程、弓不耗普通箭；雷印新层在本击伤后加入，供后续合格雷攻；无本体雷攻击的施层器具不直接引雷。 | S30: 01 M01/M06/M08；03 C010；04武器 | U30: 候选数值，未试跑 | V30: 第1批基础；第2批微调；第3批复查；用户直接更正优先 | W30: W19 | X30: 雷印 | Y30: 2 | Z30: 命中；敌方 | AA30: 0 | AB30: 0 | AC30: t01.asset.0043.effect.01；t01.asset.0043.effect.02 | AD30: 固定元素与单状态匹配；不是运行时由状态改变元素
A31: t01.asset.0044 | B31: 炎纹锤 | C31: 凡品 | D31: 火 | E31: 锤 | F31: 钝击 | G31: 1 | H31: 2 | I31: =G31*H31 -> 2 | J31: 20 | K31: 6 | L31: 4 | P31: 基础＋单状态 | R31: 不耗本体；体力为单把基础，多武器加算另查19／20表；无射程、弓不耗普通箭；具体效果与施加时序依02和核心01，不由七系标签自动增加额外伤害。 | S31: 01 M01/M06/M08；03 C010；04武器 | U31: 候选数值，未试跑 | V31: 第1批基础；第2批微调；第3批复查；用户直接更正优先 | W31: W20 | X31: 破甲 | Y31: 1 | Z31: 命中；敌方 | AA31: 0 | AB31: 0 | AC31: t01.asset.0044.effect.01；t01.asset.0044.effect.02 | AD31: 固定元素与单状态匹配；不是运行时由状态改变元素
A32: t01.asset.0045 | B32: 石骨锤 | C32: 凡品 | D32: 土 | E32: 锤 | F32: 钝击 | G32: 1 | H32: 2 | I32: =G32*H32 -> 2 | J32: 26 | K32: 7 | L32: 5 | P32: 基础数值与元素 | R32: 不耗本体；体力为单把基础，多武器加算另查19／20表；无射程、弓不耗普通箭 | S32: 01 M01/M06/M08；03 C010；04武器 | U32: 候选数值，未试跑 | V32: 第1批基础；第2批微调；第3批复查；用户直接更正优先 | W32: W21 | Z32: 无；敌方 | AA32: 0 | AB32: 0 | AC32: t01.asset.0045.effect.01 | AD32: 固定元素与单状态匹配；不是运行时由状态改变元素
A33: t01.asset.0046 | B33: 镇土印 | C33: 凡品 | D33: 土 | E33: 印 | F33: 钝击 | G33: 1 | H33: 1 | I33: =G33*H33 -> 1 | J33: 16 | K33: 7 | L33: 3 | P33: 基础＋单状态 | R33: 不耗本体；体力为单把基础，多武器加算另查19／20表；无射程、弓不耗普通箭；具体效果与施加时序依02和核心01，不由七系标签自动增加额外伤害。 | S33: 01 M01/M06/M08；03 C010；04武器 | U33: 候选数值，未试跑 | V33: 第1批基础；第2批微调；第3批复查；用户直接更正优先 | W33: W22 | X33: 疲惫 | Y33: 1 | Z33: 命中；敌方 | AA33: 0 | AB33: 0 | AC33: t01.asset.0046.effect.01；t01.asset.0046.effect.02 | AD33: 固定元素与单状态匹配；不是运行时由状态改变元素
A34: t01.asset.0047 | B34: 雷纹印 | C34: 凡品 | D34: 雷 | E34: 印 | F34: 钝击 | G34: 1 | H34: 1 | I34: =G34*H34 -> 1 | J34: 14 | K34: 6 | L34: 3 | P34: 基础＋单状态 | R34: 不耗本体；体力为单把基础，多武器加算另查19／20表；无射程、弓不耗普通箭；具体效果与施加时序依02和核心01，不由七系标签自动增加额外伤害。 | S34: 01 M01/M06/M08；03 C010；04武器 | U34: 候选数值，未试跑 | V34: 第1批基础；第2批微调；第3批复查；用户直接更正优先 | W34: W23 | X34: 雷蕴 | Y34: 1 | Z34: 命中；自身 | AA34: 0 | AB34: 0 | AC34: t01.asset.0047.effect.01；t01.asset.0047.effect.02 | AD34: 固定元素与单状态匹配；不是运行时由状态改变元素
A35: t01.asset.0048 | B35: 藤鞭 | C35: 凡品 | D35: 木 | E35: 鞭 | F35: 钝击 | G35: 3 | H35: 1 | I35: =G35*H35 -> 3 | J35: 14 | K35: 4 | L35: 3 | P35: 基础＋单状态 | R35: 不耗本体；体力为单把基础，多武器加算另查19／20表；无射程、弓不耗普通箭；具体效果与施加时序依02和核心01，不由七系标签自动增加额外伤害。 | S35: 01 M01/M06/M08；03 C010；04武器 | U35: 候选数值，未试跑 | V35: 第1批基础；第2批微调；第3批复查；用户直接更正优先 | W35: W24 | X35: 毒蚀 | Y35: 1 | Z35: 命中；敌方 | AA35: 0 | AB35: 0 | AC35: t01.asset.0048.effect.01；t01.asset.0048.effect.02 | AD35: 固定元素与单状态匹配；不是运行时由状态改变元素
A36: t01.asset.0049 | B36: 雷鞭 | C36: 凡品 | D36: 雷 | E36: 鞭 | F36: 钝击 | G36: 3 | H36: 1 | I36: =G36*H36 -> 3 | J36: 15 | K36: 4.5 | L36: 4 | P36: 基础＋单状态 | R36: 不耗本体；体力为单把基础，多武器加算另查19／20表；无射程、弓不耗普通箭；雷印新层在本击伤后加入，供后续合格雷攻；无本体雷攻击的施层器具不直接引雷。 | S36: 01 M01/M06/M08；03 C010；04武器 | U36: 候选数值，未试跑 | V36: 第1批基础；第2批微调；第3批复查；用户直接更正优先 | W36: W25 | X36: 雷印 | Y36: 1 | Z36: 命中；敌方 | AA36: 0 | AB36: 0 | AC36: t01.asset.0049.effect.01；t01.asset.0049.effect.02 | AD36: 固定元素与单状态匹配；不是运行时由状态改变元素
A37: t01.asset.0050 | B37: 刺血匕 | C37: 凡品 | D37: 金 | E37: 短刃 | F37: 穿刺 | G37: 1 | H37: 1 | I37: =G37*H37 -> 1 | J37: 8 | K37: 4.5 | L37: 2 | P37: 基础＋单状态 | R37: 不耗本体；体力为单把基础，多武器加算另查19／20表；无射程、弓不耗普通箭；本件流血须本次攻击实际伤及气血；只命中或只扣盾甲不足。 | S37: 01 M01/M06/M08；03 C010；04武器 | U37: 候选数值，未试跑 | V37: 第1批基础；第2批微调；第3批复查；用户直接更正优先 | W37: W28 | X37: 流血 | Y37: 2 | Z37: 实际伤到气血；敌方 | AA37: 0 | AB37: 0 | AC37: t01.asset.0050.effect.01；t01.asset.0050.effect.02 | AD37: 固定元素与单状态匹配；不是运行时由状态改变元素
A38: t01.asset.0051 | B38: 震骨锤 | C38: 凡品 | D38: 土 | E38: 锤 | F38: 钝击 | G38: 1 | H38: 2 | I38: =G38*H38 -> 2 | J38: 32 | K38: 9 | L38: 7 | P38: 基础＋单状态 | R38: 不耗本体；体力为单把基础，多武器加算另查19／20表；无射程、弓不耗普通箭；具体效果与施加时序依02和核心01，不由七系标签自动增加额外伤害。 | S38: 01 M01/M06/M08；03 C010；04武器 | U38: 候选数值，未试跑 | V38: 第1批基础；第2批微调；第3批复查；用户直接更正优先 | W38: W30 | X38: 重伤 | Y38: 2 | Z38: 命中；敌方 | AA38: 0 | AB38: 0 | AC38: t01.asset.0051.effect.01；t01.asset.0051.effect.02 | AD38: 固定元素与单状态匹配；不是运行时由状态改变元素
A39: t01.asset.0052 | B39: 清风印 | C39: 凡品 | D39: 风 | E39: 印 | F39: 钝击 | G39: 1 | H39: 1 | I39: =G39*H39 -> 1 | J39: 13 | K39: 7 | L39: 3 | P39: 基础＋单状态 | R39: 不耗本体；体力为单把基础，多武器加算另查19／20表；无射程、弓不耗普通箭；具体效果与施加时序依02和核心01，不由七系标签自动增加额外伤害。 | S39: 01 M01/M06/M08；03 C010；04武器 | U39: 候选数值，未试跑 | V39: 第1批基础；第2批微调；第3批复查；用户直接更正优先 | W39: W31 | X39: 驱散 | Y39: 1 | Z39: 命中；敌方 | AA39: 0 | AB39: 0 | AC39: t01.asset.0052.effect.01；t01.asset.0052.effect.02 | AD39: 固定元素与单状态匹配；不是运行时由状态改变元素
A40: t01.asset.0053 | B40: 荆鞭 | C40: 凡品 | D40: 木 | E40: 鞭 | F40: 钝击 | G40: 3 | H40: 1 | I40: =G40*H40 -> 3 | J40: 16 | K40: 4.5 | L40: 3 | P40: 基础＋单状态 | R40: 不耗本体；体力为单把基础，多武器加算另查19／20表；无射程、弓不耗普通箭；缠绕由后续合格火、雷伤害利用；木攻击本身不因此获得火雷增幅。 | S40: 01 M01/M06/M08；03 C010；04武器 | U40: 候选数值，未试跑 | V40: 第1批基础；第2批微调；第3批复查；用户直接更正优先 | W40: W32 | X40: 缠绕 | Y40: 1 | Z40: 命中；敌方 | AA40: 0 | AB40: 0 | AC40: t01.asset.0053.effect.01；t01.asset.0053.effect.02 | AD40: 固定元素与单状态匹配；不是运行时由状态改变元素
A41: t01.asset.0054 | B41: 赤焰枪 | C41: 凡品 | D41: 火 | E41: 枪 | F41: 穿刺 | G41: 3 | H41: 1 | I41: =G41*H41 -> 3 | J41: 36 | K41: 9 | L41: 8 | P41: 基础＋单状态 | R41: 不耗本体；体力为单把基础，多武器加算另查19／20表；无射程、弓不耗普通箭；具体效果与施加时序依02和核心01，不由七系标签自动增加额外伤害。 | S41: 01 M01/M06/M08；03 C010；04武器 | U41: 候选数值，未试跑 | V41: 第1批基础；第2批微调；第3批复查；用户直接更正优先 | W41: W33 | X41: 灼烧 | Y41: 2 | Z41: 命中；敌方 | AA41: 0 | AB41: 0 | AC41: t01.asset.0054.effect.01；t01.asset.0054.effect.02 | AD41: 固定元素与单状态匹配；不是运行时由状态改变元素

Sheet 03_防具
A1: t01-08｜防具
A2: 2026-09-28 · 27下品＋88凡品＝115件 · 候选数值／当前规则／游戏实现分列 · 不含平衡测试结论
A5: 资产ID | B5: 名称 | C5: 品级 | D5: 元素 | E5: 部位 | F5: 甲型 | G5: 宽_格 | H5: 高_格 | I5: 实际占格 | J5: CD_秒 | K5: 护甲上限贡献 | L5: 单次回甲 | M5: 名义回甲每秒 | N5: 甲型权重倍率 | O5: 甲型统计权重 | P5: 上阵部位限制 | Q5: 基础联动 | R5: 费用／数量 | S5: 机制引用 | T5: 现有游戏ID | U5: 设计状态 | V5: 来源 | W5: 来源编号 | X5: 状态 | Y5: 层数 | Z5: 状态触发 | AA5: 受击状态独立CD_秒 | AB5: 防御元素权重 | AC5: 效果引用
A6: t01.asset.0010 | B6: 粗布甲 | C6: 下品 | D6: NONE | E6: 身甲 | F6: 轻甲 | G6: 1 | H6: 2 | I6: =G6*H6 -> 2 | J6: 4 | K6: 7 | L6: 3 | M6: =L6/J6 -> 0.75 | N6: 2 | O6: =I6*N6 -> 4 | P6: 同一部位最多1件；护臂／护腿分别计限（Q03） | Q6: 布甲联动 | R6: 零体力沿用防具基线；数量不消耗 | S6: 01 C01/I11；04防具；06 Link | T6: base.map_item.coarse_cloth_armor | U6: 保留资料已有值；甲型加权Q02已确认 | V6: B2/C；U | AB6: =O6 -> 4
A7: t01.asset.0011 | B7: 铁甲 | C7: 下品 | D7: NONE | E7: 身甲 | F7: 重甲 | G7: 1 | H7: 2 | I7: =G7*H7 -> 2 | J7: 6 | K7: 10 | L7: 4 | M7: =L7/J7 -> 0.66666667 | N7: 2 | O7: =I7*N7 -> 4 | P7: 同一部位最多1件；护臂／护腿分别计限（Q03） | Q7: 铁甲联动 | R7: 零体力沿用防具基线；数量不消耗 | S7: 01 C01/I11；04防具；06 Link | T7: 未配置 | U7: 新增试玩候选；本体6秒；甲型加权Q02已确认 | V7: B2/C；U | AB7: =O7 -> 4
A8: t01.asset.0012 | B8: 旧铁盔 | C8: 下品 | D8: NONE | E8: 头具 | F8: 重甲 | G8: 1 | H8: 1 | I8: =G8*H8 -> 1 | J8: 5 | K8: 2 | L8: 1 | M8: =L8/J8 -> 0.2 | N8: 1 | O8: =I8*N8 -> 1 | P8: 同一部位最多1件；护臂／护腿分别计限（Q03） | Q8: 无 | R8: 零体力沿用防具基线；数量不消耗 | S8: 01 C01/I11；04防具；06 Link | T8: base.map_item.old_iron_helmet | U8: 保留资料已有值；补甲型；甲型加权Q02已确认 | V8: B2/C；U | AB8: =O8 -> 1
A9: t01.asset.0013 | B9: 木圆盾 | C9: 下品 | D9: NONE | E9: 盾 | F9: 轻甲 | G9: 1 | H9: 2 | I9: =G9*H9 -> 2 | J9: 5 | K9: 2 | L9: 3 | M9: =L9/J9 -> 0.6 | N9: 1 | O9: =I9*N9 -> 2 | P9: 可多件上阵，仅受阵盘空间限制（Q03） | Q9: 无 | R9: 零体力沿用防具基线；数量不消耗 | S9: 01 C01/I11；04防具；06 Link | T9: base.map_item.round_wood_shield | U9: 保留资料已有值；补甲型；甲型加权Q02已确认 | V9: B2/C；U | AB9: =O9 -> 2
A10: t01.asset.0014 | B10: 布护臂 | C10: 下品 | D10: NONE | E10: 护具·臂 | F10: 轻甲 | G10: 1 | H10: 1 | I10: =G10*H10 -> 1 | J10: 5 | K10: 1 | L10: 1 | M10: =L10/J10 -> 0.2 | N10: 1 | O10: =I10*N10 -> 1 | P10: 同一部位最多1件；护臂／护腿分别计限（Q03） | Q10: 布甲联动 | R10: 零体力沿用防具基线；数量不消耗 | S10: 01 C01/I11；04防具；06 Link | T10: 未配置 | U10: 新增试玩候选；甲型加权Q02已确认 | V10: B2/C；U | AB10: =O10 -> 1
A11: t01.asset.0015 | B11: 布护腿 | C11: 下品 | D11: NONE | E11: 护具·腿 | F11: 轻甲 | G11: 1 | H11: 1 | I11: =G11*H11 -> 1 | J11: 6 | K11: 2 | L11: 1 | M11: =L11/J11 -> 0.16666667 | N11: 1 | O11: =I11*N11 -> 1 | P11: 同一部位最多1件；护臂／护腿分别计限（Q03） | Q11: 布甲联动 | R11: 零体力沿用防具基线；数量不消耗 | S11: 01 C01/I11；04防具；06 Link | T11: 未配置 | U11: 新增试玩候选；甲型加权Q02已确认 | V11: B2/C；U | AB11: =O11 -> 1
A12: t01.asset.0016 | B12: 铁护臂 | C12: 下品 | D12: NONE | E12: 护具·臂 | F12: 重甲 | G12: 1 | H12: 1 | I12: =G12*H12 -> 1 | J12: 5 | K12: 2 | L12: 2 | M12: =L12/J12 -> 0.4 | N12: 1 | O12: =I12*N12 -> 1 | P12: 同一部位最多1件；护臂／护腿分别计限（Q03） | Q12: 铁甲联动 | R12: 零体力沿用防具基线；数量不消耗 | S12: 01 C01/I11；04防具；06 Link | T12: 未配置 | U12: C新增试玩候选；甲型加权Q02已确认 | V12: C | AB12: =O12 -> 1
A13: t01.asset.0017 | B13: 铁护腿 | C13: 下品 | D13: NONE | E13: 护具·腿 | F13: 重甲 | G13: 1 | H13: 1 | I13: =G13*H13 -> 1 | J13: 6 | K13: 3 | L13: 3 | M13: =L13/J13 -> 0.5 | N13: 1 | O13: =I13*N13 -> 1 | P13: 同一部位最多1件；护臂／护腿分别计限（Q03） | Q13: 铁甲联动 | R13: 零体力沿用防具基线；数量不消耗 | S13: 01 C01/I11；04防具；06 Link | T13: 未配置 | U13: C新增试玩候选；甲型加权Q02已确认 | V13: C | AB13: =O13 -> 1
A14: t01.asset.0055 | B14: 细布衣 | C14: 凡品 | D14: NONE | E14: 身甲 | F14: 轻甲 | G14: 1 | H14: 2 | I14: =G14*H14 -> 2 | J14: 6 | K14: 13 | L14: 7 | M14: =IF(OR(J14="",J14=0),0,L14/J14) -> 1.1666667 | N14: 2 | O14: =I14*N14 -> 4 | P14: 盾可多件；其他同一部位最多1件 | Q14: 无 | R14: 体力0／灵力0／数量0 | S14: 01 C01/I11；02状态；04；06 Link | U14: 候选数值，未试跑 | V14: 第1批基础；第2批微调；第3批复查；用户直接更正优先 | W14: A01 | Z14: 无 | AB14: =O14 -> 4 | AC14: t01.asset.0055.effect.01；t01.asset.0055.effect.02
A15: t01.asset.0056 | B15: 水纹衣 | C15: 凡品 | D15: 水 | E15: 身甲 | F15: 轻甲 | G15: 1 | H15: 2 | I15: =G15*H15 -> 2 | J15: 7 | K15: 12 | L15: 6 | M15: =IF(OR(J15="",J15=0),0,L15/J15) -> 0.85714286 | N15: 2 | O15: =I15*N15 -> 4 | P15: 盾可多件；其他同一部位最多1件 | Q15: 水纹三件 | R15: 体力0／灵力0／数量0 | S15: 01 C01/I11；02状态；04；06 Link | U15: 候选数值，未试跑 | V15: 第1批基础；第2批微调；第3批复查；用户直接更正优先 | W15: A02 | X15: 润脉 | Y15: 1 | Z15: 轮转 | AB15: =O15 -> 4 | AC15: t01.asset.0056.effect.01；t01.asset.0056.effect.02；t01.asset.0056.effect.03
A16: t01.asset.0057 | B16: 札甲 | C16: 凡品 | D16: NONE | E16: 身甲 | F16: 重甲 | G16: 1 | H16: 2 | I16: =G16*H16 -> 2 | J16: 8.5 | K16: 18 | L16: 8 | M16: =IF(OR(J16="",J16=0),0,L16/J16) -> 0.94117647 | N16: 2 | O16: =I16*N16 -> 4 | P16: 盾可多件；其他同一部位最多1件 | Q16: 铁甲三件_凡品 | R16: 体力0／灵力0／数量0 | S16: 01 C01/I11；02状态；04；06 Link | U16: 候选数值，未试跑 | V16: 第1批基础；第2批微调；第3批复查；用户直接更正优先 | W16: A03 | Z16: 无 | AB16: =O16 -> 4 | AC16: t01.asset.0057.effect.01；t01.asset.0057.effect.02
A17: t01.asset.0058 | B17: 赤铜甲 | C17: 凡品 | D17: 火 | E17: 身甲 | F17: 重甲 | G17: 1 | H17: 2 | I17: =G17*H17 -> 2 | J17: 8.5 | K17: 16 | L17: 6 | M17: =IF(OR(J17="",J17=0),0,L17/J17) -> 0.70588235 | N17: 2 | O17: =I17*N17 -> 4 | P17: 盾可多件；其他同一部位最多1件 | Q17: 无 | R17: 体力0／灵力0／数量0 | S17: 01 C01/I11；02状态；04；06 Link | U17: 候选数值，未试跑 | V17: 第1批基础；第2批微调；第3批复查；用户直接更正优先 | W17: A04 | X17: 附炎 | Y17: 2 | Z17: 受击 | AA17: 9 | AB17: =O17 -> 4 | AC17: t01.asset.0058.effect.01；t01.asset.0058.effect.02；t01.asset.0058.effect.03
A18: t01.asset.0059 | B18: 雷纹法袍 | C18: 凡品 | D18: 雷 | E18: 身甲 | F18: 灵甲 | G18: 1 | H18: 2 | I18: =G18*H18 -> 2 | J18: 9 | K18: 14 | L18: 6 | M18: =IF(OR(J18="",J18=0),0,L18/J18) -> 0.66666667 | N18: 2 | O18: =I18*N18 -> 4 | P18: 盾可多件；其他同一部位最多1件 | Q18: 雷纹三件 | R18: 体力0／灵力0／数量0 | S18: 01 C01/I11；02状态；04；06 Link | U18: 候选数值，未试跑 | V18: 第1批基础；第2批微调；第3批复查；用户直接更正优先 | W18: A06 | X18: 雷蕴 | Y18: 2 | Z18: 轮转 | AB18: =O18 -> 4 | AC18: t01.asset.0059.effect.01；t01.asset.0059.effect.02；t01.asset.0059.effect.03
A19: t01.asset.0060 | B19: 皮帽 | C19: 凡品 | D19: 风 | E19: 头具 | F19: 轻甲 | G19: 1 | H19: 1 | I19: =G19*H19 -> 1 | J19: 7 | K19: 4 | L19: 2 | M19: =IF(OR(J19="",J19=0),0,L19/J19) -> 0.28571429 | N19: 1 | O19: =I19*N19 -> 1 | P19: 盾可多件；其他同一部位最多1件 | Q19: 无 | R19: 体力0／灵力0／数量0 | S19: 01 C01/I11；02状态；04；06 Link | U19: 候选数值，未试跑 | V19: 第1批基础；第2批微调；第3批复查；用户直接更正优先 | W19: A07 | X19: 轻灵 | Y19: 1 | Z19: 受击 | AA19: 9 | AB19: =O19 -> 1 | AC19: t01.asset.0060.effect.01；t01.asset.0060.effect.02；t01.asset.0060.effect.03
A20: t01.asset.0061 | B20: 铁盔 | C20: 凡品 | D20: 土 | E20: 头具 | F20: 重甲 | G20: 1 | H20: 1 | I20: =G20*H20 -> 1 | J20: 7.5 | K20: 4 | L20: 3 | M20: =IF(OR(J20="",J20=0),0,L20/J20) -> 0.4 | N20: 1 | O20: =I20*N20 -> 1 | P20: 盾可多件；其他同一部位最多1件 | Q20: 无 | R20: 体力0／灵力0／数量0 | S20: 01 C01/I11；02状态；04；06 Link | U20: 候选数值，未试跑 | V20: 第1批基础；第2批微调；第3批复查；用户直接更正优先 | W20: A08 | X20: 坚韧 | Y20: 1 | Z20: 受击 | AA20: 9 | AB20: =O20 -> 1 | AC20: t01.asset.0061.effect.01；t01.asset.0061.effect.02；t01.asset.0061.effect.03
A21: t01.asset.0062 | B21: 木纹冠 | C21: 凡品 | D21: 木 | E21: 头具 | F21: 灵甲 | G21: 1 | H21: 1 | I21: =G21*H21 -> 1 | J21: 9 | K21: 4 | L21: 2 | M21: =IF(OR(J21="",J21=0),0,L21/J21) -> 0.22222222 | N21: 1 | O21: =I21*N21 -> 1 | P21: 盾可多件；其他同一部位最多1件 | Q21: 无 | R21: 体力0／灵力0／数量0 | S21: 01 C01/I11；02状态；04；06 Link | U21: 候选数值，未试跑 | V21: 第1批基础；第2批微调；第3批复查；用户直接更正优先 | W21: A09 | X21: 生机 | Y21: 1 | Z21: 轮转 | AB21: =O21 -> 1 | AC21: t01.asset.0062.effect.01；t01.asset.0062.effect.02；t01.asset.0062.effect.03
A22: t01.asset.0063 | B22: 风纹冠 | C22: 凡品 | D22: 风 | E22: 头具 | F22: 灵甲 | G22: 1 | H22: 1 | I22: =G22*H22 -> 1 | J22: 8.5 | K22: 3 | L22: 2 | M22: =IF(OR(J22="",J22=0),0,L22/J22) -> 0.23529412 | N22: 1 | O22: =I22*N22 -> 1 | P22: 盾可多件；其他同一部位最多1件 | Q22: 无 | R22: 体力0／灵力0／数量0 | S22: 01 C01/I11；02状态；04；06 Link | U22: 候选数值，未试跑 | V22: 第1批基础；第2批微调；第3批复查；用户直接更正优先 | W22: A10 | X22: 轻灵 | Y22: 1 | Z22: 轮转 | AB22: =O22 -> 1 | AC22: t01.asset.0063.effect.01；t01.asset.0063.effect.02；t01.asset.0063.effect.03
A23: t01.asset.0064 | B23: 皮护臂 | C23: 凡品 | D23: 金 | E23: 护具·臂 | F23: 轻甲 | G23: 1 | H23: 1 | I23: =G23*H23 -> 1 | J23: 7 | K23: 3 | L23: 2 | M23: =IF(OR(J23="",J23=0),0,L23/J23) -> 0.28571429 | N23: 1 | O23: =I23*N23 -> 1 | P23: 盾可多件；其他同一部位最多1件 | Q23: 无 | R23: 体力0／灵力0／数量0 | S23: 01 C01/I11；02状态；04；06 Link | U23: 候选数值，未试跑 | V23: 第1批基础；第2批微调；第3批复查；用户直接更正优先 | W23: A11 | X23: 反锋 | Y23: 1 | Z23: 受击 | AA23: 9 | AB23: =O23 -> 1 | AC23: t01.asset.0064.effect.01；t01.asset.0064.effect.02；t01.asset.0064.effect.03
A24: t01.asset.0065 | B24: 铁护腕 | C24: 凡品 | D24: 金 | E24: 护具·臂 | F24: 重甲 | G24: 1 | H24: 1 | I24: =G24*H24 -> 1 | J24: 7.5 | K24: 3 | L24: 4 | M24: =IF(OR(J24="",J24=0),0,L24/J24) -> 0.53333333 | N24: 1 | O24: =I24*N24 -> 1 | P24: 盾可多件；其他同一部位最多1件 | Q24: 铁甲三件_凡品 | R24: 体力0／灵力0／数量0 | S24: 01 C01/I11；02状态；04；06 Link | U24: 候选数值，未试跑 | V24: 第1批基础；第2批微调；第3批复查；用户直接更正优先 | W24: A12 | X24: 反锋 | Y24: 1 | Z24: 轮转 | AB24: =O24 -> 1 | AC24: t01.asset.0065.effect.01；t01.asset.0065.effect.02；t01.asset.0065.effect.03
A25: t01.asset.0066 | B25: 水纹护臂 | C25: 凡品 | D25: 水 | E25: 护具·臂 | F25: 轻甲 | G25: 1 | H25: 1 | I25: =G25*H25 -> 1 | J25: 8.5 | K25: 3 | L25: 2 | M25: =IF(OR(J25="",J25=0),0,L25/J25) -> 0.23529412 | N25: 1 | O25: =I25*N25 -> 1 | P25: 盾可多件；其他同一部位最多1件 | Q25: 水纹三件 | R25: 体力0／灵力0／数量0 | S25: 01 C01/I11；02状态；04；06 Link | U25: 候选数值，未试跑 | V25: 第1批基础；第2批微调；第3批复查；用户直接更正优先 | W25: A13 | X25: 润脉 | Y25: 1 | Z25: 受击 | AA25: 9 | AB25: =O25 -> 1 | AC25: t01.asset.0066.effect.01；t01.asset.0066.effect.02；t01.asset.0066.effect.03
A26: t01.asset.0067 | B26: 雷纹护腕 | C26: 凡品 | D26: 雷 | E26: 护具·臂 | F26: 重甲 | G26: 1 | H26: 1 | I26: =G26*H26 -> 1 | J26: 9 | K26: 4 | L26: 3 | M26: =IF(OR(J26="",J26=0),0,L26/J26) -> 0.33333333 | N26: 1 | O26: =I26*N26 -> 1 | P26: 盾可多件；其他同一部位最多1件 | Q26: 雷纹三件 | R26: 体力0／灵力0／数量0 | S26: 01 C01/I11；02状态；04；06 Link | U26: 候选数值，未试跑 | V26: 第1批基础；第2批微调；第3批复查；用户直接更正优先 | W26: A14 | X26: 雷蕴 | Y26: 2 | Z26: 受击 | AA26: 9 | AB26: =O26 -> 1 | AC26: t01.asset.0067.effect.01；t01.asset.0067.effect.02；t01.asset.0067.effect.03
A27: t01.asset.0068 | B27: 皮护腿 | C27: 凡品 | D27: 风 | E27: 护具·腿 | F27: 轻甲 | G27: 1 | H27: 1 | I27: =G27*H27 -> 1 | J27: 9 | K27: 4 | L27: 2 | M27: =IF(OR(J27="",J27=0),0,L27/J27) -> 0.22222222 | N27: 1 | O27: =I27*N27 -> 1 | P27: 盾可多件；其他同一部位最多1件 | Q27: 无 | R27: 体力0／灵力0／数量0 | S27: 01 C01/I11；02状态；04；06 Link | U27: 候选数值，未试跑 | V27: 第1批基础；第2批微调；第3批复查；用户直接更正优先 | W27: A15 | X27: 轻灵 | Y27: 1 | Z27: 轮转 | AB27: =O27 -> 1 | AC27: t01.asset.0068.effect.01；t01.asset.0068.effect.02；t01.asset.0068.effect.03
A28: t01.asset.0069 | B28: 铁胫甲 | C28: 凡品 | D28: 土 | E28: 护具·腿 | F28: 重甲 | G28: 1 | H28: 1 | I28: =G28*H28 -> 1 | J28: 9 | K28: 4 | L28: 5 | M28: =IF(OR(J28="",J28=0),0,L28/J28) -> 0.55555556 | N28: 1 | O28: =I28*N28 -> 1 | P28: 盾可多件；其他同一部位最多1件 | Q28: 铁甲三件_凡品 | R28: 体力0／灵力0／数量0 | S28: 01 C01/I11；02状态；04；06 Link | U28: 候选数值，未试跑 | V28: 第1批基础；第2批微调；第3批复查；用户直接更正优先 | W28: A16 | X28: 坚韧 | Y28: 2 | Z28: 受击 | AA28: 9 | AB28: =O28 -> 1 | AC28: t01.asset.0069.effect.01；t01.asset.0069.effect.02；t01.asset.0069.effect.03
A29: t01.asset.0070 | B29: 水纹护腿 | C29: 凡品 | D29: 水 | E29: 护具·腿 | F29: 轻甲 | G29: 1 | H29: 1 | I29: =G29*H29 -> 1 | J29: 8.5 | K29: 4 | L29: 3 | M29: =IF(OR(J29="",J29=0),0,L29/J29) -> 0.35294118 | N29: 1 | O29: =I29*N29 -> 1 | P29: 盾可多件；其他同一部位最多1件 | Q29: 水纹三件 | R29: 体力0／灵力0／数量0 | S29: 01 C01/I11；02状态；04；06 Link | U29: 候选数值，未试跑 | V29: 第1批基础；第2批微调；第3批复查；用户直接更正优先 | W29: A17 | X29: 润脉 | Y29: 1 | Z29: 轮转 | AB29: =O29 -> 1 | AC29: t01.asset.0070.effect.01；t01.asset.0070.effect.02；t01.asset.0070.effect.03
A30: t01.asset.0071 | B30: 藤甲护腿 | C30: 凡品 | D30: 木 | E30: 护具·腿 | F30: 重甲 | G30: 1 | H30: 1 | I30: =G30*H30 -> 1 | J30: 10.5 | K30: 5 | L30: 4 | M30: =IF(OR(J30="",J30=0),0,L30/J30) -> 0.38095238 | N30: 1 | O30: =I30*N30 -> 1 | P30: 盾可多件；其他同一部位最多1件 | Q30: 无 | R30: 体力0／灵力0／数量0 | S30: 01 C01/I11；02状态；04；06 Link | U30: 候选数值，未试跑 | V30: 第1批基础；第2批微调；第3批复查；用户直接更正优先 | W30: A18 | X30: 生机 | Y30: 2 | Z30: 轮转 | AB30: =O30 -> 1 | AC30: t01.asset.0071.effect.01；t01.asset.0071.effect.02；t01.asset.0071.effect.03
A31: t01.asset.0072 | B31: 皮护肩 | C31: 凡品 | D31: 土 | E31: 护具·肩 | F31: 轻甲 | G31: 1 | H31: 1 | I31: =G31*H31 -> 1 | K31: 8 | L31: 0 | M31: =IF(OR(J31="",J31=0),0,L31/J31) -> 0 | N31: 1 | O31: =I31*N31 -> 1 | P31: 盾可多件；其他同一部位最多1件 | Q31: 无 | R31: 体力0／灵力0／数量0 | S31: 01 C01/I11；02状态；04；06 Link | U31: 候选数值，未试跑 | V31: 第1批基础；第2批微调；第3批复查；用户直接更正优先 | W31: A19 | X31: 坚韧 | Y31: 1 | Z31: 受击 | AA31: 9 | AB31: =O31 -> 1 | AC31: t01.asset.0072.effect.01；t01.asset.0072.effect.02
A32: t01.asset.0073 | B32: 金纹护肩 | C32: 凡品 | D32: 金 | E32: 护具·肩 | F32: 重甲 | G32: 1 | H32: 1 | I32: =G32*H32 -> 1 | J32: 9 | K32: 6 | L32: 3 | M32: =IF(OR(J32="",J32=0),0,L32/J32) -> 0.33333333 | N32: 1 | O32: =I32*N32 -> 1 | P32: 盾可多件；其他同一部位最多1件 | Q32: 无 | R32: 体力0／灵力0／数量0 | S32: 01 C01/I11；02状态；04；06 Link | U32: 候选数值，未试跑 | V32: 第1批基础；第2批微调；第3批复查；用户直接更正优先 | W32: A20 | X32: 反锋 | Y32: 2 | Z32: 受击 | AA32: 9 | AB32: =O32 -> 1 | AC32: t01.asset.0073.effect.01；t01.asset.0073.effect.02；t01.asset.0073.effect.03
A33: t01.asset.0074 | B33: 灵丝腰带 | C33: 凡品 | D33: 风 | E33: 护具·腰 | F33: 灵甲 | G33: 1 | H33: 1 | I33: =G33*H33 -> 1 | J33: 9 | K33: 3 | L33: 0 | M33: =IF(OR(J33="",J33=0),0,L33/J33) -> 0 | N33: 1 | O33: =I33*N33 -> 1 | P33: 盾可多件；其他同一部位最多1件 | Q33: 无 | R33: 体力0／灵力0／数量0 | S33: 01 C01/I11；02状态；04；06 Link | U33: 候选数值，未试跑 | V33: 第1批基础；第2批微调；第3批复查；用户直接更正优先 | W33: A21 | X33: 轻灵 | Y33: 2 | Z33: 轮转 | AB33: =O33 -> 1 | AC33: t01.asset.0074.effect.01；t01.asset.0074.effect.02
A34: t01.asset.0075 | B34: 包铁木盾 | C34: 凡品 | D34: 木 | E34: 盾 | F34: 轻甲 | G34: 1 | H34: 2 | I34: =G34*H34 -> 2 | J34: 7.5 | K34: 5 | L34: 6 | M34: =IF(OR(J34="",J34=0),0,L34/J34) -> 0.8 | N34: 1 | O34: =I34*N34 -> 2 | P34: 盾可多件；其他同一部位最多1件 | Q34: 无 | R34: 体力0／灵力0／数量0 | S34: 01 C01/I11；02状态；04；06 Link | U34: 候选数值，未试跑 | V34: 第1批基础；第2批微调；第3批复查；用户直接更正优先 | W34: A22 | X34: 生机 | Y34: 1 | Z34: 轮转 | AB34: =O34 -> 2 | AC34: t01.asset.0075.effect.01；t01.asset.0075.effect.02；t01.asset.0075.effect.03
A35: t01.asset.0076 | B35: 铁盾 | C35: 凡品 | D35: 金 | E35: 盾 | F35: 重甲 | G35: 1 | H35: 2 | I35: =G35*H35 -> 2 | J35: 9 | K35: 8 | L35: 5 | M35: =IF(OR(J35="",J35=0),0,L35/J35) -> 0.55555556 | N35: 1 | O35: =I35*N35 -> 2 | P35: 盾可多件；其他同一部位最多1件 | Q35: 无 | R35: 体力0／灵力0／数量0 | S35: 01 C01/I11；02状态；04；06 Link | U35: 候选数值，未试跑 | V35: 第1批基础；第2批微调；第3批复查；用户直接更正优先 | W35: A23 | X35: 反锋 | Y35: 2 | Z35: 受击 | AA35: 9 | AB35: =O35 -> 2 | AC35: t01.asset.0076.effect.01；t01.asset.0076.effect.02；t01.asset.0076.effect.03
A36: t01.asset.0077 | B36: 水纹盾 | C36: 凡品 | D36: 水 | E36: 盾 | F36: 轻甲 | G36: 1 | H36: 2 | I36: =G36*H36 -> 2 | J36: 8.5 | K36: 6 | L36: 5 | M36: =IF(OR(J36="",J36=0),0,L36/J36) -> 0.58823529 | N36: 1 | O36: =I36*N36 -> 2 | P36: 盾可多件；其他同一部位最多1件 | Q36: 无 | R36: 体力0／灵力0／数量0 | S36: 01 C01/I11；02状态；04；06 Link | U36: 候选数值，未试跑 | V36: 第1批基础；第2批微调；第3批复查；用户直接更正优先 | W36: A24 | X36: 润脉 | Y36: 1 | Z36: 轮转 | AB36: =O36 -> 2 | AC36: t01.asset.0077.effect.01；t01.asset.0077.effect.02；t01.asset.0077.effect.03
A37: t01.asset.0078 | B37: 束甲带 | C37: 凡品 | D37: NONE | E37: 护具·腰 | F37: 重甲 | G37: 1 | H37: 1 | I37: =G37*H37 -> 1 | K37: 12 | L37: 0 | M37: =IF(OR(J37="",J37=0),0,L37/J37) -> 0 | N37: 1 | O37: =I37*N37 -> 1 | P37: 盾可多件；其他同一部位最多1件 | Q37: 无 | R37: 体力0／灵力0／数量0 | S37: 01 C01/I11；02状态；04；06 Link | U37: 候选数值，未试跑 | V37: 第1批基础；第2批微调；第3批复查；用户直接更正优先 | W37: A26 | Z37: 无 | AB37: =O37 -> 1 | AC37: t01.asset.0078.effect.01
A38: t01.asset.0079 | B38: 燎火护臂 | C38: 凡品 | D38: 火 | E38: 护具·臂 | F38: 轻甲 | G38: 1 | H38: 1 | I38: =G38*H38 -> 1 | J38: 8 | K38: 4 | L38: 2 | M38: =IF(OR(J38="",J38=0),0,L38/J38) -> 0.25 | N38: 1 | O38: =I38*N38 -> 1 | P38: 盾可多件；其他同一部位最多1件 | Q38: 无 | R38: 体力0／灵力0／数量0 | S38: 01 C01/I11；02状态；04；06 Link | U38: 候选数值，未试跑 | V38: 第1批基础；第2批微调；第3批复查；用户直接更正优先 | W38: A28 | X38: 附炎 | Y38: 1 | Z38: 轮转 | AB38: =O38 -> 1 | AC38: t01.asset.0079.effect.01；t01.asset.0079.effect.02；t01.asset.0079.effect.03
A39: t01.asset.0080 | B39: 雷纹护腿 | C39: 凡品 | D39: 雷 | E39: 护具·腿 | F39: 灵甲 | G39: 1 | H39: 1 | I39: =G39*H39 -> 1 | J39: 9 | K39: 4 | L39: 2 | M39: =IF(OR(J39="",J39=0),0,L39/J39) -> 0.22222222 | N39: 1 | O39: =I39*N39 -> 1 | P39: 盾可多件；其他同一部位最多1件 | Q39: 雷纹三件 | R39: 体力0／灵力0／数量0 | S39: 01 C01/I11；02状态；04；06 Link | U39: 候选数值，未试跑 | V39: 第1批基础；第2批微调；第3批复查；用户直接更正优先 | W39: A29 | X39: 雷蕴 | Y39: 1 | Z39: 轮转 | AB39: =O39 -> 1 | AC39: t01.asset.0080.effect.01；t01.asset.0080.effect.02；t01.asset.0080.effect.03
A40: t01.asset.0081 | B40: 炎纹护肩 | C40: 凡品 | D40: 火 | E40: 护具·肩 | F40: 重甲 | G40: 1 | H40: 1 | I40: =G40*H40 -> 1 | J40: 10 | K40: 6 | L40: 2 | M40: =IF(OR(J40="",J40=0),0,L40/J40) -> 0.2 | N40: 1 | O40: =I40*N40 -> 1 | P40: 盾可多件；其他同一部位最多1件 | Q40: 无 | R40: 体力0／灵力0／数量0 | S40: 01 C01/I11；02状态；04；06 Link | U40: 候选数值，未试跑 | V40: 第1批基础；第2批微调；第3批复查；用户直接更正优先 | W40: A30 | X40: 附炎 | Y40: 2 | Z40: 轮转 | AB40: =O40 -> 1 | AC40: t01.asset.0081.effect.01；t01.asset.0081.effect.02；t01.asset.0081.effect.03
A41: t01.asset.0082 | B41: 润脉腰带 | C41: 凡品 | D41: 水 | E41: 护具·腰 | F41: 灵甲 | G41: 1 | H41: 1 | I41: =G41*H41 -> 1 | J41: 9 | K41: 4 | L41: 0 | M41: =IF(OR(J41="",J41=0),0,L41/J41) -> 0 | N41: 1 | O41: =I41*N41 -> 1 | P41: 盾可多件；其他同一部位最多1件 | Q41: 无 | R41: 体力0／灵力0／数量0 | S41: 01 C01/I11；02状态；04；06 Link | U41: 候选数值，未试跑 | V41: 第1批基础；第2批微调；第3批复查；用户直接更正优先 | W41: A31 | X41: 润脉 | Y41: 2 | Z41: 轮转 | AB41: =O41 -> 1 | AC41: t01.asset.0082.effect.01；t01.asset.0082.effect.02

Sheet 04_法器
A1: t01-08｜法器
A2: 2026-09-28 · 27下品＋88凡品＝115件 · 候选数值／当前规则／游戏实现分列 · 不含平衡测试结论
A5: 资产ID | B5: 名称 | C5: 品级 | D5: 元素 | E5: 定位 | F5: 攻击类型 | G5: 宽_格 | H5: 高_格 | I5: 实际占格 | J5: CD_秒 | K5: 气血恢复 | L5: 体力恢复 | M5: 灵力恢复 | N5: 恢复上限分子 | O5: 恢复上限分母 | P5: 恢复上限状态 | Q5: 成本与效果边界 | R5: 机制引用 | S5: 现有游戏ID | T5: 设计状态 | U5: 来源 | V5: 来源编号 | W5: 本体伤害 | X5: 灵力费 | Y5: 体力费 | Z5: 护甲上限贡献 | AA5: 单次回甲 | AB5: 普通灵障生成 | AC5: 状态 | AD5: 层数 | AE5: 施加时机与目标 | AF5: 完整效果 | AG5: 效果引用
A6: t01.asset.0018 | B6: 温玉佩 | C6: 下品 | D6: NONE | E6: 基础资源恢复 | F6: 无攻击 | G6: 1 | H6: 1 | I6: =G6*H6 -> 1 | J6: 4 | K6: 4 | L6: 6 | M6: 0 | N6: 2 | O6: 3 | P6: 已有配置上限2/3；保留 | Q6: 道具消耗0、灵力费0；资料称免费恢复，不附Buff／净化。 | R6: 01资源恢复／上限；04法器 | S6: base.map_item.warm_jade | T6: 保留已有值；具体恢复条件按主表边界 | U6: B3；U
A7: t01.asset.0019 | B7: 回春玉 | C7: 下品 | D7: NONE | E7: 基础资源恢复 | F7: 无攻击 | G7: 1 | H7: 1 | I7: =G7*H7 -> 1 | J7: 5 | K7: 6 | L7: 0 | M7: 0 | N7: 2 | O7: 3 | P7: Q04已确认：最多恢复至对应最大值2/3；已超上限不扣减、不继续恢复 | Q7: 道具消耗0、灵力费0；资料称免费恢复，不附Buff／净化。 | R7: 01资源恢复／上限；04法器 | S7: 未配置 | T7: 新增试玩候选；具体恢复条件按主表边界 | U7: B3；U；Q04用户答复2026-09-28
A8: t01.asset.0020 | B8: 养息珠 | C8: 下品 | D8: NONE | E8: 基础资源恢复 | F8: 无攻击 | G8: 1 | H8: 1 | I8: =G8*H8 -> 1 | J8: 5 | K8: 0 | L8: 9 | M8: 0 | N8: 2 | O8: 3 | P8: Q04已确认：最多恢复至对应最大值2/3；已超上限不扣减、不继续恢复 | Q8: 道具消耗0、灵力费0；资料称免费恢复，不附Buff／净化。 | R8: 01资源恢复／上限；04法器 | S8: 未配置 | T8: 新增试玩候选；具体恢复条件按主表边界 | U8: B3；U；Q04用户答复2026-09-28
A9: t01.asset.0021 | B9: 聚灵珠 | C9: 下品 | D9: NONE | E9: 基础资源恢复 | F9: 无攻击 | G9: 1 | H9: 1 | I9: =G9*H9 -> 1 | J9: 5 | K9: 0 | L9: 0 | M9: 6 | N9: 2 | O9: 3 | P9: Q04已确认：最多恢复至对应最大值2/3；已超上限不扣减、不继续恢复 | Q9: 道具消耗0、灵力费0；资料称免费恢复，不附Buff／净化。 | R9: 01资源恢复／上限；04法器 | S9: 未配置 | T9: 新增试玩候选；具体恢复条件按主表边界 | U9: B3；U；Q04用户答复2026-09-28
A10: t01.asset.0083 | B10: 回春佩 | C10: 凡品 | D10: NONE | E10: 资源恢复 | F10: 无攻击 | G10: 1 | H10: 1 | I10: =G10*H10 -> 1 | J10: 7.5 | K10: 13 | L10: 0 | M10: 0 | N10: 1 | O10: 1 | P10: 正常上限 | Q10: 灵力2／体力0／数量0；元素分类不自动创造攻击 | R10: 01效果；02状态；04法器 | T10: 候选数值，未试跑 | U10: 第1批基础；第2批微调；第3批复查；用户直接更正优先 | V10: F01 | X10: 2 | Y10: 0 | Z10: 0 | AA10: 0 | AB10: 0 | AE10: 轮转；自身 | AF10: 气血＋13，可至正常上限 | AG10: t01.asset.0083.effect.01
A11: t01.asset.0084 | B11: 行气珠 | C11: 凡品 | D11: NONE | E11: 资源恢复 | F11: 无攻击 | G11: 1 | H11: 1 | I11: =G11*H11 -> 1 | J11: 7.5 | K11: 0 | L11: 18 | M11: 0 | N11: 2 | O11: 3 | P11: 2/3向下取整 | Q11: 灵力0／体力0／数量0；元素分类不自动创造攻击 | R11: 01效果；02状态；04法器 | T11: 候选数值，未试跑 | U11: 第1批基础；第2批微调；第3批复查；用户直接更正优先 | V11: F02 | X11: 0 | Y11: 0 | Z11: 0 | AA11: 0 | AB11: 0 | AE11: 轮转；自身 | AF11: 体力＋18，最多至上限2/3 | AG11: t01.asset.0084.effect.01
A12: t01.asset.0085 | B12: 聚元环 | C12: 凡品 | D12: NONE | E12: 资源恢复 | F12: 无攻击 | G12: 1 | H12: 1 | I12: =G12*H12 -> 1 | J12: 7.5 | K12: 0 | L12: 0 | M12: 13 | N12: 2 | O12: 3 | P12: 2/3向下取整 | Q12: 灵力0／体力0／数量0；元素分类不自动创造攻击 | R12: 01效果；02状态；04法器 | T12: 候选数值，未试跑 | U12: 第1批基础；第2批微调；第3批复查；用户直接更正优先 | V12: F03 | X12: 0 | Y12: 0 | Z12: 0 | AA12: 0 | AB12: 0 | AE12: 轮转；自身 | AF12: 灵力＋13，最多至上限2/3 | AG12: t01.asset.0085.effect.01
A13: t01.asset.0086 | B13: 调息玉 | C13: 凡品 | D13: NONE | E13: 资源恢复 | F13: 无攻击 | G13: 1 | H13: 1 | I13: =G13*H13 -> 1 | J13: 8.5 | K13: 7 | L13: 0 | M13: 10 | N13: 2 | O13: 3 | P13: 2/3向下取整 | Q13: 灵力0／体力0／数量0；元素分类不自动创造攻击 | R13: 01效果；02状态；04法器 | T13: 候选数值，未试跑 | U13: 第1批基础；第2批微调；第3批复查；用户直接更正优先 | V13: F04 | X13: 0 | Y13: 0 | Z13: 0 | AA13: 0 | AB13: 0 | AE13: 轮转；自身 | AF13: 气血＋7、灵力＋10，各至上限2/3 | AG13: t01.asset.0086.effect.01；t01.asset.0086.effect.02
A14: t01.asset.0087 | B14: 金光镜 | C14: 凡品 | D14: 金 | E14: 攻击／状态／防护 | F14: 法术型 | G14: 1 | H14: 1 | I14: =G14*H14 -> 1 | J14: 7 | K14: 0 | L14: 0 | M14: 0 | P14: 不适用 | Q14: 灵力6／体力0／数量0；元素分类不自动创造攻击 | R14: 01效果；02状态；04法器 | T14: 候选数值，未试跑 | U14: 第1批基础；第2批微调；第3批复查；用户直接更正优先 | V14: F05 | W14: 22 | X14: 6 | Y14: 0 | Z14: 0 | AA14: 0 | AB14: 0 | AC14: 锋痕 | AD14: 1 | AE14: 命中；敌方 | AF14: 金属性法术攻击22，命中锋痕＋1；锋痕由合格武器攻击兑现；金光镜仍是法器来源，不因金元素或SPELL攻击类型取得武器资格。 | AG14: t01.asset.0087.effect.01；t01.asset.0087.effect.02
A15: t01.asset.0088 | B15: 青木铃 | C15: 凡品 | D15: 木 | E15: 攻击／状态／防护 | F15: 无攻击 | G15: 1 | H15: 1 | I15: =G15*H15 -> 1 | J15: 9 | K15: 0 | L15: 0 | M15: 0 | P15: 不适用 | Q15: 灵力4／体力0／数量0；元素分类不自动创造攻击 | R15: 01效果；02状态；04法器 | T15: 候选数值，未试跑 | U15: 第1批基础；第2批微调；第3批复查；用户直接更正优先 | V15: F06 | X15: 4 | Y15: 0 | Z15: 0 | AA15: 0 | AB15: 0 | AC15: 生机 | AD15: 3 | AE15: 轮转；自身 | AF15: 自身生机＋3；具体效果与施加时序依02和核心01，不由七系标签自动增加额外伤害。 | AG15: t01.asset.0088.effect.01
A16: t01.asset.0089 | B16: 寒水珠 | C16: 凡品 | D16: 水 | E16: 攻击／状态／防护 | F16: 法术型 | G16: 1 | H16: 1 | I16: =G16*H16 -> 1 | J16: 7.5 | K16: 0 | L16: 0 | M16: 0 | P16: 不适用 | Q16: 灵力6／体力0／数量0；元素分类不自动创造攻击 | R16: 01效果；02状态；04法器 | T16: 候选数值，未试跑 | U16: 第1批基础；第2批微调；第3批复查；用户直接更正优先 | V16: F07 | W16: 23 | X16: 6 | Y16: 0 | Z16: 0 | AA16: 0 | AB16: 0 | AC16: 寒霜 | AD16: 1 | AE16: 命中；敌方 | AF16: 水属性法术攻击23，命中寒霜＋1；寒霜正常新层先施加、后由本次合格主动水攻触发；初霜专属额外层例外留后次。 | AG16: t01.asset.0089.effect.01；t01.asset.0089.effect.02
A17: t01.asset.0090 | B17: 火灵珠 | C17: 凡品 | D17: 火 | E17: 攻击／状态／防护 | F17: 无攻击 | G17: 1 | H17: 1 | I17: =G17*H17 -> 1 | J17: 7.5 | K17: 0 | L17: 0 | M17: 0 | P17: 不适用 | Q17: 灵力4／体力0／数量0；元素分类不自动创造攻击 | R17: 01效果；02状态；04法器 | T17: 候选数值，未试跑 | U17: 第1批基础；第2批微调；第3批复查；用户直接更正优先 | V17: F08 | X17: 4 | Y17: 0 | Z17: 0 | AA17: 0 | AB17: 0 | AC17: 附炎 | AD17: 3 | AE17: 轮转；自身 | AF17: 自身附炎＋3；具体效果与施加时序依02和核心01，不由七系标签自动增加额外伤害。 | AG17: t01.asset.0090.effect.01
A18: t01.asset.0091 | B18: 坤土珠 | C18: 凡品 | D18: 土 | E18: 攻击／状态／防护 | F18: 无攻击 | G18: 1 | H18: 1 | I18: =G18*H18 -> 1 | J18: 9 | K18: 0 | L18: 0 | M18: 0 | P18: 不适用 | Q18: 灵力4／体力0／数量0；元素分类不自动创造攻击 | R18: 01效果；02状态；04法器 | T18: 候选数值，未试跑 | U18: 第1批基础；第2批微调；第3批复查；用户直接更正优先 | V18: F09 | X18: 4 | Y18: 0 | Z18: 0 | AA18: 0 | AB18: 0 | AC18: 坚韧 | AD18: 3 | AE18: 轮转；自身 | AF18: 自身坚韧＋3；具体效果与施加时序依02和核心01，不由七系标签自动增加额外伤害。 | AG18: t01.asset.0091.effect.01
A19: t01.asset.0092 | B19: 逐风旗 | C19: 凡品 | D19: 风 | E19: 攻击／状态／防护 | F19: 无攻击 | G19: 1 | H19: 2 | I19: =G19*H19 -> 2 | J19: 7.5 | K19: 0 | L19: 0 | M19: 0 | P19: 不适用 | Q19: 灵力4／体力0／数量0；元素分类不自动创造攻击 | R19: 01效果；02状态；04法器 | T19: 候选数值，未试跑 | U19: 第1批基础；第2批微调；第3批复查；用户直接更正优先 | V19: F10 | X19: 4 | Y19: 0 | Z19: 0 | AA19: 0 | AB19: 0 | AC19: 失衡 | AD19: 4 | AE19: 轮转；敌方 | AF19: 直接向敌方施加失衡＋4；具体效果与施加时序依02和核心01，不由七系标签自动增加额外伤害。 | AG19: t01.asset.0092.effect.01
A20: t01.asset.0093 | B20: 引雷珠 | C20: 凡品 | D20: 雷 | E20: 攻击／状态／防护 | F20: 无攻击 | G20: 1 | H20: 1 | I20: =G20*H20 -> 1 | J20: 9 | K20: 0 | L20: 0 | M20: 0 | P20: 不适用 | Q20: 灵力4／体力0／数量0；元素分类不自动创造攻击 | R20: 01效果；02状态；04法器 | T20: 候选数值，未试跑 | U20: 第1批基础；第2批微调；第3批复查；用户直接更正优先 | V20: F11 | X20: 4 | Y20: 0 | Z20: 0 | AA20: 0 | AB20: 0 | AC20: 雷印 | AD20: 4 | AE20: 轮转；敌方 | AF20: 直接向敌方施加雷印＋4；雷印新层在本击伤后加入，供后续合格雷攻；无本体雷攻击的施层器具不直接引雷。 | AG20: t01.asset.0093.effect.01
A21: t01.asset.0094 | B21: 护心镜 | C21: 凡品 | D21: NONE | E21: 攻击／状态／防护 | F21: 无攻击 | G21: 1 | H21: 1 | I21: =G21*H21 -> 1 | K21: 0 | L21: 0 | M21: 0 | P21: 不适用 | Q21: 灵力0／体力0／数量0；元素分类不自动创造攻击 | R21: 01效果；02状态；04法器 | T21: 候选数值，未试跑 | U21: 第1批基础；第2批微调；第3批复查；用户直接更正优先 | V21: F12 | X21: 0 | Y21: 0 | Z21: 10 | AA21: 0 | AB21: 0 | AE21: 静态；自身 | AF21: 护甲上限＋10，无甲型权重 | AG21: t01.asset.0094.effect.01
A22: t01.asset.0095 | B22: 复甲环 | C22: 凡品 | D22: NONE | E22: 攻击／状态／防护 | F22: 无攻击 | G22: 1 | H22: 1 | I22: =G22*H22 -> 1 | J22: 6 | K22: 0 | L22: 0 | M22: 0 | P22: 不适用 | Q22: 灵力3／体力0／数量0；元素分类不自动创造攻击 | R22: 01效果；02状态；04法器 | T22: 候选数值，未试跑 | U22: 第1批基础；第2批微调；第3批复查；用户直接更正优先 | V22: F13 | X22: 3 | Y22: 0 | Z22: 0 | AA22: 7 | AB22: 0 | AE22: 轮转；自身 | AF22: 当前护甲＋7，不增加上限 | AG22: t01.asset.0095.effect.01
A23: t01.asset.0096 | B23: 灵障珠 | C23: 凡品 | D23: NONE | E23: 攻击／状态／防护 | F23: 无攻击 | G23: 1 | H23: 1 | I23: =G23*H23 -> 1 | J23: 10.5 | K23: 0 | L23: 0 | M23: 0 | P23: 不适用 | Q23: 灵力6／体力0／数量0；满灵障仍发动扣费并重开CD，普通控制和资源资格仍检查。 | R23: 01效果；02状态；04法器 | T23: 候选数值，未试跑 | U23: 第1批基础；第2批微调；第3批复查；用户直接更正优先 | V23: F14 | X23: 6 | Y23: 0 | Z23: 0 | AA23: 0 | AB23: 15 | AE23: 轮转；自身 | AF23: 普通灵障＋15（受当前上限限制）；F14灵障珠满上限仍正常发动，消耗6灵力并重开10.5秒CD，实际增加0；未满时实际增加min(15,容量缺口)，费用仍6。仍检查控制、资源等正常发动资格；费用不足不能发动。此空转支付是F14的已定策略，不自动推广其他资产。 | AG23: t01.asset.0096.effect.01
A24: t01.asset.0097 | B24: 枯脉瓶 | C24: 凡品 | D24: 水 | E24: 攻击／状态／防护 | F24: 无攻击 | G24: 1 | H24: 1 | I24: =G24*H24 -> 1 | J24: 9 | K24: 0 | L24: 0 | M24: 0 | P24: 不适用 | Q24: 灵力4／体力0／数量0；元素分类不自动创造攻击 | R24: 01效果；02状态；04法器 | T24: 候选数值，未试跑 | U24: 第1批基础；第2批微调；第3批复查；用户直接更正优先 | V24: F15 | X24: 4 | Y24: 0 | Z24: 0 | AA24: 0 | AB24: 0 | AC24: 枯脉 | AD24: 3 | AE24: 轮转；敌方 | AF24: 直接向敌方施加枯脉＋3；具体效果与施加时序依02和核心01，不由七系标签自动增加额外伤害。 | AG24: t01.asset.0097.effect.01
A25: t01.asset.0098 | B25: 清风拂 | C25: 凡品 | D25: 风 | E25: 攻击／状态／防护 | F25: 无攻击 | G25: 1 | H25: 2 | I25: =G25*H25 -> 2 | J25: 10.5 | K25: 0 | L25: 0 | M25: 0 | P25: 不适用 | Q25: 灵力4／体力0／数量0；元素分类不自动创造攻击 | R25: 01效果；02状态；04法器 | T25: 候选数值，未试跑 | U25: 第1批基础；第2批微调；第3批复查；用户直接更正优先 | V25: F16 | X25: 4 | Y25: 0 | Z25: 0 | AA25: 0 | AB25: 0 | AC25: 驱散 | AD25: 2 | AE25: 轮转；敌方 | AF25: 直接向敌方施加驱散＋2；具体效果与施加时序依02和核心01，不由七系标签自动增加额外伤害。 | AG25: t01.asset.0098.effect.01
A26: t01.asset.0099 | B26: 锁雷环 | C26: 凡品 | D26: 雷 | E26: 攻击／状态／防护 | F26: 无攻击 | G26: 1 | H26: 1 | I26: =G26*H26 -> 1 | J26: 9 | K26: 0 | L26: 0 | M26: 0 | P26: 不适用 | Q26: 灵力4／体力0／数量0；元素分类不自动创造攻击 | R26: 01效果；02状态；04法器 | T26: 候选数值，未试跑 | U26: 第1批基础；第2批微调；第3批复查；用户直接更正优先 | V26: F17 | X26: 4 | Y26: 0 | Z26: 0 | AA26: 0 | AB26: 0 | AC26: 连环 | AD26: 2 | AE26: 轮转；敌方 | AF26: 直接向敌方施加连环＋2；连环供后续合格雷攻击利用；锁雷环无本体攻击，不直接制造雷击或闪电。 | AG26: t01.asset.0099.effect.01
A27: t01.asset.0100 | B27: 蕴雷铃 | C27: 凡品 | D27: 雷 | E27: 攻击／状态／防护 | F27: 无攻击 | G27: 1 | H27: 1 | I27: =G27*H27 -> 1 | J27: 9 | K27: 0 | L27: 0 | M27: 0 | P27: 不适用 | Q27: 灵力4／体力0／数量0；元素分类不自动创造攻击 | R27: 01效果；02状态；04法器 | T27: 候选数值，未试跑 | U27: 第1批基础；第2批微调；第3批复查；用户直接更正优先 | V27: F18 | X27: 4 | Y27: 0 | Z27: 0 | AA27: 0 | AB27: 0 | AC27: 雷蕴 | AD27: 3 | AE27: 轮转；自身 | AF27: 自身雷蕴＋3；具体效果与施加时序依02和核心01，不由七系标签自动增加额外伤害。 | AG27: t01.asset.0100.effect.01

Sheet 05_丹药
A1: t01-08｜丹药
A2: 2026-09-28 · 27下品＋88凡品＝115件 · 候选数值／当前规则／游戏实现分列 · 不含平衡测试结论
A5: 资产ID | B5: 名称 | C5: 品级 | D5: 元素 | E5: 效果类型 | F5: 宽_格 | G5: 高_格 | H5: 实际占格 | I5: CD_秒 | J5: 每次气血恢复 | K5: 每次体力恢复 | L5: 每次灵力恢复 | M5: 跳间隔_秒 | N5: 次数 | O5: 总气血恢复 | P5: 总体力恢复 | Q5: 总灵力恢复 | R5: 毒蚀免疫_秒 | S5: 发动耗数量 | T5: 单位 | U5: 结算时点 | V5: 效果边界 | W5: 机制引用 | X5: 现有游戏ID | Y5: 设计状态 | Z5: 来源 | AA5: 来源编号 | AB5: 状态 | AC5: 层数 | AD5: 减伤元素 | AE5: 减伤比例 | AF5: 持续_秒 | AG5: 首瓶与CD规则 | AH5: 自动使用条件 | AI5: 效果引用
A6: t01.asset.0022 | B6: 止血丹 | C6: 下品 | D6: NONE | E6: 分次 | F6: 1 | G6: 1 | H6: =F6*G6 -> 1 | I6: 6.5 | J6: 2 | K6: 0 | L6: 0 | M6: 2 | N6: 3 | O6: =IF(N6="",0,J6*N6) -> 6 | P6: =IF(N6="",0,K6*N6) -> 0 | Q6: =IF(N6="",0,L6*N6) -> 0 | R6: 0 | S6: 1 | T6: 瓶 | U6: 第2/4/6秒结算；不是发动即首跳 | V6: 仅消毒散清除毒蚀并免疫毒蚀；不扩为全负面净化。 | W6: 01时序／恢复／免疫；02 OP；03专门用途 | X6: base.map_item.hemostatic_pill | Y6: 保留资料已有值 | Z6: B4；U | AG6: 首瓶开战可用；未用不进入CD；实际使用后重开完整CD
A7: t01.asset.0023 | B7: 强筋丸 | C7: 下品 | D7: NONE | E7: 分次 | F7: 1 | G7: 1 | H7: =F7*G7 -> 1 | I7: 7.5 | J7: 0 | K7: 4 | L7: 0 | M7: 2 | N7: 3 | O7: =IF(N7="",0,J7*N7) -> 0 | P7: =IF(N7="",0,K7*N7) -> 12 | Q7: =IF(N7="",0,L7*N7) -> 0 | R7: 0 | S7: 1 | T7: 瓶 | U7: 第2/4/6秒结算；不是发动即首跳 | V7: 仅消毒散清除毒蚀并免疫毒蚀；不扩为全负面净化。 | W7: 01时序／恢复／免疫；02 OP；03专门用途 | X7: base.map_item.sinew_pill | Y7: 保留资料已有值 | Z7: B4；U | AG7: 首瓶开战可用；未用不进入CD；实际使用后重开完整CD
A8: t01.asset.0024 | B8: 消毒散 | C8: 下品 | D8: NONE | E8: 清毒＋毒蚀免疫 | F8: 1 | G8: 1 | H8: =F8*G8 -> 1 | I8: 5.5 | J8: 0 | K8: 0 | L8: 0 | O8: =IF(N8="",0,J8*N8) -> 0 | P8: =IF(N8="",0,K8*N8) -> 0 | Q8: =IF(N8="",0,L8*N8) -> 0 | R8: 15 | S8: 1 | T8: 瓶 | U8: 发动立即生效 | V8: 仅消毒散清除毒蚀并免疫毒蚀；不扩为全负面净化。 | W8: 01时序／恢复／免疫；02 OP；03专门用途 | X8: base.map_item.detox_powder | Y8: 保留资料已有值 | Z8: B4；U | AG8: 首瓶开战可用；未用不进入CD；实际使用后重开完整CD
A9: t01.asset.0025 | B9: 回灵丹 | C9: 下品 | D9: NONE | E9: 分次 | F9: 1 | G9: 1 | H9: =F9*G9 -> 1 | I9: 7.5 | J9: 0 | K9: 0 | L9: 3 | M9: 2 | N9: 3 | O9: =IF(N9="",0,J9*N9) -> 0 | P9: =IF(N9="",0,K9*N9) -> 0 | Q9: =IF(N9="",0,L9*N9) -> 9 | R9: 0 | S9: 1 | T9: 瓶 | U9: 第2/4/6秒结算；不是发动即首跳 | V9: 仅消毒散清除毒蚀并免疫毒蚀；不扩为全负面净化。 | W9: 01时序／恢复／免疫；02 OP；03专门用途 | X9: 未配置 | Y9: 新增试玩候选 | Z9: B4；U | AG9: 首瓶开战可用；未用不进入CD；实际使用后重开完整CD
A10: t01.asset.0026 | B10: 金疮散 | C10: 下品 | D10: NONE | E10: 即时 | F10: 1 | G10: 1 | H10: =F10*G10 -> 1 | I10: 5.5 | J10: 4 | K10: 0 | L10: 0 | M10: 0 | N10: 1 | O10: =IF(N10="",0,J10*N10) -> 4 | P10: =IF(N10="",0,K10*N10) -> 0 | Q10: =IF(N10="",0,L10*N10) -> 0 | R10: 0 | S10: 1 | T10: 份 | U10: 发动立即生效 | V10: 仅消毒散清除毒蚀并免疫毒蚀；不扩为全负面净化。 | W10: 01时序／恢复／免疫；02 OP；03专门用途 | X10: 未配置 | Y10: 新增试玩候选 | Z10: B4；U | AG10: 首瓶开战可用；未用不进入CD；实际使用后重开完整CD
A11: t01.asset.0027 | B11: 回元散 | C11: 下品 | D11: NONE | E11: 即时 | F11: 1 | G11: 1 | H11: =F11*G11 -> 1 | I11: 7 | J11: 3 | K11: 6 | L11: 0 | M11: 0 | N11: 1 | O11: =IF(N11="",0,J11*N11) -> 3 | P11: =IF(N11="",0,K11*N11) -> 6 | Q11: =IF(N11="",0,L11*N11) -> 0 | R11: 0 | S11: 1 | T11: 份 | U11: 发动立即生效 | V11: 仅消毒散清除毒蚀并免疫毒蚀；不扩为全负面净化。 | W11: 01时序／恢复／免疫；02 OP；03专门用途 | X11: 未配置 | Y11: 新增试玩候选 | Z11: B4；U | AG11: 首瓶开战可用；未用不进入CD；实际使用后重开完整CD
A12: t01.asset.0101 | B12: 回春丹 | C12: 凡品 | D12: NONE | E12: 分次 | F12: 1 | G12: 1 | H12: =F12*G12 -> 1 | I12: 12 | J12: 7 | K12: 0 | L12: 0 | M12: 2 | N12: 3 | O12: =J12*N12 -> 21 | P12: =K12*N12 -> 0 | Q12: =L12*N12 -> 0 | R12: 0 | S12: 1 | T12: 份 | U12: 第2/4/6战斗秒 | V12: 发动后第2、4、6战斗秒各恢复气血7，总21 | W12: 01时序／恢复；02状态／S3；04丹药 | Y12: 候选数值，未试跑 | Z12: 本次Q01用户补充丹药完整表；用户首瓶机制修正 | AA12: P01 | AG12: 首瓶开战可用；未用不进入CD；实际使用后重开完整CD | AH12: 对应资源未缺不自动消耗；同款持续恢复未结束不再自动服用 | AI12: t01.asset.0101.effect.01
A13: t01.asset.0102 | B13: 益气丹 | C13: 凡品 | D13: NONE | E13: 分次 | F13: 1 | G13: 1 | H13: =F13*G13 -> 1 | I13: 13 | J13: 0 | K13: 10 | L13: 0 | M13: 2 | N13: 3 | O13: =J13*N13 -> 0 | P13: =K13*N13 -> 30 | Q13: =L13*N13 -> 0 | R13: 0 | S13: 1 | T13: 份 | U13: 第2/4/6战斗秒 | V13: 发动后第2、4、6战斗秒各恢复体力10，总30 | W13: 01时序／恢复；02状态／S3；04丹药 | Y13: 候选数值，未试跑 | Z13: 本次Q01用户补充丹药完整表；用户首瓶机制修正 | AA13: P02 | AG13: 首瓶开战可用；未用不进入CD；实际使用后重开完整CD | AH13: 对应资源未缺不自动消耗；同款持续恢复未结束不再自动服用 | AI13: t01.asset.0102.effect.01
A14: t01.asset.0103 | B14: 聚灵丹 | C14: 凡品 | D14: NONE | E14: 分次 | F14: 1 | G14: 1 | H14: =F14*G14 -> 1 | I14: 13 | J14: 0 | K14: 0 | L14: 9 | M14: 2 | N14: 3 | O14: =J14*N14 -> 0 | P14: =K14*N14 -> 0 | Q14: =L14*N14 -> 27 | R14: 0 | S14: 1 | T14: 份 | U14: 第2/4/6战斗秒 | V14: 发动后第2、4、6战斗秒各恢复灵力9，总27 | W14: 01时序／恢复；02状态／S3；04丹药 | Y14: 候选数值，未试跑 | Z14: 本次Q01用户补充丹药完整表；用户首瓶机制修正 | AA14: P03 | AG14: 首瓶开战可用；未用不进入CD；实际使用后重开完整CD | AH14: 对应资源未缺不自动消耗；同款持续恢复未结束不再自动服用 | AI14: t01.asset.0103.effect.01
A15: t01.asset.0104 | B15: 培元丹 | C15: 凡品 | D15: NONE | E15: 即时恢复 | F15: 1 | G15: 1 | H15: =F15*G15 -> 1 | I15: 12 | J15: 12 | K15: 18 | L15: 0 | N15: 1 | O15: =J15*N15 -> 12 | P15: =K15*N15 -> 18 | Q15: =L15*N15 -> 0 | R15: 0 | S15: 1 | T15: 份 | U15: 使用当刻 | V15: 立即恢复气血12、体力18 | W15: 01时序／恢复；02状态／S3；04丹药 | Y15: 候选数值，未试跑 | Z15: 本次Q01用户补充丹药完整表；用户首瓶机制修正 | AA15: P04 | AG15: 首瓶开战可用；未用不进入CD；实际使用后重开完整CD | AH15: 对应资源未缺不自动消耗；同款持续恢复未结束不再自动服用 | AI15: t01.asset.0104.effect.01；t01.asset.0104.effect.02
A16: t01.asset.0105 | B16: 铁骨丸 | C16: 凡品 | D16: NONE | E16: 状态 | F16: 1 | G16: 1 | H16: =F16*G16 -> 1 | I16: 18 | J16: 0 | K16: 0 | L16: 0 | N16: 1 | O16: =J16*N16 -> 0 | P16: =K16*N16 -> 0 | Q16: =L16*N16 -> 0 | R16: 0 | S16: 1 | T16: 份 | U16: 使用当刻 | V16: 立即给予自身坚韧＋4层 | W16: 01时序／恢复；02状态／S3；04丹药 | Y16: 候选数值，未试跑 | Z16: 本次Q01用户补充丹药完整表；用户首瓶机制修正 | AA16: P05 | AB16: 坚韧 | AC16: 4 | AG16: 首瓶开战可用；未用不进入CD；实际使用后重开完整CD | AH16: 坚韧仍有新增容量时使用 | AI16: t01.asset.0105.effect.01
A17: t01.asset.0106 | B17: 避火丹 | C17: 凡品 | D17: NONE | E17: 元素减伤 | F17: 1 | G17: 1 | H17: =F17*G17 -> 1 | I17: 22.5 | J17: 0 | K17: 0 | L17: 0 | N17: 1 | O17: =J17*N17 -> 0 | P17: =K17*N17 -> 0 | Q17: =L17*N17 -> 0 | R17: 0 | S17: 1 | T17: 份 | U17: 使用当刻 | V17: 持续12秒，合格直接攻击的火伤分量－10%；同基础百分比加算 | W17: 01时序／恢复；02状态／S3；04丹药 | Y17: 候选数值，未试跑 | Z17: 本次Q01用户补充丹药完整表；用户首瓶机制修正 | AA17: P06 | AD17: 火 | AE17: 0.1 | AF17: 12 | AG17: 首瓶开战可用；未用不进入CD；实际使用后重开完整CD | AH17: 同款幅度不叠加；不同款可并存；不免疫状态／控制，不减持续跳伤 | AI17: t01.asset.0106.effect.01
A18: t01.asset.0107 | B18: 辟寒丹 | C18: 凡品 | D18: NONE | E18: 元素减伤 | F18: 1 | G18: 1 | H18: =F18*G18 -> 1 | I18: 22.5 | J18: 0 | K18: 0 | L18: 0 | N18: 1 | O18: =J18*N18 -> 0 | P18: =K18*N18 -> 0 | Q18: =L18*N18 -> 0 | R18: 0 | S18: 1 | T18: 份 | U18: 使用当刻 | V18: 持续12秒，合格直接攻击的水伤分量－10%；同基础百分比加算 | W18: 01时序／恢复；02状态／S3；04丹药 | Y18: 候选数值，未试跑 | Z18: 本次Q01用户补充丹药完整表；用户首瓶机制修正 | AA18: P07 | AD18: 水 | AE18: 0.1 | AF18: 12 | AG18: 首瓶开战可用；未用不进入CD；实际使用后重开完整CD | AH18: 同款幅度不叠加；不同款可并存；不免疫状态／控制，不减持续跳伤 | AI18: t01.asset.0107.effect.01
A19: t01.asset.0108 | B19: 辟金丹 | C19: 凡品 | D19: NONE | E19: 元素减伤 | F19: 1 | G19: 1 | H19: =F19*G19 -> 1 | I19: 22.5 | J19: 0 | K19: 0 | L19: 0 | N19: 1 | O19: =J19*N19 -> 0 | P19: =K19*N19 -> 0 | Q19: =L19*N19 -> 0 | R19: 0 | S19: 1 | T19: 份 | U19: 使用当刻 | V19: 持续12秒，合格直接攻击的金伤分量－10%；同基础百分比加算 | W19: 01时序／恢复；02状态／S3；04丹药 | Y19: 候选数值，未试跑 | Z19: 本次Q01用户补充丹药完整表；用户首瓶机制修正 | AA19: P08 | AD19: 金 | AE19: 0.1 | AF19: 12 | AG19: 首瓶开战可用；未用不进入CD；实际使用后重开完整CD | AH19: 同款幅度不叠加；不同款可并存；不免疫状态／控制，不减持续跳伤 | AI19: t01.asset.0108.effect.01
A20: t01.asset.0109 | B20: 御木丹 | C20: 凡品 | D20: NONE | E20: 元素减伤 | F20: 1 | G20: 1 | H20: =F20*G20 -> 1 | I20: 22.5 | J20: 0 | K20: 0 | L20: 0 | N20: 1 | O20: =J20*N20 -> 0 | P20: =K20*N20 -> 0 | Q20: =L20*N20 -> 0 | R20: 0 | S20: 1 | T20: 份 | U20: 使用当刻 | V20: 持续12秒，合格直接攻击的木伤分量－10%；同基础百分比加算 | W20: 01时序／恢复；02状态／S3；04丹药 | Y20: 候选数值，未试跑 | Z20: 本次Q01用户补充丹药完整表；用户首瓶机制修正 | AA20: P09 | AD20: 木 | AE20: 0.1 | AF20: 12 | AG20: 首瓶开战可用；未用不进入CD；实际使用后重开完整CD | AH20: 同款幅度不叠加；不同款可并存；不免疫状态／控制，不减持续跳伤 | AI20: t01.asset.0109.effect.01
A21: t01.asset.0110 | B21: 镇土丹 | C21: 凡品 | D21: NONE | E21: 元素减伤 | F21: 1 | G21: 1 | H21: =F21*G21 -> 1 | I21: 22.5 | J21: 0 | K21: 0 | L21: 0 | N21: 1 | O21: =J21*N21 -> 0 | P21: =K21*N21 -> 0 | Q21: =L21*N21 -> 0 | R21: 0 | S21: 1 | T21: 份 | U21: 使用当刻 | V21: 持续12秒，合格直接攻击的土伤分量－10%；同基础百分比加算 | W21: 01时序／恢复；02状态／S3；04丹药 | Y21: 候选数值，未试跑 | Z21: 本次Q01用户补充丹药完整表；用户首瓶机制修正 | AA21: P10 | AD21: 土 | AE21: 0.1 | AF21: 12 | AG21: 首瓶开战可用；未用不进入CD；实际使用后重开完整CD | AH21: 同款幅度不叠加；不同款可并存；不免疫状态／控制，不减持续跳伤 | AI21: t01.asset.0110.effect.01

Sheet 06_符箓
A1: t01-08｜符箓
A2: 2026-09-28 · 27下品＋88凡品＝115件 · 候选数值／当前规则／游戏实现分列 · 不含平衡测试结论
A5: 资产ID | B5: 名称 | C5: 品级 | D5: 元素 | E5: 规格 | F5: 宽_格 | G5: 高_格 | H5: 效果 | I5: CD_秒 | J5: 数量消耗 | K5: 机制引用 | L5: 设计状态 | M5: 来源

Sheet 07_暗器
A1: t01-08｜暗器
A2: 2026-09-28 · 27下品＋88凡品＝115件 · 候选数值／当前规则／游戏实现分列 · 不含平衡测试结论
A5: 资产ID | B5: 名称 | C5: 品级 | D5: 元素 | E5: 规格 | F5: 宽_格 | G5: 高_格 | H5: 效果 | I5: CD_秒 | J5: 数量消耗 | K5: 机制引用 | L5: 设计状态 | M5: 来源 | N5: 来源编号 | O5: 攻击类型 | P5: 基础伤害 | Q5: 体力费 | R5: 灵力费 | S5: 状态 | T5: 层数 | U5: 状态门槛 | V5: 效果引用
A6: t01.asset.0111 | B6: 飞针 | C6: 凡品 | D6: NONE | E6: 1×1，数量消耗；非武器来源 | F6: 1 | G6: 1 | H6: 无 | I6: 6 | J6: 1 | K6: 01伤害；02状态；04暗器 | L6: 候选数值，未试跑 | M6: 第1批基础；第2批微调；第3批复查；用户直接更正优先 | N6: H01 | O6: 穿刺 | P6: 18 | Q6: 0 | R6: 0 | U6: 无 | V6: t01.asset.0111.effect.01
A7: t01.asset.0112 | B7: 柳叶镖 | C7: 凡品 | D7: NONE | E7: 1×1，数量消耗；非武器来源 | F7: 1 | G7: 1 | H7: 无 | I7: 8.5 | J7: 1 | K7: 01伤害；02状态；04暗器 | L7: 候选数值，未试跑 | M7: 第1批基础；第2批微调；第3批复查；用户直接更正优先 | N7: H02 | O7: 斩击 | P7: 26 | Q7: 0 | R7: 0 | U7: 无 | V7: t01.asset.0112.effect.01
A8: t01.asset.0113 | B8: 铁丸 | C8: 凡品 | D8: NONE | E8: 1×1，数量消耗；非武器来源 | F8: 1 | G8: 1 | H8: 无 | I8: 9.5 | J8: 1 | K8: 01伤害；02状态；04暗器 | L8: 候选数值，未试跑 | M8: 第1批基础；第2批微调；第3批复查；用户直接更正优先 | N8: H03 | O8: 钝击 | P8: 32 | Q8: 0 | R8: 0 | U8: 无 | V8: t01.asset.0113.effect.01
A9: t01.asset.0114 | B9: 毒针 | C9: 凡品 | D9: NONE | E9: 1×1，数量消耗；非武器来源 | F9: 1 | G9: 1 | H9: 命中毒蚀＋3 | I9: 7.5 | J9: 1 | K9: 01伤害；02状态；04暗器 | L9: 候选数值，未试跑 | M9: 第1批基础；第2批微调；第3批复查；用户直接更正优先 | N9: H04 | O9: 穿刺 | P9: 12 | Q9: 0 | R9: 0 | S9: 毒蚀 | T9: 3 | U9: 命中 | V9: t01.asset.0114.effect.01；t01.asset.0114.effect.02
A10: t01.asset.0115 | B10: 火砂 | C10: 凡品 | D10: 火 | E10: 1×1，数量消耗；非武器来源 | F10: 1 | G10: 1 | H10: 无 | I10: 9 | J10: 1 | K10: 01伤害；02状态；04暗器 | L10: 候选数值，未试跑 | M10: 第1批基础；第2批微调；第3批复查；用户直接更正优先 | N10: H05 | O10: 法术型 | P10: 30 | Q10: 0 | R10: 0 | U10: 无 | V10: t01.asset.0115.effect.01

Sheet 08_数量统计
A1: t01-08｜数量统计
A2: 2026-09-28 · 27下品＋88凡品＝115件 · 候选数值／当前规则／游戏实现分列 · 不含平衡测试结论
A5: 类别 | B5: 下品 | C5: 凡品 | D5: 良品 | E5: 上品 | F5: 灵品 | G5: 玄品 | H5: 仙品 | I5: 合计
A6: 武器 | B6: =COUNTIF(T08Weapon[品级],B$5) -> 9 | C6: =COUNTIF(T08Weapon[品级],C$5) -> 27 | D6: =COUNTIF(T08Weapon[品级],D$5) -> 0 | E6: =COUNTIF(T08Weapon[品级],E$5) -> 0 | F6: =COUNTIF(T08Weapon[品级],F$5) -> 0 | G6: =COUNTIF(T08Weapon[品级],G$5) -> 0 | H6: =COUNTIF(T08Weapon[品级],H$5) -> 0 | I6: =SUM(B6:H6) -> 36
