Workbook

Sheet 00_使用说明
A1: T01-04 | 使用说明
A2: 新版两批＋第3份审查合编 · 2026-09-26 | 类型／元素／来源分开；候选与未决不当定案
A3: 返回说明 | B3: 37条记录 | 表头可筛选 | R3审查优先，原始行号L可回查14表
A5: 记录ID | B5: 分类 | C5: 规格／主题 | D5: 现行内容 | E5: 边界／不应推导 | F5: 记录性质 | G5: 依据
A6: 00-001 | B6: 使用原则 | C6: 职责 | D6: 定义器具类别、固有规格及角色装备派生状态。 | E6: 机制引用01，状态控制引用02，品级权限引用03；不编造材料、配方。 | F6: 编制说明 | G6: B1§一 L21–40；B2§四十四 L1155–1176；B2§四十五 L1177–1202；B2§四十六 L1203–1232
A7: 00-002 | B7: 使用原则 | C7: 资料优先级 | D7: 仅本次新版两批进入正文；第3份审查覆盖两批冲突。 | E7: 此前撤销的旧04两批不作为汇总正文。 | F7: 编制说明 | G7: B1§一 L21–40；R3§一 L9–55
A8: 00-003 | B8: 使用原则 | C8: 记录性质 | D8: 区分材料记载已确认、审查澄清、字段建议、候选、待专项与历史。 | E8: 本文不是生产数据；英文名与ID是设计标识，不代表现有程序接口。 | F8: 编制说明 | G8: R3§十七 L527–558
A9: 00-004 | B9: 使用原则 | C9: 类别／类型／元素／来源 | D9: 类别是物品身份，攻击类型是甲型交互，元素是元素体系，来源与行为按01分层。 | E9: SPELL不等于功法法术；反击不是与武器／防具互斥的来源类别。 | F9: 编制说明 | G9: B1§五 L110–165；R3§四 L122–156
A10: 00-005 | B10: 使用原则 | C10: 四种攻击类型 | D10: 斩击、穿刺、钝击、法术型；同一个参与甲型判定的独立伤害包至多一种。 | E10: NONE是不适用标识，不是第五攻击类型；状态跳伤不机械套SPELL。 | F10: 材料记载已确认＋审查边界 | G10: B1§三 L56–83；R3§七 L214–243
A11: 00-006 | B11: 使用原则 | C11: 三个计数不要混用 | D11: 发动次数、命中判定、伤害包数量和消耗数量分别记录。 | E11: 多包、多元素、多件消耗或动画多段均不自动增加攻击事件。 | F11: 编制说明 | G11: R3§五 L157–186
A12: 00-007 | B12: 使用原则 | C12: 单值限制的范围 | D12: 单件防具当前元素和角色主身甲元素均单值；攻击元素可保留已许可的多元素。 | E12: 多元素须有真实分量；不能复制同一份完整基础伤害。 | F12: 编制说明 | G12: R3§六 L187–213
A13: 00-008 | B13: 使用原则 | C13: 固定占格 | D13: Width为列、Height为行；所有器具摆盘与战斗中不可旋转。 | E13: 不设武器射程与耐久；阵盘邻接、同行、距离范围保留。 | F13: 材料记载已确认 | G13: B1§十一 L280–304；B1§十二 L305–326；B1§十三 L327–344；R3§十六 L498–526
A14: 00-009 | B14: 使用原则 | C14: 消耗与承载 | D14: 消耗品也可在阵盘占格、等待CD并受控；使用环境与入口分别记录。 | E14: 不由类别新增快捷栏、免占格或从储物袋随时发动。 | F14: 编制说明 | G14: R3§一 L9–55
A15: 00-010 | B15: 使用原则 | C15: 参数唯一来源 | D15: 全局模板管判定；具体动作／效果管伤害、费用和节奏；运行记录当前值。 | E15: 类别表仅引用；不在武器表、动作表、攻击模板重复保存同一数值。 | F15: 编制说明 | G15: R3§十七 L527–558
A16: 00-011 | B16: 使用原则 | C16: 持久与战斗 | D16: 定义、持久个体、库存数量、战斗运行四个概念层。 | E16: 成长进度不随战后清理；普通药品无需强制建立复杂个体档案。 | F16: 编制说明 | G16: R3§九 L266–300
... A42: 00-037 | B42: 分表导航 | C42: 15_审查修正与覆盖 | D42: 点击分表名称打开。 | E42: 资料出处可点击跳到14表；案例与原文不等于游戏测试结果。 | F42: 导航 | G42: 本次编制

Sheet 01_公共字段
A1: T01-04 | 公共字段
A2: 新版两批＋第3份审查合编 · 2026-09-26 | 类型／元素／来源分开；候选与未决不当定案
A3: 返回说明 | B3: 60条记录 | 表头可筛选 | R3审查优先，原始行号L可回查14表
A5: 字段ID | B5: 字段设计名 | C5: 权威归属层 | D5: 类型／值域 | E5: 职责与权威数据位置 | F5: 约束／不应推导 | G5: 记录性质 | H5: 依据
A6: F001 | B6: Item_ID | C6: 物品定义 | D6: 稳定标识 | E6: 物品定义是身份唯一来源；动作／库存／实例引用。 | F6: 本表英文名是设计标识，需映射现有命名空间ID。 | G6: 字段建议 | H6: R3§十七 L527–558
A7: F002 | B7: Display_Name | C7: 物品定义 | D7: 文本 | E7: 仅为显示和内容命名。 | F7: 名称不自动授予元素、反击、回血或必中。 | G7: 字段建议 | H7: B2§四十三 L1137–1154
A8: F003 | B8: Item_Category | C8: 物品定义 | D8: 六类枚举 | E8: 采用六种器具类别。 | F8: 阵盘本体不纳入；类别不决定攻击类型与战斗入口。 | G8: 字段建议 | H8: B1§二 L41–55；R3§一 L9–55
A9: F004 | B9: Grade | C9: 物品定义 | D9: 七品级 | E9: 引用t01-03权限与使用门槛。 | F9: 高品级不自动获得所有能力；仙品另有成长档案。 | G9: 字段建议 | H9: B2§四十四 L1155–1176
A10: F005 | B10: Width／Height | C10: 物品定义 | D10: 正整数：列／行 | E10: Width×Height为固定外包尺寸。普通矩形默认全部占据；经明确批准的Mask器具以规格中的实际占据格集合决定碰撞、邻接与占格数。入阵检查引用同一规格。 | F10: 阵盘承载必填W/H；无Mask按完整矩形兼容。可选Occupied_Cell_Mask为配套设计规格；当前固定非连续形态仅授权风雷翅候选（6×2外包／8实占格）。仍不可旋转；部分翼不是独立2×2器具。 | G10: 字段建议 | H10: B1§十一 L280–304；R3§一 L9–55 t01-06第3份审查R3-B；2026-09-27；详见06第10／14表
A11: F006 | B11: Can_Rotate | C11: 全局规格 | D11: False | E11: 全局禁止旋转，不逐物品重复配置。 | F11: 横向与纵向需不同规格定义；高品级不默认豁免。 | G11: 材料记载已确认 | H11: B1§四十八 L1131–1152
A12: F007 | B12: Allowed_Environments | C12: 物品定义 | D12: 明确环境集合 | E12: 列出战斗、修炼、探索等实际允许环境。 | F12: 可多个，不使用笼统MULTI_CONTEXT；不代替M03资格。 | G12: 字段建议 | H12: R3§一 L9–55
A13: F008 | B13: Use_Entry_Refs | C13: 物品定义 | D13: 已确认入口引用集合 | E13: 区分阵盘承载与非战斗直接使用等已确认入口。 | F13: 不新增免占格快捷栏；BATTLE_CONSUMABLE不再混作环境枚举。 | G13: 字段建议 | H13: R3§一 L9–55
A14: F009 | B14: Consumption_Model | C14: 动作／成本引用 | D14: 实体数量／内部次数／其他资源 | E14: 由实际成本组规定；类别只给常见方向。 | F14: 会被消耗不代表不占格。 | G14: 字段建议 | H14: R3§一 L9–55
A15: F010 | B15: Unique_Rule_Ref | C15: 物品定义 | D15: 规则引用／不适用 | E15: 若存在唯一性限制，引用明确规则。 | F15: 不因仙品名自动认定永远唯一。 | G15: 字段建议 | H15: B2§四十七 L1233–1293
A16: F011 | B16: Growth_Scheme_Ref | C16: 物品定义 | D16: 成长方案引用 | E16: 仙品等有成长器具引用成长档案。 | F16: 成长材料、阶段与解锁条件未定则显式待定。 | G16: 字段建议 | H16: B2§四十九 L1324–1355；R3§九 L266–300
... A65: F060 | B65: Field_Value_State | C65: 字段元数据 | D65: 已定值／待定／不适用／推导／运行时 | E65: 明确区分零值、未决与无适用对象。 | F65: 空白不能冒充0；本表必填字段若未定仍标待定并阻止正式投产。 | G65: 字段建议 | H65: R3§十七 L527–558

Sheet 02_攻击与防御规格
A1: T01-04 | 攻击与防御规格
A2: 新版两批＋第3份审查合编 · 2026-09-26 | 类型／元素／来源分开；候选与未决不当定案
A3: 返回说明 | B3: 32条记录 | 表头可筛选 | R3审查优先，原始行号L可回查14表
A5: 规格ID | B5: 分组 | C5: 对象／规格项 | D5: 值／规则引用 | E5: 单位／值类别 | F5: 作用与现行说明 | G5: 边界／不应推导 | H5: 记录性质 | I5: 依据
A6: AT001 | B6: 攻击类型 | C6: 斩击 | D6: SLASH | E6: 设计枚举 | F6: 每个适用伤害包只取一个攻击类型。 | G6: 类型也可供明确条件读取；不决定来源／命中／普通暴击／共鸣。 | H6: 材料记载已确认 | I6: B1§三 L56–83；R3§八 L244–265
A7: AT002 | B7: 攻击类型 | C7: 穿刺 | D7: PIERCE | E7: 设计枚举 | F7: 每个适用伤害包只取一个攻击类型。 | G7: 类型也可供明确条件读取；不决定来源／命中／普通暴击／共鸣。 | H7: 材料记载已确认 | I7: B1§三 L56–83；R3§八 L244–265
A8: AT003 | B8: 攻击类型 | C8: 钝击 | D8: BLUNT | E8: 设计枚举 | F8: 每个适用伤害包只取一个攻击类型。 | G8: 类型也可供明确条件读取；不决定来源／命中／普通暴击／共鸣。 | H8: 材料记载已确认 | I8: B1§三 L56–83；R3§八 L244–265
A9: AT004 | B9: 攻击类型 | C9: 法术型 | D9: SPELL | E9: 设计枚举 | F9: 每个适用伤害包只取一个攻击类型。 | G9: 类型也可供明确条件读取；不决定来源／命中／普通暴击／共鸣。 | H9: 材料记载已确认 | I9: B1§三 L56–83；R3§八 L244–265
A10: AT005 | B10: 法术型效率 | C10: 无甲 | D10: 1.1 | E10: 效率 | F10: 仅SPELL行的新甲型修正值。 | G10: 按既有修正组合方式应用一次；不新设与其他加成连乘的乘区。 | H10: 材料记载已确认 | I10: B1§七 L196–213；R3§十五 L475–497
A11: AT006 | B11: 法术型效率 | C11: 轻甲 | D11: 1 | E11: 效率 | F11: 仅SPELL行的新甲型修正值。 | G11: 按既有修正组合方式应用一次；不新设与其他加成连乘的乘区。 | H11: 材料记载已确认 | I11: B1§七 L196–213；R3§十五 L475–497
A12: AT007 | B12: 法术型效率 | C12: 重甲 | D12: 1 | E12: 效率 | F12: 仅SPELL行的新甲型修正值。 | G12: 按既有修正组合方式应用一次；不新设与其他加成连乘的乘区。 | H12: 材料记载已确认 | I12: B1§七 L196–213；R3§十五 L475–497
A13: AT008 | B13: 法术型效率 | C13: 灵甲 | D13: 0.9 | E13: 效率 | F13: 仅SPELL行的新甲型修正值。 | G13: 按既有修正组合方式应用一次；不新设与其他加成连乘的乘区。 | H13: 材料记载已确认 | I13: B1§七 L196–213；R3§十五 L475–497
A14: AT009 | B14: 物理矩阵 | C14: 斩／刺／钝 | D14: 引用既有战斗矩阵 | E14: 外部规则 | F14: 原三类甲型效率保留。 | G14: 不采纳旧提案物理对灵甲115%或法术对灵甲85%。 | H14: 材料记载已确认 | I14: B1§八 L214–229；R3§十五 L475–497
A15: AT010 | B15: 元素值域 | C15: 无属性 | D15: NONE | E15: 设计枚举 | F15: 用于防具单元素或攻击的具体元素分量。 | G15: 攻击多元素需声明分配；物品检索标签不等于伤害量。 | H15: 材料记载已确认 | I15: B1§九 L230–259；R3§六 L187–213
A16: AT011 | B16: 元素值域 | C16: 金 | D16: METAL | E16: 设计枚举 | F16: 用于防具单元素或攻击的具体元素分量。 | G16: 攻击多元素需声明分配；物品检索标签不等于伤害量。 | H16: 材料记载已确认 | I16: B1§九 L230–259；R3§六 L187–213
A17: AT012 | B17: 元素值域 | C17: 木 | D17: WOOD | E17: 设计枚举 | F17: 用于防具单元素或攻击的具体元素分量。 | G17: 攻击多元素需声明分配；物品检索标签不等于伤害量。 | H17: 材料记载已确认 | I17: B1§九 L230–259；R3§六 L187–213
A18: AT013 | B18: 元素值域 | C18: 水 | D18: WATER | E18: 设计枚举 | F18: 用于防具单元素或攻击的具体元素分量。 | G18: 攻击多元素需声明分配；物品检索标签不等于伤害量。 | H18: 材料记载已确认 | I18: B1§九 L230–259；R3§六 L187–213
A19: AT014 | B19: 元素值域 | C19: 火 | D19: FIRE | E19: 设计枚举 | F19: 用于防具单元素或攻击的具体元素分量。 | G19: 攻击多元素需声明分配；物品检索标签不等于伤害量。 | H19: 材料记载已确认 | I19: B1§九 L230–259；R3§六 L187–213
A20: AT015 | B20: 元素值域 | C20: 土 | D20: EARTH | E20: 设计枚举 | F20: 用于防具单元素或攻击的具体元素分量。 | G20: 攻击多元素需声明分配；物品检索标签不等于伤害量。 | H20: 材料记载已确认 | I20: B1§九 L230–259；R3§六 L187–213
A21: AT016 | B21: 元素值域 | C21: 风 | D21: WIND | E21: 设计枚举 | F21: 用于防具单元素或攻击的具体元素分量。 | G21: 攻击多元素需声明分配；物品检索标签不等于伤害量。 | H21: 材料记载已确认 | I21: B1§九 L230–259；R3§六 L187–213
A22: AT017 | B22: 元素值域 | C22: 雷 | D22: THUNDER | E22: 设计枚举 | F22: 用于防具单元素或攻击的具体元素分量。 | G22: 攻击多元素需声明分配；物品检索标签不等于伤害量。 | H22: 材料记载已确认 | I22: B1§九 L230–259；R3§六 L187–213
A23: AT018 | B23: 防具甲型 | C23: 轻甲 | D23: LIGHT | E23: 设计枚举 | F23: 单件防具必须具有三者之一。 | G23: 角色主甲型另可为NONE；单件防具不能填无甲。 | H23: 材料记载已确认 | I23: B1§二十七 L640–668
A24: AT019 | B24: 防具甲型 | C24: 重甲 | D24: HEAVY | E24: 设计枚举 | F24: 单件防具必须具有三者之一。 | G24: 角色主甲型另可为NONE；单件防具不能填无甲。 | H24: 材料记载已确认 | I24: B1§二十七 L640–668
A25: AT020 | B25: 防具甲型 | C25: 灵甲 | D25: SPIRIT | E25: 设计枚举 | F25: 单件防具必须具有三者之一。 | G25: 角色主甲型另可为NONE；单件防具不能填无甲。 | H25: 材料记载已确认 | I25: B1§二十七 L640–668
... A37: AT032 | B37: 结构与资格 | C37: 控制目标 | D37: 按来源与Scope | E37: 引用／字段 | F37: 禁用针对道具；沉默针对法术。 | G37: SPELL型符箓或法器不自动进入沉默范围；仍按道具控制资格。 | H37: 审查澄清 | I37: R3§十六 L498–526

Sheet 03_武器规格
A1: T01-04 | 武器规格
A2: 新版两批＋第3份审查合编 · 2026-09-26 | 类型／元素／来源分开；候选与未决不当定案
A3: 返回说明 | B3: 17条记录 | 表头可筛选 | R3审查优先，原始行号L可回查14表
A5: 记录ID | B5: 分类 | C5: 规格／主题 | D5: 现行内容 | E5: 边界／不应推导 | F5: 记录性质 | G5: 依据
A6: 03-001 | B6: 九种器型 | C6: DAGGER｜短刃／匕首 | D6: 基础攻击类型固定为PIERCE；类别WEAPON。 | E6: 由器型派生，不逐物品自由改变；特殊效果独立声明。 | F6: 材料记载已确认 | G6: B1§十五 L377–400；B1§十六 L401–425
A7: 03-002 | B7: 九种器型 | C7: SWORD｜剑 | D7: 基础攻击类型固定为SLASH；类别WEAPON。 | E7: 由器型派生，不逐物品自由改变；特殊效果独立声明。 | F7: 材料记载已确认 | G7: B1§十五 L377–400；B1§十六 L401–425
A8: 03-003 | B8: 九种器型 | C8: SABER｜刀 | D8: 基础攻击类型固定为SLASH；类别WEAPON。 | E8: 由器型派生，不逐物品自由改变；特殊效果独立声明。 | F8: 材料记载已确认 | G8: B1§十五 L377–400；B1§十六 L401–425
A9: 03-004 | B9: 九种器型 | C9: SPEAR｜枪／矛 | D9: 基础攻击类型固定为PIERCE；类别WEAPON。 | E9: 由器型派生，不逐物品自由改变；特殊效果独立声明。 | F9: 材料记载已确认 | G9: B1§十五 L377–400；B1§十六 L401–425
A10: 03-005 | B10: 九种器型 | C10: BOW｜弓 | D10: 基础攻击类型固定为PIERCE；类别WEAPON。 | E10: 由器型派生，不逐物品自由改变；特殊效果独立声明。 | F10: 材料记载已确认 | G10: B1§十五 L377–400；B1§十六 L401–425
A11: 03-006 | B11: 九种器型 | C11: AXE｜斧 | D11: 基础攻击类型固定为SLASH；类别WEAPON。 | E11: 由器型派生，不逐物品自由改变；特殊效果独立声明。 | F11: 材料记载已确认 | G11: B1§十五 L377–400；B1§十六 L401–425
A12: 03-007 | B12: 九种器型 | C12: HAMMER｜锤 | D12: 基础攻击类型固定为BLUNT；类别WEAPON。 | E12: 由器型派生，不逐物品自由改变；特殊效果独立声明。 | F12: 材料记载已确认 | G12: B1§十五 L377–400；B1§十六 L401–425
A13: 03-008 | B13: 九种器型 | C13: WHIP｜鞭 | D13: 基础攻击类型固定为BLUNT；类别WEAPON。 | E13: 由器型派生，不逐物品自由改变；特殊效果独立声明。 | F13: 材料记载已确认 | G13: B1§十五 L377–400；B1§十六 L401–425
A14: 03-009 | B14: 九种器型 | C14: SEAL｜印 | D14: 基础攻击类型固定为BLUNT；类别WEAPON。 | E14: 由器型派生，不逐物品自由改变；特殊效果独立声明。 | F14: 材料记载已确认 | G14: B1§十五 L377–400；B1§十六 L401–425
A15: 03-010 | B15: 规格规则 | C15: 撤销旧器型 | D15: 弩、棍、索不再是基础武器器型。 | E15: 迁移旧提及时列清单，不自动把旧资产改名或新增补偿。 | F15: 审查合并基线 | G15: B1§十五 L377–400
A16: 03-011 | B16: 规格规则 | C16: 基础动作 | D16: 普通武器基础动作是武器攻击。 | E16: 动画三段、伤害多包和消耗多件不等于多次发动；按动作结构定义。 | F16: 审查合并基线 | G16: B1§十八 L446–465；R3§五 L157–186
... A22: 03-017 | B22: 规格规则 | C22: 印的身份 | D22: 武器印：WEAPON＋SEAL＋BLUNT；外形像印的法器仍是ARTIFACT。 | E22: 名称与美术形状不自动决定类别。 | F22: 审查合并基线 | G22: B2§九 L236–281

Sheet 04_防具规格
A1: T01-04 | 防具规格
A2: 新版两批＋第3份审查合编 · 2026-09-26 | 类型／元素／来源分开；候选与未决不当定案
A3: 返回说明 | B3: 26条记录 | 表头可筛选 | R3审查优先，原始行号L可回查14表
A5: 记录ID | B5: 分类 | C5: 规格／主题 | D5: 现行内容 | E5: 边界／不应推导 | F5: 记录性质 | G5: 依据
A6: 04-001 | B6: 防具形态 | C6: BODY_ARMOR｜身甲 | D6: 身甲形态含衣、甲、袍等；类别ARMOR。形态按05补充收束为身甲／头具／护具／盾。 | E6: 身甲最多1件；仍摆阵盘，不新增固定装备槽；甲型每实际格权重2、元素每格1票。 | F6: 用户确认t01-08 Q03；其他既有规则保持 | G6: B1§二十三 L552–569；t01-05新版B1§三十（2026-09-27四形态补充）；t01-08 Q03，2026-09-28
A7: 04-002 | B7: 防具形态 | C7: GUARD｜护具 | D7: 护具显示名可为护腕、护肩、护臂、护腿、腰甲等；类别ARMOR。头盔／冠按05补充归头具。 | E7: 护臂最多1件、护腿最多1件，二者分别计限可同时上阵；不把整个GUARD大类设为只能1件。其他护具部位随具体资产明配，仍占阵盘格。 | F7: 用户确认t01-08 Q03；其他既有规则保持 | G7: B1§二十三 L552–569；t01-05新版B1§三十（2026-09-27四形态补充）；t01-08 Q03，2026-09-28
A8: 04-003 | B8: 防具形态 | C8: SHIELD｜盾 | D8: 盾独立保留为防具形态；类别ARMOR。参与护甲、甲型与元素贡献；反击需明确Effect。 | E8: 允许多件盾同时上阵，只受阵盘空间限制；不套用同部位最多1件，不新增固定装备槽。 | F8: 用户确认t01-08 Q03；其他既有规则保持 | G8: B1§二十三 L552–569；t01-05新版B1§三十（2026-09-27四形态补充）；t01-08 Q03，2026-09-28
A9: 04-004 | B9: 聚合与生命周期 | C9: 盾身份与反击 | D9: 盾始终属于防具，参与护甲、甲型和元素贡献；可有明确反击Effect。 | E9: 反击非盾的自动固有能力；不能因可攻击改为武器。 | F9: 材料记载已确认＋审查澄清 | G9: B1§二十四 L570–588；B2§四十三 L1137–1154
A10: 04-005 | B10: 聚合与生命周期 | C10: 盾反击攻击类型 | D10: 盾的反击固定BLUNT；来源类别ARMOR，行为身份COUNTER。 | E10: 只约束盾反击；不强制所有防具反制钝击，不授予普通武器暴击。 | F10: 材料记载已确认＋审查澄清 | G10: B1§二十五 L589–607；R3§四 L122–156
A11: 04-006 | B11: 聚合与生命周期 | C11: 防御与攻击元素 | D11: 防具当前元素与反击攻击元素分别定义。 | E11: 火盾不自动火反击；反击可明确无属性或按Effect定义。 | F11: 材料记载已确认＋审查澄清 | G11: B1§二十六 L608–639
A12: 04-007 | B12: 聚合与生命周期 | C12: 单件甲型 | D12: 每件防具LIGHT／HEAVY／SPIRIT三选一。 | E12: NONE只用于角色无防具的派生状态。 | F12: 材料记载已确认＋审查澄清 | G12: B1§二十七 L640–668
A13: 04-008 | B13: 聚合与生命周期 | C13: 主甲型统计 | D13: 双方均按上阵防具实际占格加权：身甲每格2、其他防具每格1；同甲型权重累计，唯一最高成为主甲型。 | E13: 不是按件数或护甲贡献值投票；仅主甲型加权，防御元素仍按实际占格。 | F13: 用户确认：t01-08 Q02 | G13: B1§二十八 L669–694；B1§二十九 L695–728；t01-08 Q02用户确认，2026-09-28
A14: 04-009 | B14: 聚合与生命周期 | C14: 玩家甲型并列 | D14: 最高权重并列含身甲甲型时优先身甲；无身甲或并列最高不含身甲时，玩家从最高候选中指定。 | E14: 旧选择不在当前最高候选中时失效；身甲优先时不由玩家改选；无防具为NONE。 | F14: 用户确认：t01-08 Q02 | G14: B1§二十八 L669–694；R3§十二 L386–404；t01-08 Q02用户确认，2026-09-28
A15: 04-010 | B15: 聚合与生命周期 | C15: 敌方甲型并列 | D15: 最高权重并列含身甲甲型时优先身甲；否则按阵盘从上到下、每行从左到右扫描，首遇最高并列候选胜出。 | E15: 仅从最高权重并列甲型中决胜，跳过非候选、不随机；玩家仅在无身甲优先可用时手选。 | F15: 用户确认：t01-08 Q02 | G15: 2026-09-26逐项确认Q05／Q06；docs/sources/t01-04-器具类别与规格词典_逐项确认_2026-09-26.txt；t01-08 Q02用户确认，2026-09-28
A16: 04-011 | B16: 聚合与生命周期 | C16: 单件元素 | D16: 无属性或七系之一，同一时点单值。 | E16: 可变仙甲也只有一个当前贡献值，不同时取得多元素。 | F16: 材料记载已确认＋审查澄清 | G16: B1§三十 L729–751；B1§三十一 L752–775
... A32: 04-027 | B32: 防具形态 | C32: HEADGEAR｜头具 | D32: 头盔、冠等归头具；类别ARMOR。形态按05明确补为身甲／头具／护具／盾四类。 | E32: 头具最多1件，仍占阵盘格；甲型每格权重1、元素每格1票。HEADGEAR为设计字段，不宣称已实现。 | F32: 用户确认t01-08 Q03；其他既有规则保持 | G32: t01-05新版第1批§三十；核心01第1.11节；2026-09-27；t01-08 Q03，2026-09-28

Sheet 05_法器规格
A1: T01-04 | 法器规格
A2: 新版两批＋第3份审查合编 · 2026-09-26 | 类型／元素／来源分开；候选与未决不当定案
A3: 返回说明 | B3: 17条记录 | 表头可筛选 | R3审查优先，原始行号L可回查14表
A5: 记录ID | B5: 分类 | C5: 规格／主题 | D5: 现行内容 | E5: 边界／不应推导 | F5: 记录性质 | G5: 依据
A6: 05-001 | B6: 功能检索标签 | C6: ATTACK | D6: 主动攻击 | E6: 角色标签可多个，可选主要与次要；标签不授予能力或品级权限。 | F6: 字段建议 | G6: B2§八 L207–235
A7: 05-002 | B7: 功能检索标签 | C7: RECOVERY | D7: 气血／灵力／体力／护甲恢复 | E7: 角色标签可多个，可选主要与次要；标签不授予能力或品级权限。 | F7: 字段建议 | G7: B2§八 L207–235
A8: 05-003 | B8: 功能检索标签 | C8: DEFENSE | D8: 护盾、防护、减伤 | E8: 角色标签可多个，可选主要与次要；标签不授予能力或品级权限。 | F8: 字段建议 | G8: B2§八 L207–235
A9: 05-004 | B9: 功能检索标签 | C9: STATUS | D9: 状态生成、兑现、转换 | E9: 角色标签可多个，可选主要与次要；标签不授予能力或品级权限。 | F9: 字段建议 | G9: B2§八 L207–235
A10: 05-005 | B10: 功能检索标签 | C10: CONTROL | D10: CD、控制和运行干预 | E10: 角色标签可多个，可选主要与次要；标签不授予能力或品级权限。 | F10: 字段建议 | G10: B2§八 L207–235
A11: 05-006 | B11: 功能检索标签 | C11: FIELD | D11: 领域、邻接和阵位 | E11: 角色标签可多个，可选主要与次要；标签不授予能力或品级权限。 | F11: 字段建议 | G11: B2§八 L207–235
A12: 05-007 | B12: 功能检索标签 | C12: SUPPORT | D12: 命中、闪避和资源辅助 | E12: 角色标签可多个，可选主要与次要；标签不授予能力或品级权限。 | F12: 字段建议 | G12: B2§八 L207–235
A13: 05-008 | B13: 功能检索标签 | C13: TRAINING | D13: 修炼场景 | E13: 角色标签可多个，可选主要与次要；标签不授予能力或品级权限。 | F13: 字段建议 | G13: B2§八 L207–235
A14: 05-009 | B14: 功能检索标签 | C14: RULE_CORE | D14: 高品级规则核心 | E14: 角色标签可多个，可选主要与次要；标签不授予能力或品级权限。 | F14: 字段建议 | G14: B2§八 L207–235
A15: 05-010 | B15: 规格规则 | C15: 外观形制 | D15: 镜、珠、炉、钟、旗、塔、印等用Visual_Form或美术标签。 | E15: 不作为强制互斥系统子类；印字不决定武器或法器类别。 | F15: 审查合并基线 | G15: B2§九 L236–281
A16: 05-011 | B16: 规格规则 | C16: 运行方式可组合 | D16: 可有轮转动作、事件监听、常驻修正、静态领域、维持等。 | E16: 逐能力引用M01；常驻不等于监听、领域不等于持续支付；不能做互斥三选一。 | F16: 审查合并基线 | G16: B2§十 L282–337；R3§十三 L405–438
... A24: 05-019 | B24: 仙品候选 | C24: 风雷翅运行引用 | D24: CD目标单独持续覆盖时用时2/3，大耗灵方向；引用01 H03、M07/M08及02控制。 | E24: 模式、覆盖、费用和控制恢复模板待06专项；规格存在不等于正式可运行资产。 | F24: 候选／待专项 | G24: t01-06第3份审查R3-B；2026-09-27；详见06第10／14表

Sheet 06_消耗品规格
A1: T01-04 | 消耗品规格
A2: 新版两批＋第3份审查合编 · 2026-09-26 | 类型／元素／来源分开；候选与未决不当定案
A3: 返回说明 | B3: 14条记录 | 表头可筛选 | R3审查优先，原始行号L可回查14表
A5: 记录ID | B5: 分类 | C5: 规格／主题 | D5: 现行内容 | E5: 边界／不应推导 | F5: 记录性质 | G5: 依据
A6: 06-001 | B6: 消耗品共用 | C6: 战斗承载 | D6: 依已确认入口选择阵盘等承载方式，和数量消耗正交。 | E6: 阵盘消耗品仍有尺寸、位置、实例、CD与控制；不自动提供快捷栏。 | F6: 审查澄清 | G6: R3§一 L9–55
A7: 06-002 | B7: 消耗品共用 | C7: 使用环境 | D7: 允许环境为明确集合，如战斗、修炼、探索等。 | E7: MULTI_CONTEXT不用作独立值；环境不代替入口和M03条件。 | F7: 字段建议 | G7: R3§一 L9–55
A8: 06-003 | B8: 消耗品共用 | C8: 数量账本 | D8: 库存总数量、本场可用数量、本次成本分别记录。 | E8: 模板不保存Quantity_Current；库存数量与每战使用限制分开。 | F8: 审查澄清 | G8: R3§二 L56–93；B2§五 L140–170
A9: 06-004 | B9: 消耗品共用 | C9: 运行实例 | D9: 同一位置整叠符箓共用一条CD，每次发动按该符箓规则消耗数量；分叠上阵时每叠独立CD。 | E9: 增加同一叠数量不增加并行CD；运行实例拥有该叠CD与控制状态。 | F9: 用户确认Q02／Q03 | G9: R3§二；2026-09-26逐项确认Q01～Q04；docs/sources/t01-04-器具类别与规格词典_逐项确认_2026-09-26.txt
A10: 06-005 | B10: 消耗品共用 | C10: 上阵分配与分装 | D10: 玩家自选上阵数量，其余留储物袋；同款符箓可分成多叠，各自占位并独立计算CD。 | E10: 同一库存单位不能复制；分装不增加总量、未用完不可重复返还。 | F10: 用户确认Q01／Q03 | G10: R3§二；2026-09-26逐项确认Q01～Q04；docs/sources/t01-04-器具类别与规格词典_逐项确认_2026-09-26.txt
A11: 06-006 | B11: 消耗品共用 | C11: 耗尽处理 | D11: 上阵符箓数量耗尽后移除该叠，腾出原占位，不再提供邻接或类别效果。 | E11: 不保留空壳参与位置或类别判定；具体药物执行及已提交效果按各自规则。 | F11: 用户确认Q04 | G11: R3§二；2026-09-26逐项确认Q01～Q04；docs/sources/t01-04-器具类别与规格词典_逐项确认_2026-09-26.txt
A12: 06-007 | B12: 消耗品共用 | C12: 不自动补给 | D12: 数量耗尽不据此自动从仓库换上另一种物品。 | E12: 补给、替换须有明确规则；符箓耗尽移除不自动从储物袋补入。 | F12: 审查澄清 | G12: B2§六 L171–192；R3§二 L56–93
A13: 06-008 | B13: 消耗品共用 | C13: 成本提交 | D13: 在能力约定支付节点，整组检查后提交数量及其他成本。 | E13: 资格失败与发动后未命中／抵抗／吸收分开；不能先发成功事件再付费失败。 | F13: 引用t01-01 | G13: R3§三 L94–121
A14: 06-009 | B14: 消耗品共用 | C14: 已发动未命中 | D14: 合法发动且数量已提交，之后闪避不自动退款。 | E14: 退款必须有明确策略且关联支付记录；不按最终效果倒推未发动。 | F14: 审查澄清 | G14: R3§三 L94–121
A15: 06-010 | B15: 消耗品共用 | C15: 使用条件 | D15: 满血是否可回血、无负面是否可净化，应由具体使用条件控制。 | E15: 本词典不替所有药／符统一选择可用或不可用。 | F15: 待资产 | G15: R3§三 L94–121
A16: 06-011 | B16: 消耗品共用 | C16: 数量成本 | D16: 可有1件的常见用法，也可明确一次消耗3枚等。 | E16: 示例1不是所有消耗品不可变全局值；数量成本不等于发动次数。 | F16: 字段建议 | G16: B2§三十四 L929–944；R3§五 L157–186
... A19: 06-014 | B19: 消耗品共用 | C19: 物品个体 | D19: 成长阶段、已解锁形态保存于持久个体。 | E19: 战后只清相应运行值；不强制每颗普通药建立成长档案。 | F19: 审查澄清 | G19: R3§九 L266–300

Sheet 07_丹药规格
A1: T01-04 | 丹药规格
A2: 新版两批＋第3份审查合编 · 2026-09-26 | 类型／元素／来源分开；候选与未决不当定案
A3: 返回说明 | B3: 13条记录 | 表头可筛选 | R3审查优先，原始行号L可回查14表
A5: 记录ID | B5: 分类 | C5: 规格／主题 | D5: 现行内容 | E5: 边界／不应推导 | F5: 记录性质 | G5: 依据
A6: 07-001 | B6: 用途标签 | C6: RECOVERY | D6: 恢复 | E6: 可多个标签并选主要用途；具体效果与清除资格引用01／02。 | F6: 字段建议 | G6: B2§十八 L521–540
A7: 07-002 | B7: 用途标签 | C7: CURE | D7: 净化／解除指定负面 | E7: 可多个标签并选主要用途；具体效果与清除资格引用01／02。 | F7: 字段建议 | G7: B2§十八 L521–540
A8: 07-003 | B8: 用途标签 | C8: BUFF | D8: 临时强化 | E8: 可多个标签并选主要用途；具体效果与清除资格引用01／02。 | F8: 字段建议 | G8: B2§十八 L521–540
A9: 07-004 | B9: 用途标签 | C9: RESISTANCE | D9: 临时免疫／抵抗 | E9: 可多个标签并选主要用途；具体效果与清除资格引用01／02。 | F9: 字段建议 | G9: B2§十八 L521–540
A10: 07-005 | B10: 用途标签 | C10: CULTIVATION | D10: 修炼 | E10: 可多个标签并选主要用途；具体效果与清除资格引用01／02。 | F10: 字段建议 | G10: B2§十八 L521–540
A11: 07-006 | B11: 用途标签 | C11: RESET | D11: 重置／洗点 | E11: 可多个标签并选主要用途；具体效果与清除资格引用01／02。 | F11: 字段建议 | G11: B2§十八 L521–540
A12: 07-007 | B12: 用途标签 | C12: SPECIAL | D12: 剧情／特殊机制 | E12: 可多个标签并选主要用途；具体效果与清除资格引用01／02。 | F12: 字段建议 | G12: B2§十八 L521–540
A13: 07-008 | B13: 药效规格 | C13: 核心身份 | D13: 消耗药物单位，执行药效。 | E13: 可通过阵盘参加战斗；不能从“不是长期器物”推出不占格。 | F13: 审查合并基线 | G13: B2§十七 L509–520；R3§一 L9–55
A14: 07-009 | B14: 药效规格 | C14: 执行方式 | D14: 即时执行、创建持续实例或其他明确效果操作分别描述。 | E14: 与结果保存范围分开；即时操作也可能永久改变成长数据。 | F14: 审查合并基线 | G14: R3§十三 L405–438
A15: 07-010 | B15: 药效规格 | C15: 持续药效 | D15: 可创建明确S3效果或S2状态，生命周期引用M07。 | E15: 不统一假定跨战；清除单位及通道按02。 | F15: 审查合并基线 | G15: B2§十九 L541–583
A16: 07-011 | B16: 药效规格 | C16: 成长结果 | D16: 重置功法等可一次执行后修改成长数据。 | E16: 不是挂永久“重置Buff”；用途与资源成本须后续明确。 | F16: 审查合并基线 | G16: R3§十三 L405–438
... A18: 07-013 | B18: 药效规格 | C18: 最低规格 | D18: 用途、环境、入口、数量成本、动作／Effect引用及条件CD。 | E18: 库存数量、当前CD属运行／库存；阵盘使用仍需固定尺寸。 | F18: 审查合并基线 | G18: B2§二十二 L622–638；R3§一 L9–55

Sheet 08_符箓规格
A1: T01-04 | 符箓规格
A2: 新版两批＋第3份审查合编 · 2026-09-26 | 类型／元素／来源分开；候选与未决不当定案
A3: 返回说明 | B3: 8条记录 | 表头可筛选 | R3审查优先，原始行号L可回查14表
A5: 记录ID | B5: 分类 | C5: 规格／主题 | D5: 现行内容 | E5: 边界／不应推导 | F5: 记录性质 | G5: 依据
A6: 08-001 | B6: 符箓规格 | C6: 核心身份 | D6: 预制术式载体；消耗数量后执行封装效果。 | E6: 可上阵占格；符箓不是功法法术。 | F6: 审查合并基线 | G6: B2§二十三 L639–652；R3§一 L9–55
A7: 08-002 | B7: 符箓规格 | C7: 真实来源 | D7: Source_Category=TALISMAN。 | E7: 施展功法法术的监听默认不认符；SPELL类型监听须检查实际字段。 | F7: 审查合并基线 | G7: B2§二十四 L653–690
A8: 08-003 | B8: 符箓规格 | C8: 攻击类型 | D8: 逐符按实际攻击选择SLASH／PIERCE／BLUNT／SPELL之一。 | E8: 金针符可明确PIERCE，炎爆符可SPELL；不由美术强制类型。 | F8: 审查合并基线 | G8: B2§二十五 L691–733
A9: 08-004 | B9: 符箓规格 | C9: 纯辅助符 | D9: 净化、护盾、解控或剧情等可不创建攻击。 | E9: 没有攻击不强塞0伤包；若施加伤害状态则按状态通路。 | F9: 审查合并基线 | G9: B2§二十六 L734–753；R3§七 L214–243
A10: 08-005 | B10: 符箓规格 | C10: 命中模板 | D10: 攻击符引用明确命中或必中规则。 | E10: 既不默认所有符必中，也不自动给SPELL符95%。 | F10: 审查合并基线 | G10: B2§二十七 L754–785
A11: 08-006 | B11: 符箓规格 | C11: 区别法器 | D11: 符箓以消耗实体数量释放术式；法器通常重复运行而不消耗本体。 | E11: 相同火球效果不改变载体类别；二者都可能占阵盘。 | F11: 审查合并基线 | G11: B2§二十八 L786–812；R3§一 L9–55
A12: 08-007 | B12: 符箓规格 | C12: 控制衔接 | D12: 按道具身份与控制Scope处理禁用等。 | E12: 法术型符不因SPELL一概被沉默；不能扩大沉默对象。 | F12: 审查合并基线 | G12: R3§十六 L498–526
A13: 08-008 | B13: 符箓规格 | C13: 最低规格 | D13: 数量成本、环境／入口、使用动作与Effect；若攻击需类型／元素组成／命中引用。 | E13: 上阵数量由玩家选择；每叠共用CD，可分叠独立运行；耗尽移除腾位。具体CD时长及数量成本按资产填写。 | F13: 审查合并基线 | G13: R3§二；2026-09-26逐项确认Q01～Q04；docs/sources/t01-04-器具类别与规格词典_逐项确认_2026-09-26.txt

Sheet 09_暗器规格
A1: T01-04 | 暗器规格
A2: 新版两批＋第3份审查合编 · 2026-09-26 | 类型／元素／来源分开；候选与未决不当定案
A3: 返回说明 | B3: 7条记录 | 表头可筛选 | R3审查优先，原始行号L可回查14表
A5: 记录ID | B5: 分类 | C5: 规格／主题 | D5: 现行内容 | E5: 边界／不应推导 | F5: 记录性质 | G5: 依据
A6: 09-001 | B6: 暗器规格 | C6: 核心身份 | D6: 以消耗实体库存数量换取直接或短促战术攻击。 | E6: 与长期轮转武器的区别是载体与成本；也可先上阵占格。 | F6: 审查合并基线 | G6: B2§三十 L829–844；R3§一 L9–55
A7: 09-002 | B7: 暗器规格 | C7: 区别符箓 | D7: 实体飞针／飛刀／铁丸属暗器方向；预制金针术式载体属符箓。 | E7: 按实际载体认类别，不按伤害是否物理判断。 | F7: 审查合并基线 | G7: B2§三十一 L845–880
A8: 09-003 | B8: 暗器规格 | C8: 主体攻击类型 | D8: 逐暗器定义斩／刺／钝；飞针穿刺、铁丸钝击等是示例。 | E8: 特殊法术爆炸可有明确独立Effect包；不把全暗器默认法术化。 | F8: 审查合并基线 | G8: B2§三十二 L881–902
A9: 09-004 | B9: 暗器规格 | C9: 来源与暴击 | D9: Source_Category=HIDDEN_WEAPON，普通武器暴击不自动继承。 | E9: 某暗器允许暴击时须明确资格，不从PIERCE推武器身份。 | F9: 审查合并基线 | G9: B2§三十三 L903–928
A10: 09-005 | B10: 暗器规格 | C10: 数量与次数 | D10: 允许具体配置一次消耗1或3等单位。 | E10: 消耗3枚不等于3次发动／3次命中，动作结构须明确。 | F10: 审查合并基线 | G10: B2§三十四 L929–944；R3§五 L157–186
A11: 09-006 | B11: 暗器规格 | C11: 状态特效 | D11: 毒针命中施加状态等使用Effect。 | E11: 有毒不是新的器型，也不从毒针名字自动决定具体Debuff。 | F11: 审查合并基线 | G11: B2§三十五 L945–967
A12: 09-007 | B12: 暗器规格 | C12: 最低规格 | D12: 使用入口、环境、数量成本、攻击动作／伤害参数与判定引用，条件CD。 | E12: 不沿用混合BATTLE_CONSUMABLE枚举；阵盘入口需尺寸与位置。 | F12: 审查合并基线 | G12: B2§三十六 L968–983；R3§一 L9–55

Sheet 10_字段适用矩阵
A1: T01-04 | 字段适用矩阵
A2: 字段名称、权威归属与边界按字段ID引用01公共字段表；适用性按类填写，不新增生产参数。
A3: 返回说明 | B3: 60条记录 | 表头可筛选 | R3审查优先，原始行号L可回查14表
A5: 字段ID | B5: 字段设计名 | C5: 权威归属层 | D5: 武器 | E5: 防具 | F5: 法器 | G5: 丹药 | H5: 符箓 | I5: 暗器 | J5: 适用条件／填写边界 | K5: 依据
A6: F001 | B6: =INDEX('01_公共字段'!$B$6:$B$65,MATCH($A6,'01_公共字段'!$A$6:$A$65,0)) -> Item_ID | C6: =INDEX('01_公共字段'!$C$6:$C$65,MATCH($A6,'01_公共字段'!$A$6:$A$65,0)) -> 物品定义 | D6: 必填 | E6: 必填 | F6: 必填 | G6: 必填 | H6: 必填 | I6: 必填 | J6: =INDEX('01_公共字段'!$F$6:$F$65,MATCH($A6,'01_公共字段'!$A$6:$A$65,0)) -> 本表英文名是设计标识，需映射现有命名空间ID。 | K6: =INDEX('01_公共字段'!$H$6:$H$65,MATCH($A6,'01_公共字段'!$A$6:$A$65,0)) -> R3§十七 L527–558
A7: F002 | B7: =INDEX('01_公共字段'!$B$6:$B$65,MATCH($A7,'01_公共字段'!$A$6:$A$65,0)) -> Display_Name | C7: =INDEX('01_公共字段'!$C$6:$C$65,MATCH($A7,'01_公共字段'!$A$6:$A$65,0)) -> 物品定义 | D7: 必填 | E7: 必填 | F7: 必填 | G7: 必填 | H7: 必填 | I7: 必填 | J7: =INDEX('01_公共字段'!$F$6:$F$65,MATCH($A7,'01_公共字段'!$A$6:$A$65,0)) -> 名称不自动授予元素、反击、回血或必中。 | K7: =INDEX('01_公共字段'!$H$6:$H$65,MATCH($A7,'01_公共字段'!$A$6:$A$65,0)) -> B2§四十三 L1137–1154
A8: F003 | B8: =INDEX('01_公共字段'!$B$6:$B$65,MATCH($A8,'01_公共字段'!$A$6:$A$65,0)) -> Item_Category | C8: =INDEX('01_公共字段'!$C$6:$C$65,MATCH($A8,'01_公共字段'!$A$6:$A$65,0)) -> 物品定义 | D8: 必填 | E8: 必填 | F8: 必填 | G8: 必填 | H8: 必填 | I8: 必填 | J8: =INDEX('01_公共字段'!$F$6:$F$65,MATCH($A8,'01_公共字段'!$A$6:$A$65,0)) -> 阵盘本体不纳入；类别不决定攻击类型与战斗入口。 | K8: =INDEX('01_公共字段'!$H$6:$H$65,MATCH($A8,'01_公共字段'!$A$6:$A$65,0)) -> B1§二 L41–55；R3§一 L9–55
A9: F004 | B9: =INDEX('01_公共字段'!$B$6:$B$65,MATCH($A9,'01_公共字段'!$A$6:$A$65,0)) -> Grade | C9: =INDEX('01_公共字段'!$C$6:$C$65,MATCH($A9,'01_公共字段'!$A$6:$A$65,0)) -> 物品定义 | D9: 必填 | E9: 必填 | F9: 必填 | G9: 必填 | H9: 必填 | I9: 必填 | J9: =INDEX('01_公共字段'!$F$6:$F$65,MATCH($A9,'01_公共字段'!$A$6:$A$65,0)) -> 高品级不自动获得所有能力；仙品另有成长档案。 | K9: =INDEX('01_公共字段'!$H$6:$H$65,MATCH($A9,'01_公共字段'!$A$6:$A$65,0)) -> B2§四十四 L1155–1176
A10: F005 | B10: =INDEX('01_公共字段'!$B$6:$B$65,MATCH($A10,'01_公共字段'!$A$6:$A$65,0)) -> Width／Height | C10: =INDEX('01_公共字段'!$C$6:$C$65,MATCH($A10,'01_公共字段'!$A$6:$A$65,0)) -> 物品定义 | D10: 必填 | E10: 必填 | F10: 条件必填 | G10: 条件必填 | H10: 条件必填 | I10: 条件必填 | J10: =INDEX('01_公共字段'!$F$6:$F$65,MATCH($A10,'01_公共字段'!$A$6:$A$65,0)) -> 阵盘承载必填W/H；无Mask按完整矩形兼容。可选Occupied_Cell_Mask为配套设计规格；当前固定非连续形态仅授权风雷翅候选（6×2外包／8实占格）。仍不可旋转；部分翼不是独立2×2器具。 | K10: =INDEX('01_公共字段'!$H$6:$H$65,MATCH($A10,'01_公共字段'!$A$6:$A$65,0)) -> B1§十一 L280–304；R3§一 L9–55 t01-06第3份审查R3-B；2026-09-27；详见06第10／14表
A11: F006 | B11: =INDEX('01_公共字段'!$B$6:$B$65,MATCH($A11,'01_公共字段'!$A$6:$A$65,0)) -> Can_Rotate | C11: =INDEX('01_公共字段'!$C$6:$C$65,MATCH($A11,'01_公共字段'!$A$6:$A$65,0)) -> 全局规格 | D11: 全局规则 | E11: 全局规则 | F11: 全局规则 | G11: 全局规则 | H11: 全局规则 | I11: 全局规则 | J11: =INDEX('01_公共字段'!$F$6:$F$65,MATCH($A11,'01_公共字段'!$A$6:$A$65,0)) -> 横向与纵向需不同规格定义；高品级不默认豁免。 | K11: =INDEX('01_公共字段'!$H$6:$H$65,MATCH($A11,'01_公共字段'!$A$6:$A$65,0)) -> B1§四十八 L1131–1152
A12: F007 | B12: =INDEX('01_公共字段'!$B$6:$B$65,MATCH($A12,'01_公共字段'!$A$6:$A$65,0)) -> Allowed_Environments | C12: =INDEX('01_公共字段'!$C$6:$C$65,MATCH($A12,'01_公共字段'!$A$6:$A$65,0)) -> 物品定义 | D12: 必填 | E12: 必填 | F12: 必填 | G12: 必填 | H12: 必填 | I12: 必填 | J12: =INDEX('01_公共字段'!$F$6:$F$65,MATCH($A12,'01_公共字段'!$A$6:$A$65,0)) -> 可多个，不使用笼统MULTI_CONTEXT；不代替M03资格。 | K12: =INDEX('01_公共字段'!$H$6:$H$65,MATCH($A12,'01_公共字段'!$A$6:$A$65,0)) -> R3§一 L9–55
A13: F008 | B13: =INDEX('01_公共字段'!$B$6:$B$65,MATCH($A13,'01_公共字段'!$A$6:$A$65,0)) -> Use_Entry_Refs | C13: =INDEX('01_公共字段'!$C$6:$C$65,MATCH($A13,'01_公共字段'!$A$6:$A$65,0)) -> 物品定义 | D13: 必填 | E13: 必填 | F13: 必填 | G13: 必填 | H13: 必填 | I13: 必填 | J13: =INDEX('01_公共字段'!$F$6:$F$65,MATCH($A13,'01_公共字段'!$A$6:$A$65,0)) -> 不新增免占格快捷栏；BATTLE_CONSUMABLE不再混作环境枚举。 | K13: =INDEX('01_公共字段'!$H$6:$H$65,MATCH($A13,'01_公共字段'!$A$6:$A$65,0)) -> R3§一 L9–55
A14: F009 | B14: =INDEX('01_公共字段'!$B$6:$B$65,MATCH($A14,'01_公共字段'!$A$6:$A$65,0)) -> Consumption_Model | C14: =INDEX('01_公共字段'!$C$6:$C$65,MATCH($A14,'01_公共字段'!$A$6:$A$65,0)) -> 动作／成本引用 | D14: 必填 | E14: 必填 | F14: 必填 | G14: 必填 | H14: 必填 | I14: 必填 | J14: =INDEX('01_公共字段'!$F$6:$F$65,MATCH($A14,'01_公共字段'!$A$6:$A$65,0)) -> 会被消耗不代表不占格。 | K14: =INDEX('01_公共字段'!$H$6:$H$65,MATCH($A14,'01_公共字段'!$A$6:$A$65,0)) -> R3§一 L9–55
A15: F010 | B15: =INDEX('01_公共字段'!$B$6:$B$65,MATCH($A15,'01_公共字段'!$A$6:$A$65,0)) -> Unique_Rule_Ref | C15: =INDEX('01_公共字段'!$C$6:$C$65,MATCH($A15,'01_公共字段'!$A$6:$A$65,0)) -> 物品定义 | D15: 可选 | E15: 可选 | F15: 可选 | G15: 可选 | H15: 可选 | I15: 可选 | J15: =INDEX('01_公共字段'!$F$6:$F$65,MATCH($A15,'01_公共字段'!$A$6:$A$65,0)) -> 不因仙品名自动认定永远唯一。 | K15: =INDEX('01_公共字段'!$H$6:$H$65,MATCH($A15,'01_公共字段'!$A$6:$A$65,0)) -> B2§四十七 L1233–1293
A16: F011 | B16: =INDEX('01_公共字段'!$B$6:$B$65,MATCH($A16,'01_公共字段'!$A$6:$A$65,0)) -> Growth_Scheme_Ref | C16: =INDEX('01_公共字段'!$C$6:$C$65,MATCH($A16,'01_公共字段'!$A$6:$A$65,0)) -> 物品定义 | D16: 条件必填 | E16: 条件必填 | F16: 条件必填 | G16: 条件必填 | H16: 条件必填 | I16: 条件必填 | J16: =INDEX('01_公共字段'!$F$6:$F$65,MATCH($A16,'01_公共字段'!$A$6:$A$65,0)) -> 成长材料、阶段与解锁条件未定则显式待定。 | K16: =INDEX('01_公共字段'!$H$6:$H$65,MATCH($A16,'01_公共字段'!$A$6:$A$65,0)) -> B2§四十九 L1324–1355；R3§九 L266–300
A17: F012 | B17: =INDEX('01_公共字段'!$B$6:$B$65,MATCH($A17,'01_公共字段'!$A$6:$A$65,0)) -> Persistent_Instance_ID | C17: =INDEX('01_公共字段'!$C$6:$C$65,MATCH($A17,'01_公共字段'!$A$6:$A$65,0)) -> 持久个体 | D17: 持久个体条件 | E17: 持久个体条件 | F17: 持久个体条件 | G17: 持久个体条件 | H17: 持久个体条件 | I17: 持久个体条件 | J17: =INDEX('01_公共字段'!$F$6:$F$65,MATCH($A17,'01_公共字段'!$A$6:$A$65,0)) -> 普通无差异药品不强建复杂个体层；修改本件不能覆盖共享模板或其他成品。结果示例见05 PV08及本次修订记录。 | K17: =INDEX('01_公共字段'!$H$6:$H$65,MATCH($A17,'01_公共字段'!$A$6:$A$65,0)) -> R3§九；05 PV08；2026-09-27三词典朋友反馈；docs/t01-03至05_朋友反馈逐项修订_2026-09-27.md
... A65: F060 | B65: =INDEX('01_公共字段'!$B$6:$B$65,MATCH($A65,'01_公共字段'!$A$6:$A$65,0)) -> Field_Value_State | C65: =INDEX('01_公共字段'!$C$6:$C$65,MATCH($A65,'01_公共字段'!$A$6:$A$65,0)) -> 字段元数据 | D65: 全局规则 | E65: 全局规则 | F65: 全局规则 | G65: 全局规则 | H65: 全局规则 | I65: 全局规则 | J65: =INDEX('01_公共字段'!$F$6:$F$65,MATCH($A65,'01_公共字段'!$A$6:$A$65,0)) -> 空白不能冒充0；本表必填字段若未定仍标待定并阻止正式投产。 | K65: =INDEX('01_公共字段'!$H$6:$H$65,MATCH($A65,'01_公共字段'!$A$6:$A$65,0)) -> R3§十七 L527–558

Sheet 11_审查案例
A1: T01-04 | 审查案例
A2: 文本反查条件，包含审查提出的12项案例；没有把设计案例记成游戏测试通过。
A3: 返回说明 | B3: 30条记录 | 表头可筛选 | R3审查优先，原始行号L可回查14表
A5: 案例ID | B5: 类别 | C5: 输入／场景 | D5: 应有结果 | E5: 边界／复核点 | F5: 文档核对 | G5: 实现验证 | H5: 运行验证 | I5: 依据
A6: CHK01 | B6: 审查反向条件 | C6: 一叠符箓放入阵盘 | D6: 符箓上阵数量由玩家选择；可分叠，每叠独立占位和CD，同一叠共用一条CD；耗尽移除并停止邻接／类别贡献。 | E6: 符箓规则已确认；不自动推广至丹药和暗器的全部使用方式。 | F6: 按Q01～Q04完成文本核对 | G6: 未实现验证 | H6: 未运行 | I6: R3§十八 L559–594
A7: CHK02 | B7: 审查反向条件 | C7: 攻击符合法发动并扣数量后未命中 | D7: 不因未命中自动返还已提交数量。 | E7: 资格失败与发动后效果失败分开。 | F7: 文本条件已纳入 | G7: 未实现验证 | H7: 未运行 | I7: R3§十八 L559–594
A8: CHK03 | B8: 审查反向条件 | C8: 一次消耗3枚飞针 | D8: 数量成本为3不自动形成3次发动事件。 | E8: 命中次数与动作结构另行明确。 | F8: 文本条件已纳入 | G8: 未实现验证 | H8: 未运行 | I8: R3§十八 L559–594
A9: CHK04 | B9: 审查反向条件 | C9: 一次攻击另有一个附加伤害包 | D9: 不自动多扣基础费用或多记攻击发动。 | E9: 保留原有行动、结算轮和包的关系。 | F9: 文本条件已纳入 | G9: 未实现验证 | H9: 未运行 | I9: R3§十八 L559–594
A10: CHK05 | B10: 审查反向条件 | C10: 多元素弓 | D10: 基础类型PIERCE；元素分量按定义分配。 | E10: 不把同一100总伤复制成100火＋100雷。 | F10: 文本条件已纳入 | G10: 未实现验证 | H10: 未运行 | I10: R3§十八 L559–594
A11: CHK06 | B11: 审查反向条件 | C11: 仙品成长后战斗结束 | D11: 清本场运行值，保留持久成长阶段。 | E11: 本场择相与永久解锁元素集合不混层。 | F11: 文本条件已纳入 | G11: 未实现验证 | H11: 未运行 | I11: R3§十八 L559–594
A12: CHK07 | B12: 审查反向条件 | C12: 水择相甲4格＋火防具5格 | D12: 普通规则下角色主元素为火。 | E12: 仙甲指定角色元素须额外明确权限。 | F12: 文本条件已纳入 | G12: 未实现验证 | H12: 未运行 | I12: R3§十八 L559–594
A13: CHK08 | B13: 审查反向条件 | C13: 一次合法替换：80/100，新上限90 | D13: 结果80/90。 | E13: 不因内部移除中间态先截为0。 | F13: 文本条件已纳入 | G13: 未实现验证 | H13: 未运行 | I13: R3§十八 L559–594
A14: CHK09 | B14: 审查反向条件 | C14: 换装把当前护甲80截到60 | D14: 属于上限变化导致减少，不自动触发承伤收益。 | E14: 不能伪造成敌方攻击或护甲受击反击。 | F14: 文本条件已纳入 | G14: 未实现验证 | H14: 未运行 | I14: R3§十八 L559–594
A15: CHK10 | B15: 审查反向条件 | C15: 御兵术调用一把剑攻击 | D15: 被调用剑仍SLASH，费用与条件按武器。 | E15: 不能把法术父事件传播成子攻击SPELL。 | F15: 文本条件已纳入 | G15: 未实现验证 | H15: 未运行 | I15: R3§十八 L559–594
A16: CHK11 | B16: 审查反向条件 | C16: SPELL型符箓受到沉默 | D16: 按来源和控制Scope检查，不能仅凭SPELL封锁。 | E16: 道具禁用与法术沉默对象不能互换。 | F16: 文本条件已纳入 | G16: 未实现验证 | H16: 未运行 | I16: R3§十八 L559–594
... A41: CHK36 | B41: 风雷翅／Mask兼容 | C41: 普通玄品要求非连续占格 | D41: 不能由风雷翅候选自动获得此内容授权。 | E41: C037不被本次放宽。 | F41: 文本要求已纳入 | G41: 未实现验证 | H41: 未运行 | I41: t01-06第3份审查R3-B；2026-09-27；详见06第10／14表

Sheet 12_待定与外部衔接
A1: T01-04 | 待定与外部衔接
A2: 候选或具体资产待定集中记录；已明确的普通规则不重复追问，不自动采用建议。
A3: 返回说明 | B3: 11条记录 | 表头可筛选 | R3审查优先，原始行号L可回查14表
A5: 记录ID | B5: 分类 | C5: 规格／主题 | D5: 现行内容 | E5: 边界／不应推导 | F5: 记录性质 | G5: 依据
A6: 12-001 | B6: P01 | C6: 消耗品数量分配 | D6: 玩家选择符箓上阵数量，剩余留储物袋；可分叠到不同位置，各叠独立CD。 | E6: 不能由可堆叠推导；同一库存单位不可被多入口复制。 | F6: 已确认Q01／Q03 | G6: R3§二；2026-09-26逐项确认Q01～Q04；docs/sources/t01-04-器具类别与规格词典_逐项确认_2026-09-26.txt
A7: 12-002 | B7: P02 | C7: 消耗品CD组织 | D7: 同一位置的一叠符箓共用一条CD，每次发动按符箓规则消耗数量。 | E7: 同叠数量不增加并行CD；多个上阵堆叠各自独立CD。 | F7: 已确认Q02／Q03 | G7: R3§二；2026-09-26逐项确认Q01～Q04；docs/sources/t01-04-器具类别与规格词典_逐项确认_2026-09-26.txt
A8: 12-003 | B8: P03 | C8: 耗尽占位与身份 | D8: 符箓耗尽后该叠移除、腾出位置，不再提供邻接或类别效果。 | E8: 不默认留槽或保留类别；不自动补给。 | F8: 已确认Q04 | G8: R3§二；2026-09-26逐项确认Q01～Q04；docs/sources/t01-04-器具类别与规格词典_逐项确认_2026-09-26.txt
A9: 12-004 | B9: P04 | C9: 择相仙甲最终权限 | D9: 本次不设计具体仙甲；保留普通元素聚合，特殊最终指定权限留仙品正式设计。 | E9: 普通聚合已定；指定权不得默认附赠，等正式仙品设计。 | F9: 用户明确延后Q05 | G9: 2026-09-26逐项确认Q05／Q06；docs/sources/t01-04-器具类别与规格词典_逐项确认_2026-09-26.txt
A10: 12-005 | B10: P05 | C10: 敌方甲型并列 | D10: 敌方最高权重并列含身甲甲型时优先身甲，否则逐行从左到右扫描，首遇最高候选胜出。 | E10: 无身甲或最高并列不含身甲才用扫描后备；玩家对应后备为手选。 | F10: 用户确认：t01-08 Q02 | G10: 2026-09-26逐项确认Q05／Q06；docs/sources/t01-04-器具类别与规格词典_逐项确认_2026-09-26.txt；t01-08 Q02用户确认，2026-09-28
A11: 12-006 | B11: P06 | C11: 攻击模板与具体参数 | D11: 法器／符箓／暗器命中、暴击资格、费用、频率、元素分量与数量。 | E11: 不以类别或SPELL自动填95%／必中／暴击；参考例数不变成配置。 | F11: 待专项 | G11: B2§十三 L405–437；B2§二十七 L754–785；R3§十七 L527–558
A12: 12-007 | B12: P07 | C12: 旧资格条件迁移 | D12: 本次扫描的旧物理法术语句已逐项核对：主体类型已迁SPELL，指名本术强化保留；未发现必须扩为全部法术的已定通用条件。 | E12: 后续新增或发现真正依赖“穿刺法术”的独立条件，仍须逐条确认；不得自行扩大。 | F12: 本轮已复核；新增条件按资产审查 | G12: B2迁移§十八 L1919–1950；R3§十四 L439–474
A13: 12-008 | B13: P08 | C13: 跨文件回填 | D13: 当前处理结果以13_规则迁移记录F列逐目标记录为准；本页仅作入口，不另维护一份相互竞争的同步状态。 | E13: 原扫描内容与旧行号保留为历史；复核证据见本次修订记录。具体资产、仙甲额外权限、代码映射及运行验证仍分别处理。 | F13: 转13表当前状态；实现状态另记 | G13: B2迁移§十九 L1951–1968；R3§十四 L439–474
A14: 12-009 | B14: 外部衔接 | C14: 已关闭事项 | D14: 四攻击类型、SPELL四甲效率、九器型、盾反击、固定尺寸、无射程／耐久。 固定尺寸继续有效；风雷翅仅补固定外包尺寸与实际Mask的局部例外，见F005／05-018。 | E14: 不从旧候选或高品级权限重新开放。 | F14: 已明确边界 | G14: B1§五十三 L1272–1287；R3§十六 L498–526
A15: 12-010 | B15: 外部衔接 | C15: 已关闭防具算法 | D15: 双方均按身甲每实际占格权重2、其他防具每格权重1，汇总轻／重／灵；唯一最高直接采用。最高并列含身甲甲型时优先身甲，否则玩家选最高候选、敌方逐行从左至右扫描决胜；无防具为NONE。元素按实际占格、最高并列扫描；当前护甲超新上限立即截除，不回满。 | E15: Q02覆盖原甲型等权与直接决胜规则；防御元素、护甲池及仙品待专项边界不变。 | F15: 用户确认：t01-08 Q02 | G15: B1§二十八 L669–694；B1§三十三 L810–843；R3§十一 L344–385；R3§十二 L386–404；t01-08 Q02用户确认，2026-09-28
A16: 12-011 | B16: 外部衔接 | C16: 后续材料打造 | D16: 04输出类别、尺寸、攻击与防具规格，供后续材料与打造使用。 | E16: 本次没有启动t01-05或制作配方。 | F16: 已明确边界 | G16: B2§四十六 L1203–1232

Sheet 13_规则迁移记录
A1: T01-04 | 规则迁移记录
A2: C／D保留初稿目标、原扫描位置与旧摘录；F是文档当前状态的唯一记录（2026-09-27复核），G列实现状态及复核依据。初稿曾未回写，后续同步已复核；本表不表示游戏迁移或运行验证完成。
A3: 返回说明 | B3: 129条记录 | 表头可筛选 | R3审查优先，原始行号L可回查14表
A5: 迁移ID | B5: 类型 | C5: 目标／原位置 | D5: 旧说法／原扫描内容 | E5: 现行要求／迁移方向 | F5: 文档当前状态（2026-09-27复核） | G5: 实现状态／复核依据与边界 | H5: 依据
A6: MG001 | B6: 迁移规则 | C6: 核心01／攻击类型 | D6: 法术仍可叠物理甲型标签。 | E6: 适用伤害包SLASH／PIERCE／BLUNT／SPELL四选一；功法法术主体SPELL。 | F6: 已同步相应词典正文；字段／筛选／控制按04现行规则；本次外部记录复核通过 | G6: 本次未迁移／验证游戏；只迁主体，不迁法术调用的一切。 197项外部既有修改已与当前文件逐项匹配；详见本次修订记录 | H6: B2迁移§一 L1493–1512；R3§十四 L439–474
A7: MG002 | B7: 迁移规则 | C7: 核心01§5.3／SPELL效率 | D7: 纯属性法术对无／轻／重均100%。 | E7: 无甲110%、轻甲100%、重甲100%、灵甲90%。 | F7: 已同步相应词典正文；字段／筛选／控制按04现行规则；本次外部记录复核通过 | G7: 本次未迁移／验证游戏；沿既有修正组合方式；旧物理矩阵不改。 197项外部既有修改已与当前文件逐项匹配；详见本次修订记录 | H7: B2迁移§五 L1588–1612；R3§十五 L475–497
A8: MG003 | B8: 迁移规则 | C8: 01 M03-05／类型筛选 | D8: 物理标签可能被理解为SPELL再附穿刺等。 | E8: 类型字段四选一；物理三类条件只能匹配对应类型。 | F8: 已同步相应词典正文；字段／筛选／控制按04现行规则；本次外部记录复核通过 | G8: 本次未迁移／验证游戏；旧依赖某种物理法术的条件逐条复核，不能扩大。 197项外部既有修改已与当前文件逐项匹配；详见本次修订记录 | H8: B2迁移§十二 L1763–1793；R3§八 L244–265
A9: MG004 | B9: 迁移规则 | C9: 01 M06／完整攻击与直接伤害 | D9: 多包、直接伤害、完整攻击边界易混。 | E9: 分开攻击动作、伤害效果、甲型参与；引用既有行动／轮／包。 | F9: 已同步相应词典正文；字段／筛选／控制按04现行规则；本次外部记录复核通过 | G9: 本次未迁移／验证游戏；不新增攻击包、命中判定、发动次数或费用。 197项外部既有修改已与当前文件逐项匹配；详见本次修订记录 | H9: B2迁移§十三 L1794–1813；R3§五 L157–186；R3§七 L214–243
A10: MG005 | B10: 迁移规则 | C10: 01／03／旋转耐久射程 | D10: 旋转与耐久仍有预留描述。 | E10: 固定尺寸不可旋转；不建武器射程、耐久与修理。 | F10: 已同步01／03正文及联动缓存：固定尺寸不可旋转、耐久停用；阵盘空间规则保留；本次外部记录复核通过 | G10: 本次未迁移／验证游戏；不得删除阵盘Range／邻接／同行／距离能力。 197项外部既有修改已与当前文件逐项匹配；详见本次修订记录 | H10: B1§十一 L280–304；B1§十二 L305–326；B1§十三 L327–344；R3§十六 L498–526
A11: MG006 | B11: 迁移规则 | C11: 02／控制与监听 | D11: 把SPELL误当功法法术对象。 | E11: 禁用道具、沉默法术，依来源与Scope筛选。 | F11: 已同步相应词典正文；字段／筛选／控制按04现行规则；本次外部记录复核通过 | G11: 本次未迁移／验证游戏；SPELL符箓／法器不自动进入沉默。 197项外部既有修改已与当前文件逐项匹配；详见本次修订记录 | H11: R3§十六 L498–526
A12: MG007 | B12: 迁移规则 | C12: 03／择相甲案例 | D12: “选择本场身甲元素”可能被理解为指定最终角色元素。 | E12: 普通择相改自身贡献，再走聚合；最终指定权待仙品专案。 | F12: 已同步03案例与仙品对照：普通贡献参与聚合，最终指定权按Q05延后；本次外部记录复核通过 | G12: 本次未迁移／验证游戏；4水＋5火仍火；不默送规则例外。 197项外部既有修改已与当前文件逐项匹配；详见本次修订记录 | H12: R3§十 L301–343
A13: MG008 | B13: 迁移规则 | C13: 费用／数量 | D13: 效果成功才算数量消耗。 | E13: 约定支付节点整组提交，效果未命中不自动返还。 | F13: 已复核：04数量支付引用01成本组与提交／失败策略，未另建支付算法；本次外部记录复核通过 | G13: 本次未迁移／验证游戏；实际发动失败与支付失败、效果失败分开。 197项外部既有修改已与当前文件逐项匹配；详见本次修订记录 | H13: R3§三 L94–121
A14: MG009 | B14: 迁移规则 | C14: 物品字段／模板 | D14: 物品表、攻击模板和独立攻击规格重复存参数。 | E14: 规则模板管通用判定，动作／效果管具体参数，运行保存当前值。 | F14: 已复核：04字段按模板／动作参数／运行值分权威位置；生产接口映射留实现；本次外部记录复核通过 | G14: 本次未迁移／验证游戏；示例英文名需映射现有接口，不强行当已发布ID。 197项外部既有修改已与当前文件逐项匹配；详见本次修订记录 | H14: R3§十七 L527–558
A15: MG010 | B15: 法术主体受影响 | C15: 庚锋剑 | D15: 旧主体物理甲型身份：SLASH；元素金 | E15: 主体Attack_Type=SPELL；元素仍金；来源仍功法法术。 | F15: 已回填七系法术设计正文及核心对应说明；生产资产／游戏未改；本次外部记录复核通过 | G15: 本次未迁移／验证游戏；主体伤害、CD与费用保持；原按物理类型过滤的资格失配需复核。 197项外部既有修改已与当前文件逐项匹配；详见本次修订记录 | H15: docs/metal-cultivation-design-2026-09-22.md 原扫描L558；R3§十四 L439–474
A16: MG011 | B16: 法术主体受影响 | C16: 玄庚归一剑 | D16: 旧主体物理甲型身份：SLASH；元素金 | E16: 主体Attack_Type=SPELL；元素仍金；来源仍功法法术。 | F16: 已回填七系法术设计正文及核心对应说明；生产资产／游戏未改；本次外部记录复核通过 | G16: 本次未迁移／验证游戏；主体伤害、CD与费用保持；原按物理类型过滤的资格失配需复核。 197项外部既有修改已与当前文件逐项匹配；详见本次修订记录 | H16: docs/metal-cultivation-design-2026-09-22.md 原扫描L652；R3§十四 L439–474
... A135: WING-M01 | B135: 本轮规格补充 | C135: 01空间／04 F005及视图／02控制／03仙品／05专项 | D135: 04旧F005曾把固定W×H直接当占格权威；缺非连续单实例候选说明。 | E135: 矩形默认填满；风雷翅Mask实占8格一件；跨表只同步已明确需求及待定边界。 | F135: 已同步本轮五份词典；明细见06编制记录与修改证据 | G135: 游戏放置、碰撞、点击、拖拽、存取和战斗均未迁移／验证；CD模式及费用不代定。 | H135: t01-06第3份审查R3-B；2026-09-27；详见06第10／14表

Sheet 14_原文与出处
A1: T01-04 | 原文与出处
A2: 原字节来源档案＋全部非空原始行；B1／B2为新版两批，R3审查修正优先。原文错误保留追溯。
A3: 返回说明 | B3: 2334条记录 | 表头可筛选 | R3审查优先，原始行号L可回查14表
A5: 来源ID | B5: 来源名称 | C5: 原始行号 | D5: 原文／档案信息 | E5: 适用性质
A6: B1 | B6: 新版第1批 | C6: 档案 | D6: docs/sources/t01-04-器具类别与规格词典_新版第1批_2026-09-26.txt SHA-256: a81dbb8ec277eef5aad824b86779a5082947e79ac335c039be6b1395d5bcbad1 | E6: 新版两批作为来源，第三份审查优先；原文不直接当生产数据。
A7: B1 | B7: 新版第1批 | C7: 1 | D7: 确认，逻辑已经闭合。**`t01-04`从这一版重新起算，前面两批只保留为讨论历史，不再作为Codex汇总正文。** | E7: 原文保留；现行内容查正文，冲突处理查15表。
A8: B1 | B8: 新版第1批 | C8: 3 | D8: 另外你要求的我也记住了：**新版第2批收尾时，我会单独给一段《法术型攻击规则变更清单》**，专门写给Codex，明确哪些旧规则要覆盖、哪些Excel/核心文档需要同步修改，避免它只更新04却留下01和核心规则里的旧“双标签法术”。 | E8: 原文保留；现行内容查正文，冲突处理查15表。
A9: B1 | B9: 新版第1批 | C9: 5 | D9: 先把你刚确认的身甲元素判定完整落地： | E9: 原文保留；现行内容查正文，冲突处理查15表。
A10: B1 | B10: 新版第1批 | C10: 7 | D10: > 先按上阵防具的占格数统计七种元素贡献；无属性防具不参与元素统计。 | E10: 原文保留；现行内容查正文，冲突处理查15表。
A11: B1 | B11: 新版第1批 | C11: 8 | D11: > 唯一最高元素直接成为当前身甲元素。 | E11: 原文保留；现行内容查正文，冲突处理查15表。
A12: B1 | B12: 新版第1批 | C12: 9 | D12: > 若多个最高元素并列，则按阵盘扫描顺序，从左上 `(1,1)` 开始，**每行从左到右，再从上到下**扫描；遇到的第一件“元素属于并列最高集合”的有属性防具，其元素成为当前身甲元素。 | E12: 原文保留；现行内容查正文，冲突处理查15表。
A13: B1 | B13: 新版第1批 | C13: 10 | D13: > 若没有任何有属性防具，则当前身甲为无属性。 | E13: 原文保留；现行内容查正文，冲突处理查15表。
A14: B1 | B14: 新版第1批 | C14: 12 | D14: 多格防具在扫描到它占据的第一个格时即视为遇到该防具，不重复判断。 | E14: 原文保留；现行内容查正文，冲突处理查15表。
A15: B1 | B15: 新版第1批 | C15: 14 | D15: 下面重新开始。 | E15: 原文保留；现行内容查正文，冲突处理查15表。
A16: B1 | B16: 新版第1批 | C16: 16 | D16: # `t01-04-器具类别与规格词典` | E16: 原文保留；现行内容查正文，冲突处理查15表。
A17: B1 | B17: 新版第1批 | C17: 17 | D17: ## 新版第1批｜全局规格＋武器＋防具 v1.0基线 | E17: 原文保留；现行内容查正文，冲突处理查15表。
A18: B1 | B18: 新版第1批 | C18: 19 | D18: --- | E18: 原文保留；现行内容查正文，冲突处理查15表。
... A813: B1 | B813: 新版第1批 | C813: 1332 | D813: 这样Codex不会遗漏跨文件修改。 | E813: 原文保留；现行内容查正文，冲突处理查15表。
A814: B2 | B814: 新版第2批含迁移清单 | C814: 档案 | D814: docs/sources/t01-04-器具类别与规格词典_新版第2批含迁移清单_2026-09-26.txt SHA-256: ea05b72339e7bc0ba7f270d2ec5b8c4c38e46ba5c36f553ede384ae6ef337042 | E814: 新版两批作为来源，第三份审查优先；原文不直接当生产数据。
A815: B2 | B815: 新版第2批含迁移清单 | C815: 1 | D815: 好。新版 `t01-04` 到这一批就可以完整收束。我会按刚才重新确定的底层口径来做，不再继承旧版第一、第二批中已经撤销的部分。 | E815: 原文保留；现行内容查正文，冲突处理查15表。
A816: B2 | B816: 新版第2批含迁移清单 | C816: 3 | D816: 这一批包括两部分： | E816: 原文保留；现行内容查正文，冲突处理查15表。
A817: B2 | B817: 新版第2批含迁移清单 | C817: 5 | D817: > **A. `t01-04`新版第2批：法器＋丹药＋符箓＋暗器＋全04终审** | E817: 原文保留；现行内容查正文，冲突处理查15表。
A818: B2 | B818: 新版第2批含迁移清单 | C818: 6 | D818: > **B. 独立章节：《法术型攻击规则迁移清单｜给Codex》** | E818: 原文保留；现行内容查正文，冲突处理查15表。
A819: B2 | B819: 新版第2批含迁移清单 | C819: 8 | D819: --- | E819: 原文保留；现行内容查正文，冲突处理查15表。
A820: B2 | B820: 新版第2批含迁移清单 | C820: 10 | D820: # t01-04｜器具类别与规格词典 | E820: 原文保留；现行内容查正文，冲突处理查15表。
A821: B2 | B821: 新版第2批含迁移清单 | C821: 11 | D821: ## 新版第2批｜法器＋丹药＋符箓＋暗器＋整体终审 v1.0基线 | E821: 原文保留；现行内容查正文，冲突处理查15表。
A822: B2 | B822: 新版第2批含迁移清单 | C822: 13 | D822: # 一、先重新确认六类物品的系统身份 | E822: 原文保留；现行内容查正文，冲突处理查15表。
A823: B2 | B823: 新版第2批含迁移清单 | C823: 15 | D823: 经过新版两批，目前六类可以正式整理为： | E823: 原文保留；现行内容查正文，冲突处理查15表。
A824: B2 | B824: 新版第2批含迁移清单 | C824: 17 | D824: | 类别 | 是否持续上阵 | 核心身份 | 默认资源模型 | | E824: 原文保留；现行内容查正文，冲突处理查15表。
A825: B2 | B825: 新版第2批含迁移清单 | C825: 18 | D825: |---|---:|---|---| | E825: 原文保留；现行内容查正文，冲突处理查15表。
A826: B2 | B826: 新版第2批含迁移清单 | C826: 19 | D826: | **武器** | 是 | 持续轮转攻击器具 | CD＋灵力/体力等 | | E826: 原文保留；现行内容查正文，冲突处理查15表。
... A1998: B2 | B1998: 新版第2批含迁移清单 | C1998: 1992 | D1998: 接下来就可以让Codex先把`t01-04`汇总，同时按上面的独立迁移章节去扫描旧规则。之后进入 `t01-05` 时，我们就可以真正开始做**材料与打造体系**了。 | E1998: 原文保留；现行内容查正文，冲突处理查15表。
A1999: R3 | B1999: 第3份审查修正 | C1999: 档案 | D1999: docs/sources/t01-04-器具类别与规格词典_第3份审查修正_2026-09-26.txt SHA-256: b1ad8e6e45bc04f8671f20dbd7654f466c107b4c830005da16471cde69c6f9e5 | E1999: 新版两批作为来源，第三份审查优先；原文不直接当生产数据。
A2000: R3 | B2000: 第3份审查修正 | C2000: 1 | D2000: **有几处需要修正和补齐，但这次不需要再从头重写。**新版04已经把你刚确认的攻击类型、武器器型、防具元素和换装规则放到了正确的位置。现在的问题主要在**不同规格之间的衔接**，尤其是消耗品、伤害包、来源身份，以及迁移清单的操作范围。 | E2000: 原文保留；现行内容查正文，冲突处理查15表。
A2001: R3 | B2001: 第3份审查修正 | C2001: 3 | D2001: 这次我审的是**新版两批正文＋独立迁移清单**，并对照了已上传的01、02词典；不是在审查尚未提供的04 Excel。 | E2001: 原文保留；现行内容查正文，冲突处理查15表。
A2002: R3 | B2002: 第3份审查修正 | C2002: 5 | D2002: 先明确：**你已经确认的四攻击类型、法术型效率、九种武器器型、盾反击为钝击、防具元素聚合、护甲换装截上限、不可旋转、无射程、无耐久，这轮都不重新打开讨论。** | E2002: 原文保留；现行内容查正文，冲突处理查15表。
A2003: R3 | B2003: 第3份审查修正 | C2003: 7 | D2003: 下面是建议交给Codex合并的审校内容。 | E2003: 原文保留；现行内容查正文，冲突处理查15表。
A2004: R3 | B2004: 第3份审查修正 | C2004: 9 | D2004: # 一、最先要改：消耗品“会被消耗”，不等于“不在阵盘上” | E2004: 原文保留；现行内容查正文，冲突处理查15表。
A2005: R3 | B2005: 第3份审查修正 | C2005: 11 | D2005: 新版第2批的最终矩阵，把丹药、符箓、暗器的“持续上阵”统一填成了“否”。**这个表述不准确，应撤回。** | E2005: 原文保留；现行内容查正文，冲突处理查15表。
A2006: R3 | B2006: 第3份审查修正 | C2006: 13 | D2006: 它混淆了两件事： | E2006: 原文保留；现行内容查正文，冲突处理查15表。
...

Sheet 15_审查修正与覆盖
A1: T01-04 | 审查修正与覆盖
A2: 新版两批＋第3份审查合编 · 2026-09-26 | 类型／元素／来源分开；候选与未决不当定案
A3: 返回说明 | B3: 164条记录 | 表头可筛选 | R3审查优先，原始行号L可回查14表
A5: 核对ID | B5: 记录类型 | C5: 主题／原章节 | D5: 现行处理 | E5: 落点 | F5: 处理状态 | G5: 依据
A6: R01 | B6: 审查修正 | C6: 消耗品上阵与消耗分开 | D6: 撤回六类矩阵中消耗品一律不持续上阵；环境集合与已确认入口分列。 | E6: 00／01／06／10 | F6: 已纳入04；未决按12表保留 | G6: R3§一 L9–55
A7: R02 | B7: 审查修正 | C7: 消耗品库存、上阵和CD | D7: 库存、本场可用、成本与实例分层；Q01～Q04确认自选数量、每叠一条CD、可分叠、耗尽移除。 | E7: 01／06／12 | F7: 已按用户答复关闭P01～P03 | G7: R3§二；2026-09-26逐项确认Q01～Q04；docs/sources/t01-04-器具类别与规格词典_逐项确认_2026-09-26.txt
A8: R03 | B8: 审查修正 | C8: 成功使用与支付节点 | D8: 成本在约定节点整组提交；闪避等后果不自动退款；使用条件先检查。 | E8: 06／11 | F8: 已纳入04；未决按12表保留 | G8: R3§三 L94–121
A9: R04 | B9: 审查修正 | C9: 来源类别与行为身份 | D9: 防具＋反击同时存在；盾反击钝击只约束盾。 | E9: 02／04／10 | F9: 已纳入04；未决按12表保留 | G9: R3§四 L122–156
A10: R05 | B10: 审查修正 | C10: 行动、轮、包与元素分量 | D10: 多包不自动多次发动／命中／支付；数量与次数独立。 | E10: 02／11 | F10: 已纳入04；未决按12表保留 | G10: R3§五 L157–186
A11: R06 | B11: 审查修正 | C11: 多元素攻击保留 | D11: 单件防具单值，攻击可合法多元素；真实伤害分配不可复制总量。 | E11: 01／02／03 | F11: 已纳入04；未决按12表保留 | G11: R3§六 L187–213
A12: R07 | B12: 审查修正 | C12: 无攻击不等于无伤害 | D12: 分创建攻击、伤害效果、是否读甲型；状态跳伤和资源变化不套假攻击。 | E12: 01／02／11 | F12: 已纳入04；未决按12表保留 | G12: R3§七 L214–243
A13: R08 | B13: 审查修正 | C13: 攻击类型可供过滤 | D13: 主要管甲型，也可由明确机制读取；不决定来源、命中、暴击与共鸣。 | E13: 02／13 | F13: 已纳入04；未决按12表保留 | G13: R3§八 L244–265
A14: R09 | B14: 审查修正 | C14: 持久个体与战斗数据 | D14: 成长与解锁保存在持久层，堆叠要求兼容。 | E14: 01／06／11 | F14: 已纳入04；未决按12表保留 | G14: R3§九 L266–300
A15: R10 | B15: 审查修正 | C15: 择相甲与普通聚合 | D15: 普通聚合保留；Q05明确具体仙甲及最终指定权留后续。 | E15: 04／11／12 | F15: 用户明确延后特殊权限 | G15: 2026-09-26逐项确认Q05／Q06；docs/sources/t01-04-器具类别与规格词典_逐项确认_2026-09-26.txt
A16: R11 | B16: 审查修正 | C16: 换装原子结果与截除原因 | D16: 一次替换只结最终集合；两次操作分次结；截甲不触发承伤。 | E16: 04／11 | F16: 已纳入04；未决按12表保留 | G16: R3§十一 L344–385
... A169: R3-S18 | B169: 原文逐节覆盖 | C169: 这次应该增加的反向检查案例 | D169: 按本次审查修正归入现行正文；完整原文保留14表。 | E169: 11_审查案例 | F169: 已归类；原文建议不自动变成已定 | G169: R3§十八 L559–594
